Workbook

Sheet Figs
R4: At min measured temp
A5: Salt Composition | B5: Melting Temp (K) | C5: Min Measured Temp (K) | D5: Gheribi-KTCPÎ» at Melt Temp (W/m-K) | E5: Gheribi-KTCPÎ», Mix Data at Melt Temp (W/m-K) | F5: Gheribi-KT-Emp at Melt Temp (W/m-K) | G5: Gheribi-KT-Emp-Mix at Melt Temp (W/m-K) | H5: Gheribi-KT24 at Melt Temp (W/m-K) | I5: Gheribi-KT24, Mix Data at Melt Temp (W/m-K) | J5: Zhao-PGM at Melt Temp (W/m-K) | K5: Zhao-PGM, Mix Data at Melt Temp (W/m-K) | L5: Present Model at Melt Temp (W/m-K) | M5: Present Model, Mix Data at Melt Temp (W/m-K) | N5: Present Model-VelCorr at Melt Temp (W/m-K) | O5: Bridgman at Melt Temp (W/m-K) | P5: Chapman-Enskog at Melt Temp (W/m-K) | Q5: Ideal at Melt Temp (W/m-K) | R5: Gheribi-KT-k_min (W/m-K) | S5: Gheribi-KT-k_min, Mix Data (W/m-K) | T5: Gheribi-KT-Emp (W/m-K) | U5: Gheribi-KT-Emp-Mix (W/m-K) | V5: Gheribi-KT24 | W5: % Dev | X5: Gheribi-KT24, Mix Data (W/m-K) | Y5: Zhao-PGM | Z5: % Dev | AA5: Zhao-PGM, Mix Data (W/m-K) | AB5: Present Model (W/m-K) | AC5: Present Model, Mix Data (W/m-K) | AD5: Present Model-VelCorr (W/m-K) | AE5: Bridgman (W/m-K) | AF5: Chapman-Enskog (W/m-K) | AG5: Ideal (W/m-K) | AH5: TC Experimental (W/m-K) | AI5: Exp. Reference | AJ5: TC MSTDB (W/m-K) | AK5: MSTDB Reference
A6: 0.725LiF-0.265BeF2-0.01UF4 | B6: 723 | C6: 882 | D6: 0.36678342 | F6: 0.39875169 | H6: 0.69535872 | J6: 0.78147755 | Q6: 1.3452379 | R6: 0.3588139 | T6: 0.39008756 | V6: 0.67741221 | W6: =ABS(($AH6-V6)/$AH6) -> 0.11985885 | Y6: 0.74096563 | Z6: =ABS(($AH6-Y6)/$AH6) -> 0.037285823 | AG6: 1.3016119 | AH6: 0.76966315 | AI6: 0.725LiF-0.265BeF2-0.01UF4 (Bobrova, 2023)
A7: 0.72LiF-0.26BeF2-0.02UF4 | B7: 723 | C7: 832 | D7: -0.1376048 | F7: -0.030277384 | H7: 0.56670078 | J7: 0.74820769 | Q7: 1.3360263 | R7: -0.13553534 | T7: -0.029822039 | V7: 0.55550594 | W7: =ABS(($AH7-V7)/$AH7) -> 0.2232675 | Y7: 0.72228652 | Z7: =ABS(($AH7-Y7)/$AH7) -> 0.009932345 | AG7: 1.3058004 | AH7: 0.71518308 | AI7: 0.72LiF-0.26BeF2-0.02UF4 (Bobrova, 2023)
A8: 0.63NaCl-0.37UCl3 | B8: 750 | C8: 802 | D8: 0.12623785 | F8: 0.13414681 | H8: 0.11469448 | J8: 0.30786468 | Q8: 0.45071802 | R8: 0.12332465 | T8: 0.13105109 | V8: 0.11214895 | W8: =ABS(($AH8-V8)/$AH8) -> 0.55163115 | Y8: 0.29987597 | Z8: =ABS(($AH8-Y8)/$AH8) -> 0.19889702 | AG8: 0.44198046 | AH8: 0.25012655 | AI8: 63NaCl-37UCl3 (Termini, 2024)
A9: 0.658NaCl-0.342UCl3 | B9: 750 | C9: 869.15 | D9: 0.11100367 | F9: 0.12242465 | H9: 0.11113907 | J9: 0.3107182 | Q9: 0.45854797 | R9: 0.10497932 | T9: 0.11578047 | V9: 0.10540828 | W9: =ABS(($AH9-V9)/$AH9) -> 0.49064414 | Y9: 0.29112923 | Z9: =ABS(($AH9-Y9)/$AH9) -> 0.40680012 | AG9: 0.43759544 | AH9: 0.20694427 | AI9: 65.8NaCl-34.2UCl3 (Rose, 2023)
A10: 0.712LiF-0.23BeF2-0.05ZrF4-0.008UF4 | B10: 723 | C10: 785.88122 | D10: 0.11450404 | F10: 0.21993592 | H10: 0.46469757 | J10: 0.72737521 | Q10: 1.322616 | R10: 0.11327849 | T10: 0.21758192 | V10: 0.46141777 | W10: =ABS(($AH10-V10)/$AH10) -> 0.63105706 | Y10: 0.71241195 | Z10: =ABS(($AH10-Y10)/$AH10) -> 0.43036576 | AG10: 1.3049988 | AH10: 1.2506481 | AI10: 0.712LiF-0.23BeF2-0.05ZrF4-0.008UF4 (Rosenthal, 1969)
A11: 0.675LiF-0.2BeF2-0.12ThF4-0.005UF4 | B11: 723 | C11: 811.82664 | D11: -0.68451425 | F11: -0.44302642 | H11: 0.11179706 | J11: 0.59758238 | Q11: 1.2528784 | R11: -0.67658391 | T11: -0.4378938 | V11: 0.10753765 | W11: =ABS(($AH11-V11)/$AH11) -> 0.91498381 | Y11: 0.58317547 | Z11: =ABS(($AH11-Y11)/$AH11) -> 0.53895815 | AG11: 1.2304066 | AH11: 1.2649079 | AI11: 0.675LiF-0.20BeF2-0.12ThF4-0.005UF4 (Rosenthal, 1969)
A12: 0.28NaF-0.42KF-0.3UF4 | B12: 878 | C12: 1023 | D12: 0.11971805 | F12: 0.13951714 | H12: 0.15108649 | J12: 0.3836312 | Q12: 0.62595318 | R12: 0.11574283 | T12: 0.1348845 | V12: 0.14300503 | W12: =ABS(($AH12-V12)/$AH12) -> 0.72446699 | Y12: 0.35966985 | Z12: =ABS(($AH12-Y12)/$AH12) -> 0.30701098 | AG12: 0.59800659 | AH12: 0.51901235 | AI12: 0.42KF-0.28NaF-0.30UF4 (Rudenko, 2024)
A13: 0.24NaF-0.36KF-0.4UF4 | B13: 878 | C13: 1073 | D13: 0.18851371 | F13: 0.19057901 | H13: 0.15917343 | J13: 0.36475139 | Q13: 0.57924146 | R13: 0.18133469 | T13: 0.18332134 | V13: 0.15118127 | W13: =ABS(($AH13-V13)/$AH13) -> 0.70253623 | Y13: 0.33864101 | Z13: =ABS(($AH13-Y13)/$AH13) -> 0.33369106 | AG13: 0.54654293 | AH13: 0.50823423 | AI13: 0.36KF-0.24NaF-0.40UF4 (Rudenko, 2024)
A14: 0.2NaF-0.3KF-0.5UF4 | B14: 878 | C14: 1073 | D14: 0.23423673 | F14: 0.21977532 | H14: 0.17464564 | J14: 0.34979074 | Q14: 0.53252974 | R14: 0.22647803 | T14: 0.21249562 | V14: 0.16870277 | W14: =ABS(($AH14-V14)/$AH14) -> 0.57854411 | Y14: 0.32853146 | Z14: =ABS(($AH14-Y14)/$AH14) -> 0.17925758 | AG14: 0.50439481 | AH14: 0.40028571 | AI14: 0.30KF-0.20NaF-0.50UF4 (Rudenko, 2024)
A15: 0.712LiF-0.23BeF2-0.05ZrF4-0.008UF4 | B15: 735 | C15: 785.88122 | D15: 0.11450404 | F15: 0.21993592 | H15: 0.46469757 | J15: 0.72737521 | L15: 0.72737521 | Q15: 1.322616 | R15: 0.11327849 | T15: 0.21758192 | V15: 0.46141777 | W15: =ABS(($AH15-V15)/$AH15) -> 0.63105706 | Y15: 0.71241195 | Z15: =ABS(($AH15-Y15)/$AH15) -> 0.43036576 | AB15: 0.71241195 | AG15: 1.3049988 | AH15: 1.2506481 | AI15: 0.465LiF-0.115NaF-0.42KF (Merritt, 2022),0.465LiF-0.115NaF-0.42KF (Gallagher, 2022),0.465LiF-0.115NaF-0.42KF (Rudenko, 2022)
A16: 0.73LiF-0.27BeF2 | B16: 723 | C16: 884 | D16: 1.1694201 | F16: 1.0901411 | H16: 1.0169508 | J16: 0.81942429 | Q16: 1.3544496 | R16: 1.143821 | T16: 1.0662774 | V16: 0.99333381 | W16: =ABS(($AH16-V16)/$AH16) -> 0.095706389 | Y16: 0.77570442 | Z16: =ABS(($AH16-Y16)/$AH16) -> 0.1443518 | AG16: 1.310565 | AH16: 0.90656933 | AI16: 0.73LiF-0.27BeF2 (Bobrova, 2023)
A17: 0.66LiF-0.34BeF2 | B17: 733 | C17: 884 | D17: 1.1321639 | E17: 1.6545464 | F17: 1.0327876 | G17: 1.5087682 | H17: 1.0025337 | I17: 1.518486 | J17: 0.77455399 | K17: 1.194875 | R17: 1.1128792 | S17: 1.6155238 | T17: 1.0151956 | U17: 1.4731838 | V17: 0.98447068 | W17: =ABS(($AH17-V17)/$AH17) -> 0.080050058 | X17: 1.4811883 | Y17: 0.74095938 | Z17: =ABS(($AH17-Y17)/$AH17) -> 0.18710304 | AA17: 1.1045267 | AH17: 0.91150468 | AI17: 0.73LiF-0.27BeF2 (Bobrova, 2023) | AJ17: 1.1 | AK17: Rosenthal 1969 [122]
A18: 0.4NaF-0.6KF | B18: 1000 | D18: 0.67334765 | F18: 0.67819467 | H18: 0.64214261 | J18: 0.4684939 | Q18: 0.73423486 | R18: 0.67334765 | T18: 0.67819467 | V18: 0.64214261 | W18: =ABS(($AH18-V18)/$AH18) -> 0.082653417 | Y18: 0.4684939 | Z18: =ABS(($AH18-Y18)/$AH18) -> 0.330723 | AG18: 0.73423486 | AH18: =AJ18 -> 0.7 | AJ18: 0.7 | AK18: Rudenko 2024 [178]
A19: 0.465LiF-0.115NaF-0.42KF | B19: 735 | C19: 742.4 | D19: 0.75544862 | F19: 0.76389433 | G19: 1.0241817 | H19: 0.6954626 | I19: 0.90509687 | J19: 0.65005469 | K19: 0.77295464 | Q19: 1.0993871 | R19: 0.75296021 | T19: 0.7613781 | U19: 1.0203939 | V19: 0.69317886 | W19: =ABS(($AH19-V19)/$AH19) -> 0.1226106 | X19: 0.90175871 | Y19: 0.6459406 | Z19: =ABS(($AH19-Y19)/$AH19) -> 0.1824023 | AA19: 0.76685546 | AG19: 1.0964289 | AH19: 0.79004699 | AI19: 0.465LiF-0.115NaF-0.42KF (Merritt, 2022),0.465LiF-0.115NaF-0.42KF (Gallagher, 2022),0.465LiF-0.115NaF-0.42KF (Rudenko, 2022)
A20: 0.2046NaCl-0.4131KCl-0.3823MgCl2 | B20: 700 | C20: 722.73281 | D20: 0.42631828 | F20: 0.39868607 | G20: 0.35511104 | H20: 0.39369828 | I20: 0.38744636 | J20: 0.34234495 | Q20: 0.47430496 | R20: 0.42244769 | T20: 0.39506636 | U20: 0.35163381 | V20: 0.39011154 | W20: =ABS(($AH20-V20)/$AH20) -> 0.17217062 | X20: 0.3836404 | Y20: 0.33784078 | Z20: =ABS(($AH20-Y20)/$AH20) -> 0.28309088 | AG20: 0.47038278 | AH20: 0.47124631 | AI20: 0.2046NaCl-0.4131KCl-0.3823MgCl2 (Wang, 2021)
A21: 0.345NaF-0.59KF-0.065MgF2 | B21: 958 | C21: 993.01378 | D21: 0.6779149 | F21: 0.67261166 | H21: 0.57197135 | I21: 0.59758621 | J21: 0.4860452 | K21: 0.49336011 | Q21: 0.74453173 | R21: 0.66907211 | T21: 0.66383804 | V21: 0.56448951 | W21: =ABS(($AH21-V21)/$AH21) -> 0.26308813 | X21: 0.58988275 | Y21: 0.47418606 | Z21: =ABS(($AH21-Y21)/$AH21) -> 0.38097462 | AA21: 0.48283679 | AG21: 0.73580725 | AH21: 0.76602038 | AI21: 0.345NaF-0.59KF-0.065MgF2 (Rudenko, 2024)
A22: 1.0LiCl | B22: 883 | C22: 965.57734 | D22: 0.68568905 | F22: 0.72519297 | H22: 0.68631947 | J22: 0.41038419 | Q22: 0.68524115 | R22: 0.66731827 | T22: 0.70576381 | V22: 0.6679318 | W22: =ABS(($AH22-V22)/$AH22) -> 0.018943205 | Y22: 0.3868412 | Z22: =ABS(($AH22-Y22)/$AH22) -> 0.40986607 | AG22: 0.66685348 | AH22: 0.65551426 | AI22: LiCl (Nagasaka, 1992)
A23: 1.0NaCl | B23: 1073.8 | C23: 1169.4387 | D23: 0.48765041 | F23: 0.492992 | H23: 0.48681288 | J23: 0.31017075 | Q23: 0.48673467 | R23: 0.46764534 | T23: 0.4727678 | V23: 0.46684217 | W23: =ABS(($AH23-V23)/$AH23) -> 0.11307557 | Y23: 0.28504925 | Z23: =ABS(($AH23-Y23)/$AH23) -> 0.45845264 | AG23: 0.46682997 | AH23: 0.5263607 | AI23: NaCl (Nagasaka 1992)
A24: 1.0KCl | B24: 1042.7 | C24: 1052.1639 | D24: 0.37448386 | F24: 0.39772402 | H24: 0.3742357 | J24: 0.26186835 | Q24: 0.37411661 | R24: 0.37273884 | T24: 0.39587071 | V24: 0.37249184 | W24: =ABS(($AH24-V24)/$AH24) -> 0.013588159 | Y24: 0.25964867 | Z24: =ABS(($AH24-Y24)/$AH24) -> 0.29346958 | AG24: 0.37237546 | AH24: 0.36749822 | AI24: KCl (Harada, 1992),KCl (Nagasaka, 1992)
A25: 1.0LiF | B25: 1121.2 | C25: 1121.2 | D25: 1.3492012 | F25: 1.4344247 | H25: 1.3498415 | J25: 0.80194503 | Q25: 1.3569764 | R25: 1.3492012 | T25: 1.4344247 | V25: 1.3498415 | W25: =ABS(($AH25-V25)/$AH25) -> 0.071577209 | Y25: 0.80194503 | Z25: =ABS(($AH25-Y25)/$AH25) -> 0.36337265 | AG25: 1.3569764 | AH25: 1.2596773 | AI25: LiF (Golyshev, 1982),LiF (Golyshev, 1983),LiF (Golyshev, 1992),LiF (Smirnov, 1987),LiF (Khlebnikov, 1981)
A26: 1.0NaF | B26: 1268 | C26: 1276.2108 | D26: 0.84228951 | F26: 0.90253851 | H26: 0.8422681 | J26: 0.53047696 | Q26: 0.84054676 | R26: 0.83982795 | T26: 0.89990088 | V26: 0.83980661 | W26: =ABS(($AH26-V26)/$AH26) -> 0.28778769 | Y26: 0.52656453 | Z26: =ABS(($AH26-Y26)/$AH26) -> 0.55343797 | AG26: 0.83809041 | AH26: 1.179152 | AI26: NaF (Smirnov, 1987),NaF (Polyakov, 1975)
A27: 1.0KF | B27: 1131.2 | C27: 1130.597 | D27: 0.58239325 | F27: 0.56777343 | H27: 0.58268228 | J27: 0.36409719 | Q27: 0.58236909 | R27: 0.58239325 | T27: 0.56777343 | V27: 0.58268228 | W27: =ABS(($AH27-V27)/$AH27) -> 0.064372614 | Y27: 0.36409719 | Z27: =ABS(($AH27-Y27)/$AH27) -> 0.41536011 | AG27: 0.58236909 | AH27: 0.62277172 | AI27: KF (Smirnov, 1987)
A28: 1.0MgCl2 | B28: 987 | C28: 986.86211 | D28: 0.43829221 | F28: 0.36348786 | H28: 0.4382922 | J28: 0.28861058 | Q28: 0.4382922 | R28: 0.43829221 | T28: 0.36348786 | V28: 0.4382922 | W28: =ABS(($AH28-V28)/$AH28) -> 0.19417783 | Y28: 0.28861058 | Z28: =ABS(($AH28-Y28)/$AH28) -> 0.469375 | AG28: 0.4382922 | AH28: 0.54390686 | AI28: MgCl2 (Filatov, 2005)
A29: 1.0MgF2 | B29: 1534.2 | C29: 1554.2416 | D29: 0.76994949 | F29: 0.65134847 | H29: 0.76994949 | J29: 0.55165642 | Q29: 0.76994949 | R29: 0.76680975 | T29: 0.64869236 | V29: 0.76680975 | W29: =ABS(($AH29-V29)/$AH29) -> 0.091875731 | Y29: 0.54942631 | Z29: =ABS(($AH29-Y29)/$AH29) -> 0.21766089 | AG29: 0.76680975 | AH29: 0.70228665 | AI29: MgF2 (Khlebnikov, 1981),MgF2 (Golyshev, 1992)
A30: 1.0CaF2 | B30: 1692 | C30: 1697.8471 | D30: 0.53240327 | F30: 0.56536852 | H30: 0.53240327 | J30: 0.42810664 | Q30: 0.53240327 | R30: 0.53209376 | T30: 0.56503984 | V30: 0.53209375 | W30: =ABS(($AH30-V30)/$AH30) -> 0.10256458 | Y30: 0.4277441 | Z30: =ABS(($AH30-Y30)/$AH30) -> 0.2785619 | AG30: 0.53209375 | AH30: 0.59290478 | AI30: CaF2 (Golyshev, 1992),CaF2 (Khlebnikov, 1981)
U35: Gheribi | V35: Zhao | X35: Labels
S36: Avg Error | T36: Actinide | U36: =AVERAGE(W6:W15) -> 0.55680469 | V36: =AVERAGE(Z6:Z15) -> 0.28725646 | X36: Gheribi; 11.8% MAE | Z36: Non-Actinides
T37: Non-actinide | U37: =AVERAGE(W16:W30) -> 0.11828279 | V37: =AVERAGE(Z16:Z30) -> 0.3312135 | X37: Zhao; 33.1% MAE | Z37: Actinides
X38: Gheribi; 55.7% MAE
U39: Deviation | X39: Zhao; 28.7% MAE
T40: 0 | U40: 1.15
T41: 0 | U41: 0.85
C42: Figures below
B44: Fig 1 -->
B67: Fig 2 -->
B98: Fig 3 -->

Sheet Fig1_Fig2 (2)
R4: At min measured temp
A5: Salt Composition | B5: Melting Temp (K) | C5: Min Measured Temp (K) | D5: Gheribi-KTCPÎ» at Melt Temp (W/m-K) | E5: Gheribi-KTCPÎ», Mix Data at Melt Temp (W/m-K) | F5: Gheribi-KT-Emp at Melt Temp (W/m-K) | G5: Gheribi-KT-Emp-Mix at Melt Temp (W/m-K) | H5: Gheribi-KT24 at Melt Temp (W/m-K) | I5: Gheribi-KT24, Mix Data at Melt Temp (W/m-K) | J5: Zhao-PGM at Melt Temp (W/m-K) | K5: Zhao-PGM, Mix Data at Melt Temp (W/m-K) | L5: Present Model at Melt Temp (W/m-K) | M5: Present Model, Mix Data at Melt Temp (W/m-K) | N5: Present Model-VelCorr at Melt Temp (W/m-K) | O5: Bridgman at Melt Temp (W/m-K) | P5: Chapman-Enskog at Melt Temp (W/m-K) | Q5: Ideal at Melt Temp (W/m-K) | R5: Gheribi-KT-k_min (W/m-K) | S5: Gheribi-KT-k_min, Mix Data (W/m-K) | T5: Gheribi-KT-Emp (W/m-K) | U5: Gheribi-KT-Emp-Mix (W/m-K) | V5: Gheribi-KT24 | W5: % Dev | X5: Gheribi-KT24, Mix Data (W/m-K) | Y5: Zhao-PGM | Z5: % Dev | AA5: Zhao-PGM, Mix Data (W/m-K) | AB5: Present Model (W/m-K) | AC5: Present Model, Mix Data (W/m-K) | AD5: Present Model-VelCorr (W/m-K) | AE5: Bridgman (W/m-K) | AF5: Chapman-Enskog (W/m-K) | AG5: Ideal (W/m-K) | AH5: TC Experimental (W/m-K) | AI5: Exp. Reference | AJ5: TC MSTDB (W/m-K) | AK5: MSTDB Reference
A6: 0.725LiF-0.265BeF2-0.01UF4 | B6: 723 | C6: 882 | D6: 0.36678342 | F6: 0.39875169 | H6: 0.69535872 | J6: 0.78147755 | Q6: 1.3452379 | R6: 0.3588139 | T6: 0.39008756 | V6: 0.67741221 | W6: =ABS(($AH6-V6)/$AH6) -> 0.11985885 | Y6: 0.74096563 | Z6: =ABS(($AH6-Y6)/$AH6) -> 0.037285823 | AG6: 1.3016119 | AH6: 0.76966315 | AI6: 0.725LiF-0.265BeF2-0.01UF4 (Bobrova, 2023)
A7: 0.72LiF-0.26BeF2-0.02UF4 | B7: 723 | C7: 832 | D7: -0.1376048 | F7: -0.030277384 | H7: 0.56670078 | J7: 0.74820769 | Q7: 1.3360263 | R7: -0.13553534 | T7: -0.029822039 | V7: 0.55550594 | W7: =ABS(($AH7-V7)/$AH7) -> 0.2232675 | Y7: 0.72228652 | Z7: =ABS(($AH7-Y7)/$AH7) -> 0.009932345 | AG7: 1.3058004 | AH7: 0.71518308 | AI7: 0.72LiF-0.26BeF2-0.02UF4 (Bobrova, 2023)
A8: 0.63NaCl-0.37UCl3 | B8: 750 | C8: 802 | D8: 0.12623785 | F8: 0.13414681 | H8: 0.11469448 | J8: 0.30786468 | Q8: 0.45071802 | R8: 0.12332465 | T8: 0.13105109 | V8: 0.11214895 | W8: =ABS(($AH8-V8)/$AH8) -> 0.55163115 | Y8: 0.29987597 | Z8: =ABS(($AH8-Y8)/$AH8) -> 0.19889702 | AG8: 0.44198046 | AH8: 0.25012655 | AI8: 63NaCl-37UCl3 (Termini, 2024)
A9: 0.658NaCl-0.342UCl3 | B9: 750 | C9: 869.15 | D9: 0.11100367 | F9: 0.12242465 | H9: 0.11113907 | J9: 0.3107182 | Q9: 0.45854797 | R9: 0.10497932 | T9: 0.11578047 | V9: 0.10540828 | W9: =ABS(($AH9-V9)/$AH9) -> 0.49064414 | Y9: 0.29112923 | Z9: =ABS(($AH9-Y9)/$AH9) -> 0.40680012 | AG9: 0.43759544 | AH9: 0.20694427 | AI9: 65.8NaCl-34.2UCl3 (Rose, 2023)
A10: 0.712LiF-0.23BeF2-0.05ZrF4-0.008UF4 | B10: 723 | C10: 785.88122 | D10: 0.11450404 | F10: 0.21993592 | H10: 0.46469757 | J10: 0.72737521 | Q10: 1.322616 | R10: 0.11327849 | T10: 0.21758192 | V10: 0.46141777 | W10: =ABS(($AH10-V10)/$AH10) -> 0.63105706 | Y10: 0.71241195 | Z10: =ABS(($AH10-Y10)/$AH10) -> 0.43036576 | AG10: 1.3049988 | AH10: 1.2506481 | AI10: 0.712LiF-0.23BeF2-0.05ZrF4-0.008UF4 (Rosenthal, 1969)
A11: 0.675LiF-0.2BeF2-0.12ThF4-0.005UF4 | B11: 723 | C11: 811.82664 | D11: -0.68451425 | F11: -0.44302642 | H11: 0.11179706 | J11: 0.59758238 | Q11: 1.2528784 | R11: -0.67658391 | T11: -0.4378938 | V11: 0.10753765 | W11: =ABS(($AH11-V11)/$AH11) -> 0.91498381 | Y11: 0.58317547 | Z11: =ABS(($AH11-Y11)/$AH11) -> 0.53895815 | AG11: 1.2304066 | AH11: 1.2649079 | AI11: 0.675LiF-0.20BeF2-0.12ThF4-0.005UF4 (Rosenthal, 1969)
A12: 0.28NaF-0.42KF-0.3UF4 | B12: 878 | C12: 1023 | D12: 0.11971805 | F12: 0.13951714 | H12: 0.15108649 | J12: 0.3836312 | Q12: 0.62595318 | R12: 0.11574283 | T12: 0.1348845 | V12: 0.14300503 | W12: =ABS(($AH12-V12)/$AH12) -> 0.72446699 | Y12: 0.35966985 | Z12: =ABS(($AH12-Y12)/$AH12) -> 0.30701098 | AG12: 0.59800659 | AH12: 0.51901235 | AI12: 0.42KF-0.28NaF-0.30UF4 (Rudenko, 2024)
A13: 0.24NaF-0.36KF-0.4UF4 | B13: 878 | C13: 1073 | D13: 0.18851371 | F13: 0.19057901 | H13: 0.15917343 | J13: 0.36475139 | Q13: 0.57924146 | R13: 0.18133469 | T13: 0.18332134 | V13: 0.15118127 | W13: =ABS(($AH13-V13)/$AH13) -> 0.70253623 | Y13: 0.33864101 | Z13: =ABS(($AH13-Y13)/$AH13) -> 0.33369106 | AG13: 0.54654293 | AH13: 0.50823423 | AI13: 0.36KF-0.24NaF-0.40UF4 (Rudenko, 2024)
A14: 0.2NaF-0.3KF-0.5UF4 | B14: 878 | C14: 1073 | D14: 0.23423673 | F14: 0.21977532 | H14: 0.17464564 | J14: 0.34979074 | Q14: 0.53252974 | R14: 0.22647803 | T14: 0.21249562 | V14: 0.16870277 | W14: =ABS(($AH14-V14)/$AH14) -> 0.57854411 | Y14: 0.32853146 | Z14: =ABS(($AH14-Y14)/$AH14) -> 0.17925758 | AG14: 0.50439481 | AH14: 0.40028571 | AI14: 0.30KF-0.20NaF-0.50UF4 (Rudenko, 2024)
A15: 0.712LiF-0.23BeF2-0.05ZrF4-0.008UF4 | B15: 735 | C15: 785.88122 | D15: 0.11450404 | F15: 0.21993592 | H15: 0.46469757 | J15: 0.72737521 | L15: 0.72737521 | Q15: 1.322616 | R15: 0.11327849 | T15: 0.21758192 | V15: 0.46141777 | W15: =ABS(($AH15-V15)/$AH15) -> 0.63105706 | Y15: 0.71241195 | Z15: =ABS(($AH15-Y15)/$AH15) -> 0.43036576 | AB15: 0.71241195 | AG15: 1.3049988 | AH15: 1.2506481 | AI15: 0.465LiF-0.115NaF-0.42KF (Merritt, 2022),0.465LiF-0.115NaF-0.42KF (Gallagher, 2022),0.465LiF-0.115NaF-0.42KF (Rudenko, 2022)
A16: 0.73LiF-0.27BeF2 | B16: 723 | C16: 884 | D16: 1.1694201 | F16: 1.0901411 | H16: 1.0169508 | J16: 0.81942429 | Q16: 1.3544496 | R16: 1.143821 | T16: 1.0662774 | V16: 0.99333381 | W16: =ABS(($AH16-V16)/$AH16) -> 0.095706389 | Y16: 0.77570442 | Z16: =ABS(($AH16-Y16)/$AH16) -> 0.1443518 | AG16: 1.310565 | AH16: 0.90656933 | AI16: 0.73LiF-0.27BeF2 (Bobrova, 2023)
A17: 0.66LiF-0.34BeF2 | B17: 733 | C17: 884 | D17: 1.1321639 | E17: 1.6545464 | F17: 1.0327876 | G17: 1.5087682 | H17: 1.0025337 | I17: 1.518486 | J17: 0.77455399 | K17: 1.194875 | R17: 1.1128792 | S17: 1.6155238 | T17: 1.0151956 | U17: 1.4731838 | V17: 0.98447068 | W17: =ABS(($AH17-V17)/$AH17) -> 0.080050058 | X17: 1.4811883 | Y17: 0.74095938 | Z17: =ABS(($AH17-Y17)/$AH17) -> 0.18710304 | AA17: 1.1045267 | AH17: 0.91150468 | AI17: 0.73LiF-0.27BeF2 (Bobrova, 2023) | AJ17: 1.1 | AK17: Rosenthal 1969 [122]
A18: 0.4NaF-0.6KF | B18: 1000 | D18: 0.67334765 | F18: 0.67819467 | H18: 0.64214261 | J18: 0.4684939 | Q18: 0.73423486 | R18: 0.67334765 | T18: 0.67819467 | V18: 0.64214261 | W18: =ABS(($AH18-V18)/$AH18) -> 0.082653417 | Y18: 0.4684939 | Z18: =ABS(($AH18-Y18)/$AH18) -> 0.330723 | AG18: 0.73423486 | AH18: =AJ18 -> 0.7 | AJ18: 0.7 | AK18: Rudenko 2024 [178]
A19: 0.465LiF-0.115NaF-0.42KF | B19: 735 | C19: 742.4 | D19: 0.75544862 | F19: 0.76389433 | G19: 1.0241817 | H19: 0.6954626 | I19: 0.90509687 | J19: 0.65005469 | K19: 0.77295464 | Q19: 1.0993871 | R19: 0.75296021 | T19: 0.7613781 | U19: 1.0203939 | V19: 0.69317886 | W19: =ABS(($AH19-V19)/$AH19) -> 0.1226106 | X19: 0.90175871 | Y19: 0.6459406 | Z19: =ABS(($AH19-Y19)/$AH19) -> 0.1824023 | AA19: 0.76685546 | AG19: 1.0964289 | AH19: 0.79004699 | AI19: 0.465LiF-0.115NaF-0.42KF (Merritt, 2022),0.465LiF-0.115NaF-0.42KF (Gallagher, 2022),0.465LiF-0.115NaF-0.42KF (Rudenko, 2022)
A20: 0.2046NaCl-0.4131KCl-0.3823MgCl2 | B20: 700 | C20: 722.73281 | D20: 0.42631828 | F20: 0.39868607 | G20: 0.35511104 | H20: 0.39369828 | I20: 0.38744636 | J20: 0.34234495 | Q20: 0.47430496 | R20: 0.42244769 | T20: 0.39506636 | U20: 0.35163381 | V20: 0.39011154 | W20: =ABS(($AH20-V20)/$AH20) -> 0.17217062 | X20: 0.3836404 | Y20: 0.33784078 | Z20: =ABS(($AH20-Y20)/$AH20) -> 0.28309088 | AG20: 0.47038278 | AH20: 0.47124631 | AI20: 0.2046NaCl-0.4131KCl-0.3823MgCl2 (Wang, 2021)
A21: 0.345NaF-0.59KF-0.065MgF2 | B21: 958 | C21: 993.01378 | D21: 0.6779149 | F21: 0.67261166 | H21: 0.57197135 | I21: 0.59758621 | J21: 0.4860452 | K21: 0.49336011 | Q21: 0.74453173 | R21: 0.66907211 | T21: 0.66383804 | V21: 0.56448951 | W21: =ABS(($AH21-V21)/$AH21) -> 0.26308813 | X21: 0.58988275 | Y21: 0.47418606 | Z21: =ABS(($AH21-Y21)/$AH21) -> 0.38097462 | AA21: 0.48283679 | AG21: 0.73580725 | AH21: 0.76602038 | AI21: 0.345NaF-0.59KF-0.065MgF2 (Rudenko, 2024)
A22: 1.0LiCl | B22: 883 | C22: 965.57734 | D22: 0.68568905 | F22: 0.72519297 | H22: 0.68631947 | J22: 0.41038419 | Q22: 0.68524115 | R22: 0.66731827 | T22: 0.70576381 | V22: 0.6679318 | W22: =ABS(($AH22-V22)/$AH22) -> 0.018943205 | Y22: 0.3868412 | Z22: =ABS(($AH22-Y22)/$AH22) -> 0.40986607 | AG22: 0.66685348 | AH22: 0.65551426 | AI22: LiCl (Nagasaka, 1992)
A23: 1.0NaCl | B23: 1073.8 | C23: 1169.4387 | D23: 0.48765041 | F23: 0.492992 | H23: 0.48681288 | J23: 0.31017075 | Q23: 0.48673467 | R23: 0.46764534 | T23: 0.4727678 | V23: 0.46684217 | W23: =ABS(($AH23-V23)/$AH23) -> 0.11307557 | Y23: 0.28504925 | Z23: =ABS(($AH23-Y23)/$AH23) -> 0.45845264 | AG23: 0.46682997 | AH23: 0.5263607 | AI23: NaCl (Nagasaka 1992)
A24: 1.0KCl | B24: 1042.7 | C24: 1052.1639 | D24: 0.37448386 | F24: 0.39772402 | H24: 0.3742357 | J24: 0.26186835 | Q24: 0.37411661 | R24: 0.37273884 | T24: 0.39587071 | V24: 0.37249184 | W24: =ABS(($AH24-V24)/$AH24) -> 0.013588159 | Y24: 0.25964867 | Z24: =ABS(($AH24-Y24)/$AH24) -> 0.29346958 | AG24: 0.37237546 | AH24: 0.36749822 | AI24: KCl (Harada, 1992),KCl (Nagasaka, 1992)
A25: 1.0LiF | B25: 1121.2 | C25: 1121.2 | D25: 1.3492012 | F25: 1.4344247 | H25: 1.3498415 | J25: 0.80194503 | Q25: 1.3569764 | R25: 1.3492012 | T25: 1.4344247 | V25: 1.3498415 | W25: =ABS(($AH25-V25)/$AH25) -> 0.071577209 | Y25: 0.80194503 | Z25: =ABS(($AH25-Y25)/$AH25) -> 0.36337265 | AG25: 1.3569764 | AH25: 1.2596773 | AI25: LiF (Golyshev, 1982),LiF (Golyshev, 1983),LiF (Golyshev, 1992),LiF (Smirnov, 1987),LiF (Khlebnikov, 1981)
A26: 1.0NaF | B26: 1268 | C26: 1276.2108 | D26: 0.84228951 | F26: 0.90253851 | H26: 0.8422681 | J26: 0.53047696 | Q26: 0.84054676 | R26: 0.83982795 | T26: 0.89990088 | V26: 0.83980661 | W26: =ABS(($AH26-V26)/$AH26) -> 0.28778769 | Y26: 0.52656453 | Z26: =ABS(($AH26-Y26)/$AH26) -> 0.55343797 | AG26: 0.83809041 | AH26: 1.179152 | AI26: NaF (Smirnov, 1987),NaF (Polyakov, 1975)
A27: 1.0KF | B27: 1131.2 | C27: 1130.597 | D27: 0.58239325 | F27: 0.56777343 | H27: 0.58268228 | J27: 0.36409719 | Q27: 0.58236909 | R27: 0.58239325 | T27: 0.56777343 | V27: 0.58268228 | W27: =ABS(($AH27-V27)/$AH27) -> 0.064372614 | Y27: 0.36409719 | Z27: =ABS(($AH27-Y27)/$AH27) -> 0.41536011 | AG27: 0.58236909 | AH27: 0.62277172 | AI27: KF (Smirnov, 1987)
A28: 1.0MgCl2 | B28: 987 | C28: 986.86211 | D28: 0.43829221 | F28: 0.36348786 | H28: 0.4382922 | J28: 0.28861058 | Q28: 0.4382922 | R28: 0.43829221 | T28: 0.36348786 | V28: 0.4382922 | W28: =ABS(($AH28-V28)/$AH28) -> 0.19417783 | Y28: 0.28861058 | Z28: =ABS(($AH28-Y28)/$AH28) -> 0.469375 | AG28: 0.4382922 | AH28: 0.54390686 | AI28: MgCl2 (Filatov, 2005)
A29: 1.0MgF2 | B29: 1534.2 | C29: 1554.2416 | D29: 0.76994949 | F29: 0.65134847 | H29: 0.76994949 | J29: 0.55165642 | Q29: 0.76994949 | R29: 0.76680975 | T29: 0.64869236 | V29: 0.76680975 | W29: =ABS(($AH29-V29)/$AH29) -> 0.091875731 | Y29: 0.54942631 | Z29: =ABS(($AH29-Y29)/$AH29) -> 0.21766089 | AG29: 0.76680975 | AH29: 0.70228665 | AI29: MgF2 (Khlebnikov, 1981),MgF2 (Golyshev, 1992)
A30: 1.0CaF2 | B30: 1692 | C30: 1697.8471 | D30: 0.53240327 | F30: 0.56536852 | H30: 0.53240327 | J30: 0.42810664 | Q30: 0.53240327 | R30: 0.53209376 | T30: 0.56503984 | V30: 0.53209375 | W30: =ABS(($AH30-V30)/$AH30) -> 0.10256458 | Y30: 0.4277441 | Z30: =ABS(($AH30-Y30)/$AH30) -> 0.2785619 | AG30: 0.53209375 | AH30: 0.59290478 | AI30: CaF2 (Golyshev, 1992),CaF2 (Khlebnikov, 1981)
U35: Gheribi | V35: Zhao | X35: Labels
S36: Avg Error | T36: Actinide | U36: =AVERAGE(W6:W15) -> 0.55680469 | V36: =AVERAGE(Z6:Z15) -> 0.28725646 | X36: Gheribi; 11.8% MAE | Z36: Non-Actinides
T37: Non-actinide | U37: =AVERAGE(W16:W30) -> 0.11828279 | V37: =AVERAGE(Z16:Z30) -> 0.3312135 | X37: Zhao; 33.1% MAE | Z37: Actinides
X38: Gheribi; 55.7% MAE
U39: Deviation | X39: Zhao; 28.7% MAE
T40: 0 | U40: 1.15
T41: 0 | U41: 0.85

Sheet MFP-rsum
A1: Compound | B1: S/cm | C1: order | D1: protons | E1: electrons | F1: Mp/molecule | G1: Me/molecule | H1: ratio of Mpe*# | I1: ratio | J1: Dif mass | K1: M_i (g/mol) | L1: Visc (N*s/m^2) | M1: T_i_m (K) inverse | N1: T_i_m (K) | O1: V_i_m (m^3/mol) | P1: alpha_i_m (K^-1) | R1: r_c (m) | S1: r_a (m) | T1: sum_radii | U1: delta | V1: --> Scaled | W1: rho_m (g/m^3) | X1: SoS(T)_A (A+B*T) | Y1: SoS(T)_B | Z1: A (Density (g/cm3): A - BT(K)) | AA1: B (Density (g/cm3): A - BT(K)) | AB1: #_cations | AC1: #_anions | AD1: sum_ions | AE1: λ_meas | AF1: 1/3*Cp*vs*r_sumCorrect | AG1: Error | AH1: 1/3*Cp*vs*1stPk | AI1: 1/3*Cp*vs*AvgPk | AJ1: 1/3*Cp*vs*r_sum | AK1: dev_λ | AL1: c_BC,rsum | AM1: c_BC_λBC | AN1: 1/3*Cp*vs | AO1: r_sum | AP1: 1stPeak | AQ1: AvgMFP | AR1: λBC | AS1: MFP_calc | AT1: MFP_dev | AU1: 1/3*Cp*r_sum | AV1: SoS_Tm | AW1: SoS_metal | AX1: vs_calc | AY1: vs_dev | AZ1: 1/3*vs*r_sum | BA1: C_i_p (J/mol/K) | BB1: Cp(MJ/m3-K) | BC1: Cp(J/m3-K) | BD1: Cp_calc | BE1: Cp_dev | BF1: vs*cp | BG1: --> Scaled | BH1: 1/3*vs*cp*rsum | BI1: mu | BJ1: V_ca(r ) | BK1: R(pm) | BL1: R(pm)/mu | BM1: 1/sqrt(mu) | BN1: x_ca,peak | BO1: R(pm)/mu | BP1: V/mu | BQ1: R | BR1: Visc/(Dens*C0)
A2: LiF | B2: 9.95 | C2: 1 | D2: 12 | E2: 12 | F2: =D2*1.6726219E-27 -> 2.0071463e-26 | G2: =E2*9.1093856E-31 -> 1.0931263e-29 | H2: =((F2*D2)/(G2*E2)) -> 1836.1523 | I2: =D2/E2 -> 1 | J2: =(F2)-(G2) -> 2.0060532e-26 | K2: 25.939 | L2: =0.115*EXP(27000/(8.3144598*N2))/1000 -> 0.0020988673 | M2: =N2^-1 -> 0.00089433439 | N2: 1118.15 | O2: 1.42e-05 | P2: 0.000268 | R2: 7.6e-11 | S2: 1.33e-10 | T2: =S2+R2 -> 2.09e-10 | U2: =S2/R2 -> 1.75 | V2: =T2*10000000000 -> 2.09 | W2: 1810000 | X2: 2547.8 | Y2: 0 | Z2: 2.3581 | AA2: -0.0004902 | AB2: 1 | AC2: 1 | AD2: =AB2+AC2 -> 2 | AE2: 1.33125 | AF2: =1/3*BC2*AV2*T2 -> 0.80248523 | AG2: =ABS((AE2-AF2)/AE2) -> 0.39719419 | AH2: =1/3*BC2*AV2*AP2 -> 0.72246878 | AI2: =1/3*BC2*AV2*AQ2 -> 0.90368251 | AJ2: 0.79448872 | AK2: =(AE2-AJ2)/AE2 -> 0.40320096 | AL2: =AE2/(1/3*AV2*T2) -> 7500138 | AM2: =AE2/(1/3*AV2*AR2) -> 4521126.8 | AN2: 3.8013815e+09 | AO2: =AJ2/AN2 -> 2.09e-10 | AP2: 1.8816044e-10 | AQ2: 2.3535591e-10 | AR2: =AE2/(1/3*BC2*AV2) -> 3.4671199e-10 | AS2: =AE2/AN2 -> 3.5020164e-10 | AT2: =(AS2-AO2)/AO2 -> 0.67560591 | AU2: =AJ2/AV2 -> 0.00031183324 | AV2: =X2+Y2*N2 -> 2547.8 | AW2: 3500 | AX2: =AE2/AU2 -> 4269.1087 | AY2: =(AX2-AV2)/AV2 -> 0.67560591 | AZ2: =AJ2/BA2 -> 0.012375214 | BA2: 64.2 | BB2: =BC2/1000000 -> 4.5211268 | BC2: =BA2/O2 -> 4521126.8 | BD2: =AE2/(AZ2) -> 107.5739 | BE2: =(BD2-BA2)/BA2 -> 0.67560591 | BF2: =AV2*BC2 -> 1.1518927e+10 | BG2: =BF2*0.0000000001 -> 1.1518927 | BH2: =BF2*T2 -> 2.4074557 | BI2: 5.083691 | BJ2: -6.5464269e-05 | BK2: 0.87109136 | BL2: =SQRT(BK2)/BI2 -> 0.18359156 | BM2: =SQRT(1/BI2) -> 0.44351716 | BN2: 1.84e-10 | BO2: =BN2*SQRT(BK2/BI2) -> 7.6165817e-11 | BP2: =SQRT(ABS(BJ2))/BI2 -> 0.00159156 | BQ2: =AV2^(2/3)*O2 -> 0.002648898 | BR2: =L2/(W2/1000*(X2+Y2*N2)) -> 4.5513588e-10
A3: NaF | B3: 6.9 | C3: 1 | D3: 20 | E3: 20 | F3: =D3*1.6726219E-27 -> 3.3452438e-26 | G3: =E3*9.1093856E-31 -> 1.8218771e-29 | H3: =((F3*D3)/(G3*E3)) -> 1836.1523 | I3: =D3/E3 -> 1 | J3: =(F3)-(G3) -> 3.3434219e-26 | K3: 41.988 | L3: =0.12*EXP(26500/(8.3144598*N3))/1000 -> 0.0014814456 | M3: =N3^-1 -> 0.00078855025 | N3: 1268.15 | O3: 2.16e-05 | P3: 0.000288 | R3: 1.02e-10 | S3: 1.33e-10 | T3: =S3+R3 -> 2.35e-10 | U3: =S3/R3 -> 1.3039216 | V3: =T3*10000000000 -> 2.35 | W3: 1950000 | X3: 2085.5 | Y3: 0 | Z3: 2.755 | AA3: -0.000636 | AB3: 1 | AC3: 1 | AD3: =AB3+AC3 -> 2 | AE3: 0.8279 | AF3: =1/3*BC3*AV3*T3 -> 0.53093354 | AG3: =ABS((AE3-AF3)/AE3) -> 0.35869846 | AH3: =1/3*BC3*AV3*AP3 -> 0.49109756 | AI3: =1/3*BC3*AV3*AQ3 -> 0.59812176 | AJ3: 0.53220718 | AK3: =(AE3-AJ3)/AE3 -> 0.35716007 | AL3: =AE3/(1/3*AV3*T3) -> 5067818.8 | AM3: =AE3/(1/3*AV3*AR3) -> 3250000 | AN3: 2.2647114e+09 | AO3: =AJ3/AN3 -> 2.35e-10 | AP3: 2.1736793e-10 | AQ3: 2.6473862e-10 | AR3: =AE3/(1/3*BC3*AV3) -> 3.6644228e-10 | AS3: =AE3/AN3 -> 3.6556535e-10 | AT3: =(AS3-AO3)/AO3 -> 0.55559722 | AU3: =AJ3/AV3 -> 0.00025519404 | AV3: =X3+Y3*N3 -> 2085.5 | AW3: 2720 | AX3: =AE3/AU3 -> 3244.198 | AY3: =(AX3-AV3)/AV3 -> 0.55559722 | AZ3: =AJ3/BA3 -> 0.0075812988 | BA3: 70.2 | BB3: =BC3/1000000 -> 3.25 | BC3: =BA3/O3 -> 3250000 | BD3: =AE3/(AZ3) -> 109.20292 | BE3: =(BD3-BA3)/BA3 -> 0.55559722 | BF3: =AV3*BC3 -> 6777875000 | BG3: =BF3*0.0000000001 -> 0.6777875 | BH3: =BF3*T3 -> 1.5928006 | BI3: 10.402189 | BJ3: -0.00064235936 | BK3: 0.88236536 | BL3: =SQRT(BK3)/BI3 -> 0.09030244 | BM3: =SQRT(1/BI3) -> 0.31005421 | BN3: 2.14e-10 | BO3: =BN3*SQRT(BK3/BI3) -> 6.2326915e-11 | BP3: =SQRT(ABS(BJ3))/BI3 -> 0.0024364881 | BQ3: =AV3^(2/3)*O3 -> 0.0035258233 | BR3: =L3/(W3/1000*(X3+Y3*N3)) -> 3.6428469e-10
A4: KF | B4: 5.1 | C4: 1 | D4: 28 | E4: 28 | F4: =D4*1.6726219E-27 -> 4.6833413e-26 | G4: =E4*9.1093856E-31 -> 2.550628e-29 | H4: =((F4*D4)/(G4*E4)) -> 1836.1523 | I4: =D4/E4 -> 1 | J4: =(F4)-(G4) -> 4.6807907e-26 | K4: 58.097 | L4: =0.107*EXP(23800/(8.3144598*N4))/1000 -> 0.001350063 | M4: =N4^-1 -> 0.00088562193 | N4: 1129.15 | O4: 3.04e-05 | P4: 0.000341 | R4: 1.38e-10 | S4: 1.33e-10 | T4: =S4+R4 -> 2.71e-10 | U4: =S4/R4 -> 0.96376812 | V4: =T4*10000000000 -> 2.71 | W4: 1910000 | X4: 1816.4 | Y4: 0 | Z4: 2.6464 | AA4: -0.0006515 | AB4: 1 | AC4: 1 | AD4: =AB4+AC4 -> 2 | AE4: 0.57 | AF4: =1/3*BC4*AV4*T4 -> 0.36108718 | AG4: =ABS((AE4-AF4)/AE4) -> 0.36651373 | AH4: =1/3*BC4*AV4*AP4 -> 0.32961603 | AI4: =1/3*BC4*AV4*AQ4 -> 0.40376311 | AJ4: 0.36077309 | AK4: =(AE4-AJ4)/AE4 -> 0.36706476 | AL4: =AE4/(1/3*AV4*T4) -> 3473884.1 | AM4: =AE4/(1/3*AV4*AR4) -> 2200657.9 | AN4: 1.331266e+09 | AO4: =AJ4/AN4 -> 2.71e-10 | AP4: 2.4738055e-10 | AQ4: 3.0302877e-10 | AR4: =AE4/(1/3*BC4*AV4) -> 4.2779143e-10 | AS4: =AE4/AN4 -> 4.2816386e-10 | AT4: =(AS4-AO4)/AO4 -> 0.57994046 | AU4: =AJ4/AV4 -> 0.00019861985 | AV4: =X4+Y4*N4 -> 1816.4 | AW4: 2360 | AX4: =AE4/AU4 -> 2869.8038 | AY4: =(AX4-AV4)/AV4 -> 0.57994046 | AZ4: =AJ4/BA4 -> 0.0053927218 | BA4: 66.9 | BB4: =BC4/1000000 -> 2.2006579 | BC4: =BA4/O4 -> 2200657.9 | BD4: =AE4/(AZ4) -> 105.69802 | BE4: =(BD4-BA4)/BA4 -> 0.57994046 | BF4: =AV4*BC4 -> 3.997275e+09 | BG4: =BF4*0.0000000001 -> 0.3997275 | BH4: =BF4*T4 -> 1.0832615 | BI4: 12.78567 | BJ4: -0.0013975067 | BK4: 0.88025103 | BL4: =SQRT(BK4)/BI4 -> 0.07338035 | BM4: =SQRT(1/BI4) -> 0.27966509 | BN4: 2.44e-10 | BO4: =BN4*SQRT(BK4/BI4) -> 6.4022312e-11 | BP4: =SQRT(ABS(BJ4))/BI4 -> 0.0029238391 | BQ4: =AV4^(2/3)*O4 -> 0.0045256529 | BR4: =L4/(W4/1000*(X4+Y4*N4)) -> 3.8914297e-10
A5: RbF | C5: 1 | D5: 46 | E5: 46 | F5: =D5*1.6726219E-27 -> 7.6940607e-26 | G5: =E5*9.1093856E-31 -> 4.1903174e-29 | H5: =((F5*D5)/(G5*E5)) -> 1836.1523 | I5: =D5/E5 -> 1 | J5: =(F5)-(G5) -> 7.6898704e-26 | K5: 104.4662 | L5: =0.115*EXP(27000/(8.3144598*N5))/1000 -> 0.0025481161 | M5: =N5^-1 -> 0.00095406192 | N5: 1048.15 | O5: 3.57e-05 | P5: 0.000349 | R5: 1.52e-10 | S5: 1.33e-10 | T5: =S5+R5 -> 2.85e-10 | U5: =S5/R5 -> 0.875 | V5: =T5*10000000000 -> 2.85 | W5: =K5/O5 -> 2926224.1 | X5: 1760.4 | Y5: 0 | Z5: =W5*100^3/1000 -> 2.9262241e+09 | AA5: 0 | AE5: 0.48965 | AF5: =1/3*BC5*AV5*T5 -> 0.32557538 | AG5: =ABS((AE5-AF5)/AE5) -> 0.33508551 | AH5: =1/3*BC5*AV5*AP5 -> 0.29579641 | AL5: =AE5/(1/3*AV5*T5) -> 2927863.3 | AM5: =AE5/(1/3*AV5*AR5) -> 1946778.7 | AP5: 2.5893228e-10 | AR5: =AE5/(1/3*BC5*AV5) -> 4.2862655e-10 | AS5: 2.5893228e-10 | AV5: =X5+Y5*N5 -> 1760.4 | AZ5: =AJ5/BA5 -> 0 | BA5: 69.5 | BB5: =BC5/1000000 -> 1.9467787 | BC5: =BA5/O5 -> 1946778.7 | BF5: =AV5*BC5 -> 3.4271092e+09 | BG5: =BF5*0.0000000001 -> 0.34271092 | BH5: =BF5*T5 -> 0.97672613 | BI5: 15.543321 | BJ5: -0.0018393987 | BM5: =SQRT(1/BI5) -> 0.25364604 | BN5: 2.56e-10 | BO5: =T5*SQRT(0.9/BI5) -> 6.8579483e-11 | BP5: =SQRT(ABS(BJ5))/BI5 -> 0.0027592695 | BQ5: =AV5^(2/3)*O5 -> 0.0052048608 | BR5: =L5/(W5/1000*(X5+Y5*N5)) -> 4.9465257e-10
A6: CsF | C6: 1 | D6: 64 | E6: 64 | F6: =D6*1.6726219E-27 -> 1.070478e-25 | G6: =E6*9.1093856E-31 -> 5.8300068e-29 | H6: =((F6*D6)/(G6*E6)) -> 1836.1523 | I6: =D6/E6 -> 1 | J6: =(F6)-(G6) -> 1.069895e-25 | K6: 58.44 | L6: =0.115*EXP(27000/(8.3144598*N6))/1000 -> 0.0034453112 | M6: =N6^-1 -> 0.001046956 | N6: 955.15 | O6: 4.57e-05 | P6: 0.000385 | R6: 1.67e-10 | S6: 1.33e-10 | T6: =S6+R6 -> 3e-10 | U6: =S6/R6 -> 0.79640719 | V6: =T6*10000000000 -> 3 | W6: 2196977.2 | X6: 2732.9322 | Y6: -0.915 | Z6: 4.8985 | AA6: -0.000543 | AE6: 0.36715 | AF6: =1/3*BC6*AV6*T6 -> 0.30142161 | AG6: =ABS((AE6-AF6)/AE6) -> 0.17902325 | AH6: =1/3*BC6*AV6*AP6 -> 0.28095437 | AL6: =AE6/(1/3*AV6*T6) -> 1975018.4 | AM6: =AE6/(1/3*AV6*AR6) -> 1621444.2 | AP6: 2.7962928e-10 | AR6: =AE6/(1/3*BC6*AV6) -> 3.6541839e-10 | AS6: 2.7962928e-10 | AV6: =X6+Y6*N6 -> 1858.97 | AZ6: =AJ6/BA6 -> 0 | BA6: 74.1 | BB6: =BC6/1000000 -> 1.6214442 | BC6: =BA6/O6 -> 1621444.2 | BF6: =AV6*BC6 -> 3.0142161e+09 | BG6: =BF6*0.0000000001 -> 0.30142161 | BH6: =BF6*T6 -> 0.90426484 | BI6: 16.622299 | BJ6: -0.0029196881 | BM6: =SQRT(1/BI6) -> 0.24527566 | BN6: 2.76e-10 | BO6: =T6*SQRT(0.9/BI6) -> 6.9806677e-11 | BP6: =SQRT(ABS(BJ6))/BI6 -> 0.0032507018 | BQ6: =AV6^(2/3)*O6 -> 0.0069092534 | BR6: =L6/(W6/1000*(X6+Y6*N6)) -> 8.4358824e-10
A7: LiCl | B7: 3.67 | C7: 1 | D7: 20 | E7: 20 | F7: =D7*1.6726219E-27 -> 3.3452438e-26 | G7: =E7*9.1093856E-31 -> 1.8218771e-29 | H7: =((F7*D7)/(G7*E7)) -> 1836.1523 | I7: =D7/E7 -> 1 | J7: =(F7)-(G7) -> 3.3434219e-26 | K7: 42.394 | L7: =0.0726*EXP(22400/(8.3144598*N7))/1000 -> 0.0015609789 | M7: =N7^-1 -> 0.0011388225 | N7: 878.1 | O7: =K7/W7 -> 2.8281521e-05 | P7: 0.000288 | R7: 7.6e-11 | S7: 1.81e-10 | T7: =S7+R7 -> 2.57e-10 | U7: =S7/R7 -> 2.3815789 | V7: =T7*10000000000 -> 2.57 | W7: 1499000 | X7: 2787.9043 | Y7: -0.849 | Z7: 1.8842 | AA7: -0.0004328 | AB7: 1 | AC7: 1 | AD7: =AB7+AC7 -> 2 | AE7: 0.6126 | AF7: =1/3*BC7*AV7*T7 -> 0.40225026 | AG7: =ABS((AE7-AF7)/AE7) -> 0.34337209 | AH7: =1/3*BC7*AV7*AP7 -> 0.37226977 | AI7: =1/3*BC7*AV7*AQ7 -> 0.46741266 | AJ7: 0.40224439 | AK7: =(AE7-AJ7)/AE7 -> 0.34338166 | AL7: =AE7/(1/3*AV7*T7) -> 3501264 | AM7: =AE7/(1/3*AV7*AR7) -> 2299027.7 | AN7: 1.5651533e+09 | AO7: =AJ7/AN7 -> 2.57e-10 | AP7: 2.378453e-10 | AQ7: 2.9863264e-10 | AR7: =AE7/(1/3*BC7*AV7) -> 3.9139366e-10 | AS7: =AE7/AN7 -> 3.9139937e-10 | AT7: =(AS7-AO7)/AO7 -> 0.52295473 | AU7: =AJ7/AV7 -> 0.00019694717 | AV7: =X7+Y7*N7 -> 2042.3974 | AW7: 3500 | AX7: =AE7/AU7 -> 3110.4789 | AY7: =(AX7-AV7)/AV7 -> 0.52295473 | AZ7: =AJ7/BA7 -> 0.0061864717 | BA7: 65.02 | BB7: =BC7/1000000 -> 2.2990277 | BC7: =BA7/O7 -> 2299027.7 | BD7: =AE7/(AZ7) -> 99.022517 | BE7: =(BD7-BA7)/BA7 -> 0.52295473 | BF7: =AV7*BC7 -> 4.6955283e+09 | BG7: =BF7*0.0000000001 -> 0.46955283 | BH7: =BF7*T7 -> 1.2067508 | BI7: 5.804497 | BJ7: -0.00044547221 | BK7: 0.88854851 | BL7: =SQRT(BK7)/BI7 -> 0.16239624 | BM7: =SQRT(1/BI7) -> 0.41506652 | BN7: 2.36e-10 | BO7: =BN7*SQRT(BK7/BI7) -> 9.2335835e-11 | BP7: =SQRT(ABS(BJ7))/BI7 -> 0.0036361829 | BQ7: =AV7^(2/3)*O7 -> 0.0045526361 | BR7: =L7/(W7/1000*(X7+Y7*N7)) -> 5.0986493e-10
A8: NaCl | B8: 3.94 | C8: 1 | D8: 28 | E8: 28 | F8: =D8*1.6726219E-27 -> 4.6833413e-26 | G8: =E8*9.1093856E-31 -> 2.550628e-29 | H8: =((F8*D8)/(G8*E8)) -> 1836.1523 | I8: =D8/E8 -> 1 | J8: =(F8)-(G8) -> 4.6807907e-26 | K8: 58.44 | L8: =0.0893*EXP(22000/(8.3144598*N8))/1000 -> 0.0010321391 | M8: =N8^-1 -> 0.00092494104 | N8: 1081.15 | O8: 3.765e-05 | P8: 0.00035 | R8: 1.02e-10 | S8: 1.81e-10 | T8: =S8+R8 -> 2.83e-10 | U8: =S8/R8 -> 1.7745098 | V8: =T8*10000000000 -> 2.83 | W8: 1560000 | X8: 2732.9322 | Y8: -0.915 | Z8: 2.1393 | AA8: -0.000543 | AB8: 1 | AC8: 1 | AD8: =AB8+AC8 -> 2 | AE8: 0.4665 | AF8: =1/3*BC8*AV8*T8 -> 0.30415923 | AG8: =ABS((AE8-AF8)/AE8) -> 0.34799736 | AH8: =1/3*BC8*AV8*AP8 -> 0.28617344 | AI8: =1/3*BC8*AV8*AQ8 -> 0.34614447 | AJ8: 0.30612615 | AK8: =(AE8-AJ8)/AE8 -> 0.34378102 | AL8: =AE8/(1/3*AV8*T8) -> 2836087.9 | AM8: =AE8/(1/3*AV8*AR8) -> 1849136.8 | AN8: 1.0817179e+09 | AO8: =AJ8/AN8 -> 2.83e-10 | AP8: 2.6626541e-10 | AQ8: 3.2206448e-10 | AR8: =AE8/(1/3*BC8*AV8) -> 4.3404732e-10 | AS8: =AE8/AN8 -> 4.3125848e-10 | AT8: =(AS8-AO8)/AO8 -> 0.52388156 | AU8: =AJ8/AV8 -> 0.00017556326 | AV8: =X8+Y8*N8 -> 1743.68 | AW8: 2720 | AX8: =AE8/AU8 -> 2657.1618 | AY8: =(AX8-AV8)/AV8 -> 0.52388156 | AZ8: =AJ8/BA8 -> 0.0043971007 | BA8: 69.62 | BB8: =BC8/1000000 -> 1.8491368 | BC8: =BA8/O8 -> 1849136.8 | BD8: =AE8/(AZ8) -> 106.09263 | BE8: =(BD8-BA8)/BA8 -> 0.52388156 | BF8: =AV8*BC8 -> 3.2243028e+09 | BG8: =BF8*0.0000000001 -> 0.32243028 | BH8: =BF8*T8 -> 0.9124777 | BI8: 13.945766 | BJ8: -0.0023782148 | BK8: 0.89095701 | BL8: =SQRT(BK8)/BI8 -> 0.067683998 | BM8: =SQRT(1/BI8) -> 0.26778042 | BN8: 2.64e-10 | BO8: =BN8*SQRT(BK8/BI8) -> 6.6728462e-11 | BP8: =SQRT(ABS(BJ8))/BI8 -> 0.0034968996 | BQ8: =AV8^(2/3)*O8 -> 0.0054543479 | BR8: =L8/(W8/1000*(X8+Y8*N8)) -> 3.7944326e-10
A9: KCl | B9: 3.34 | C9: 1 | D9: 36 | E9: 36 | F9: =D9*1.6726219E-27 -> 6.0214388e-26 | G9: =E9*9.1093856E-31 -> 3.2793788e-29 | H9: =((F9*D9)/(G9*E9)) -> 1836.1523 | I9: =D9/E9 -> 1 | J9: =(F9)-(G9) -> 6.0181595e-26 | K9: 74.5513 | L9: =0.0708*EXP(23900/(8.3144598*N9))/1000 -> 0.0011078669 | M9: =N9^-1 -> 0.00095680046 | N9: 1045.15 | O9: 4.884e-05 | P9: 0.000382 | R9: 1.38e-10 | S9: 1.81e-10 | T9: =S9+R9 -> 3.19e-10 | U9: =S9/R9 -> 1.3115942 | V9: =T9*10000000000 -> 3.19 | W9: 1530000 | X9: 2514.8257 | Y9: -0.878 | Z9: 2.1359 | AA9: -0.0005831 | AB9: 1 | AC9: 1 | AD9: =AB9+AC9 -> 2 | AE9: 0.35505 | AF9: =1/3*BC9*AV9*T9 -> 0.25593315 | AG9: =ABS((AE9-AF9)/AE9) -> 0.27916308 | AH9: =1/3*BC9*AV9*AP9 -> 0.23977579 | AI9: =1/3*BC9*AV9*AQ9 -> 0.2878106 | AJ9: 0.25652334 | AK9: =(AE9-AJ9)/AE9 -> 0.2775008 | AL9: =AE9/(1/3*AV9*T9) -> 2090572 | AM9: =AE9/(1/3*AV9*AR9) -> 1506961.5 | AN9: 8.041484e+08 | AO9: =AJ9/AN9 -> 3.19e-10 | AP9: 2.9886116e-10 | AQ9: 3.5873267e-10 | AR9: =AE9/(1/3*BC9*AV9) -> 4.4254115e-10 | AS9: =AE9/AN9 -> 4.4152298e-10 | AT9: =(AS9-AO9)/AO9 -> 0.38408459 | AU9: =AJ9/AV9 -> 0.00016060976 | AV9: =X9+Y9*N9 -> 1597.184 | AW9: 2360 | AX9: =AE9/AU9 -> 2210.6378 | AY9: =(AX9-AV9)/AV9 -> 0.38408459 | AZ9: =AJ9/BA9 -> 0.0034853715 | BA9: 73.6 | BB9: =BC9/1000000 -> 1.5069615 | BC9: =BA9/O9 -> 1506961.5 | BD9: =AE9/(AZ9) -> 101.86863 | BE9: =(BD9-BA9)/BA9 -> 0.38408459 | BF9: =AV9*BC9 -> 2.4068948e+09 | BG9: =BF9*0.0000000001 -> 0.24068948 | BH9: =BF9*T9 -> 0.76779944 | BI9: 18.592439 | BJ9: -0.0036120436 | BK9: 0.8909863 | BL9: =SQRT(BK9)/BI9 -> 0.050769063 | BM9: =SQRT(1/BI9) -> 0.23191659 | BN9: 2.96e-10 | BO9: =BN9*SQRT(BK9/BI9) -> 6.4797618e-11 | BP9: =SQRT(ABS(BJ9))/BI9 -> 0.0032325119 | BQ9: =AV9^(2/3)*O9 -> 0.0066733764 | BR9: =L9/(W9/1000*(X9+Y9*N9)) -> 4.5335792e-10
A10: BeF2 | B10: 0.52 | C10: 1 | D10: 13 | E10: 12 | F10: =D10*1.6726219E-27 -> 2.1744085e-26 | G10: =E10*9.1093856E-31 -> 1.0931263e-29 | H10: =((F10*D10)/(G10*E10)) -> 2154.9287 | I10: =D10/E10 -> 1.0833333 | J10: =(F10)-(G10) -> 2.1733153e-26 | K10: 47.01 | L10: =10^(-8.12+11500/N10+639000/N10^2)/1000 -> 1.5280163 | M10: =N10^-1 -> 0.00093444844 | N10: 1070.15 | O10: 2.4e-05 | P10: 7.42e-06 | R10: 3.4e-11 | S10: 1.33e-10 | T10: =S10+R10 -> 1.67e-10 | U10: =S10/R10 -> 3.9117647 | V10: =T10*10000000000 -> 1.67 | W10: 1960000 | X10: 2547.8 | Y10: 0 | Z10: 1.972 | AA10: -1.45e-05 | AB10: 1 | AC10: 2 | AD10: =AB10+AC10 -> 3 | AE10: 0.79925906 | AF10: =1/3*BC10*AV10*T10 -> 0.51944334 | AG10: =ABS((AE10-AF10)/AE10) -> 0.35009389 | AJ10: 0.51979939 | AK10: =(AE10-AJ10)/AE10 -> 0.34964842 | AL10: =AE10/(1/3*AV10*T10) -> 5635429.4 | AM10: =AE10/(1/3*AV10*AR10) -> 3662500 | AN10: 3.1125712e+09 | AO10: =AJ10/AN10 -> 1.67e-10 | AR10: =AE10/(1/3*BC10*AV10) -> 2.569602e-10 | AS10: =AE10/AN10 -> 2.5678419e-10 | AT10: =(AS10-AO10)/AO10 -> 0.53762986 | AU10: =AJ10/AV10 -> 0.00020401891 | AV10: =X10+Y10*N10 -> 2547.8 | AX10: =AE10/AU10 -> 3917.5733 | AY10: =(AX10-AV10)/AV10 -> 0.53762986 | AZ10: =AJ10/BA10 -> 0.0059135311 | BA10: 87.9 | BB10: =BC10/1000000 -> 3.6625 | BC10: =BA10/O10 -> 3662500 | BD10: =AE10/(AZ10) -> 135.15766 | BE10: =(BD10-BA10)/BA10 -> 0.53762986 | BF10: =AV10*BC10 -> 9331317500 | BG10: =BF10*0.0000000001 -> 0.93313175 | BH10: =BF10*T10 -> 1.55833 | BI10: 6.112585 | BJ10: -4.1051313e-06 | BM10: =SQRT(1/BI10) -> 0.40447114 | BO10: =T10*SQRT(0.9/BI10) -> 6.4080408e-11 | BP10: =SQRT(ABS(BJ10))/BI10 -> 0.00033146571 | BQ10: =AV10^(2/3)*O10 -> 0.0044770107
A11: MgF2 | B11: 0.02 | C11: 1 | D11: 21 | E11: 20 | F11: =D11*1.6726219E-27 -> 3.512506e-26 | G11: =E11*9.1093856E-31 -> 1.8218771e-29 | H11: =((F11*D11)/(G11*E11)) -> 2024.3579 | I11: =D11/E11 -> 1.05 | J11: =(F11)-(G11) -> 3.5106841e-26 | K11: 62.3018 | L11: =0.187*EXP(32100/(8.3144598*N11))/1000 -> 0.002315921 | M11: =N11^-1 -> 0.0006518055 | N11: 1534.2 | O11: =K11/W11 -> 2.557462e-05 | P11: 0.000216 | R11: 7.2e-11 | S11: 1.33e-10 | T11: =S11+R11 -> 2.05e-10 | U11: =S11/R11 -> 1.8472222 | V11: =T11*10000000000 -> 2.05 | W11: =(Z11+N11*AA11)*1000000 -> 2436079.2 | X11: 2175.6 | Y11: 0 | Z11: 3.24 | AA11: -0.000524 | AB11: 1 | AC11: 2 | AD11: =AB11+AC11 -> 3 | AE11: 0.6506778 | AF11: =1/3*BC11*AV11*T11 -> 0.55165642 | AG11: =ABS((AE11-AF11)/AE11) -> 0.15218189 | AJ11: 0.55165642 | AK11: =(AE11-AJ11)/AE11 -> 0.15218189 | AL11: =AE11/(1/3*AV11*T11) -> 4376776.1 | AM11: =AE11/(1/3*AV11*AR11) -> 3710710.1 | AN11: 2.6910069e+09 | AO11: =AJ11/AN11 -> 2.05e-10 | AR11: =AE11/(1/3*BC11*AV11) -> 2.4179715e-10 | AS11: =AE11/AN11 -> 2.4179715e-10 | AT11: =(AS11-AO11)/AO11 -> 0.17949828 | AU11: =AJ11/AV11 -> 0.00025356519 | AV11: =X11+Y11*N11 -> 2175.6 | AX11: =AE11/AU11 -> 2566.1165 | AY11: =(AX11-AV11)/AV11 -> 0.17949828 | AZ11: =AJ11/BA11 -> 0.0058130287 | BA11: 94.9 | BB11: =BC11/1000000 -> 3.7107101 | BC11: =BA11/O11 -> 3710710.1 | BD11: =AE11/(AZ11) -> 111.93439 | BE11: =(BD11-BA11)/BA11 -> 0.17949828 | BF11: =AV11*BC11 -> 8.0730208e+09 | BG11: =BF11*0.0000000001 -> 0.80730208 | BH11: =BF11*T11 -> 1.6549693 | BI11: 10.663277 | BJ11: -4.942153e-05 | BM11: =SQRT(1/BI11) -> 0.30623488 | BO11: =T11*SQRT(0.9/BI11) -> 5.9556583e-11 | BP11: =SQRT(ABS(BJ11))/BI11 -> 0.00065927621 | BQ11: =AV11^(2/3)*O11 -> 0.0042939985 | BR11: =L11/(W11/1000*(X11+Y11*N11)) -> 4.3697168e-10
A12: CaF2 | B12: 0.12 | C12: 1 | D12: 29 | E12: 28 | F12: =D12*1.6726219E-27 -> 4.8506035e-26 | G12: =E12*9.1093856E-31 -> 2.550628e-29 | H12: =((F12*D12)/(G12*E12)) -> 1969.648 | I12: =D12/E12 -> 1.0357143 | J12: =(F12)-(G12) -> 4.8480529e-26 | K12: 78.0748 | L12: =0.1*EXP(47600/(8.3144598*N12))/1000 -> 0.0029475213 | M12: =N12^-1 -> 0.00059101655 | N12: 1692 | O12: =K12/W12 -> 3.1001402e-05 | P12: 0.000155 | R12: 1e-10 | S12: 1.33e-10 | T12: =S12+R12 -> 2.33e-10 | U12: =S12/R12 -> 1.33 | V12: =T12*10000000000 -> 2.33 | W12: =(Z12+N12*AA12)*1000000 -> 2518428 | X12: 1710.3 | Y12: 0 | Z12: 3.18 | AA12: -0.000391 | AB12: 1 | AC12: 2 | AD12: =AB12+AC12 -> 3 | AE12: 0.5648032 | AF12: =1/3*BC12*AV12*T12 -> 0.42810664 | AG12: =ABS((AE12-AF12)/AE12) -> 0.24202511 | AJ12: 0.42810664 | AK12: =(AE12-AJ12)/AE12 -> 0.24202511 | AL12: =AE12/(1/3*AV12*T12) -> 4251970 | AM12: =AE12/(1/3*AV12*AR12) -> 3222886.5 | AN12: 1.8373676e+09 | AO12: =AJ12/AN12 -> 2.33e-10 | AR12: =AE12/(1/3*BC12*AV12) -> 3.0739805e-10 | AS12: =AE12/AN12 -> 3.0739805e-10 | AT12: =(AS12-AO12)/AO12 -> 0.31930492 | AU12: =AJ12/AV12 -> 0.00025031085 | AV12: =X12+Y12*N12 -> 1710.3 | AX12: =AE12/AU12 -> 2256.4072 | AY12: =(AX12-AV12)/AV12 -> 0.31930492 | AZ12: =AJ12/BA12 -> 0.0042847513 | BA12: 99.914 | BB12: =BC12/1000000 -> 3.2228865 | BC12: =BA12/O12 -> 3222886.5 | BD12: =AE12/(AZ12) -> 131.81703 | BE12: =(BD12-BA12)/BA12 -> 0.31930492 | BF12: =AV12*BC12 -> 5.5121027e+09 | BG12: =BF12*0.0000000001 -> 0.55121027 | BH12: =BF12*T12 -> 1.2843199 | BI12: 12.888699 | BJ12: -0.00020540721 | BM12: =SQRT(1/BI12) -> 0.27854506 | BO12: =T12*SQRT(0.9/BI12) -> 6.1570494e-11 | BP12: =SQRT(ABS(BJ12))/BI12 -> 0.0011119846 | BQ12: =AV12^(2/3)*O12 -> 0.004433665 | BR12: =L12/(W12/1000*(X12+Y12*N12)) -> 6.8431351e-10
A13: SrF2 | C13: 1 | D13: 47 | E13: 46 | F13: =D13*1.6726219E-27 -> 7.8613229e-26 | G13: =E13*9.1093856E-31 -> 4.1903174e-29 | H13: =((F13*D13)/(G13*E13)) -> 1916.8527 | I13: =D13/E13 -> 1.0217391 | J13: =(F13)-(G13) -> 7.8571326e-26 | K13: 125.6168 | L13: =0.0703*EXP(54500/(8.3144598*N13))/1000 -> 0.0030018345 | M13: =N13^-1 -> 0.00057273769 | N13: 1746 | O13: =K13/W13 -> 3.621381e-05 | P13: 0.000213 | R13: 1.18e-10 | S13: 1.33e-10 | T13: =S13+R13 -> 2.51e-10 | U13: =S13/R13 -> 1.1271186 | V13: =T13*10000000000 -> 2.51 | W13: =(Z13+N13*AA13)*1000000 -> 3468754 | X13: 1398.6 | Y13: 0 | Z13: 4.78 | AA13: -0.000751 | AB13: 1 | AC13: 2 | AD13: =AB13+AC13 -> 3 | AE13: 0.390415 | AF13: =1/3*BC13*AV13*T13 -> 0.31989464 | AG13: =ABS((AE13-AF13)/AE13) -> 0.18062923 | AJ13: 0.31989464 | AK13: =(AE13-AJ13)/AE13 -> 0.18062923 | AL13: =AE13/(1/3*AV13*T13) -> 3336418.4 | AM13: =AE13/(1/3*AV13*AR13) -> 2733763.7 | AN13: 1.2744806e+09 | AO13: =AJ13/AN13 -> 2.51e-10 | AR13: =AE13/(1/3*BC13*AV13) -> 3.0633263e-10 | AS13: =AE13/AN13 -> 3.0633263e-10 | AT13: =(AS13-AO13)/AO13 -> 0.22044872 | AU13: =AJ13/AV13 -> 0.00022872489 | AV13: =X13+Y13*N13 -> 1398.6 | AX13: =AE13/AU13 -> 1706.9196 | AY13: =(AX13-AV13)/AV13 -> 0.22044872 | AZ13: =AJ13/BA13 -> 0.003231259 | BA13: 99 | BB13: =BC13/1000000 -> 2.7337637 | BC13: =BA13/O13 -> 2733763.7 | BD13: =AE13/(AZ13) -> 120.82442 | BE13: =(BD13-BA13)/BA13 -> 0.22044872 | BF13: =AV13*BC13 -> 3.8234419e+09 | BG13: =BF13*0.0000000001 -> 0.38234419 | BH13: =BF13*T13 -> 0.95968391 | BI13: 15.613065 | BJ13: -0.00046321913 | BM13: =SQRT(1/BI13) -> 0.25307889 | BO13: =T13*SQRT(0.9/BI13) -> 6.026302e-11 | BP13: =SQRT(ABS(BJ13))/BI13 -> 0.0013784946 | BQ13: =AV13^(2/3)*O13 -> 0.0045290096 | BR13: =L13/(W13/1000*(X13+Y13*N13)) -> 6.1875642e-10
A14: MgCl2 | B14: 0.8 | C14: 1 | D14: 29 | E14: 28 | F14: =D14*1.6726219E-27 -> 4.8506035e-26 | G14: =E14*9.1093856E-31 -> 2.550628e-29 | H14: =((F14*D14)/(G14*E14)) -> 1969.648 | I14: =D14/E14 -> 1.0357143 | J14: =(F14)-(G14) -> 4.8480529e-26 | K14: 95.211 | L14: =0.18*EXP(20500/(8.3144598*N14))/1000 -> 0.0021885965 | M14: =N14^-1 -> 0.0010131712 | N14: 987 | O14: =K14/W14 -> 5.6510276e-05 | P14: 0.00018 | R14: 7.2e-11 | S14: 1.81e-10 | T14: =S14+R14 -> 2.53e-10 | U14: =S14/R14 -> 2.5138889 | V14: =T14*10000000000 -> 2.53 | W14: =(Z14+N14*AA14)*1000000 -> 1684844 | X14: 2101 | Y14: 0 | Z14: 1.9691 | AA14: -0.000288 | AB14: 1 | AC14: 2 | AD14: =AB14+AC14 -> 3 | AE14: 0.4568 | AF14: =1/3*BC14*AV14*T14 -> 0.28861058 | AG14: =ABS((AE14-AF14)/AE14) -> 0.3681905 | AH14: =1/3*BC14*AV14*AP14 -> 0.26994066 | AI14: =1/3*BC14*AV14*AQ14 -> 0.33370075 | AJ14: 0.28861058 | AK14: =(AE14-AJ14)/AE14 -> 0.3681905 | AL14: =AE14/(1/3*AV14*T14) -> 2578106 | AM14: =AE14/(1/3*AV14*AR14) -> 1628871.9 | AN14: 1.1407533e+09 | AO14: =AJ14/AN14 -> 2.53e-10 | AP14: 2.3663369e-10 | AQ14: 2.9252667e-10 | AR14: =AE14/(1/3*BC14*AV14) -> 4.0043716e-10 | AS14: =AE14/AN14 -> 4.0043716e-10 | AT14: =(AS14-AO14)/AO14 -> 0.58275557 | AU14: =AJ14/AV14 -> 0.0001373682 | AV14: =X14+Y14*N14 -> 2101 | AW14: 3400 | AX14: =AE14/AU14 -> 3325.3695 | AY14: =(AX14-AV14)/AV14 -> 0.58275557 | AZ14: =AJ14/BA14 -> 0.0031354356 | BA14: 92.048 | BB14: =BC14/1000000 -> 1.6288719 | BC14: =BA14/O14 -> 1628871.9 | BD14: =AE14/(AZ14) -> 145.68948 | BE14: =(BD14-BA14)/BA14 -> 0.58275557 | BF14: =AV14*BC14 -> 3.4222598e+09 | BG14: =BF14*0.0000000001 -> 0.34222598 | BH14: =BF14*T14 -> 0.86583173 | BI14: 14.419082 | BJ14: -0.00017252442 | BK14: 0.94057284 | BL14: =SQRT(BK14)/BI14 -> 0.06726027 | BM14: =SQRT(1/BI14) -> 0.26334871 | BN14: 2.36e-10 | BO14: =BN14*SQRT(BK14/BI14) -> 6.0275304e-11 | BP14: =SQRT(ABS(BJ14))/BI14 -> 0.0009109356 | BQ14: =AV14^(2/3)*O14 -> 0.0092699658 | BR14: =L14/(W14/1000*(X14+Y14*N14)) -> 6.1827252e-10
A15: CaCl2 | B15: 2.5 | C15: 1 | D15: 37 | E15: 36 | F15: =D15*1.6726219E-27 -> 6.188701e-26 | G15: =E15*9.1093856E-31 -> 3.2793788e-29 | H15: =((F15*D15)/(G15*E15)) -> 1939.5775 | I15: =D15/E15 -> 1.0277778 | J15: =(F15)-(G15) -> 6.1854217e-26 | K15: 110.984 | L15: =10^(-0.545+597/N15+546000/N15^2)/1000 -> 0.0033595447 | M15: =N15^-1 -> 0.0009569378 | N15: 1045 | O15: =K15/W15 -> 5.3154148e-05 | P15: 0.000203 | R15: 1e-10 | S15: 1.81e-10 | T15: =S15+R15 -> 2.81e-10 | U15: =S15/R15 -> 1.81 | V15: =T15*10000000000 -> 2.81 | W15: =(Z15+N15*AA15)*1000000 -> 2087965 | X15: 2065.03 | Y15: 0 | Z15: 2.53 | AA15: -0.000423 | AE15: 0.44125 | AF15: =1/3*BC15*AV15*T15 -> 0.3731109 | AG15: =ABS((AE15-AF15)/AE15) -> 0.15442289 | AH15: =1/3*BC15*AV15*AP15 -> 0.3702431 | AI15: =1/3*BC15*AV15*AQ15 -> 0.400395 | AL15: =AE15/(1/3*AV15*T15) -> 2281252.1 | AM15: =AE15/(1/3*AV15*AR15) -> 1928974.6 | AP15: 2.7884018e-10 | AQ15: 3.015484e-10 | AR15: =AE15/(1/3*BC15*AV15) -> 3.3231742e-10 | AV15: =X15+Y15*N15 -> 2065.03 | AW15: 2200 | AZ15: =AJ15/BA15 -> 0 | BA15: 102.533 | BB15: =BC15/1000000 -> 1.9289746 | BC15: =BA15/O15 -> 1928974.6 | BF15: =AV15*BC15 -> 3.9833904e+09 | BG15: =BF15*0.0000000001 -> 0.39833904 | BH15: =BF15*T15 -> 1.1193327 | BI15: 18.811104 | BJ15: -0.00016920232 | BK15: 0.99389548 | BL15: =SQRT(BK15)/BI15 -> 0.052997584 | BM15: =SQRT(1/BI15) -> 0.23056472 | BN15: 2.78e-10 | BO15: =BN15*SQRT(BK15/BI15) -> 6.3901053e-11 | BP15: =SQRT(ABS(BJ15))/BI15 -> 0.00069149472 | BQ15: =AV15^(2/3)*O15 -> 0.008619619 | BR15: =L15/(W15/1000*(X15+Y15*N15)) -> 7.7916752e-10
A16: SrCl2 | C16: 1 | D16: 55 | E16: 54 | F16: =D16*1.6726219E-27 -> 9.1994204e-26 | G16: =E16*9.1093856E-31 -> 4.9190682e-29 | H16: =((F16*D16)/(G16*E16)) -> 1904.7876 | I16: =D16/E16 -> 1.0185185 | J16: =(F16)-(G16) -> 9.1945014e-26 | K16: 158.526 | L16: =10^(-0.439+398/N16+879000/N16^2)/1000 -> 0.0037808819 | M16: =N16^-1 -> 0.00087260035 | N16: 1146 | O16: =K16/W16 -> 5.811897e-05 | P16: 0.000212 | R16: 1.18e-10 | S16: 1.81e-10 | T16: =S16+R16 -> 2.99e-10 | U16: =S16/R16 -> 1.5338983 | V16: =T16*10000000000 -> 2.99 | W16: =(Z16+N16*AA16)*1000000 -> 2727612 | X16: 1873.13 | Y16: 0 | Z16: 3.39 | AA16: -0.000578 | AB16: 1 | AC16: 2 | AD16: =AB16+AC16 -> 3 | AE16: 0.37705 | AF16: =1/3*BC16*AV16*T16 -> 0.33599408 | AG16: =ABS((AE16-AF16)/AE16) -> 0.1088872 | AH16: =1/3*BC16*AV16*AP16 -> 0.32666099 | AI16: =1/3*BC16*AV16*AQ16 -> 0.36759448 | AJ16: 0.33599408 | AK16: =(AE16-AJ16)/AE16 -> 0.1088872 | AL16: =AE16/(1/3*AV16*T16) -> 2019673.2 | AM16: =AE16/(1/3*AV16*AR16) -> 1799756.6 | AN16: 1.123726e+09 | AO16: =AJ16/AN16 -> 2.99e-10 | AP16: 2.9069451e-10 | AQ16: 3.2712108e-10 | AR16: =AE16/(1/3*BC16*AV16) -> 3.3553552e-10 | AS16: =AE16/AN16 -> 3.3553552e-10 | AT16: =(AS16-AO16)/AO16 -> 0.12219238 | AU16: =AJ16/AV16 -> 0.00017937574 | AV16: =X16+Y16*N16 -> 1873.13 | AX16: =AE16/AU16 -> 2102.0122 | AY16: =(AX16-AV16)/AV16 -> 0.12219238 | AZ16: =AJ16/BA16 -> 0.0032121805 | BA16: 104.6 | BB16: =BC16/1000000 -> 1.7997566 | BC16: =BA16/O16 -> 1799756.6 | BD16: =AE16/(AZ16) -> 117.38132 | BE16: =(BD16-BA16)/BA16 -> 0.12219238 | BF16: =AV16*BC16 -> 3.3711781e+09 | BG16: =BF16*0.0000000001 -> 0.33711781 | BH16: =BF16*T16 -> 1.0079822 | BI16: 25.238718 | BJ16: -0.00038382394 | BK16: 0.9081546 | BL16: =SQRT(BK16)/BI16 -> 0.037758315 | BM16: =SQRT(1/BI16) -> 0.19905191 | BN16: 2.9e-10 | BO16: =BN16*SQRT(BK16/BI16) -> 5.501033e-11 | BP16: =SQRT(ABS(BJ16))/BI16 -> 0.00077624486 | BQ16: =AV16^(2/3)*O16 -> 0.0088314061 | BR16: =L16/(W16/1000*(X16+Y16*N16)) -> 7.4001854e-10
A17: NaNO3 | B17: 0.3 | C17: 1 | D17: 26 | E17: 25 | F17: =D17*1.6726219E-27 -> 4.3488169e-26 | G17: =E17*9.1093856E-31 -> 2.2773464e-29 | H17: =((F17*D17)/(G17*E17)) -> 1985.9823 | I17: =D17/E17 -> 1.04 | J17: =(F17)-(G17) -> 4.3465396e-26 | K17: 84.99 | M17: =N17^-1 -> 0.0017148247 | N17: 583.15 | O17: 4.467e-05 | P17: 0.000376 | R17: 1.02e-10 | S17: 2.31e-10 | T17: =S17+R17 -> 3.33e-10 | U17: =S17/R17 -> 2.2647059 | V17: =T17*10000000000 -> 3.33 | W17: =(Z17+N17*AA17)*1000000 -> 1886915.5 | X17: 2490.4882 | Y17: -1.155 | Z17: 2.3339 | AA17: -0.0007665 | AB17: 2 | AC17: 3 | AD17: =AB17+AC17 -> 5 | AE17: 0.51225 | AF17: =1/3*BC17*AV17*T17 -> 0.70252146 | AG17: =ABS((AE17-AF17)/AE17) -> 0.37144258 | AH17: =1/3*BC17*AV17*AP17 -> 0.43236429 | AJ17: 0.6982846 | AK17: =(AE17-AJ17)/AE17 -> -0.36317149 | AL17: =AE17/(1/3*AV17*T17) -> 2539896.5 | AM17: =AE17/(1/3*AV17*AR17) -> 3483322.1 | AN17: 2.0969507e+09 | AO17: =AJ17/AN17 -> 3.33e-10 | AP17: 2.0494365e-10 | AR17: =AE17/(1/3*BC17*AV17) -> 2.4281002e-10 | AS17: =AE17/AN17 -> 2.4428328e-10 | AT17: =(AS17-AO17)/AO17 -> -0.26641658 | AU17: =AJ17/AV17 -> 0.0003843169 | AV17: =X17+Y17*N17 -> 1816.95 | AX17: =AE17/AU17 -> 1332.8844 | AY17: =(AX17-AV17)/AV17 -> -0.26641658 | AZ17: =AJ17/BA17 -> 0.0044876902 | BA17: 155.6 | BB17: =BC17/1000000 -> 3.4833221 | BC17: =BA17/O17 -> 3483322.1 | BD17: =AE17/(AZ17) -> 114.14558 | BE17: =(BD17-BA17)/BA17 -> -0.26641658 | BF17: =AV17*BC17 -> 6.3290222e+09 | BG17: =BF17*0.0000000001 -> 0.63290222 | BH17: =BF17*T17 -> 2.1075644 | BI17: 16.771319 | BJ17: -0.0062307897 | BM17: =SQRT(1/BI17) -> 0.24418354 | BO17: =T17*SQRT(0.9/BI17) -> 7.7140399e-11 | BP17: =SQRT(ABS(BJ17))/BI17 -> 0.0047065679 | BQ17: =AV17^(2/3)*O17 -> 0.0066513725
A18: KNO3 | B18: 0.2 | C18: 1 | D18: 34 | E18: 33 | F18: =D18*1.6726219E-27 -> 5.6869145e-26 | G18: =E18*9.1093856E-31 -> 3.0060972e-29 | H18: =((F18*D18)/(G18*E18)) -> 1949.1203 | I18: =D18/E18 -> 1.030303 | J18: =(F18)-(G18) -> 5.6839084e-26 | K18: 101.1 | M18: =N18^-1 -> 0.0016389412 | N18: 610.15 | O18: 5.406e-05 | P18: 0.00039 | R18: 1.38e-10 | S18: 2.31e-10 | T18: =S18+R18 -> 3.69e-10 | U18: =S18/R18 -> 1.673913 | V18: =T18*10000000000 -> 3.69 | W18: =(Z18+N18*AA18)*1000000 -> 1870200.6 | X18: 2449.928 | Y18: -1.12 | Z18: 2.315 | AA18: -0.000729 | AB18: 2 | AC18: 3 | AD18: =AB18+AC18 -> 5 | AE18: 0.4092 | AF18: =1/3*BC18*AV18*T18 -> 0.56673049 | AG18: =ABS((AE18-AF18)/AE18) -> 0.38497186 | AJ18: 0.53083305 | AK18: =(AE18-AJ18)/AE18 -> -0.29724596 | AL18: =AE18/(1/3*AV18*T18) -> 1883224.6 | AM18: =AE18/(1/3*AV18*AR18) -> 2608213.1 | AN18: 1.4385719e+09 | AO18: =AJ18/AN18 -> 3.69e-10 | AR18: =AE18/(1/3*BC18*AV18) -> 2.6643141e-10 | AS18: =AE18/AN18 -> 2.8444876e-10 | AT18: =(AS18-AO18)/AO18 -> -0.22913616 | AU18: =AJ18/AV18 -> 0.00030048968 | AV18: =X18+Y18*N18 -> 1766.56 | AX18: =AE18/AU18 -> 1361.7772 | AY18: =(AX18-AV18)/AV18 -> -0.22913616 | AZ18: =AJ18/BA18 -> 0.0037647734 | BA18: 141 | BB18: =BC18/1000000 -> 2.6082131 | BC18: =BA18/O18 -> 2608213.1 | BD18: =AE18/(AZ18) -> 108.6918 | BE18: =(BD18-BA18)/BA18 -> -0.22913616 | BF18: =AV18*BC18 -> 4.6075649e+09 | BG18: =BF18*0.0000000001 -> 0.46075649 | BH18: =BF18*T18 -> 1.7001915 | BI18: 23.978198 | BJ18: -0.010344196 | BM18: =SQRT(1/BI18) -> 0.20421692 | BO18: =T18*SQRT(0.9/BI18) -> 7.1489021e-11 | BP18: =SQRT(ABS(BJ18))/BI18 -> 0.0042416208 | BQ18: =AV18^(2/3)*O18 -> 0.007900022
A19: ZrF4 | B19: 0.05 | C19: 1 | D19: 49 | E19: 46 | F19: =D19*1.6726219E-27 -> 8.1958473e-26 | G19: =E19*9.1093856E-31 -> 4.1903174e-29 | H19: =((F19*D19)/(G19*E19)) -> 2083.4601 | I19: =D19/E19 -> 1.0652174 | J19: =(F19)-(G19) -> 8.191657e-26 | K19: 167.21 | M19: =N19^-1 -> 0.00083963056 | N19: 1191 | O19: =K19/W19 -> 4.2928625e-05 | P19: 0.000309 | R19: 7.2e-11 | S19: 1.33e-10 | T19: =S19+R19 -> 2.05e-10 | U19: =S19/R19 -> 1.8472222 | V19: =T19*10000000000 -> 2.05 | W19: =(5.36-0.00123*N19)*1000000 -> 3895070 | X19: 1700 | Y19: 0 | Z19: 5.36 | AA19: -0.00123 | AF19: =1/3*BC19*AV19*T19 -> 0.33284318 | AL19: =AE19/(1/3*AV19*T19) -> 0 | AM19: =AE19/(1/3*AV19*AR19) -> #DIV/0! | AR19: =AE19/(1/3*BC19*AV19) -> 0 | AV19: =X19+Y19*N19 -> 1700 | AZ19: =AJ19/BA19 -> 0 | BA19: 123 | BB19: =BC19/1000000 -> 2.865221 | BC19: =BA19/O19 -> 2865221 | BF19: =AV19*BC19 -> 4.8708758e+09 | BG19: =BF19*0.0000000001 -> 0.48708758 | BH19: =BF19*T19 -> 0.99852953 | BI19: 15.723757 | BJ19: -1.6744797e-08 | BM19: =SQRT(1/BI19) -> 0.2521865 | BO19: =T19*SQRT(0.9/BI19) -> 4.904525e-11 | BP19: =SQRT(ABS(BJ19))/BI19 -> 8.2296928e-06 | BQ19: =AV19^(2/3)*O19 -> 0.0061147625
A20: ThF4 | B20: 0.08 | C20: 1 | D20: 99 | E20: 96 | F20: =D20*1.6726219E-27 -> 1.6558957e-25 | G20: =E20*9.1093856E-31 -> 8.7450102e-29 | H20: =((F20*D20)/(G20*E20)) -> 1952.7049 | I20: =D20/E20 -> 1.03125 | J20: =(F20)-(G20) -> 1.6550212e-25 | K20: 308.0317 | M20: =N20^-1 -> 0.00072254335 | N20: 1384 | O20: =K20/W20 -> 5.0331977e-05 | P20: 0.000121 | R20: 9.4e-11 | S20: 1.33e-10 | T20: =S20+R20 -> 2.27e-10 | U20: =S20/R20 -> 1.4148936 | V20: =T20*10000000000 -> 2.27 | W20: 6120000 | X20: 1362 | Y20: 0 | Z20: 7.34 | AA20: -0.000808 | AF20: =1/3*BC20*AV20*T20 -> 0.34399094 | AL20: =AE20/(1/3*AV20*T20) -> 0 | AM20: =AE20/(1/3*AV20*AR20) -> #DIV/0! | AR20: =AE20/(1/3*BC20*AV20) -> 0 | AV20: =X20+Y20*N20 -> 1362 | AZ20: =AJ20/BA20 -> 0 | BA20: 168 | BB20: =BC20/1000000 -> 3.3378383 | BC20: =BA20/O20 -> 3337838.3 | BF20: =AV20*BC20 -> 4.5461357e+09 | BG20: =BF20*0.0000000001 -> 0.45461357 | BH20: =BF20*T20 -> 1.0319728 | BI20: 17.560605 | BJ20: -2.6317443e-07 | BM20: =SQRT(1/BI20) -> 0.23863287 | BO20: =T20*SQRT(0.9/BI20) -> 5.1389853e-11 | BP20: =SQRT(ABS(BJ20))/BI20 -> 2.9213418e-05 | BQ20: =AV20^(2/3)*O20 -> 0.006184369
A21: UF4 | B21: 0.09 | C21: 1 | D21: 101 | E21: 98 | F21: =D21*1.6726219E-27 -> 1.6893481e-25 | G21: =E21*9.1093856E-31 -> 8.9271979e-29 | H21: =((F21*D21)/(G21*E21)) -> 1950.2904 | I21: =D21/E21 -> 1.0306122 | J21: =(F21)-(G21) -> 1.6884554e-25 | K21: 314.0225 | L21: =10^(11.4-35400/N21+27700000/N21^2)/1000 -> 0.003329486 | M21: =N21^-1 -> 0.00076394194 | N21: 1309 | O21: =K21/W21 -> 4.8535162e-05 | P21: 0.000149 | R21: 8.9e-11 | S21: 1.33e-10 | T21: =S21+R21 -> 2.22e-10 | U21: =S21/R21 -> 1.494382 | V21: =T21*10000000000 -> 2.22 | W21: 6470000 | X21: 1062 | Y21: 0 | Z21: 7.604 | AA21: -0.000791 | AF21: =1/3*BC21*AV21*T21 -> 0.28174032 | AL21: =AE21/(1/3*AV21*T21) -> 0 | AM21: =AE21/(1/3*AV21*AR21) -> #DIV/0! | AR21: =AE21/(1/3*BC21*AV21) -> 0 | AV21: =X21+Y21*N21 -> 1062 | AZ21: =AJ21/BA21 -> 0 | BA21: 174 | BB21: =BC21/1000000 -> 3.5850297 | BC21: =BA21/O21 -> 3585029.7 | BF21: =AV21*BC21 -> 3.8073016e+09 | BG21: =BF21*0.0000000001 -> 0.38073016 | BH21: =BF21*T21 -> 0.84522095 | BI21: 17.594119 | BJ21: -1.2112877e-07 | BM21: =SQRT(1/BI21) -> 0.23840548 | BO21: =T21*SQRT(0.9/BI21) -> 5.0210028e-11 | BP21: =SQRT(ABS(BJ21))/BI21 -> 1.9781359e-05 | BQ21: =AV21^(2/3)*O21 -> 0.0050521104 | BR21: =L21/(W21/1000*(X21+Y21*N21)) -> 4.8456093e-10
A22: UCl3 | C22: 1 | D22: 109 | E22: 107 | F22: =D22*1.6726219E-27 -> 1.8231579e-25 | G22: =E22*9.1093856E-31 -> 9.7470426e-29 | H22: =((F22*D22)/(G22*E22)) -> 1905.435 | I22: =D22/E22 -> 1.0186916 | J22: =(F22)-(G22) -> 1.8221832e-25 | K22: 344.3879 | L22: =0.478*EXP(10900/(8.3144598*N22))/1000 -> 0.0015506403 | M22: =N22^-1 -> 0.00089766607 | N22: 1114 | O22: =K22/W22 -> 7.5193865e-05 | P22: 0.000333 | R22: 1.16e-10 | S22: 1.81e-10 | T22: =S22+R22 -> 2.97e-10 | U22: =S22/R22 -> 1.5603448 | V22: =T22*10000000000 -> 2.97 | W22: 4580000 | X22: 1248 | Y22: 0 | Z22: 6.3747 | AA22: -0.0015222 | AF22: =1/3*BC22*AV22*T22 -> 0.24646692 | AL22: =AE22/(1/3*AV22*T22) -> 0 | AM22: =AE22/(1/3*AV22*AR22) -> #DIV/0! | AR22: =AE22/(1/3*BC22*AV22) -> 0 | AV22: =X22+Y22*N22 -> 1248 | AZ22: =AJ22/BA22 -> 0 | BA22: 150 | BB22: =BC22/1000000 -> 1.9948436 | BC22: =BA22/O22 -> 1994843.6 | BF22: =AV22*BC22 -> 2.4895648e+09 | BG22: =BF22*0.0000000001 -> 0.24895648 | BH22: =BF22*T22 -> 0.73940075 | BI22: 30.854755 | BJ22: -2.5395582e-05 | BM22: =SQRT(1/BI22) -> 0.18002754 | BO22: =T22*SQRT(0.9/BI22) -> 5.0724369e-11 | BP22: =SQRT(ABS(BJ22))/BI22 -> 0.00016332662 | BQ22: =AV22^(2/3)*O22 -> 0.0087161654 | BR22: =L22/(W22/1000*(X22+Y22*N22)) -> 2.7128826e-10
