Workbook

Sheet MFP-rsum (2)
A1: Compound | B1: S/cm | C1: order | D1: protons | E1: electrons | F1: Mp/molecule | G1: Me/molecule | H1: ratio of Mpe*# | I1: ratio | J1: Dif mass | K1: M_i (g/mol) | L1: Visc (N*s/m^2) | M1: T_i_m (K) inverse | N1: T_i_m (K) | O1: V_i_m (m^3/mol) | P1: alpha_i_m (K^-1) | R1: r_c (m) | S1: r_a (m) | T1: sum_radii | U1: Cat_mass | V1: An_mass | W1: Red. Mass | X1: rho_m (g/m^3) | Y1: SoS(T)_A (A+B*T) | Z1: SoS(T)_B | AA1: A (Density (g/cm3): A - BT(K)) | AB1: B (Density (g/cm3): A - BT(K)) | AC1: #_cations | AD1: #_anions | AE1: sum_ions | AF1: 1/3*Cp*vs*r_sumCorrect | AG1: 1/3*Cp*vs*1stPk | AH1: λ_init | AI1: λ_T,m | AK1: 1.15 | AL1: 0.85 | AM1: λ_SCL | AN1: k_SCL | AO1: % Dev. - Present Model | AP1: k_Gheribi | AQ1: % Dev, Kinetic Theory | AR1: k_Zhao | AS1: 1/3*Cp*vs*DistPk_FstSound | AT1: Dev | AU1: 1/3*Cp*vs*DistPk | AV1: Dev | AW1: 1/3*Cp*vs*r_sum | AX1: dev_λ | AY1: c_BC,Dist | AZ1: 1/3*v*λDistFast | BA1: c_BC_fast | BB1: 1/3*Cp*vs | BC1: r_sum | BD1: frequency | BE1: 1stPeak | BF1: DistMFP | BG1: AvgMFP | BH1: λBC | BI1: MFP_calc | BJ1: MFP_dev | BK1: 1/3*Cp*r_sum | BL1: SoS_Tm | BM1: SoS_metal | BN1: vs_calc | BO1: vs_dev | BP1: 1/3*vs*r_sum | BQ1: C_i_p (J/mol/K) | BR1: Cp(J/m3-K) | BS1: Cp_calc | BT1: Cp_dev | BY1: Visc/(Dens*C0)
A2: LiF | B2: 9.95 | C2: 1 | D2: 12 | E2: 12 | F2: =D2*1.6726219E-27 -> 2.0071463e-26 | G2: =E2*9.1093856E-31 -> 1.0931263e-29 | H2: =((F2*D2)/(G2*E2)) -> 1836.1523 | I2: =D2/E2 -> 1 | J2: =(F2)-(G2) -> 2.0060532e-26 | K2: 25.939 | L2: =0.115*EXP(27000/(8.3144598*N2))/1000 -> 0.0020988673 | M2: =N2^-1 -> 0.00089433439 | N2: 1118.15 | O2: 1.42e-05 | P2: 0.000268 | R2: 7.6e-11 | S2: 1.33e-10 | T2: =S2+R2 -> 2.09e-10 | U2: 6.941 | V2: 18.9984 | W2: =U2*V2/(U2+V2) -> 5.083691 | X2: 1810000 | Y2: 2547.8 | Z2: 0 | AA2: 2.3581 | AB2: -0.0004902 | AC2: 1 | AD2: 1 | AE2: =AC2+AD2 -> 2 | AF2: =1/3*BR2*BL2*T2 -> 8.0248523e-07 | AG2: =1/3*BR2*BL2*BE2 -> 7.2246878e-07 | AH2: 1.33125 | AI2: 1.2682351 | AJ2: Golyshev, 1982; Golyshev, 1983; Golyshev, 1992; Smirnov, 1987; Khlebnikov, 1981 | AK2: =AI2*AK$1 -> 1.4584703 | AL2: =AI2*AL$1 -> 1.0779998 | AM2: 3.315991e-10 | AN2: 1.27255 | AO2: =ABS(AI2-AN2)/AI2 -> 0.0034023051 | AP2: 1.3498415 | AQ2: =ABS(AI2-AP2)/AI2 -> 0.06434646 | AR2: 0.80206173 | AS2: 1.2205689 | AT2: =ABS(($AI2-AS2)/$AI2) -> 0.037584635 | AU2: 0.89818968 | AV2: =ABS(($AI2-AU2)/$AI2) -> 0.29177981 | AW2: 0.79448872 | AX2: =(AI2-AW2)/AI2 -> 0.37354774 | AY2: . | AZ2: 2.7246206e-07 | BA2: =AI2/(AZ2)*0.000001 -> 4.6547217 | BB2: 3.8013815e+09 | BC2: =AW2/BB2 -> 2.09e-10 | BD2: =SQRT((BC2-BE2)/W2) -> 2.0246721e-06 | BE2: 1.8816044e-10 | BF2: 2.3551445e-10 | BG2: 2.3535591e-10 | BH2: =AI2/(1/3*BR2*BL2) -> 0.00033030032 | BI2: =AI2/BB2 -> 3.3362478e-10 | BJ2: =(BI2-BC2)/BC2 -> 0.59629082 | BK2: =AW2/BL2 -> 0.00031183324 | BL2: =Y2+Z2*N2 -> 2547.8 | BM2: 3500 | BN2: =AI2/BK2 -> 4067.0298 | BO2: =(BN2-BL2)/BL2 -> 0.59629082 | BP2: =AW2/BQ2 -> 0.012375214 | BQ2: 64.2 | BR2: =BQ2/O2*0.000001 -> 4.5211268 | BS2: =AI2/(BP2) -> 102.48187 | BT2: =(BS2-BQ2)/BQ2 -> 0.59629082 | BY2: =L2/(X2/1000*(Y2+Z2*N2)) -> 4.5513588e-10
A3: NaF | B3: 6.9 | C3: 1 | D3: 20 | E3: 20 | F3: =D3*1.6726219E-27 -> 3.3452438e-26 | G3: =E3*9.1093856E-31 -> 1.8218771e-29 | H3: =((F3*D3)/(G3*E3)) -> 1836.1523 | I3: =D3/E3 -> 1 | J3: =(F3)-(G3) -> 3.3434219e-26 | K3: 41.988 | L3: =0.12*EXP(26500/(8.3144598*N3))/1000 -> 0.0014814456 | M3: =N3^-1 -> 0.00078855025 | N3: 1268.15 | O3: 2.16e-05 | P3: 0.000288 | R3: 1.02e-10 | S3: 1.33e-10 | T3: =S3+R3 -> 2.35e-10 | U3: 22.98977 | V3: 18.9984 | W3: =U3*V3/(U3+V3) -> 10.402188 | X3: 1950000 | Y3: 2085.5 | Z3: 0 | AA3: 2.755 | AB3: -0.000636 | AC3: 1 | AD3: 1 | AE3: =AC3+AD3 -> 2 | AF3: =1/3*BR3*BL3*T3 -> 5.3093354e-07 | AG3: =1/3*BR3*BL3*BE3 -> 4.9109756e-07 | AH3: 0.8279 | AI3: 1.2192784 | AJ3: Smirnov, 1987; Polyakov, 1975 | AK3: =AI3*AK$1 -> 1.4021702 | AL3: =AI3*AL$1 -> 1.0363867 | AM3: 3.7969068224247864E-10 | AN3: 0.85709429 | AO3: =ABS(AI3-AN3)/AI3 -> 0.29704794 | AP3: 0.8422681 | AQ3: =ABS(AI3-AP3)/AI3 -> 0.30920775 | AR3: 0.53047696 | AS3: 0.78916546 | AT3: =ABS(($AI3-AS3)/$AI3) -> 0.35276026 | AU3: 0.60313763 | AV3: =ABS(($AI3-AU3)/$AI3) -> 0.50533232 | AW3: 0.53220718 | AX3: =(AI3-AW3)/AI3 -> 0.56350645 | AY3: =AI3/(1/3*BL3*BG3) -> 6625164.3 | AZ3: 2.4225091e-07 | BA3: =AI3/(AZ3)*0.000001 -> 5.0331223 | BB3: 2.2647114e+09 | BC3: =AW3/BB3 -> 2.35e-10 | BD3: =SQRT((BC3-BE3)/W3) -> 1.3019349e-06 | BE3: 2.1736793e-10 | BF3: 2.6496648e-10 | BG3: 2.6473862e-10 | BH3: =AI3/(1/3*BR3*BL3) -> 0.00053967288 | BI3: =AI3/BB3 -> 5.3838138e-10 | BJ3: =(BI3-BC3)/BC3 -> 1.2909846 | BK3: =AW3/BL3 -> 0.00025519404 | BL3: =Y3+Z3*N3 -> 2085.5 | BM3: 2720 | BN3: =AI3/BK3 -> 4777.8484 | BO3: =(BN3-BL3)/BL3 -> 1.2909846 | BP3: =AW3/BQ3 -> 0.0075812988 | BQ3: 70.2 | BR3: =BQ3/O3*0.000001 -> 3.25 | BS3: =AI3/(BP3) -> 160.82712 | BT3: =(BS3-BQ3)/BQ3 -> 1.2909846 | BY3: =L3/(X3/1000*(Y3+Z3*N3)) -> 3.6428469e-10
A4: KF | B4: 5.1 | C4: 1 | D4: 28 | E4: 28 | F4: =D4*1.6726219E-27 -> 4.6833413e-26 | G4: =E4*9.1093856E-31 -> 2.550628e-29 | H4: =((F4*D4)/(G4*E4)) -> 1836.1523 | I4: =D4/E4 -> 1 | J4: =(F4)-(G4) -> 4.6807907e-26 | K4: 58.097 | L4: =0.107*EXP(23800/(8.3144598*N4))/1000 -> 0.001350063 | M4: =N4^-1 -> 0.00088562193 | N4: 1129.15 | O4: 3.04e-05 | P4: 0.000341 | R4: 1.38e-10 | S4: 1.33e-10 | T4: =S4+R4 -> 2.71e-10 | U4: 39.0983 | V4: 18.9984 | W4: =U4*V4/(U4+V4) -> 12.785668 | X4: 1910000 | Y4: 1816.4 | Z4: 0 | AA4: 2.6464 | AB4: -0.0006515 | AC4: 1 | AD4: 1 | AE4: =AC4+AD4 -> 2 | AF4: =1/3*BR4*BL4*T4 -> 3.6108717e-07 | AG4: =1/3*BR4*BL4*BE4 -> 3.2961603e-07 | AH4: 0.57 | AI4: 0.62200825 | AJ4: Smirnov, 1987 | AK4: =AI4*AK$1 -> 0.71530949 | AL4: =AI4*AL$1 -> 0.52870702 | AM4: 4.254924144410876E-10 | AN4: 0.57175442 | AO4: =ABS(AI4-AN4)/AI4 -> 0.080792871 | AP4: 0.58268228 | AQ4: =ABS(AI4-AP4)/AI4 -> 0.0632242 | AR4: 0.36415561 | AS4: 0.5353456 | AT4: =ABS(($AI4-AS4)/$AI4) -> 0.13932717 | AU4: 0.41627405 | AV4: =ABS(($AI4-AU4)/$AI4) -> 0.330758 | AW4: 0.36077309 | AX4: =(AI4-AW4)/AI4 -> 0.41998665 | AY4: =AI4/(1/3*BL4*BG4) -> 3390174.5 | AZ4: 2.4330776e-07 | BA4: =AI4/(AZ4)*0.000001 -> 2.5564669 | BB4: 1.331266e+09 | BC4: =AW4/BB4 -> 2.71e-10 | BD4: =SQRT((BC4-BE4)/W4) -> 1.359168e-06 | BE4: 2.4738055e-10 | BF4: 3.0052361e-10 | BG4: 3.0302877e-10 | BH4: =AI4/(1/3*BR4*BL4) -> 0.00046682421 | BI4: =AI4/BB4 -> 4.6723063e-10 | BJ4: =(BI4-BC4)/BC4 -> 0.72409825 | BK4: =AW4/BL4 -> 0.00019861985 | BL4: =Y4+Z4*N4 -> 1816.4 | BM4: 2360 | BN4: =AI4/BK4 -> 3131.6521 | BO4: =(BN4-BL4)/BL4 -> 0.72409825 | BP4: =AW4/BQ4 -> 0.0053927218 | BQ4: 66.9 | BR4: =BQ4/O4*0.000001 -> 2.2006579 | BS4: =AI4/(BP4) -> 115.34217 | BT4: =(BS4-BQ4)/BQ4 -> 0.72409825 | BY4: =L4/(X4/1000*(Y4+Z4*N4)) -> 3.8914297e-10
A5: RbF | C5: 1 | D5: 46 | E5: 46 | F5: =D5*1.6726219E-27 -> 7.6940607e-26 | G5: =E5*9.1093856E-31 -> 4.1903174e-29 | H5: =((F5*D5)/(G5*E5)) -> 1836.1523 | I5: =D5/E5 -> 1 | J5: =(F5)-(G5) -> 7.6898704e-26 | K5: 104.4662 | L5: =0.115*EXP(27000/(8.3144598*N5))/1000 -> 0.0025481161 | M5: =N5^-1 -> 0.00095406192 | N5: 1048.15 | O5: 3.57e-05 | P5: 0.000349 | R5: 1.52e-10 | S5: 1.33e-10 | T5: =S5+R5 -> 2.85e-10 | U5: 85.4678 | V5: 18.9984 | W5: =U5*V5/(U5+V5) -> 15.543319 | X5: =K5/O5 -> 2926224.1 | Y5: 1760.4 | Z5: 0 | AA5: =X5*100^3/1000 -> 2.9262241e+09 | AB5: 0 | AF5: =1/3*BR5*BL5*T5 -> 3.2557538e-07 | AG5: =1/3*BR5*BL5*BE5 -> 2.9579641e-07 | AH5: 0.48965 | BD5: =SQRT((BC5-BE5)/W5) -> #NUM! | BE5: 2.5893228e-10 | BF5: 3.1433568e-10 | BH5: =AI5/(1/3*BR5*BL5) -> 0 | BI5: 2.5893228e-10 | BL5: =Y5+Z5*N5 -> 1760.4 | BP5: =AW5/BQ5 -> 0 | BQ5: 69.5 | BR5: =BQ5/O5*0.000001 -> 1.9467787 | BY5: =L5/(X5/1000*(Y5+Z5*N5)) -> 4.9465257e-10
A6: CsF | C6: 1 | D6: 64 | E6: 64 | F6: =D6*1.6726219E-27 -> 1.070478e-25 | G6: =E6*9.1093856E-31 -> 5.8300068e-29 | H6: =((F6*D6)/(G6*E6)) -> 1836.1523 | I6: =D6/E6 -> 1 | J6: =(F6)-(G6) -> 1.069895e-25 | K6: 58.44 | L6: =0.115*EXP(27000/(8.3144598*N6))/1000 -> 0.0034453112 | M6: =N6^-1 -> 0.001046956 | N6: 955.15 | O6: 4.57e-05 | P6: 0.000385 | R6: 1.67e-10 | S6: 1.33e-10 | T6: =S6+R6 -> 3e-10 | U6: 132.9055 | V6: 18.9984 | W6: =U6*V6/(U6+V6) -> 16.622298 | X6: 2196977.2 | Y6: 2732.9322 | Z6: -0.915 | AA6: 4.8985 | AB6: -0.000543 | AF6: =1/3*BR6*BL6*T6 -> 3.0142161e-07 | AG6: =1/3*BR6*BL6*BE6 -> 2.8095437e-07 | AH6: 0.36715 | BD6: =SQRT((BC6-BE6)/W6) -> #NUM! | BE6: 2.7962928e-10 | BF6: 3.3920043e-10 | BH6: =AI6/(1/3*BR6*BL6) -> 0 | BI6: 2.7962928e-10 | BL6: =Y6+Z6*N6 -> 1858.97 | BP6: =AW6/BQ6 -> 0 | BQ6: 74.1 | BR6: =BQ6/O6*0.000001 -> 1.6214442 | BY6: =L6/(X6/1000*(Y6+Z6*N6)) -> 8.4358824e-10
A7: LiCl | B7: 3.67 | C7: 1 | D7: 20 | E7: 20 | F7: =D7*1.6726219E-27 -> 3.3452438e-26 | G7: =E7*9.1093856E-31 -> 1.8218771e-29 | H7: =((F7*D7)/(G7*E7)) -> 1836.1523 | I7: =D7/E7 -> 1 | J7: =(F7)-(G7) -> 3.3434219e-26 | K7: 42.394 | L7: =0.0726*EXP(22400/(8.3144598*N7))/1000 -> 0.0015609789 | M7: =N7^-1 -> 0.0011388225 | N7: 878.1 | O7: =K7/X7 -> 2.8281521e-05 | P7: 0.000288 | R7: 7.6e-11 | S7: 1.81e-10 | T7: =S7+R7 -> 2.57e-10 | U7: 6.941 | V7: 35.453 | W7: =U7*V7/(U7+V7) -> 5.8045778 | X7: 1499000 | Y7: 2787.9043 | Z7: -0.849 | AA7: 1.8842 | AB7: -0.0004328 | AC7: 1 | AD7: 1 | AE7: =AC7+AD7 -> 2 | AF7: =1/3*BR7*BL7*T7 -> 4.0225026e-07 | AG7: =1/3*BR7*BL7*BE7 -> 3.7226977e-07 | AH7: 0.6126 | AI7: 0.62171538 | AJ7: Nagasaka,1992 | AK7: =AI7*AK$1 -> 0.71497269 | AL7: =AI7*AL$1 -> 0.52845808 | AM7: 4.1180986e-10 | AN7: 0.65758854 | AO7: =ABS(AI7-AN7)/AI7 -> 0.057700281 | AP7: 0.68631947 | AQ7: =ABS(AI7-AP7)/AI7 -> 0.10391264 | AR7: 0.41038419 | AS7: 0.79296638 | AT7: =ABS(($AI7-AS7)/$AI7) -> 0.27544919 | AU7: 0.47211359 | AV7: =ABS(($AI7-AU7)/$AI7) -> 0.24062746 | AW7: 0.40224439 | AX7: =(AI7-AW7)/AI7 -> 0.35300878 | AY7: =AI7/(1/3*BL7*BG7) -> 3057984.9 | AZ7: 3.4373591e-07 | BA7: =AI7/(AZ7)*0.000001 -> 1.8087007 | BB7: 1.5651533e+09 | BC7: =AW7/BB7 -> 2.57e-10 | BD7: =SQRT((BC7-BE7)/W7) -> 1.8165711e-06 | BE7: 2.378453e-10 | BF7: 2.8537175e-10 | BG7: 2.9863264e-10 | BH7: =AI7/(1/3*BR7*BL7) -> 0.00039721753 | BI7: =AI7/BB7 -> 3.9722332e-10 | BJ7: =(BI7-BC7)/BC7 -> 0.54561604 | BK7: =AW7/BL7 -> 0.00019694717 | BL7: =Y7+Z7*N7 -> 2042.3974 | BM7: 3500 | BN7: =AI7/BK7 -> 3156.7623 | BO7: =(BN7-BL7)/BL7 -> 0.54561604 | BP7: =AW7/BQ7 -> 0.0061864717 | BQ7: 65.02 | BR7: =BQ7/O7*0.000001 -> 2.2990277 | BS7: =AI7/(BP7) -> 100.49595 | BT7: =(BS7-BQ7)/BQ7 -> 0.54561604 | BY7: =L7/(X7/1000*(Y7+Z7*N7)) -> 5.0986493e-10
A8: NaCl | B8: 3.94 | C8: 1 | D8: 28 | E8: 28 | F8: =D8*1.6726219E-27 -> 4.6833413e-26 | G8: =E8*9.1093856E-31 -> 2.550628e-29 | H8: =((F8*D8)/(G8*E8)) -> 1836.1523 | I8: =D8/E8 -> 1 | J8: =(F8)-(G8) -> 4.6807907e-26 | K8: 58.44 | L8: =0.0893*EXP(22000/(8.3144598*N8))/1000 -> 0.0010321391 | M8: =N8^-1 -> 0.00092494104 | N8: 1081.15 | O8: 3.765e-05 | P8: 0.00035 | R8: 1.02e-10 | S8: 1.81e-10 | T8: =S8+R8 -> 2.83e-10 | U8: 22.98977 | V8: 35.453 | W8: =U8*V8/(U8+V8) -> 13.94623 | X8: 1560000 | Y8: 2732.9322 | Z8: -0.915 | AA8: 2.1393 | AB8: -0.000543 | AC8: 1 | AD8: 1 | AE8: =AC8+AD8 -> 2 | AF8: =1/3*BR8*BL8*T8 -> 3.0415923e-07 | AG8: =1/3*BR8*BL8*BE8 -> 2.8617344e-07 | AH8: 0.4665 | AI8: 0.47705462 | AJ8: Nagasaka,1992; Harada,1992 | AK8: =AI8*AK$1 -> 0.54861281 | AL8: =AI8*AL$1 -> 0.40549643 | AM8: 4.599211434277691E-10 | AN8: 0.50410392 | AO8: =ABS(AI8-AN8)/AI8 -> 0.056700648 | AP8: 0.48682954 | AQ8: =ABS(AI8-AP8)/AI8 -> 0.020490155 | AR8: 0.31018668 | AS8: 0.54053876 | AT8: =ABS(($AI8-AS8)/$AI8) -> 0.1330752 | AU8: 0.35117685 | AV8: =ABS(($AI8-AU8)/$AI8) -> 0.26386448 | AW8: 0.30612615 | AX8: =(AI8-AW8)/AI8 -> 0.35829957 | AY8: =AI8/(1/3*BL8*BG8) -> 2548471.3 | AZ8: 2.9231116e-07 | BA8: =AI8/(AZ8)*0.000001 -> 1.6320096 | BB8: 1.0817179e+09 | BC8: =AW8/BB8 -> 2.83e-10 | BD8: =SQRT((BC8-BE8)/W8) -> 1.0954162e-06 | BE8: 2.6626541e-10 | BF8: 3.2067644e-10 | BG8: 3.2206448e-10 | BH8: =AI8/(1/3*BR8*BL8) -> 0.00044386769 | BI8: =AI8/BB8 -> 4.4101576e-10 | BJ8: =(BI8-BC8)/BC8 -> 0.55835956 | BK8: =AW8/BL8 -> 0.00017556326 | BL8: =Y8+Z8*N8 -> 1743.68 | BM8: 2720 | BN8: =AI8/BK8 -> 2717.2804 | BO8: =(BN8-BL8)/BL8 -> 0.55835956 | BP8: =AW8/BQ8 -> 0.0043971007 | BQ8: 69.62 | BR8: =BQ8/O8*0.000001 -> 1.8491368 | BS8: =AI8/(BP8) -> 108.49299 | BT8: =(BS8-BQ8)/BQ8 -> 0.55835956 | BY8: =L8/(X8/1000*(Y8+Z8*N8)) -> 3.7944326e-10
A9: KCl | B9: 3.34 | C9: 1 | D9: 36 | E9: 36 | F9: =D9*1.6726219E-27 -> 6.0214388e-26 | G9: =E9*9.1093856E-31 -> 3.2793788e-29 | H9: =((F9*D9)/(G9*E9)) -> 1836.1523 | I9: =D9/E9 -> 1 | J9: =(F9)-(G9) -> 6.0181595e-26 | K9: 74.5513 | L9: =0.0708*EXP(23900/(8.3144598*N9))/1000 -> 0.0011078669 | M9: =N9^-1 -> 0.00095680046 | N9: 1045.15 | O9: 4.884e-05 | P9: 0.000382 | R9: 1.38e-10 | S9: 1.81e-10 | T9: =S9+R9 -> 3.19e-10 | U9: 39.0983 | V9: 35.453 | W9: =U9*V9/(U9+V9) -> 18.593264 | X9: 1530000 | Y9: 2514.8257 | Z9: -0.878 | AA9: 2.1359 | AB9: -0.0005831 | AC9: 1 | AD9: 1 | AE9: =AC9+AD9 -> 2 | AF9: =1/3*BR9*BL9*T9 -> 2.5593315e-07 | AG9: =1/3*BR9*BL9*BE9 -> 2.3977579e-07 | AH9: 0.35505 | AI9: 0.36559719 | AJ9: Harada, 1992; Nagasaka, 1992 | AK9: =AI9*AK$1 -> 0.42043677 | AL9: =AI9*AL$1 -> 0.31075761 | AM9: 5.0614944e-10 | AN9: 0.41550006 | AO9: =ABS(AI9-AN9)/AI9 -> 0.13649685 | AP9: 0.3742357 | AQ9: =ABS(AI9-AP9)/AI9 -> 0.023628479 | AR9: 0.26186835 | AS9: 0.4317683 | AT9: =ABS(($AI9-AS9)/$AI9) -> 0.18099457 | AU9: 0.29834704 | AV9: =ABS(($AI9-AU9)/$AI9) -> 0.18394604 | AW9: 0.25652334 | AX9: =(AI9-AW9)/AI9 -> 0.29834434 | AY9: =AI9/(1/3*BL9*BG9) -> 1914248.1 | AZ9: 2.865095e-07 | BA9: =AI9/(AZ9)*0.000001 -> 1.2760386 | BB9: 8.041484e+08 | BC9: =AW9/BB9 -> 3.19e-10 | BD9: =SQRT((BC9-BE9)/W9) -> 1.0407331e-06 | BE9: 2.9886116e-10 | BF9: 5.1446004e-10 | BG9: 3.5873267e-10 | BH9: =AI9/(1/3*BR9*BL9) -> 0.00045568738 | BI9: =AI9/BB9 -> 4.5463896e-10 | BJ9: =(BI9-BC9)/BC9 -> 0.42520051 | BK9: =AW9/BL9 -> 0.00016060976 | BL9: =Y9+Z9*N9 -> 1597.184 | BM9: 2360 | BN9: =AI9/BK9 -> 2276.3074 | BO9: =(BN9-BL9)/BL9 -> 0.42520051 | BP9: =AW9/BQ9 -> 0.0034853715 | BQ9: 73.6 | BR9: =BQ9/O9*0.000001 -> 1.5069615 | BS9: =AI9/(BP9) -> 104.89476 | BT9: =(BS9-BQ9)/BQ9 -> 0.42520051 | BY9: =L9/(X9/1000*(Y9+Z9*N9)) -> 4.5335792e-10
A10: BeF2 | B10: 0.52 | C10: 1 | D10: 13 | E10: 12 | F10: =D10*1.6726219E-27 -> 2.1744085e-26 | G10: =E10*9.1093856E-31 -> 1.0931263e-29 | H10: =((F10*D10)/(G10*E10)) -> 2154.9287 | I10: =D10/E10 -> 1.0833333 | J10: =(F10)-(G10) -> 2.1733153e-26 | K10: 47.01 | L10: =10^(-8.12+11500/N10+639000/N10^2)/1000 -> 1.5280163 | M10: =N10^-1 -> 0.00093444844 | N10: 1070.15 | O10: 2.4e-05 | P10: 7.42e-06 | R10: 3.4e-11 | S10: 1.33e-10 | T10: =S10+R10 -> 1.67e-10 | U10: 9.01218 | V10: 18.9984 | W10: =U10*V10/(U10+V10) -> 6.1125832 | X10: 1960000 | Y10: 2547.8 | Z10: 0 | AA10: 1.972 | AB10: -1.45e-05 | AC10: 1 | AD10: 2 | AE10: =AC10+AD10 -> 3 | AF10: =1/3*BR10*BL10*T10 -> 5.1944334e-07 | AH10: 0.79925906 | AW10: 0.51979939 | AX10: =(AI10-AW10)/AI10 -> #DIV/0! | BB10: 3.1125712e+09 | BC10: =AW10/BB10 -> 1.67e-10 | BD10: =SQRT((BC10-BE10)/W10) -> 5.2269199e-06 | BH10: =AI10/(1/3*BR10*BL10) -> 0 | BI10: =AI10/BB10 -> 0 | BJ10: =(BI10-BC10)/BC10 -> -1 | BK10: =AW10/BL10 -> 0.00020401891 | BL10: =Y10+Z10*N10 -> 2547.8 | BN10: =AI10/BK10 -> 0 | BO10: =(BN10-BL10)/BL10 -> -1 | BP10: =AW10/BQ10 -> 0.0059135311 | BQ10: 87.9 | BR10: =BQ10/O10*0.000001 -> 3.6625 | BS10: =AI10/(BP10) -> 0 | BT10: =(BS10-BQ10)/BQ10 -> -1
A11: MgF2 | B11: 0.02 | C11: 1 | D11: 21 | E11: 20 | F11: =D11*1.6726219E-27 -> 3.512506e-26 | G11: =E11*9.1093856E-31 -> 1.8218771e-29 | H11: =((F11*D11)/(G11*E11)) -> 2024.3579 | I11: =D11/E11 -> 1.05 | J11: =(F11)-(G11) -> 3.5106841e-26 | K11: 62.3018 | L11: =0.187*EXP(32100/(8.3144598*N11))/1000 -> 0.002315921 | M11: =N11^-1 -> 0.0006518055 | N11: 1534.2 | O11: =K11/X11 -> 2.557462e-05 | P11: 0.000216 | R11: 7.2e-11 | S11: 1.33e-10 | T11: =S11+R11 -> 2.05e-10 | U11: 24.305 | V11: 18.9984 | W11: =U11*V11/(U11+V11) -> 10.663276 | X11: =(AA11+N11*AB11)*1000000 -> 2436079.2 | Y11: 2175.6 | Z11: 0 | AA11: 3.24 | AB11: -0.000524 | AC11: 1 | AD11: 2 | AE11: =AC11+AD11 -> 3 | AF11: =1/3*BR11*BL11*T11 -> 5.5165642e-07 | AH11: 0.6506778 | AW11: 0.55165642 | AX11: =(AI11-AW11)/AI11 -> #DIV/0! | BB11: 2.6910069e+09 | BC11: =AW11/BB11 -> 2.05e-10 | BD11: =SQRT((BC11-BE11)/W11) -> 4.3846164e-06 | BH11: =AI11/(1/3*BR11*BL11) -> 0 | BI11: =AI11/BB11 -> 0 | BJ11: =(BI11-BC11)/BC11 -> -1 | BK11: =AW11/BL11 -> 0.00025356519 | BL11: =Y11+Z11*N11 -> 2175.6 | BN11: =AI11/BK11 -> 0 | BO11: =(BN11-BL11)/BL11 -> -1 | BP11: =AW11/BQ11 -> 0.0058130287 | BQ11: 94.9 | BR11: =BQ11/O11*0.000001 -> 3.7107101 | BS11: =AI11/(BP11) -> 0 | BT11: =(BS11-BQ11)/BQ11 -> -1 | BY11: =L11/(X11/1000*(Y11+Z11*N11)) -> 4.3697168e-10
A12: CaF2 | B12: 0.12 | C12: 1 | D12: 29 | E12: 28 | F12: =D12*1.6726219E-27 -> 4.8506035e-26 | G12: =E12*9.1093856E-31 -> 2.550628e-29 | H12: =((F12*D12)/(G12*E12)) -> 1969.648 | I12: =D12/E12 -> 1.0357143 | J12: =(F12)-(G12) -> 4.8480529e-26 | K12: 78.0748 | L12: =0.1*EXP(47600/(8.3144598*N12))/1000 -> 0.0029475213 | M12: =N12^-1 -> 0.00059101655 | N12: 1692 | O12: =K12/X12 -> 3.1001402e-05 | P12: 0.000155 | R12: 1e-10 | S12: 1.33e-10 | T12: =S12+R12 -> 2.33e-10 | U12: 40.078 | V12: 18.9984 | W12: =U12*V12/(U12+V12) -> 12.888698 | X12: =(AA12+N12*AB12)*1000000 -> 2518428 | Y12: 1710.3 | Z12: 0 | AA12: 3.18 | AB12: -0.000391 | AC12: 1 | AD12: 2 | AE12: =AC12+AD12 -> 3 | AF12: =1/3*BR12*BL12*T12 -> 4.2810664e-07 | AH12: 0.5648032 | AW12: 0.42810664 | AX12: =(AI12-AW12)/AI12 -> #DIV/0! | BB12: 1.8373676e+09 | BC12: =AW12/BB12 -> 2.33e-10 | BD12: =SQRT((BC12-BE12)/W12) -> 4.251806e-06 | BH12: =AI12/(1/3*BR12*BL12) -> 0 | BI12: =AI12/BB12 -> 0 | BJ12: =(BI12-BC12)/BC12 -> -1 | BK12: =AW12/BL12 -> 0.00025031085 | BL12: =Y12+Z12*N12 -> 1710.3 | BN12: =AI12/BK12 -> 0 | BO12: =(BN12-BL12)/BL12 -> -1 | BP12: =AW12/BQ12 -> 0.0042847513 | BQ12: 99.914 | BR12: =BQ12/O12*0.000001 -> 3.2228865 | BS12: =AI12/(BP12) -> 0 | BT12: =(BS12-BQ12)/BQ12 -> -1 | BY12: =L12/(X12/1000*(Y12+Z12*N12)) -> 6.8431351e-10
A13: SrF2 | C13: 1 | D13: 47 | E13: 46 | F13: =D13*1.6726219E-27 -> 7.8613229e-26 | G13: =E13*9.1093856E-31 -> 4.1903174e-29 | H13: =((F13*D13)/(G13*E13)) -> 1916.8527 | I13: =D13/E13 -> 1.0217391 | J13: =(F13)-(G13) -> 7.8571326e-26 | K13: 125.6168 | L13: =0.0703*EXP(54500/(8.3144598*N13))/1000 -> 0.0030018345 | M13: =N13^-1 -> 0.00057273769 | N13: 1746 | O13: =K13/X13 -> 3.621381e-05 | P13: 0.000213 | R13: 1.18e-10 | S13: 1.33e-10 | T13: =S13+R13 -> 2.51e-10 | U13: 87.62 | V13: 18.9984 | W13: =U13*V13/(U13+V13) -> 15.613063 | X13: =(AA13+N13*AB13)*1000000 -> 3468754 | Y13: 1398.6 | Z13: 0 | AA13: 4.78 | AB13: -0.000751 | AC13: 1 | AD13: 2 | AE13: =AC13+AD13 -> 3 | AF13: =1/3*BR13*BL13*T13 -> 3.1989464e-07 | AH13: 0.390415 | AW13: 0.31989464 | AX13: =(AI13-AW13)/AI13 -> #DIV/0! | BB13: 1.2744806e+09 | BC13: =AW13/BB13 -> 2.51e-10 | BD13: =SQRT((BC13-BE13)/W13) -> 4.0095239e-06 | BH13: =AI13/(1/3*BR13*BL13) -> 0 | BI13: =AI13/BB13 -> 0 | BJ13: =(BI13-BC13)/BC13 -> -1 | BK13: =AW13/BL13 -> 0.00022872489 | BL13: =Y13+Z13*N13 -> 1398.6 | BN13: =AI13/BK13 -> 0 | BO13: =(BN13-BL13)/BL13 -> -1 | BP13: =AW13/BQ13 -> 0.003231259 | BQ13: 99 | BR13: =BQ13/O13*0.000001 -> 2.7337637 | BS13: =AI13/(BP13) -> 0 | BT13: =(BS13-BQ13)/BQ13 -> -1 | BY13: =L13/(X13/1000*(Y13+Z13*N13)) -> 6.1875642e-10
A14: MgCl2 | B14: 0.8 | C14: 1 | D14: 29 | E14: 28 | F14: =D14*1.6726219E-27 -> 4.8506035e-26 | G14: =E14*9.1093856E-31 -> 2.550628e-29 | H14: =((F14*D14)/(G14*E14)) -> 1969.648 | I14: =D14/E14 -> 1.0357143 | J14: =(F14)-(G14) -> 4.8480529e-26 | K14: 95.211 | L14: =0.18*EXP(20500/(8.3144598*N14))/1000 -> 0.0021885965 | M14: =N14^-1 -> 0.0010131712 | N14: 987 | O14: =K14/X14 -> 5.6510276e-05 | P14: 0.00018 | R14: 7.2e-11 | S14: 1.81e-10 | T14: =S14+R14 -> 2.53e-10 | U14: 24.305 | V14: 35.453 | W14: =U14*V14/(U14+V14) -> 14.419578 | X14: =(AA14+N14*AB14)*1000000 -> 1684844 | Y14: 2101 | Z14: 0 | AA14: 1.9691 | AB14: -0.000288 | AC14: 1 | AD14: 2 | AE14: =AC14+AD14 -> 3 | AF14: =1/3*BR14*BL14*T14 -> 2.8861058e-07 | AG14: =1/3*BR14*BL14*BE14 -> 2.6994066e-07 | AH14: 0.4568 | AI14: 0.79107789 | AJ14: Bystrai, 1975; Filatov, 2005 | AK14: =AI14*AK$1 -> 0.90973957 | AL14: =AI14*AL$1 -> 0.6724162 | AM14: 4.7852054e-10 | AN14: 0.54587387 | AO14: =ABS(AI14-AN14)/AI14 -> 0.30996191 | AP14: 0.4382922 | AQ14: =ABS(AI14-AP14)/AI14 -> 0.44595569 | AR14: 0.28861058 | AS14: 0.5664834 | AT14: =ABS(($AI14-AS14)/$AI14) -> 0.28390944 | AU14: 0.35005342 | AV14: =ABS(($AI14-AU14)/$AI14) -> 0.55749816 | AW14: 0.28861058 | AX14: =(AI14-AW14)/AI14 -> 0.63516794 | AY14: =AI14/(1/3*BL14*BG14) -> 3861437.2 | AZ14: 3.4777653e-07 | BA14: =AI14/(AZ14)*0.000001 -> 2.274673 | BB14: 1.1407533e+09 | BC14: =AW14/BB14 -> 2.53e-10 | BD14: =SQRT((BC14-BE14)/W14) -> 1.0653665e-06 | BE14: 2.3663369e-10 | BF14: 2.9252667e-10 | BG14: 2.9252667e-10 | BH14: =AI14/(1/3*BR14*BL14) -> 0.00069346975 | BI14: =AI14/BB14 -> 6.9346975e-10 | BJ14: =(BI14-BC14)/BC14 -> 1.7409871 | BK14: =AW14/BL14 -> 0.0001373682 | BL14: =Y14+Z14*N14 -> 2101 | BM14: 3400 | BN14: =AI14/BK14 -> 5758.814 | BO14: =(BN14-BL14)/BL14 -> 1.7409871 | BP14: =AW14/BQ14 -> 0.0031354356 | BQ14: 92.048 | BR14: =BQ14/O14*0.000001 -> 1.6288719 | BS14: =AI14/(BP14) -> 252.30238 | BT14: =(BS14-BQ14)/BQ14 -> 1.7409871 | BY14: =L14/(X14/1000*(Y14+Z14*N14)) -> 6.1827252e-10
A15: CaCl2 | B15: 2.5 | C15: 1 | D15: 37 | E15: 36 | F15: =D15*1.6726219E-27 -> 6.188701e-26 | G15: =E15*9.1093856E-31 -> 3.2793788e-29 | H15: =((F15*D15)/(G15*E15)) -> 1939.5775 | I15: =D15/E15 -> 1.0277778 | J15: =(F15)-(G15) -> 6.1854217e-26 | K15: 110.984 | L15: =10^(-0.545+597/N15+546000/N15^2)/1000 -> 0.0033595447 | M15: =N15^-1 -> 0.0009569378 | N15: 1045 | O15: =K15/X15 -> 5.3154148e-05 | P15: 0.000203 | R15: 1e-10 | S15: 1.81e-10 | T15: =S15+R15 -> 2.81e-10 | U15: 40.078 | V15: 35.453 | W15: =U15*V15/(U15+V15) -> 18.811949 | X15: =(AA15+N15*AB15)*1000000 -> 2087965 | Y15: 2065.03 | Z15: 0 | AA15: 2.53 | AB15: -0.000423 | AF15: =1/3*BR15*BL15*T15 -> 3.731109e-07 | AG15: =1/3*BR15*BL15*BE15 -> 3.702431e-07 | AH15: 0.44125 | AM15: 5.033966e-10 | AN15: 0.66840839 | AP15: 0.44873599 | AR15: 0.3731109 | AS15: 0.46759092 | AT15: =ABS(($AI15-AS15)/$AI15) -> #DIV/0! | AU15: 0.43890421 | AV15: =ABS(($AI15-AU15)/$AI15) -> #DIV/0! | AY15: =AI15/(1/3*BL15*BG15) -> 0 | AZ15: 2.4240388e-07 | BA15: =AI15/(AZ15)*0.000001 -> 0 | BD15: =SQRT((BC15-BE15)/W15) -> #NUM! | BE15: 2.7884018e-10 | BF15: 3.3920043e-10 | BG15: 3.015484e-10 | BH15: =AI15/(1/3*BR15*BL15) -> 0 | BL15: =Y15+Z15*N15 -> 2065.03 | BM15: 2200 | BP15: =AW15/BQ15 -> 0 | BQ15: 102.533 | BR15: =BQ15/O15*0.000001 -> 1.9289746 | BY15: =L15/(X15/1000*(Y15+Z15*N15)) -> 7.7916752e-10
A16: SrCl2 | C16: 1 | D16: 55 | E16: 54 | F16: =D16*1.6726219E-27 -> 9.1994204e-26 | G16: =E16*9.1093856E-31 -> 4.9190682e-29 | H16: =((F16*D16)/(G16*E16)) -> 1904.7876 | I16: =D16/E16 -> 1.0185185 | J16: =(F16)-(G16) -> 9.1945014e-26 | K16: 158.526 | L16: =10^(-0.439+398/N16+879000/N16^2)/1000 -> 0.0037808819 | M16: =N16^-1 -> 0.00087260035 | N16: 1146 | O16: =K16/X16 -> 5.811897e-05 | P16: 0.000212 | R16: 1.18e-10 | S16: 1.81e-10 | T16: =S16+R16 -> 2.99e-10 | U16: 87.62 | V16: 35.453 | W16: =U16*V16/(U16+V16) -> 25.240238 | X16: =(AA16+N16*AB16)*1000000 -> 2727612 | Y16: 1873.13 | Z16: 0 | AA16: 3.39 | AB16: -0.000578 | AC16: 1 | AD16: 2 | AE16: =AC16+AD16 -> 3 | AF16: =1/3*BR16*BL16*T16 -> 3.3599408e-07 | AG16: =1/3*BR16*BL16*BE16 -> 3.2666099e-07 | AH16: 0.37705 | AM16: 5.10679e-10 | AN16: 0.57386328 | AP16: 0.38351171 | AR16: 0.33599408 | AS16: 0.39572551 | AT16: =ABS(($AI16-AS16)/$AI16) -> #DIV/0! | AU16: 0.39572551 | AV16: =ABS(($AI16-AU16)/$AI16) -> #DIV/0! | AW16: 0.33599408 | AX16: =(AI16-AW16)/AI16 -> #DIV/0! | AY16: =AI16/(1/3*BL16*BG16) -> 0 | AZ16: 2.1987724e-07 | BA16: =AI16/(AZ16)*0.000001 -> 0 | BB16: 1.123726e+09 | BC16: =AW16/BB16 -> 2.99e-10 | BD16: =SQRT((BC16-BE16)/W16) -> 5.7363527e-07 | BE16: 2.9069451e-10 | BF16: 4.2159143e-10 | BG16: 3.2712108e-10 | BH16: =AI16/(1/3*BR16*BL16) -> 0 | BI16: =AI16/BB16 -> 0 | BJ16: =(BI16-BC16)/BC16 -> -1 | BK16: =AW16/BL16 -> 0.00017937574 | BL16: =Y16+Z16*N16 -> 1873.13 | BN16: =AI16/BK16 -> 0 | BO16: =(BN16-BL16)/BL16 -> -1 | BP16: =AW16/BQ16 -> 0.0032121805 | BQ16: 104.6 | BR16: =BQ16/O16*0.000001 -> 1.7997566 | BS16: =AI16/(BP16) -> 0 | BT16: =(BS16-BQ16)/BQ16 -> -1 | BY16: =L16/(X16/1000*(Y16+Z16*N16)) -> 7.4001854e-10
A17: NaNO3 | B17: 0.3 | C17: 1 | D17: 26 | E17: 25 | F17: =D17*1.6726219E-27 -> 4.3488169e-26 | G17: =E17*9.1093856E-31 -> 2.2773464e-29 | H17: =((F17*D17)/(G17*E17)) -> 1985.9823 | I17: =D17/E17 -> 1.04 | J17: =(F17)-(G17) -> 4.3465396e-26 | K17: 84.99 | M17: =N17^-1 -> 0.0017148247 | N17: 583.15 | O17: 4.467e-05 | P17: 0.000376 | R17: 1.02e-10 | S17: 2.31e-10 | T17: =S17+R17 -> 3.33e-10 | U17: 22.98977 | V17: =14.0067+3*15.9994 -> 62.0049 | W17: =U17*V17/(U17+V17) -> 16.771386 | X17: =(AA17+N17*AB17)*1000000 -> 1886915.5 | Y17: 2490.4882 | Z17: -1.155 | AA17: 2.3339 | AB17: -0.0007665 | AC17: 2 | AD17: 3 | AE17: =AC17+AD17 -> 5 | AF17: =1/3*BR17*BL17*T17 -> 7.0252146e-07 | AG17: =1/3*BR17*BL17*BE17 -> 4.3236429e-07 | AH17: 0.51225 | AS17: 0.34093206 | AU17: =1/3*BR17*BL17*BF17 -> 6.1623593e-07 | AW17: 0.6982846 | AX17: =(AI17-AW17)/AI17 -> #DIV/0! | AZ17: 0.00022380854 | BB17: 2.0969507e+09 | BC17: =AW17/BB17 -> 3.33e-10 | BD17: =SQRT((BC17-BE17)/W17) -> 2.763224e-06 | BE17: 2.0494365e-10 | BF17: 2.9210007e-10 | BH17: =AI17/(1/3*BR17*BL17) -> 0 | BI17: =AI17/BB17 -> 0 | BJ17: =(BI17-BC17)/BC17 -> -1 | BK17: =AW17/BL17 -> 0.0003843169 | BL17: =Y17+Z17*N17 -> 1816.95 | BN17: =AI17/BK17 -> 0 | BO17: =(BN17-BL17)/BL17 -> -1 | BP17: =AW17/BQ17 -> 0.0044876902 | BQ17: 155.6 | BR17: =BQ17/O17*0.000001 -> 3.4833221 | BS17: =AI17/(BP17) -> 0 | BT17: =(BS17-BQ17)/BQ17 -> -1
A18: KNO3 | B18: 0.2 | C18: 1 | D18: 34 | E18: 33 | F18: =D18*1.6726219E-27 -> 5.6869145e-26 | G18: =E18*9.1093856E-31 -> 3.0060972e-29 | H18: =((F18*D18)/(G18*E18)) -> 1949.1203 | I18: =D18/E18 -> 1.030303 | J18: =(F18)-(G18) -> 5.6839084e-26 | K18: 101.1 | M18: =N18^-1 -> 0.0016389412 | N18: 610.15 | O18: 5.406e-05 | P18: 0.00039 | R18: 1.38e-10 | S18: 2.31e-10 | T18: =S18+R18 -> 3.69e-10 | U18: 39.0983 | V18: =14.0067+3*15.9994 -> 62.0049 | W18: =U18*V18/(U18+V18) -> 23.978333 | X18: =(AA18+N18*AB18)*1000000 -> 1870200.6 | Y18: 2449.928 | Z18: -1.12 | AA18: 2.315 | AB18: -0.000729 | AC18: 2 | AD18: 3 | AE18: =AC18+AD18 -> 5 | AF18: =1/3*BR18*BL18*T18 -> 5.6673049e-07 | AH18: 0.4092 | AW18: 0.53083305 | AX18: =(AI18-AW18)/AI18 -> #DIV/0! | BB18: 1.4385719e+09 | BC18: =AW18/BB18 -> 3.69e-10 | BD18: =SQRT((BC18-BE18)/W18) -> 3.922868e-06 | BH18: =AI18/(1/3*BR18*BL18) -> 0 | BI18: =AI18/BB18 -> 0 | BJ18: =(BI18-BC18)/BC18 -> -1 | BK18: =AW18/BL18 -> 0.00030048968 | BL18: =Y18+Z18*N18 -> 1766.56 | BN18: =AI18/BK18 -> 0 | BO18: =(BN18-BL18)/BL18 -> -1 | BP18: =AW18/BQ18 -> 0.0037647734 | BQ18: 141 | BR18: =BQ18/O18*0.000001 -> 2.6082131 | BS18: =AI18/(BP18) -> 0 | BT18: =(BS18-BQ18)/BQ18 -> -1
A19: ZrF4 | B19: 0.05 | C19: 1 | D19: 49 | E19: 46 | F19: =D19*1.6726219E-27 -> 8.1958473e-26 | G19: =E19*9.1093856E-31 -> 4.1903174e-29 | H19: =((F19*D19)/(G19*E19)) -> 2083.4601 | I19: =D19/E19 -> 1.0652174 | J19: =(F19)-(G19) -> 8.191657e-26 | K19: 167.21 | M19: =N19^-1 -> 0.00083963056 | N19: 1191 | O19: =K19/X19 -> 4.2928625e-05 | P19: 0.000309 | R19: 7.2e-11 | S19: 1.33e-10 | T19: =S19+R19 -> 2.05e-10 | U19: 91.224 | V19: 18.9984 | W19: =U19*V19/(U19+V19) -> 15.723755 | X19: =(5.36-0.00123*N19)*1000000 -> 3895070 | Y19: 1700 | Z19: 0 | AA19: 5.36 | AB19: -0.00123 | AF19: =1/3*BR19*BL19*T19 -> 3.3284318e-07 | BD19: =SQRT((BC19-BE19)/W19) -> 0 | BH19: =AI19/(1/3*BR19*BL19) -> 0 | BL19: =Y19+Z19*N19 -> 1700 | BP19: =AW19/BQ19 -> 0 | BQ19: 123 | BR19: =BQ19/O19*0.000001 -> 2.865221
A20: ThF4 | B20: 0.08 | C20: 1 | D20: 99 | E20: 96 | F20: =D20*1.6726219E-27 -> 1.6558957e-25 | G20: =E20*9.1093856E-31 -> 8.7450102e-29 | H20: =((F20*D20)/(G20*E20)) -> 1952.7049 | I20: =D20/E20 -> 1.03125 | J20: =(F20)-(G20) -> 1.6550212e-25 | K20: 308.0317 | M20: =N20^-1 -> 0.00072254335 | N20: 1384 | O20: =K20/X20 -> 5.0331977e-05 | P20: 0.000121 | R20: 9.4e-11 | S20: 1.33e-10 | T20: =S20+R20 -> 2.27e-10 | U20: 232.0381 | V20: 18.9984 | W20: =U20*V20/(U20+V20) -> 17.560604 | X20: 6120000 | Y20: 1362 | Z20: 0 | AA20: 7.34 | AB20: -0.000808 | AF20: =1/3*BR20*BL20*T20 -> 3.4399094e-07 | BD20: =SQRT((BC20-BE20)/W20) -> 0 | BH20: =AI20/(1/3*BR20*BL20) -> 0 | BL20: =Y20+Z20*N20 -> 1362 | BP20: =AW20/BQ20 -> 0 | BQ20: 168 | BR20: =BQ20/O20*0.000001 -> 3.3378383
A21: UF4 | B21: 0.09 | C21: 1 | D21: 101 | E21: 98 | F21: =D21*1.6726219E-27 -> 1.6893481e-25 | G21: =E21*9.1093856E-31 -> 8.9271979e-29 | H21: =((F21*D21)/(G21*E21)) -> 1950.2904 | I21: =D21/E21 -> 1.0306122 | J21: =(F21)-(G21) -> 1.6884554e-25 | K21: 314.0225 | L21: =10^(11.4-35400/N21+27700000/N21^2)/1000 -> 0.003329486 | M21: =N21^-1 -> 0.00076394194 | N21: 1309 | O21: =K21/X21 -> 4.8535162e-05 | P21: 0.000149 | R21: 8.9e-11 | S21: 1.33e-10 | T21: =S21+R21 -> 2.22e-10 | U21: 238.0289 | V21: 18.9984 | W21: =U21*V21/(U21+V21) -> 17.594116 | X21: 6470000 | Y21: 1062 | Z21: 0 | AA21: 7.604 | AB21: -0.000791 | AF21: =1/3*BR21*BL21*T21 -> 2.8174032e-07 | BD21: =SQRT((BC21-BE21)/W21) -> 0 | BH21: =AI21/(1/3*BR21*BL21) -> 0 | BL21: =Y21+Z21*N21 -> 1062 | BP21: =AW21/BQ21 -> 0 | BQ21: 174 | BR21: =BQ21/O21*0.000001 -> 3.5850297 | BY21: =L21/(X21/1000*(Y21+Z21*N21)) -> 4.8456093e-10
A22: UCl3 | C22: 1 | D22: 109 | E22: 107 | F22: =D22*1.6726219E-27 -> 1.8231579e-25 | G22: =E22*9.1093856E-31 -> 9.7470426e-29 | H22: =((F22*D22)/(G22*E22)) -> 1905.435 | I22: =D22/E22 -> 1.0186916 | J22: =(F22)-(G22) -> 1.8221832e-25 | K22: 344.3879 | L22: =0.478*EXP(10900/(8.3144598*N22))/1000 -> 0.0015506403 | M22: =N22^-1 -> 0.00089766607 | N22: 1114 | O22: =K22/X22 -> 7.5193865e-05 | P22: 0.000333 | R22: 1.16e-10 | S22: 1.81e-10 | T22: =S22+R22 -> 2.97e-10 | U22: 238.0289 | V22: 35.453 | W22: =U22*V22/(U22+V22) -> 30.857028 | X22: 4580000 | Y22: 1248 | Z22: 0 | AA22: 6.3747 | AB22: -0.0015222 | AF22: =1/3*BR22*BL22*T22 -> 2.4646692e-07 | BD22: =SQRT((BC22-BE22)/W22) -> 0 | BH22: =AI22/(1/3*BR22*BL22) -> 0 | BL22: =Y22+Z22*N22 -> 1248 | BP22: =AW22/BQ22 -> 0 | BQ22: 150 | BR22: =BQ22/O22*0.000001 -> 1.9948436 | BY22: =L22/(X22/1000*(Y22+Z22*N22)) -> 2.7128826e-10
A23: 0.68KCl-0.32MgCl2 | C23: 2 | D23: 33.76 | E23: 33.44 | F23: =D23*1.6726219E-27 -> 5.6467715e-26 | G23: =E23*9.1093856E-31 -> 3.0461785e-29 | H23: =((F23*D23)/(G23*E23)) -> 1871.4621 | I23: =D23/E23 -> 1.0095694 | J23: =(F23)-(G23) -> 5.6437254e-26 | K23: 81.162404 | L23: =0.141*EXP(18800/(8.3144598*N23))/1000 -> 0.0036048873 | M23: =N23^-1 -> 0.0014334862 | N23: 697.6 | O23: 4.6549051e-05 | P23: 0.00030722638 | T23: =0.68*T9+0.32*T14 -> 2.9788e-10 | X23: 1741629.2 | Y23: 1968.0306 | AC23: 2 | AD23: 3 | AE23: =AC23+AD23 -> 5 | AF23: =1/3*BR23*BL23*T23 -> 3.3375409e-07 | AH23: 0.43524 | AW23: 0.28255486 | AX23: =(AI23-AW23)/AI23 -> #DIV/0! | BB23: 1.1204313e+09 | BC23: =AW23/BB23 -> 2.52184e-10 | BH23: =AI23/(1/3*BR23*BL23) -> 0 | BI23: =AI23/BB23 -> 0 | BJ23: =(BI23-BC23)/BC23 -> -1 | BK23: =AW23/BL23 -> 0.00014357239 | BL23: =Y23+Z23*N23 -> 1968.0306 | BN23: =AI23/BK23 -> 0 | BO23: =(BN23-BL23)/BL23 -> -1 | BP23: =AW23/BQ23 -> 0.0035539989 | BQ23: 79.50336 | BR23: =BQ23/O23*0.000001 -> 1.707948 | BS23: =AI23/(BP23) -> 0 | BT23: =(BS23-BQ23)/BQ23 -> -1 | BY23: =L23/(X23/1000*(Y23+Z23*N23)) -> 1.0517297e-09
A24: 0.66LiF-0.34BeF2 | C24: 2 | D24: 12.34 | E24: 11.34 | F24: =D24*1.6726219E-27 -> 2.0640154e-26 | G24: =E24*9.1093856E-31 -> 1.0330043e-29 | H24: =((F24*D24)/(G24*E24)) -> 2174.2671 | I24: =D24/E24 -> 1.0881834 | J24: =(F24)-(G24) -> 2.0629824e-26 | K24: 33.10314 | L24: =0.116*EXP(31200/(8.3144598*N24))/1000 -> 0.019398692 | M24: =N24^-1 -> 0.0013642565 | N24: 733 | O24: 1.6714174e-05 | P24: 0.00014095269 | T24: =0.66*T2+0.34*T10 -> 1.9472e-10 | X24: 1986063.4 | Y24: 2547.6864 | AC24: 2 | AD24: 3 | AE24: =AC24+AD24 -> 5 | AF24: =1/3*BR24*BL24*T24 -> 7.1488518e-07 | AG24: =1/3*BR24*BL24*BE24 -> 6.0953584e-07 | AH24: 1.1 | AI24: 1.1 | AJ24: Rosenthal, 1969 | AK24: =AI24*AK$1 -> 1.265 | AL24: =AI24*AL$1 -> 0.935 | AM24: 2.080697e-10 | AN24: 1.2767938 | AO24: =ABS(AI24-AN24)/AI24 -> 0.16072165 | AP24: 1.518486 | AQ24: =ABS(AI24-AP24)/AI24 -> 0.38044182 | AR24: 0.3484234 | AS24: 1.0187918 | AT24: =ABS(($AI24-AS24)/$AI24) -> 0.073825681 | AU24: 1.0187918 | AV24: =ABS(($AI24-AU24)/$AI24) -> 0.073825681 | AW24: 0.62426159 | AX24: =(AI24-AW24)/AI24 -> 0.43248946 | AY24: =AI24/(1/3*BL24*BG24) -> 3706357.2 | AZ24: 1.9173646e-07 | BA24: =AI24/(AZ24)*0.000001 -> 5.7370412 | BB24: 3.6713495e+09 | BC24: =AW24/BB24 -> 1.70036e-10 | BE24: 1.6602501e-10 | BF24: 2.0909055e-10 | BG24: 3.494787e-10 | BH24: =AI24/(1/3*BR24*BL24) -> 0.00029961735 | BI24: =AI24/BB24 -> 2.9961735e-10 | BJ24: =(BI24-BC24)/BC24 -> 0.76208182 | BK24: =AW24/BL24 -> 0.00024503078 | BL24: =Y24+Z24*N24 -> 2547.6864 | BN24: =AI24/BK24 -> 4489.2319 | BO24: =(BN24-BL24)/BL24 -> 0.76208182 | BP24: =AW24/BQ24 -> 0.0086393422 | BQ24: 72.258 | BR24: =BQ24/O24*0.000001 -> 4.3231572 | BS24: =AI24/(BP24) -> 127.32451 | BT24: =(BS24-BQ24)/BQ24 -> 0.76208182 | BY24: =L24/(X24/1000*(Y24+Z24*N24)) -> 3.8338347e-09
A25: 0.465LiF-0.115NaF-0.42KF | C25: 3 | D25: 19.64 | E25: 19.64 | F25: =D25*1.6726219E-27 -> 3.2850294e-26 | G25: =E25*9.1093856E-31 -> 1.7890833e-29 | H25: =((F25*D25)/(G25*E25)) -> 1836.1523 | I25: =D25/E25 -> 1 | J25: =(F25)-(G25) -> 3.2832403e-26 | K25: 41.290995 | L25: =10^(0.213+-1200/N25+1350000/N25^2)/1000 -> 0.012003439 | M25: =N25^-1 -> 0.0013605442 | N25: 735 | O25: 1.9405588e-05 | P25: 0.00031252325 | T25: =0.465*T2+0.115*T3+0.42*T4 -> 2.3803e-10 | X25: 2102415.4 | Y25: 2012.4687 | AC25: 3 | AD25: 3 | AE25: =AC25+AD25 -> 6 | AF25: =1/3*BR25*BL25*T25 -> 5.4326859e-07 | AG25: =1/3*BR25*BL25*BE25 -> 4.8209295e-07 | AH25: 0.78024247 | AI25: 0.78633288 | AJ25: Merritt, 2022; Gallagher, 2022; Rudenko, 2022 | AK25: =AI25*AK$1 -> 0.90428281 | AL25: =AI25*AL$1 -> 0.66838294 | AM25: 2.32906e-10 | AN25: 0.75631548 | AO25: =ABS(AI25-AN25)/AI25 -> 0.038173904 | AP25: 0.90509687 | AQ25: =ABS(AI25-AP25)/AI25 -> 0.15103526 | AR25: 0.3696076 | AS25: 0.83961046 | AT25: =ABS(($AI25-AS25)/$AI25) -> 0.067754491 | AU25: 0.83961046 | AV25: =ABS(($AI25-AU25)/$AI25) -> 0.067754491 | AW25: 0.39969772 | AX25: =(AI25-AW25)/AI25 -> 0.491694 | AY25: =AI25/(1/3*BL25*BG25) -> 3145748.1 | AZ25: 2.0332455e-07 | BA25: =AI25/(AZ25)*0.000001 -> 3.8673779 | BB25: 2.2823534e+09 | BC25: =AW25/BB25 -> 1.7512525e-10 | BE25: 2.1122625e-10 | BF25: 2.4334221e-10 | BG25: 3.7262724e-10 | BH25: =AI25/(1/3*BR25*BL25) -> 0.00034452722 | BI25: =AI25/BB25 -> 3.4452722e-10 | BJ25: =(BI25-BC25)/BC25 -> 0.96731891 | BK25: =AW25/BL25 -> 0.00019861065 | BL25: =Y25+Z25*N25 -> 2012.4687 | BN25: =AI25/BK25 -> 3959.1677 | BO25: =(BN25-BL25)/BL25 -> 0.96731891 | BP25: =AW25/BQ25 -> 0.0060538246 | BQ25: 66.024 | BR25: =BQ25/O25*0.000001 -> 3.4023189 | BS25: =AI25/(BP25) -> 129.89026 | BT25: =(BS25-BQ25)/BQ25 -> 0.96731891 | BY25: =L25/(X25/1000*(Y25+Z25*N25)) -> 2.8369915e-09
A26: 0.675LiF-0.2BeF2-0.005ThF4-0.12UF4 | C26: 4 | D26: 23.315 | E26: 22.74 | F26: =D26*1.6726219E-27 -> 3.899718e-26 | G26: =E26*9.1093856E-31 -> 2.0714743e-29 | H26: =((F26*D26)/(G26*E26)) -> 1930.1836 | I26: =D26/E26 -> 1.0252858 | J26: =(F26)-(G26) -> 3.8976465e-26 | K26: 66.133684 | L26: =0.062*EXP(38800/(8.3144598*N26))/1000 -> 0.030468149 | M26: =N26^-1 -> 0.0013280212 | N26: 753 | O26: 1.9202817e-05 | P26: 0.00016787041 | T26: =0.675*T2+0.2*T10+0.005*T20+0.12*T21 -> 2.0225e-10 | X26: 2609440.5 | Y26: 1781.4332 | AC26: 4 | AD26: 11 | AE26: =AC26+AD26 -> 15 | AF26: =1/3*BR26*BL26*T26 -> 5.1681595e-07 | AH26: 1.16 | AW26: 0.43510013 | AX26: =(AI26-AW26)/AI26 -> #DIV/0! | BB26: 2.5553323e+09 | BC26: =AW26/BB26 -> 1.7027145e-10 | BH26: =AI26/(1/3*BR26*BL26) -> 0 | BI26: =AI26/BB26 -> 0 | BJ26: =(BI26-BC26)/BC26 -> -1 | BK26: =AW26/BL26 -> 0.00024424162 | BL26: =Y26+Z26*N26 -> 1781.4332 | BN26: =AI26/BK26 -> 0 | BO26: =(BN26-BL26)/BL26 -> -1 | BP26: =AW26/BQ26 -> 0.005265325 | BQ26: 82.635 | BR26: =BQ26/O26*0.000001 -> 4.3032749 | BS26: =AI26/(BP26) -> 0 | BT26: =(BS26-BQ26)/BQ26 -> -1 | BY26: =L26/(X26/1000*(Y26+Z26*N26)) -> 6.5543424e-09
A27: 0.712LiF-0.23BeF2-0.05ZrF4-0.008UF4 | C27: 4 | D27: 14.792 | E27: 14.388 | F27: =D27*1.6726219E-27 -> 2.4741423e-26 | G27: =E27*9.1093856E-31 -> 1.3106584e-29 | H27: =((F27*D27)/(G27*E27)) -> 1940.7144 | I27: =D27/E27 -> 1.028079 | J27: =(F27)-(G27) -> 2.4728317e-26 | K27: 40.153548 | M27: =N27^-1 -> 0.0014084507 | N27: 710 | O27: 1.6919881e-05 | P27: 0.00018512202 | T27: =0.712*T2+0.23*T10+0.05*T19+0.008*T21 -> 1.99244e-10 | X27: 2163027.6 | Y27: 2319.1206 | AC27: 4 | AD27: 11 | AE27: =AC27+AD27 -> 15 | AF27: =1/3*BR27*BL27*T27 -> 6.688004e-07 | AH27: 1.24 | AW27: 0.58242618 | AX27: =(AI27-AW27)/AI27 -> #DIV/0! | BB27: 3.3566903e+09 | BC27: =AW27/BB27 -> 1.7351204e-10 | BH27: =AI27/(1/3*BR27*BL27) -> 0 | BI27: =AI27/BB27 -> 0 | BJ27: =(BI27-BC27)/BC27 -> -1 | BK27: =AW27/BL27 -> 0.00025114096 | BL27: =Y27+Z27*N27 -> 2319.1206 | BN27: =AI27/BK27 -> 0 | BO27: =(BN27-BL27)/BL27 -> -1 | BP27: =AW27/BQ27 -> 0.0079274662 | BQ27: 73.4694 | BR27: =BQ27/O27*0.000001 -> 4.3421936 | BS27: =AI27/(BP27) -> 0 | BT27: =(BS27-BQ27)/BQ27 -> -1
A28: 0.73LiF-0.27BeF2 | C28: 2 | D28: 12.27 | E28: 11.73 | F28: =D28*1.6726219E-27 -> 2.0523071e-26 | G28: =E28*9.1093856E-31 -> 1.0685309e-29 | H28: =((F28*D28)/(G28*E28)) -> 2009.1011 | I28: =D28/E28 -> 1.0460358 | J28: =(F28)-(G28) -> 2.0512385e-26 | K28: 31.62817 | L28: =0.118*EXP(30100/(8.3144598*N28))/1000 -> 0.01658596 | M28: =N28^-1 -> 0.0013661202 | N28: 732 | O28: 1.5942466e-05 | P28: 0.00016222659 | T28: =0.73*T2+0.27*T10 -> 1.9766e-10 | X28: 1989043.9 | Y28: 2547.6876 | AC28: 2 | AD28: 3 | AE28: =AC28+AD28 -> 5 | AF28: =1/3*BR28*BL28*T28 -> 7.4333871e-07 | AH28: 0.98602842 | AW28: 0.66180311 | AX28: =(AI28-AW28)/AI28 -> #DIV/0! | BB28: 3.7606936e+09 | BC28: =AW28/BB28 -> 1.75979e-10 | BH28: =AI28/(1/3*BR28*BL28) -> 0 | BI28: =AI28/BB28 -> 0 | BJ28: =(BI28-BC28)/BC28 -> -1 | BK28: =AW28/BL28 -> 0.0002597662 | BL28: =Y28+Z28*N28 -> 2547.6876 | BN28: =AI28/BK28 -> 0 | BO28: =(BN28-BL28)/BL28 -> -1 | BP28: =AW28/BQ28 -> 0.0093741145 | BQ28: 70.599 | BR28: =BQ28/O28*0.000001 -> 4.4283613 | BS28: =AI28/(BP28) -> 0 | BT28: =(BS28-BQ28)/BQ28 -> -1 | BY28: =L28/(X28/1000*(Y28+Z28*N28)) -> 3.2730306e-09
A29: 0.725LiF-0.265BeF2-0.01UF4 | C29: 3 | D29: 13.155 | E29: 12.86 | F29: =D29*1.6726219E-27 -> 2.2003341e-26 | G29: =E29*9.1093856E-31 -> 1.171467e-29 | H29: =((F29*D29)/(G29*E29)) -> 1921.3587 | I29: =D29/E29 -> 1.0229393 | J29: =(F29)-(G29) -> 2.1991626e-26 | K29: 34.40365 | L29: =0.123*EXP(29800/(8.3144598*N29))/1000 -> 0.01645722 | M29: =N29^-1 -> 0.0013661202 | N29: 732 | O29: 1.6204764e-05 | P29: 0.00016258314 | T29: =0.725*T2+0.265*T10+0.01*T21 -> 1.98e-10 | X29: 2039490.5 | Y29: 2441.8706 | AC29: 3 | AD29: 7 | AE29: =AC29+AD29 -> 10 | AF29: =1/3*BR29*BL29*T29 -> 7.1187944e-07 | AH29: 0.89056772 | AW29: 0.63042336 | AX29: =(AI29-AW29)/AI29 -> #DIV/0! | BB29: 3.5953507e+09 | BC29: =AW29/BB29 -> 1.7534405e-10 | BH29: =AI29/(1/3*BR29*BL29) -> 0 | BI29: =AI29/BB29 -> 0 | BJ29: =(BI29-BC29)/BC29 -> -1 | BK29: =AW29/BL29 -> 0.00025817231 | BL29: =Y29+Z29*N29 -> 2441.8706 | BN29: =AI29/BK29 -> 0 | BO29: =(BN29-BL29)/BL29 -> -1 | BP29: =AW29/BQ29 -> 0.0088074402 | BQ29: 71.5785 | BR29: =BQ29/O29*0.000001 -> 4.4171269 | BS29: =AI29/(BP29) -> 0 | BT29: =(BS29-BQ29)/BQ29 -> -1 | BY29: =L29/(X29/1000*(Y29+Z29*N29)) -> 3.3045487e-09
A30: 0.72LiF-0.26BeF2-0.02UF4 | C30: 3 | D30: 14.04 | E30: 13.72 | F30: =D30*1.6726219E-27 -> 2.3483611e-26 | G30: =E30*9.1093856E-31 -> 1.2498077e-29 | H30: =((F30*D30)/(G30*E30)) -> 1922.8025 | I30: =D30/E30 -> 1.0233236 | J30: =(F30)-(G30) -> 2.3471113e-26 | K30: 37.17913 | L30: =0.123*EXP(29800/(8.3144598*N30))/1000 -> 0.01645722 | M30: =N30^-1 -> 0.0013661202 | N30: 732 | O30: 1.6467062e-05 | P30: 0.00016292833 | T30: =0.72*T2+0.26*T10+0.02*T21 -> 1.9834e-10 | X30: 2089937.1 | Y30: 2348.752 | AC30: 3 | AD30: 7 | AE30: =AC30+AD30 -> 10 | AF30: =1/3*BR30*BL30*T30 -> 6.8421942e-07 | AH30: 0.80397278 | AW30: 0.60277958 | AX30: =(AI30-AW30)/AI30 -> #DIV/0! | BB30: 3.4497298e+09 | BC30: =AW30/BB30 -> 1.747324e-10 | BH30: =AI30/(1/3*BR30*BL30) -> 0 | BI30: =AI30/BB30 -> 0 | BJ30: =(BI30-BC30)/BC30 -> -1 | BK30: =AW30/BL30 -> 0.00025663824 | BL30: =Y30+Z30*N30 -> 2348.752 | BN30: =AI30/BK30 -> 0 | BO30: =(BN30-BL30)/BL30 -> -1 | BP30: =AW30/BQ30 -> 0.008307555 | BQ30: 72.558 | BR30: =BQ30/O30*0.000001 -> 4.4062504 | BS30: =AI30/(BP30) -> 0 | BT30: =(BS30-BQ30)/BQ30 -> -1 | BY30: =L30/(X30/1000*(Y30+Z30*N30)) -> 3.3526337e-09
A31: 0.32KCl-0.68MgCl2 | C31: 2 | D31: 31.24 | E31: 30.56 | F31: =D31*1.6726219E-27 -> 5.2252708e-26 | G31: =E31*9.1093856E-31 -> 2.7838282e-29 | H31: =((F31*D31)/(G31*E31)) -> 1918.775 | I31: =D31/E31 -> 1.0222513 | J31: =(F31)-(G31) -> 5.222487e-26 | K31: 88.599896 | M31: =N31^-1 -> 0.001433589 | N31: 697.55 | O31: 5.0411903e-05 | P31: 0.00023528262 | T31: =0.32*T9+0.68*T14 -> 2.7412e-10 | X31: 1755710.6 | Y31: 2039.5015 | AC31: 2 | AD31: 3 | AE31: =AC31+AD31 -> 5 | AF31: =1/3*BR31*BL31*T31 -> 3.1844809e-07 | AH31: 0.45966667 | AW31: 0.26536257 | AX31: =(AI31-AW31)/AI31 -> #DIV/0! | BB31: 1.1617105e+09 | BC31: =AW31/BB31 -> 2.28424e-10 | BH31: =AI31/(1/3*BR31*BL31) -> 0 | BI31: =AI31/BB31 -> 0 | BJ31: =(BI31-BC31)/BC31 -> -1 | BK31: =AW31/BL31 -> 0.00013011149 | BL31: =Y31+Z31*N31 -> 2039.5015 | BN31: =AI31/BK31 -> 0 | BO31: =(BN31-BL31)/BL31 -> -1 | BP31: =AW31/BQ31 -> 0.0030804304 | BQ31: 86.14464 | BR31: =BQ31/O31*0.000001 -> 1.7088155 | BS31: =AI31/(BP31) -> 0 | BT31: =(BS31-BQ31)/BQ31 -> -1
A32: 0.4598NaCl-0.3891KCl-0.1511MgCl2 | C32: 3 | D32: 31.2639 | E32: 31.1128 | F32: =D32*1.6726219E-27 -> 5.2292684e-26 | G32: =E32*9.1093856E-31 -> 2.8341849e-29 | H32: =((F32*D32)/(G32*E32)) -> 1854.0302 | I32: =D32/E32 -> 1.0048565 | J32: =(F32)-(G32) -> 5.2264342e-26 | K32: 70.265005 | M32: =N32^-1 -> 0.0014824698 | N32: 674.55 | O32: 3.990775e-05 | P32: 0.00032881888 | T32: =0.4598*T8+0.3891*T9+0.1511*T14 -> 2.924746e-10 | X32: 1761445 | Y32: 2024.7769 | AC32: 3 | AD32: 4 | AE32: =AC32+AD32 -> 7 | AF32: =1/3*BR32*BL32*T32 -> 3.6878913e-07 | AH32: 0.46554762 | AW32: 0.28383634 | AX32: =(AI32-AW32)/AI32 -> #DIV/0! | BB32: 1.260927e+09 | BC32: =AW32/BB32 -> 2.2510132e-10 | BH32: =AI32/(1/3*BR32*BL32) -> 0 | BI32: =AI32/BB32 -> 0 | BJ32: =(BI32-BC32)/BC32 -> -1 | BK32: =AW32/BL32 -> 0.00014018154 | BL32: =Y32+Z32*N32 -> 2024.7769 | BN32: =AI32/BK32 -> 0 | BO32: =(BN32-BL32)/BL32 -> -1 | BP32: =AW32/BQ32 -> 0.0038069461 | BQ32: 74.557489 | BR32: =BQ32/O32*0.000001 -> 1.8682459 | BS32: =AI32/(BP32) -> 0 | BT32: =(BS32-BQ32)/BQ32 -> -1 | BU32: rho | BV32: cp
A33: 0.345NaF-0.59KF-0.065MgF2 | C33: 3 | D33: 24.785 | E33: 24.72 | F33: =D33*1.6726219E-27 -> 4.1455934e-26 | G33: =E33*9.1093856E-31 -> 2.2518401e-29 | H33: =((F33*D33)/(G33*E33)) -> 1845.8211 | I33: =D33/E33 -> 1.0026294 | J33: =(F33)-(G33) -> 4.1433415e-26 | K33: 52.812707 | M33: =N33^-1 -> 0.0010416667 | N33: 960 | O33: 2.5195547e-05 | P33: 0.00031944978 | T33: =0.345*T3+0.59*T4+0.065*T11 -> 2.5429e-10 | X33: 2110100.6 | Y33: 1885.1934 | AC33: 3 | AD33: 4 | AE33: =AC33+AD33 -> 7 | AF33: =1/3*BR33*BL33*T33 -> 4.430568e-07 | AH33: 0.71 | AI33: 0.766984 | AJ33: Rudenko, 2024 | AK33: =AI33*AK$1 -> 0.8820316 | AL33: =AI33*AL$1 -> 0.6519364 | AM33: 2.56459e-10 | AN33: 0.49756829 | AO33: =ABS(AI33-AN33)/AI33 -> 0.3512664 | AP33: 0.59758621 | AQ33: =ABS(AI33-AP33)/AI33 -> 0.22086223 | AR33: 0.025852466 | AS33: 0.52021967 | AT33: =ABS(($AI33-AS33)/$AI33) -> 0.32173335 | AU33: 0.52021967 | AV33: =ABS(($AI33-AU33)/$AI33) -> 0.32173335 | AW33: 0.33711022 | AX33: =(AI33-AW33)/AI33 -> 0.56047294 | BB33: 1.7423288e+09 | BC33: =AW33/BB33 -> 1.9348255e-10 | BF33: 2.7673725e-10 | BH33: =AI33/(1/3*BR33*BL33) -> 0.00044020623 | BI33: =AI33/BB33 -> 4.4020623e-10 | BJ33: =(BI33-BC33)/BC33 -> 1.2751728 | BK33: =AW33/BL33 -> 0.00017881997 | BL33: =Y33+Z33*N33 -> 1885.1934 | BN33: =AI33/BK33 -> 4289.1408 | BO33: =(BN33-BL33)/BL33 -> 1.2751728 | BP33: =AW33/BQ33 -> 0.004825615 | BQ33: 69.8585 | BR33: =BQ33/O33*0.000001 -> 2.7726526 | BS33: =AI33/(BP33) -> 158.94016 | BT33: =(BS33-BQ33)/BQ33 -> 1.2751728 | BU33: =2.08*100^3/1000 -> 2080 | BV33: =1.35*1000 -> 1350 | BW33: =BV33*BU33 -> 2808000 | BX33: =BQ33/O33 -> 2772652.6
A34: 0.582LiCl-0.418KCl | C34: 2 | D34: 26.688 | E34: 26.688 | F34: =D34*1.6726219E-27 -> 4.4638933e-26 | G34: =E34*9.1093856E-31 -> 2.4311128e-29 | H34: =((F34*D34)/(G34*E34)) -> 1836.1523 | I34: =D34/E34 -> 1 | J34: =(F34)-(G34) -> 4.4614622e-26 | K34: 55.835751 | L34: =0.087*EXP(20900/(8.3144598*N34))/1000 -> 0.0046437178 | M34: =N34^-1 -> 0.0015822785 | N34: 632 | O34: 3.2950649e-05 | P34: 0.00033829968 | T34: =0.582*T7+0.418*T9 -> 2.82916e-10 | X34: 1676175.3 | Y34: 2084.8843 | AC34: 2 | AD34: 2 | AE34: =AC34+AD34 -> 4 | AF34: =1/3*BR34*BL34*T34 -> 4.0937294e-07 | AH34: 0.58438111 | AW34: 0.33404178 | AX34: =(AI34-AW34)/AI34 -> #DIV/0! | BB34: 1.446977e+09 | BC34: =AW34/BB34 -> 2.3085494e-10 | BH34: =AI34/(1/3*BR34*BL34) -> 0 | BI34: =AI34/BB34 -> 0 | BJ34: =(BI34-BC34)/BC34 -> -1 | BK34: =AW34/BL34 -> 0.00016022077 | BL34: =Y34+Z34*N34 -> 2084.8843 | BN34: =AI34/BK34 -> 0 | BO34: =(BN34-BL34)/BL34 -> -1 | BP34: =AW34/BQ34 -> 0.0048689566 | BQ34: 68.60644 | BR34: =BQ34/O34*0.000001 -> 2.0820968 | BS34: =AI34/(BP34) -> 0 | BT34: =(BS34-BQ34)/BQ34 -> -1 | BW34: =BW33-BR33 -> 2807997.2 | BY34: =L34/(X34/1000*(Y34+Z34*N34)) -> 1.3288146e-09
A35: 0.6LiF-0.4NaF | C35: 2 | D35: 15.2 | E35: 15.2 | F35: =D35*1.6726219E-27 -> 2.5423853e-26 | G35: =E35*9.1093856E-31 -> 1.3846266e-29 | H35: =((F35*D35)/(G35*E35)) -> 1836.1523 | I35: =D35/E35 -> 1 | J35: =(F35)-(G35) -> 2.5410007e-26 | K35: 32.3586 | L35: =0.116*EXP(26800/(8.3144598*N35))/1000 -> 0.0039071252 | M35: =N35^-1 -> 0.0010911075 | N35: 916.5 | O35: 1.5885584e-05 | P35: 0.00027773489 | T35: =0.6*T2+0.4*T3 -> 2.194e-10 | X35: 2014141.4 | Y35: 2298.2284 | AC35: 2 | AD35: 2 | AE35: =AC35+AD35 -> 4 | AF35: =1/3*BR35*BL35*T35 -> 7.0465998e-07 | AG35: =1/3*BR35*BL35*BE35 -> 6.1490801e-07 | AH35: 0.86544945 | AI35: 0.86544945 | AJ35: BYU, 2023 | AK35: =AI35*AK$1 -> 0.99526687 | AL35: =AI35*AL$1 -> 0.73563203 | AM35: 2.28638e-10 | AN35: 0.77860023 | AO35: =ABS(AI35-AN35)/AI35 -> 0.10035158 | AP35: 1.0757818 | AQ35: =ABS(AI35-AP35)/AI35 -> 0.24303254 | AR35: 0.32010611 | AS35: 0.77665761 | AT35: =ABS(($AI35-AS35)/$AI35) -> 0.10259622 | AU35: 0.77665761 | AV35: =ABS(($AI35-AU35)/$AI35) -> 0.10259622 | AW35: 0.56745362 | AX35: =(AI35-AW35)/AI35 -> 0.34432494 | AY35: =AI35/(1/3*BL35*BG35) -> 4955239.7 | AZ35: 1.8525014e-07 | BA35: =AI35/(AZ35)*0.000001 -> 4.6717884 | BB35: 3.2117592e+09 | BC35: =AW35/BB35 -> 1.7668e-10 | BE35: 1.914552e-10 | BF35: 2.1702518e-10 | BG35: 2.2798439e-10 | BH35: =AI35/(1/3*BR35*BL35) -> 0.00026946274 | BI35: =AI35/BB35 -> 2.6946274e-10 | BJ35: =(BI35-BC35)/BC35 -> 0.52514569 | BK35: =AW35/BL35 -> 0.00024690915 | BL35: =Y35+Z35*N35 -> 2298.2284 | BN35: =AI35/BK35 -> 3505.1331 | BO35: =(BN35-BL35)/BL35 -> 0.52514569 | BP35: =AW35/BQ35 -> 0.0085203247 | BQ35: 66.6 | BR35: =BQ35/O35*0.000001 -> 4.1924806 | BS35: =AI35/(BP35) -> 101.5747 | BT35: =(BS35-BQ35)/BQ35 -> 0.52514569 | BY35: =L35/(X35/1000*(Y35+Z35*N35)) -> 8.4406168e-10
A36: 0.63NaCl-0.37UCl3 (ORNL) | C36: 2 | D36: 57.97 | E36: 57.23 | F36: =D36*1.6726219E-27 -> 9.6961892e-26 | G36: =E36*9.1093856E-31 -> 5.2133014e-29 | H36: =((F36*D36)/(G36*E36)) -> 1883.9432 | I36: =D36/E36 -> 1.0129303 | J36: =(F36)-(G36) -> 9.6909759e-26 | K36: 164.24072 | L36: =10^(-1.2675+1704/N36+0/N36^2)/1000 -> 0.0080532167 | M36: =N36^-1 -> 0.0012755102 | N36: 784 | O36: 4.6078431e-05 | P36: 0.00034092676 | T36: =0.63*T8+0.37*T22 -> 2.8818e-10 | X36: 2996639.7 | Y36: 1451.7495 | AC36: 2 | AD36: 4 | AE36: =AC36+AD36 -> 6 | AF36: =1/3*BR36*BL36*T36 -> 3.0071201e-07 | AG36: =1/3*BR36*BL36*BE36 -> 2.8418198e-07 | AH36: 0.23926258 | AI36: 0.23926258 | AJ36: Termini, 2024 | AK36: =AI36*AK$1 -> 0.27515196 | AL36: =AI36*AL$1 -> 0.20337319 | AM36: 2.89258E-10 | AN36: 0.30100333 | AO36: =ABS(AI36-AN36)/AI36 -> 0.258046 | AP36: 0.11479147 | AQ36: =ABS(AI36-AP36)/AI36 -> 0.52022805 | AR36: 0.11435209 | AS36: 0.31391915 | AT36: =ABS(($AI36-AS36)/$AI36) -> 0.3120278 | AU36: 0.31391915 | AV36: =ABS(($AI36-AU36)/$AI36) -> 0.3120278 | AW36: 0.2476864 | AX36: =(AI36-AW36)/AI36 -> -0.035207434 | AY36: =AI36/(1/3*BL36*BG36) -> 1760763.4 | AZ36: 1.5836551e-07 | BA36: =AI36/(AZ36)*0.000001 -> 1.510825 | BB36: 1.0434868e+09 | BC36: =AW36/BB36 -> 2.373642e-10 | BE36: 2.7233885e-10 | BF36: 3.0068514e-10 | BG36: 2.8080404e-10 | BH36: =AI36/(1/3*BR36*BL36) -> 0.00022929144 | BI36: =AI36/BB36 -> 2.2929144e-10 | BJ36: =(BI36-BC36)/BC36 -> -0.034010028 | BK36: =AW36/BL36 -> 0.00017061236 | BL36: =Y36+Z36*N36 -> 1451.7495 | BN36: =AI36/BK36 -> 1402.3754 | BO36: =(BN36-BL36)/BL36 -> -0.034010028 | BP36: =AW36/BQ36 -> 0.002492803 | BQ36: 99.3606 | BR36: =BQ36/O36*0.000001 -> 2.1563364 | BS36: =AI36/(BP36) -> 95.981343 | BT36: =(BS36-BQ36)/BQ36 -> -0.034010028 | BY36: =L36/(X36/1000*(Y36+Z36*N36)) -> 1.8511567e-09
A37: 0.658NaCl-0.342UCl3 (ANL) | C37: 2 | D37: 55.702 | E37: 55.018 | F37: =D37*1.6726219E-27 -> 9.3168385e-26 | G37: =E37*9.1093856E-31 -> 5.0118018e-29 | H37: =((F37*D37)/(G37*E37)) -> 1882.0912 | I37: =D37/E37 -> 1.0124323 | J37: =(F37)-(G37) -> 9.3118267e-26 | K37: 156.23418 | L37: =10^(-1.2179+1557/N37+0/N37^2)/1000 -> 0.0058623182 | M37: =N37^-1 -> 0.0012755102 | N37: 784 | O37: 4.5172249e-05 | P37: 0.00034144514 | T37: =0.658*T8+0.342*T22 -> 2.87788e-10 | X37: 2899543.9 | Y37: 1470.4556 | AC37: 2 | AD37: 4 | AE37: =AC37+AD37 -> 6 | AF37: =1/3*BR37*BL37*T37 -> 3.0324622e-07 | AG37: =1/3*BR37*BL37*BE37 -> 2.8696723e-07 | AH37: 0.27567442 | AI37: 0.27567442 | AJ37: Rose, 2023 | AK37: =AI37*AK$1 -> 0.31702559 | AL37: =AI37*AL$1 -> 0.23432326 | AM37: 2.89258E-10 | AN37: 0.29231888 | AO37: =ABS(AI37-AN37)/AI37 -> 0.060377227 | AP37: 0.11126276 | AQ37: =ABS(AI37-AP37)/AI37 -> 0.59639797 | AR37: 0.10674697 | AS37: 0.33909844 | AT37: =ABS(($AI37-AS37)/$AI37) -> 0.23006856 | AU37: 0.33909844 | AV37: =ABS(($AI37-AU37)/$AI37) -> 0.23006856 | AW37: 0.25155328 | AX37: =(AI37-AW37)/AI37 -> 0.087498657 | AY37: =AI37/(1/3*BL37*BG37) -> 1872363.9 | AZ37: 1.5836551e-07 | BA37: =AI37/(AZ37)*0.000001 -> 1.7407479 | BB37: 1.0537139e+09 | BC37: =AW37/BB37 -> 2.3873015e-10 | BE37: 2.7233885e-10 | BF37: 3.0068514e-10 | BG37: 3.0038315e-10 | BH37: =AI37/(1/3*BR37*BL37) -> 0.0002616217 | BI37: =AI37/BB37 -> 2.616217e-10 | BJ37: =(BI37-BC37)/BC37 -> 0.095888798 | BK37: =AW37/BL37 -> 0.00017107167 | BL37: =Y37+Z37*N37 -> 1470.4556 | BN37: =AI37/BK37 -> 1611.4558 | BO37: =(BN37-BL37)/BL37 -> 0.095888798 | BP37: =AW37/BQ37 -> 0.0025903963 | BQ37: 97.10996 | BR37: =BQ37/O37*0.000001 -> 2.1497703 | BS37: =AI37/(BP37) -> 106.42172 | BT37: =(BS37-BQ37)/BQ37 -> 0.095888798 | BY37: =L37/(X37/1000*(Y37+Z37*N37)) -> 1.3749528e-09
A38: (NaF-KF)-.3UF4 | K38: 128.10887 | L38: =0.0767*EXP(39300/(8.3144598*N38))/1000 -> 0.0090410767 | N38: 991 | O38: 3.0243424e-05 | P38: 0.00023876282 | T38: =0.582*T3+0.388*T4+0.3*T21 -> 3.08518e-10 | X38: 3498633.6 | Y38: =BL38 -> 1348.6175 | AC38: 3 | AD38: 6 | AE38: =AC38+AD38 -> 9 | AF38: =1/3*BR38*BL38*T38 -> 4.6048979e-07 | AH38: 0.49395062 | AW38: 0.25347402 | AX38: =(AI38-AW38)/AI38 -> #DIV/0! | BB38: 1.4925865e+09 | BC38: =AW38/BB38 -> 1.69822e-10 | BH38: =AI38/(1/3*BR38*BL38) -> 0 | BI38: =AI38/BB38 -> 0 | BJ38: =(BI38-BC38)/BC38 -> -1 | BK38: =AW38/BL38 -> 0.000187951 | BL38: 1348.6175 | BN38: =AI38/BK38 -> 0 | BO38: =(BN38-BL38)/BL38 -> -1 | BP38: =AW38/BQ38 -> 0.0025242393 | BQ38: 100.416 | BR38: =BQ38/O38*0.000001 -> 3.3202589 | BS38: =AI38/(BP38) -> 0 | BT38: =(BS38-BQ38)/BQ38 -> -1 | BY38: =L38/(X38/1000*(Y38+Z38*N38)) -> 1.916165e-09
A39: (NaF-KF)-.4UF4 | K39: 154.66796 | L39: =0.0767*EXP(39300/(8.3144598*N39))/1000 -> 0.0081514268 | N39: 1013 | O39: 3.2645143e-05 | P39: 0.00022077563 | T39: =0.576*T3+0.384*T4+0.4*T21 -> 3.28224e-10 | X39: 3957693.6 | Y39: =BL39 -> 1272.126 | AC39: 3 | AD39: 6 | AE39: =AC39+AD39 -> 9 | AF39: =1/3*BR39*BL39*T39 -> 4.729354e-07 | AH39: 0.45693694 | AW39: 0.24265777 | AX39: =(AI39-AW39)/AI39 -> #DIV/0! | BB39: 1.4408922e+09 | BC39: =AW39/BB39 -> 1.68408e-10 | BH39: =AI39/(1/3*BR39*BL39) -> 0 | BI39: =AI39/BB39 -> 0 | BJ39: =(BI39-BC39)/BC39 -> -1 | BK39: =AW39/BL39 -> 0.00019074979 | BL39: 1272.126 | BN39: =AI39/BK39 -> 0 | BO39: =(BN39-BL39)/BL39 -> -1 | BP39: =AW39/BQ39 -> 0.002187525 | BQ39: 110.928 | BR39: =BQ39/O39*0.000001 -> 3.397994 | BS39: =AI39/(BP39) -> 0 | BT39: =(BS39-BQ39)/BQ39 -> -1 | BY39: =L39/(X39/1000*(Y39+Z39*N39)) -> 1.619054e-09
A40: (NaF-KF)-.5UF4 | K40: 181.22705 | L40: =0.0767*EXP(39300/(8.3144598*N40))/1000 -> 0.0078587879 | N40: 1021 | O40: 3.494914e-05 | P40: 0.00020501178 | T40: =0.57*T3+0.38*T4+0.5*T21 -> 3.4793e-10 | X40: 4426131.4 | Y40: =BL40 -> 1215.1718 | AC40: 3 | AD40: 6 | AE40: =AC40+AD40 -> 9 | AF40: =1/3*BR40*BL40*T40 -> 4.8970392e-07 | AH40: 0.43928571 | AW40: 0.23920093 | AX40: =(AI40-AW40)/AI40 -> #DIV/0! | BB40: 1.4074783e+09 | BC40: =AW40/BB40 -> 1.6995e-10 | BH40: =AI40/(1/3*BR40*BL40) -> 0 | BI40: =AI40/BB40 -> 0 | BJ40: =(BI40-BC40)/BC40 -> -1 | BK40: =AW40/BL40 -> 0.00019684536 | BL40: 1215.1718 | BN40: =AI40/BK40 -> 0 | BO40: =(BN40-BL40)/BL40 -> -1 | BP40: =AW40/BQ40 -> 0.0019697047 | BQ40: 121.44 | BR40: =BQ40/O40*0.000001 -> 3.4747636 | BS40: =AI40/(BP40) -> 0 | BT40: =(BS40-BQ40)/BQ40 -> -1 | BY40: =L40/(X40/1000*(Y40+Z40*N40)) -> 1.4611459e-09
...

Sheet MFP-rsum
A1: Compound | B1: S/cm | C1: order | D1: protons | E1: electrons | F1: Mp/molecule | G1: Me/molecule | H1: ratio of Mpe*# | I1: ratio | J1: Dif mass | K1: M_i (g/mol) | L1: Visc (N*s/m^2) | M1: T_i_m (K) inverse | N1: T_i_m (K) | O1: V_i_m (m^3/mol) | P1: alpha_i_m (K^-1) | R1: r_c (m) | S1: r_a (m) | T1: sum_radii | U1: rho_m (g/m^3) | V1: SoS(T)_A (A+B*T) | W1: SoS(T)_B | X1: A (Density (g/cm3): A - BT(K)) | Y1: B (Density (g/cm3): A - BT(K)) | Z1: #_cations | AA1: #_anions | AB1: sum_ions | AC1: λ_meas | AD1: 1/3*Cp*vs*r_sumCorrect | AE1: Error | AF1: 1/3*Cp*vs*1stPk | AG1: 1/3*Cp*vs*AvgPk | AH1: 1/3*Cp*vs*r_sum | AI1: dev_λ | AJ1: c_BC,rsum | AK1: c_BC_λBC | AL1: 1/3*Cp*vs | AM1: r_sum | AN1: 1stPeak | AO1: AvgMFP | AP1: λBC | AQ1: MFP_calc | AR1: MFP_dev | AS1: 1/3*Cp*r_sum | AT1: SoS_Tm | AU1: SoS_metal | AV1: vs_calc | AW1: vs_dev | AX1: 1/3*vs*r_sum | AY1: C_i_p (J/mol/K) | AZ1: Cp(J/m3-K) | BA1: Cp_calc | BB1: Cp_dev | BC1: vs*cp | BD1: 1/3*vs*cp*rsum | BG1: Visc/(Dens*C0)
A2: LiF | B2: 9.95 | C2: 1 | D2: 12 | E2: 12 | F2: =D2*1.6726219E-27 -> 2.0071463e-26 | G2: =E2*9.1093856E-31 -> 1.0931263e-29 | H2: =((F2*D2)/(G2*E2)) -> 1836.1523 | I2: =D2/E2 -> 1 | J2: =(F2)-(G2) -> 2.0060532e-26 | K2: 25.939 | L2: =0.115*EXP(27000/(8.3144598*N2))/1000 -> 0.0020988673 | M2: =N2^-1 -> 0.00089433439 | N2: 1118.15 | O2: 1.42e-05 | P2: 0.000268 | R2: 7.6e-11 | S2: 1.33e-10 | T2: =S2+R2 -> 2.09e-10 | U2: 1810000 | V2: 2547.8 | W2: 0 | X2: 2.3581 | Y2: -0.0004902 | Z2: 1 | AA2: 1 | AB2: =Z2+AA2 -> 2 | AC2: 1.33125 | AD2: =1/3*AZ2*AT2*T2 -> 0.80248523 | AE2: =ABS((AC2-AD2)/AC2) -> 0.39719419 | AF2: =1/3*AZ2*AT2*AN2 -> 0.72246878 | AG2: =1/3*AZ2*AT2*AO2 -> 0.90368251 | AH2: 0.79448872 | AI2: =(AC2-AH2)/AC2 -> 0.40320096 | AJ2: =AC2/(1/3*AT2*T2) -> 7500138 | AK2: =AC2/(1/3*AT2*AP2) -> 4521126.8 | AL2: 3.8013815e+09 | AM2: =AH2/AL2 -> 2.09e-10 | AN2: 1.8816044e-10 | AO2: 2.3535591e-10 | AP2: =AC2/(1/3*AZ2*AT2) -> 3.4671199e-10 | AQ2: =AC2/AL2 -> 3.5020164e-10 | AR2: =(AQ2-AM2)/AM2 -> 0.67560591 | AS2: =AH2/AT2 -> 0.00031183324 | AT2: =V2+W2*N2 -> 2547.8 | AU2: 3500 | AV2: =AC2/AS2 -> 4269.1087 | AW2: =(AV2-AT2)/AT2 -> 0.67560591 | AX2: =AH2/AY2 -> 0.012375214 | AY2: 64.2 | AZ2: =AY2/O2 -> 4521126.8 | BA2: =AC2/(AX2) -> 107.5739 | BB2: =(BA2-AY2)/AY2 -> 0.67560591 | BC2: =AT2*AZ2 -> 1.1518927e+10 | BD2: =1/3*BC2*T2 -> 0.80248523 | BG2: =L2/(U2/1000*(V2+W2*N2)) -> 4.5513588e-10
A3: NaF | B3: 6.9 | C3: 1 | D3: 20 | E3: 20 | F3: =D3*1.6726219E-27 -> 3.3452438e-26 | G3: =E3*9.1093856E-31 -> 1.8218771e-29 | H3: =((F3*D3)/(G3*E3)) -> 1836.1523 | I3: =D3/E3 -> 1 | J3: =(F3)-(G3) -> 3.3434219e-26 | K3: 41.988 | L3: =0.12*EXP(26500/(8.3144598*N3))/1000 -> 0.0014814456 | M3: =N3^-1 -> 0.00078855025 | N3: 1268.15 | O3: 2.16e-05 | P3: 0.000288 | R3: 1.02e-10 | S3: 1.33e-10 | T3: =S3+R3 -> 2.35e-10 | U3: 1950000 | V3: 2085.5 | W3: 0 | X3: 2.755 | Y3: -0.000636 | Z3: 1 | AA3: 1 | AB3: =Z3+AA3 -> 2 | AC3: 0.8279 | AD3: =1/3*AZ3*AT3*T3 -> 0.53093354 | AE3: =ABS((AC3-AD3)/AC3) -> 0.35869846 | AF3: =1/3*AZ3*AT3*AN3 -> 0.49109756 | AG3: =1/3*AZ3*AT3*AO3 -> 0.59812176 | AH3: 0.53220718 | AI3: =(AC3-AH3)/AC3 -> 0.35716007 | AJ3: =AC3/(1/3*AT3*T3) -> 5067818.8 | AK3: =AC3/(1/3*AT3*AP3) -> 3250000 | AL3: 2.2647114e+09 | AM3: =AH3/AL3 -> 2.35e-10 | AN3: 2.1736793e-10 | AO3: 2.6473862e-10 | AP3: =AC3/(1/3*AZ3*AT3) -> 3.6644228e-10 | AQ3: =AC3/AL3 -> 3.6556535e-10 | AR3: =(AQ3-AM3)/AM3 -> 0.55559722 | AS3: =AH3/AT3 -> 0.00025519404 | AT3: =V3+W3*N3 -> 2085.5 | AU3: 2720 | AV3: =AC3/AS3 -> 3244.198 | AW3: =(AV3-AT3)/AT3 -> 0.55559722 | AX3: =AH3/AY3 -> 0.0075812988 | AY3: 70.2 | AZ3: =AY3/O3 -> 3250000 | BA3: =AC3/(AX3) -> 109.20292 | BB3: =(BA3-AY3)/AY3 -> 0.55559722 | BC3: =AT3*AZ3 -> 6777875000 | BD3: =1/3*BC3*T3 -> 0.53093354 | BG3: =L3/(U3/1000*(V3+W3*N3)) -> 3.6428469e-10
A4: KF | B4: 5.1 | C4: 1 | D4: 28 | E4: 28 | F4: =D4*1.6726219E-27 -> 4.6833413e-26 | G4: =E4*9.1093856E-31 -> 2.550628e-29 | H4: =((F4*D4)/(G4*E4)) -> 1836.1523 | I4: =D4/E4 -> 1 | J4: =(F4)-(G4) -> 4.6807907e-26 | K4: 58.097 | L4: =0.107*EXP(23800/(8.3144598*N4))/1000 -> 0.001350063 | M4: =N4^-1 -> 0.00088562193 | N4: 1129.15 | O4: 3.04e-05 | P4: 0.000341 | R4: 1.38e-10 | S4: 1.33e-10 | T4: =S4+R4 -> 2.71e-10 | U4: 1910000 | V4: 1816.4 | W4: 0 | X4: 2.6464 | Y4: -0.0006515 | Z4: 1 | AA4: 1 | AB4: =Z4+AA4 -> 2 | AC4: 0.57 | AD4: =1/3*AZ4*AT4*T4 -> 0.36108718 | AE4: =ABS((AC4-AD4)/AC4) -> 0.36651373 | AF4: =1/3*AZ4*AT4*AN4 -> 0.32961603 | AG4: =1/3*AZ4*AT4*AO4 -> 0.40376311 | AH4: 0.36077309 | AI4: =(AC4-AH4)/AC4 -> 0.36706476 | AJ4: =AC4/(1/3*AT4*T4) -> 3473884.1 | AK4: =AC4/(1/3*AT4*AP4) -> 2200657.9 | AL4: 1.331266e+09 | AM4: =AH4/AL4 -> 2.71e-10 | AN4: 2.4738055e-10 | AO4: 3.0302877e-10 | AP4: =AC4/(1/3*AZ4*AT4) -> 4.2779143e-10 | AQ4: =AC4/AL4 -> 4.2816386e-10 | AR4: =(AQ4-AM4)/AM4 -> 0.57994046 | AS4: =AH4/AT4 -> 0.00019861985 | AT4: =V4+W4*N4 -> 1816.4 | AU4: 2360 | AV4: =AC4/AS4 -> 2869.8038 | AW4: =(AV4-AT4)/AT4 -> 0.57994046 | AX4: =AH4/AY4 -> 0.0053927218 | AY4: 66.9 | AZ4: =AY4/O4 -> 2200657.9 | BA4: =AC4/(AX4) -> 105.69802 | BB4: =(BA4-AY4)/AY4 -> 0.57994046 | BC4: =AT4*AZ4 -> 3.997275e+09 | BD4: =1/3*BC4*T4 -> 0.36108717 | BG4: =L4/(U4/1000*(V4+W4*N4)) -> 3.8914297e-10
A5: RbF | C5: 1 | D5: 46 | E5: 46 | F5: =D5*1.6726219E-27 -> 7.6940607e-26 | G5: =E5*9.1093856E-31 -> 4.1903174e-29 | H5: =((F5*D5)/(G5*E5)) -> 1836.1523 | I5: =D5/E5 -> 1 | J5: =(F5)-(G5) -> 7.6898704e-26 | K5: 104.4662 | L5: =0.115*EXP(27000/(8.3144598*N5))/1000 -> 0.0025481161 | M5: =N5^-1 -> 0.00095406192 | N5: 1048.15 | O5: 3.57e-05 | P5: 0.000349 | R5: 1.52e-10 | S5: 1.33e-10 | T5: =S5+R5 -> 2.85e-10 | U5: =K5/O5 -> 2926224.1 | V5: 1760.4 | W5: 0 | X5: =U5*100^3/1000 -> 2.9262241e+09 | Y5: 0 | AC5: 0.48965 | AD5: =1/3*AZ5*AT5*T5 -> 0.32557538 | AE5: =ABS((AC5-AD5)/AC5) -> 0.33508551 | AF5: =1/3*AZ5*AT5*AN5 -> 0.29579641 | AJ5: =AC5/(1/3*AT5*T5) -> 2927863.3 | AK5: =AC5/(1/3*AT5*AP5) -> 1946778.7 | AN5: 2.5893228e-10 | AP5: =AC5/(1/3*AZ5*AT5) -> 4.2862655e-10 | AQ5: 2.5893228e-10 | AT5: =V5+W5*N5 -> 1760.4 | AX5: =AH5/AY5 -> 0 | AY5: 69.5 | AZ5: =AY5/O5 -> 1946778.7 | BC5: =AT5*AZ5 -> 3.4271092e+09 | BD5: =1/3*BC5*T5 -> 0.32557538 | BG5: =L5/(U5/1000*(V5+W5*N5)) -> 4.9465257e-10
