Workbook

Sheet Figs
R4: At min measured temp
A5: Salt Composition | B5: Melting Temp (K) | C5: Min Measured Temp (K) | D5: Gheribi-KTCPÎ» at Melt Temp (W/m-K) | E5: Gheribi-KTCPÎ», Mix Data at Melt Temp (W/m-K) | F5: Gheribi-KT-Emp at Melt Temp (W/m-K) | G5: Gheribi-KT-Emp-Mix at Melt Temp (W/m-K) | H5: Gheribi-KT24 at Melt Temp (W/m-K) | I5: Gheribi-KT24, Mix Data at Melt Temp (W/m-K) | J5: Zhao-PGM at Melt Temp (W/m-K) | K5: Zhao-PGM, Mix Data at Melt Temp (W/m-K) | L5: Present Model at Melt Temp (W/m-K) | M5: Present Model, Mix Data at Melt Temp (W/m-K) | N5: Present Model-VelCorr at Melt Temp (W/m-K) | O5: Bridgman at Melt Temp (W/m-K) | P5: Chapman-Enskog at Melt Temp (W/m-K) | Q5: Ideal at Melt Temp (W/m-K) | R5: Gheribi-KT-k_min (W/m-K) | S5: Gheribi-KT-k_min, Mix Data (W/m-K) | T5: Gheribi-KT-Emp (W/m-K) | U5: Gheribi-KT-Emp-Mix (W/m-K) | V5: Gheribi-KT24 | W5: % Dev | X5: Gheribi-KT24, Mix Data (W/m-K) | Y5: Zhao-PGM | Z5: % Dev | AA5: Zhao-PGM, Mix Data (W/m-K) | AB5: Present Model (W/m-K) | AC5: Present Model, Mix Data (W/m-K) | AD5: Present Model-VelCorr (W/m-K) | AE5: Bridgman (W/m-K) | AF5: Chapman-Enskog (W/m-K) | AG5: Ideal (W/m-K) | AH5: TC Experimental (W/m-K) | AI5: Exp. Reference | AJ5: TC MSTDB (W/m-K) | AK5: MSTDB Reference
A6: 0.725LiF-0.265BeF2-0.01UF4 | B6: 723 | C6: 882 | D6: 0.36678342 | F6: 0.39875169 | H6: 0.69535872 | J6: 0.78147755 | Q6: 1.3452379 | R6: 0.3588139 | T6: 0.39008756 | V6: 0.67741221 | W6: =ABS(($AH6-V6)/$AH6) -> 0.11985885 | Y6: 0.74096563 | Z6: =ABS(($AH6-Y6)/$AH6) -> 0.037285823 | AG6: 1.3016119 | AH6: 0.76966315 | AI6: 0.725LiF-0.265BeF2-0.01UF4 (Bobrova, 2023)
A7: 0.72LiF-0.26BeF2-0.02UF4 | B7: 723 | C7: 832 | D7: -0.1376048 | F7: -0.030277384 | H7: 0.56670078 | J7: 0.74820769 | Q7: 1.3360263 | R7: -0.13553534 | T7: -0.029822039 | V7: 0.55550594 | W7: =ABS(($AH7-V7)/$AH7) -> 0.2232675 | Y7: 0.72228652 | Z7: =ABS(($AH7-Y7)/$AH7) -> 0.009932345 | AG7: 1.3058004 | AH7: 0.71518308 | AI7: 0.72LiF-0.26BeF2-0.02UF4 (Bobrova, 2023)
A8: 0.63NaCl-0.37UCl3 | B8: 750 | C8: 802 | D8: 0.12623785 | F8: 0.13414681 | H8: 0.11469448 | J8: 0.30786468 | Q8: 0.45071802 | R8: 0.12332465 | T8: 0.13105109 | V8: 0.11214895 | W8: =ABS(($AH8-V8)/$AH8) -> 0.55163115 | Y8: 0.29987597 | Z8: =ABS(($AH8-Y8)/$AH8) -> 0.19889702 | AG8: 0.44198046 | AH8: 0.25012655 | AI8: 63NaCl-37UCl3 (Termini, 2024)
A9: 0.658NaCl-0.342UCl3 | B9: 750 | C9: 869.15 | D9: 0.11100367 | F9: 0.12242465 | H9: 0.11113907 | J9: 0.3107182 | Q9: 0.45854797 | R9: 0.10497932 | T9: 0.11578047 | V9: 0.10540828 | W9: =ABS(($AH9-V9)/$AH9) -> 0.49064414 | Y9: 0.29112923 | Z9: =ABS(($AH9-Y9)/$AH9) -> 0.40680012 | AG9: 0.43759544 | AH9: 0.20694427 | AI9: 65.8NaCl-34.2UCl3 (Rose, 2023)
A10: 0.712LiF-0.23BeF2-0.05ZrF4-0.008UF4 | B10: 723 | C10: 785.88122 | D10: 0.11450404 | F10: 0.21993592 | H10: 0.46469757 | J10: 0.72737521 | Q10: 1.322616 | R10: 0.11327849 | T10: 0.21758192 | V10: 0.46141777 | W10: =ABS(($AH10-V10)/$AH10) -> 0.63105706 | Y10: 0.71241195 | Z10: =ABS(($AH10-Y10)/$AH10) -> 0.43036576 | AG10: 1.3049988 | AH10: 1.2506481 | AI10: 0.712LiF-0.23BeF2-0.05ZrF4-0.008UF4 (Rosenthal, 1969)
A11: 0.675LiF-0.2BeF2-0.12ThF4-0.005UF4 | B11: 723 | C11: 811.82664 | D11: -0.68451425 | F11: -0.44302642 | H11: 0.11179706 | J11: 0.59758238 | Q11: 1.2528784 | R11: -0.67658391 | T11: -0.4378938 | V11: 0.10753765 | W11: =ABS(($AH11-V11)/$AH11) -> 0.91498381 | Y11: 0.58317547 | Z11: =ABS(($AH11-Y11)/$AH11) -> 0.53895815 | AG11: 1.2304066 | AH11: 1.2649079 | AI11: 0.675LiF-0.20BeF2-0.12ThF4-0.005UF4 (Rosenthal, 1969)
A12: 0.28NaF-0.42KF-0.3UF4 | B12: 878 | C12: 1023 | D12: 0.11971805 | F12: 0.13951714 | H12: 0.15108649 | J12: 0.3836312 | Q12: 0.62595318 | R12: 0.11574283 | T12: 0.1348845 | V12: 0.14300503 | W12: =ABS(($AH12-V12)/$AH12) -> 0.72446699 | Y12: 0.35966985 | Z12: =ABS(($AH12-Y12)/$AH12) -> 0.30701098 | AG12: 0.59800659 | AH12: 0.51901235 | AI12: 0.42KF-0.28NaF-0.30UF4 (Rudenko, 2024)
A13: 0.24NaF-0.36KF-0.4UF4 | B13: 878 | C13: 1073 | D13: 0.18851371 | F13: 0.19057901 | H13: 0.15917343 | J13: 0.36475139 | Q13: 0.57924146 | R13: 0.18133469 | T13: 0.18332134 | V13: 0.15118127 | W13: =ABS(($AH13-V13)/$AH13) -> 0.70253623 | Y13: 0.33864101 | Z13: =ABS(($AH13-Y13)/$AH13) -> 0.33369106 | AG13: 0.54654293 | AH13: 0.50823423 | AI13: 0.36KF-0.24NaF-0.40UF4 (Rudenko, 2024)
A14: 0.2NaF-0.3KF-0.5UF4 | B14: 878 | C14: 1073 | D14: 0.23423673 | F14: 0.21977532 | H14: 0.17464564 | J14: 0.34979074 | Q14: 0.53252974 | R14: 0.22647803 | T14: 0.21249562 | V14: 0.16870277 | W14: =ABS(($AH14-V14)/$AH14) -> 0.57854411 | Y14: 0.32853146 | Z14: =ABS(($AH14-Y14)/$AH14) -> 0.17925758 | AG14: 0.50439481 | AH14: 0.40028571 | AI14: 0.30KF-0.20NaF-0.50UF4 (Rudenko, 2024)
A15: 0.712LiF-0.23BeF2-0.05ZrF4-0.008UF4 | B15: 735 | C15: 785.88122 | D15: 0.11450404 | F15: 0.21993592 | H15: 0.46469757 | J15: 0.72737521 | L15: 0.72737521 | Q15: 1.322616 | R15: 0.11327849 | T15: 0.21758192 | V15: 0.46141777 | W15: =ABS(($AH15-V15)/$AH15) -> 0.63105706 | Y15: 0.71241195 | Z15: =ABS(($AH15-Y15)/$AH15) -> 0.43036576 | AB15: 0.71241195 | AG15: 1.3049988 | AH15: 1.2506481 | AI15: 0.465LiF-0.115NaF-0.42KF (Merritt, 2022),0.465LiF-0.115NaF-0.42KF (Gallagher, 2022),0.465LiF-0.115NaF-0.42KF (Rudenko, 2022)
A16: 0.73LiF-0.27BeF2 | B16: 723 | C16: 884 | D16: 1.1694201 | F16: 1.0901411 | H16: 1.0169508 | J16: 0.81942429 | Q16: 1.3544496 | R16: 1.143821 | T16: 1.0662774 | V16: 0.99333381 | W16: =ABS(($AH16-V16)/$AH16) -> 0.095706389 | Y16: 0.77570442 | Z16: =ABS(($AH16-Y16)/$AH16) -> 0.1443518 | AG16: 1.310565 | AH16: 0.90656933 | AI16: 0.73LiF-0.27BeF2 (Bobrova, 2023)
A17: 0.66LiF-0.34BeF2 | B17: 733 | C17: 884 | D17: 1.1321639 | E17: 1.6545464 | F17: 1.0327876 | G17: 1.5087682 | H17: 1.0025337 | I17: 1.518486 | J17: 0.77455399 | K17: 1.194875 | R17: 1.1128792 | S17: 1.6155238 | T17: 1.0151956 | U17: 1.4731838 | V17: 0.98447068 | W17: =ABS(($AH17-V17)/$AH17) -> 0.080050058 | X17: 1.4811883 | Y17: 0.74095938 | Z17: =ABS(($AH17-Y17)/$AH17) -> 0.18710304 | AA17: 1.1045267 | AH17: 0.91150468 | AI17: 0.73LiF-0.27BeF2 (Bobrova, 2023) | AJ17: 1.1 | AK17: Rosenthal 1969 [122]
A18: 0.4NaF-0.6KF | B18: 1000 | D18: 0.67334765 | F18: 0.67819467 | H18: 0.64214261 | J18: 0.4684939 | Q18: 0.73423486 | R18: 0.67334765 | T18: 0.67819467 | V18: 0.64214261 | W18: =ABS(($AH18-V18)/$AH18) -> 0.082653417 | Y18: 0.4684939 | Z18: =ABS(($AH18-Y18)/$AH18) -> 0.330723 | AG18: 0.73423486 | AH18: =AJ18 -> 0.7 | AJ18: 0.7 | AK18: Rudenko 2024 [178]
A19: 0.465LiF-0.115NaF-0.42KF | B19: 735 | C19: 742.4 | D19: 0.75544862 | F19: 0.76389433 | G19: 1.0241817 | H19: 0.6954626 | I19: 0.90509687 | J19: 0.65005469 | K19: 0.77295464 | Q19: 1.0993871 | R19: 0.75296021 | T19: 0.7613781 | U19: 1.0203939 | V19: 0.69317886 | W19: =ABS(($AH19-V19)/$AH19) -> 0.1226106 | X19: 0.90175871 | Y19: 0.6459406 | Z19: =ABS(($AH19-Y19)/$AH19) -> 0.1824023 | AA19: 0.76685546 | AG19: 1.0964289 | AH19: 0.79004699 | AI19: 0.465LiF-0.115NaF-0.42KF (Merritt, 2022),0.465LiF-0.115NaF-0.42KF (Gallagher, 2022),0.465LiF-0.115NaF-0.42KF (Rudenko, 2022)
A20: 0.2046NaCl-0.4131KCl-0.3823MgCl2 | B20: 700 | C20: 722.73281 | D20: 0.42631828 | F20: 0.39868607 | G20: 0.35511104 | H20: 0.39369828 | I20: 0.38744636 | J20: 0.34234495 | Q20: 0.47430496 | R20: 0.42244769 | T20: 0.39506636 | U20: 0.35163381 | V20: 0.39011154 | W20: =ABS(($AH20-V20)/$AH20) -> 0.17217062 | X20: 0.3836404 | Y20: 0.33784078 | Z20: =ABS(($AH20-Y20)/$AH20) -> 0.28309088 | AG20: 0.47038278 | AH20: 0.47124631 | AI20: 0.2046NaCl-0.4131KCl-0.3823MgCl2 (Wang, 2021)
A21: 0.345NaF-0.59KF-0.065MgF2 | B21: 958 | C21: 993.01378 | D21: 0.6779149 | F21: 0.67261166 | H21: 0.57197135 | I21: 0.59758621 | J21: 0.4860452 | K21: 0.49336011 | Q21: 0.74453173 | R21: 0.66907211 | T21: 0.66383804 | V21: 0.56448951 | W21: =ABS(($AH21-V21)/$AH21) -> 0.26308813 | X21: 0.58988275 | Y21: 0.47418606 | Z21: =ABS(($AH21-Y21)/$AH21) -> 0.38097462 | AA21: 0.48283679 | AG21: 0.73580725 | AH21: 0.76602038 | AI21: 0.345NaF-0.59KF-0.065MgF2 (Rudenko, 2024)
A22: 1.0LiCl | B22: 883 | C22: 965.57734 | D22: 0.68568905 | F22: 0.72519297 | H22: 0.68631947 | J22: 0.41038419 | Q22: 0.68524115 | R22: 0.66731827 | T22: 0.70576381 | V22: 0.6679318 | W22: =ABS(($AH22-V22)/$AH22) -> 0.018943205 | Y22: 0.3868412 | Z22: =ABS(($AH22-Y22)/$AH22) -> 0.40986607 | AG22: 0.66685348 | AH22: 0.65551426 | AI22: LiCl (Nagasaka, 1992)
A23: 1.0NaCl | B23: 1073.8 | C23: 1169.4387 | D23: 0.48765041 | F23: 0.492992 | H23: 0.48681288 | J23: 0.31017075 | Q23: 0.48673467 | R23: 0.46764534 | T23: 0.4727678 | V23: 0.46684217 | W23: =ABS(($AH23-V23)/$AH23) -> 0.11307557 | Y23: 0.28504925 | Z23: =ABS(($AH23-Y23)/$AH23) -> 0.45845264 | AG23: 0.46682997 | AH23: 0.5263607 | AI23: NaCl (Nagasaka 1992)
A24: 1.0KCl | B24: 1042.7 | C24: 1052.1639 | D24: 0.37448386 | F24: 0.39772402 | H24: 0.3742357 | J24: 0.26186835 | Q24: 0.37411661 | R24: 0.37273884 | T24: 0.39587071 | V24: 0.37249184 | W24: =ABS(($AH24-V24)/$AH24) -> 0.013588159 | Y24: 0.25964867 | Z24: =ABS(($AH24-Y24)/$AH24) -> 0.29346958 | AG24: 0.37237546 | AH24: 0.36749822 | AI24: KCl (Harada, 1992),KCl (Nagasaka, 1992)
A25: 1.0LiF | B25: 1121.2 | C25: 1121.2 | D25: 1.3492012 | F25: 1.4344247 | H25: 1.3498415 | J25: 0.80194503 | Q25: 1.3569764 | R25: 1.3492012 | T25: 1.4344247 | V25: 1.3498415 | W25: =ABS(($AH25-V25)/$AH25) -> 0.071577209 | Y25: 0.80194503 | Z25: =ABS(($AH25-Y25)/$AH25) -> 0.36337265 | AG25: 1.3569764 | AH25: 1.2596773 | AI25: LiF (Golyshev, 1982),LiF (Golyshev, 1983),LiF (Golyshev, 1992),LiF (Smirnov, 1987),LiF (Khlebnikov, 1981)
A26: 1.0NaF | B26: 1268 | C26: 1276.2108 | D26: 0.84228951 | F26: 0.90253851 | H26: 0.8422681 | J26: 0.53047696 | Q26: 0.84054676 | R26: 0.83982795 | T26: 0.89990088 | V26: 0.83980661 | W26: =ABS(($AH26-V26)/$AH26) -> 0.28778769 | Y26: 0.52656453 | Z26: =ABS(($AH26-Y26)/$AH26) -> 0.55343797 | AG26: 0.83809041 | AH26: 1.179152 | AI26: NaF (Smirnov, 1987),NaF (Polyakov, 1975)
A27: 1.0KF | B27: 1131.2 | C27: 1130.597 | D27: 0.58239325 | F27: 0.56777343 | H27: 0.58268228 | J27: 0.36409719 | Q27: 0.58236909 | R27: 0.58239325 | T27: 0.56777343 | V27: 0.58268228 | W27: =ABS(($AH27-V27)/$AH27) -> 0.064372614 | Y27: 0.36409719 | Z27: =ABS(($AH27-Y27)/$AH27) -> 0.41536011 | AG27: 0.58236909 | AH27: 0.62277172 | AI27: KF (Smirnov, 1987)
A28: 1.0MgCl2 | B28: 987 | C28: 986.86211 | D28: 0.43829221 | F28: 0.36348786 | H28: 0.4382922 | J28: 0.28861058 | Q28: 0.4382922 | R28: 0.43829221 | T28: 0.36348786 | V28: 0.4382922 | W28: =ABS(($AH28-V28)/$AH28) -> 0.19417783 | Y28: 0.28861058 | Z28: =ABS(($AH28-Y28)/$AH28) -> 0.469375 | AG28: 0.4382922 | AH28: 0.54390686 | AI28: MgCl2 (Filatov, 2005)
A29: 1.0MgF2 | B29: 1534.2 | C29: 1554.2416 | D29: 0.76994949 | F29: 0.65134847 | H29: 0.76994949 | J29: 0.55165642 | Q29: 0.76994949 | R29: 0.76680975 | T29: 0.64869236 | V29: 0.76680975 | W29: =ABS(($AH29-V29)/$AH29) -> 0.091875731 | Y29: 0.54942631 | Z29: =ABS(($AH29-Y29)/$AH29) -> 0.21766089 | AG29: 0.76680975 | AH29: 0.70228665 | AI29: MgF2 (Khlebnikov, 1981),MgF2 (Golyshev, 1992)
A30: 1.0CaF2 | B30: 1692 | C30: 1697.8471 | D30: 0.53240327 | F30: 0.56536852 | H30: 0.53240327 | J30: 0.42810664 | Q30: 0.53240327 | R30: 0.53209376 | T30: 0.56503984 | V30: 0.53209375 | W30: =ABS(($AH30-V30)/$AH30) -> 0.10256458 | Y30: 0.4277441 | Z30: =ABS(($AH30-Y30)/$AH30) -> 0.2785619 | AG30: 0.53209375 | AH30: 0.59290478 | AI30: CaF2 (Golyshev, 1992),CaF2 (Khlebnikov, 1981)
U35: Gheribi | V35: Zhao | X35: Labels
S36: Avg Error | T36: Actinide | U36: =AVERAGE(W6:W15) -> 0.55680469 | V36: =AVERAGE(Z6:Z15) -> 0.28725646 | X36: Gheribi; 11.8% MAE | Z36: Non-Actinides
T37: Non-actinide | U37: =AVERAGE(W16:W30) -> 0.11828279 | V37: =AVERAGE(Z16:Z30) -> 0.3312135 | X37: Zhao; 33.1% MAE | Z37: Actinides
X38: Gheribi; 55.7% MAE
U39: Deviation | X39: Zhao; 28.7% MAE
T40: 0 | U40: 1.15
T41: 0 | U41: 0.85
C42: Figures below
B44: Fig 1 -->
B67: Fig 2 -->
B98: Fig 3 -->
B118: Fig 4 -->

Sheet Fig1_Fig2 (2)
R4: At min measured temp
A5: Salt Composition | B5: Melting Temp (K) | C5: Min Measured Temp (K) | D5: Gheribi-KTCPÎ» at Melt Temp (W/m-K) | E5: Gheribi-KTCPÎ», Mix Data at Melt Temp (W/m-K) | F5: Gheribi-KT-Emp at Melt Temp (W/m-K) | G5: Gheribi-KT-Emp-Mix at Melt Temp (W/m-K) | H5: Gheribi-KT24 at Melt Temp (W/m-K) | I5: Gheribi-KT24, Mix Data at Melt Temp (W/m-K) | J5: Zhao-PGM at Melt Temp (W/m-K) | K5: Zhao-PGM, Mix Data at Melt Temp (W/m-K) | L5: Present Model at Melt Temp (W/m-K) | M5: Present Model, Mix Data at Melt Temp (W/m-K) | N5: Present Model-VelCorr at Melt Temp (W/m-K) | O5: Bridgman at Melt Temp (W/m-K) | P5: Chapman-Enskog at Melt Temp (W/m-K) | Q5: Ideal at Melt Temp (W/m-K) | R5: Gheribi-KT-k_min (W/m-K) | S5: Gheribi-KT-k_min, Mix Data (W/m-K) | T5: Gheribi-KT-Emp (W/m-K) | U5: Gheribi-KT-Emp-Mix (W/m-K) | V5: Gheribi-KT24 | W5: % Dev | X5: Gheribi-KT24, Mix Data (W/m-K) | Y5: Zhao-PGM | Z5: % Dev | AA5: Zhao-PGM, Mix Data (W/m-K) | AB5: Present Model (W/m-K) | AC5: Present Model, Mix Data (W/m-K) | AD5: Present Model-VelCorr (W/m-K) | AE5: Bridgman (W/m-K) | AF5: Chapman-Enskog (W/m-K) | AG5: Ideal (W/m-K) | AH5: TC Experimental (W/m-K) | AI5: Exp. Reference | AJ5: TC MSTDB (W/m-K) | AK5: MSTDB Reference
A6: 0.725LiF-0.265BeF2-0.01UF4 | B6: 723 | C6: 882 | D6: 0.36678342 | F6: 0.39875169 | H6: 0.69535872 | J6: 0.78147755 | Q6: 1.3452379 | R6: 0.3588139 | T6: 0.39008756 | V6: 0.67741221 | W6: =ABS(($AH6-V6)/$AH6) -> 0.11985885 | Y6: 0.74096563 | Z6: =ABS(($AH6-Y6)/$AH6) -> 0.037285823 | AG6: 1.3016119 | AH6: 0.76966315 | AI6: 0.725LiF-0.265BeF2-0.01UF4 (Bobrova, 2023)
A7: 0.72LiF-0.26BeF2-0.02UF4 | B7: 723 | C7: 832 | D7: -0.1376048 | F7: -0.030277384 | H7: 0.56670078 | J7: 0.74820769 | Q7: 1.3360263 | R7: -0.13553534 | T7: -0.029822039 | V7: 0.55550594 | W7: =ABS(($AH7-V7)/$AH7) -> 0.2232675 | Y7: 0.72228652 | Z7: =ABS(($AH7-Y7)/$AH7) -> 0.009932345 | AG7: 1.3058004 | AH7: 0.71518308 | AI7: 0.72LiF-0.26BeF2-0.02UF4 (Bobrova, 2023)
A8: 0.63NaCl-0.37UCl3 | B8: 750 | C8: 802 | D8: 0.12623785 | F8: 0.13414681 | H8: 0.11469448 | J8: 0.30786468 | Q8: 0.45071802 | R8: 0.12332465 | T8: 0.13105109 | V8: 0.11214895 | W8: =ABS(($AH8-V8)/$AH8) -> 0.55163115 | Y8: 0.29987597 | Z8: =ABS(($AH8-Y8)/$AH8) -> 0.19889702 | AG8: 0.44198046 | AH8: 0.25012655 | AI8: 63NaCl-37UCl3 (Termini, 2024)
A9: 0.658NaCl-0.342UCl3 | B9: 750 | C9: 869.15 | D9: 0.11100367 | F9: 0.12242465 | H9: 0.11113907 | J9: 0.3107182 | Q9: 0.45854797 | R9: 0.10497932 | T9: 0.11578047 | V9: 0.10540828 | W9: =ABS(($AH9-V9)/$AH9) -> 0.49064414 | Y9: 0.29112923 | Z9: =ABS(($AH9-Y9)/$AH9) -> 0.40680012 | AG9: 0.43759544 | AH9: 0.20694427 | AI9: 65.8NaCl-34.2UCl3 (Rose, 2023)
A10: 0.712LiF-0.23BeF2-0.05ZrF4-0.008UF4 | B10: 723 | C10: 785.88122 | D10: 0.11450404 | F10: 0.21993592 | H10: 0.46469757 | J10: 0.72737521 | Q10: 1.322616 | R10: 0.11327849 | T10: 0.21758192 | V10: 0.46141777 | W10: =ABS(($AH10-V10)/$AH10) -> 0.63105706 | Y10: 0.71241195 | Z10: =ABS(($AH10-Y10)/$AH10) -> 0.43036576 | AG10: 1.3049988 | AH10: 1.2506481 | AI10: 0.712LiF-0.23BeF2-0.05ZrF4-0.008UF4 (Rosenthal, 1969)
A11: 0.675LiF-0.2BeF2-0.12ThF4-0.005UF4 | B11: 723 | C11: 811.82664 | D11: -0.68451425 | F11: -0.44302642 | H11: 0.11179706 | J11: 0.59758238 | Q11: 1.2528784 | R11: -0.67658391 | T11: -0.4378938 | V11: 0.10753765 | W11: =ABS(($AH11-V11)/$AH11) -> 0.91498381 | Y11: 0.58317547 | Z11: =ABS(($AH11-Y11)/$AH11) -> 0.53895815 | AG11: 1.2304066 | AH11: 1.2649079 | AI11: 0.675LiF-0.20BeF2-0.12ThF4-0.005UF4 (Rosenthal, 1969)
A12: 0.28NaF-0.42KF-0.3UF4 | B12: 878 | C12: 1023 | D12: 0.11971805 | F12: 0.13951714 | H12: 0.15108649 | J12: 0.3836312 | Q12: 0.62595318 | R12: 0.11574283 | T12: 0.1348845 | V12: 0.14300503 | W12: =ABS(($AH12-V12)/$AH12) -> 0.72446699 | Y12: 0.35966985 | Z12: =ABS(($AH12-Y12)/$AH12) -> 0.30701098 | AG12: 0.59800659 | AH12: 0.51901235 | AI12: 0.42KF-0.28NaF-0.30UF4 (Rudenko, 2024)
A13: 0.24NaF-0.36KF-0.4UF4 | B13: 878 | C13: 1073 | D13: 0.18851371 | F13: 0.19057901 | H13: 0.15917343 | J13: 0.36475139 | Q13: 0.57924146 | R13: 0.18133469 | T13: 0.18332134 | V13: 0.15118127 | W13: =ABS(($AH13-V13)/$AH13) -> 0.70253623 | Y13: 0.33864101 | Z13: =ABS(($AH13-Y13)/$AH13) -> 0.33369106 | AG13: 0.54654293 | AH13: 0.50823423 | AI13: 0.36KF-0.24NaF-0.40UF4 (Rudenko, 2024)
A14: 0.2NaF-0.3KF-0.5UF4 | B14: 878 | C14: 1073 | D14: 0.23423673 | F14: 0.21977532 | H14: 0.17464564 | J14: 0.34979074 | Q14: 0.53252974 | R14: 0.22647803 | T14: 0.21249562 | V14: 0.16870277 | W14: =ABS(($AH14-V14)/$AH14) -> 0.57854411 | Y14: 0.32853146 | Z14: =ABS(($AH14-Y14)/$AH14) -> 0.17925758 | AG14: 0.50439481 | AH14: 0.40028571 | AI14: 0.30KF-0.20NaF-0.50UF4 (Rudenko, 2024)
A15: 0.712LiF-0.23BeF2-0.05ZrF4-0.008UF4 | B15: 735 | C15: 785.88122 | D15: 0.11450404 | F15: 0.21993592 | H15: 0.46469757 | J15: 0.72737521 | L15: 0.72737521 | Q15: 1.322616 | R15: 0.11327849 | T15: 0.21758192 | V15: 0.46141777 | W15: =ABS(($AH15-V15)/$AH15) -> 0.63105706 | Y15: 0.71241195 | Z15: =ABS(($AH15-Y15)/$AH15) -> 0.43036576 | AB15: 0.71241195 | AG15: 1.3049988 | AH15: 1.2506481 | AI15: 0.465LiF-0.115NaF-0.42KF (Merritt, 2022),0.465LiF-0.115NaF-0.42KF (Gallagher, 2022),0.465LiF-0.115NaF-0.42KF (Rudenko, 2022)
A16: 0.73LiF-0.27BeF2 | B16: 723 | C16: 884 | D16: 1.1694201 | F16: 1.0901411 | H16: 1.0169508 | J16: 0.81942429 | Q16: 1.3544496 | R16: 1.143821 | T16: 1.0662774 | V16: 0.99333381 | W16: =ABS(($AH16-V16)/$AH16) -> 0.095706389 | Y16: 0.77570442 | Z16: =ABS(($AH16-Y16)/$AH16) -> 0.1443518 | AG16: 1.310565 | AH16: 0.90656933 | AI16: 0.73LiF-0.27BeF2 (Bobrova, 2023)
A17: 0.66LiF-0.34BeF2 | B17: 733 | C17: 884 | D17: 1.1321639 | E17: 1.6545464 | F17: 1.0327876 | G17: 1.5087682 | H17: 1.0025337 | I17: 1.518486 | J17: 0.77455399 | K17: 1.194875 | R17: 1.1128792 | S17: 1.6155238 | T17: 1.0151956 | U17: 1.4731838 | V17: 0.98447068 | W17: =ABS(($AH17-V17)/$AH17) -> 0.080050058 | X17: 1.4811883 | Y17: 0.74095938 | Z17: =ABS(($AH17-Y17)/$AH17) -> 0.18710304 | AA17: 1.1045267 | AH17: 0.91150468 | AI17: 0.73LiF-0.27BeF2 (Bobrova, 2023) | AJ17: 1.1 | AK17: Rosenthal 1969 [122]
A18: 0.4NaF-0.6KF | B18: 1000 | D18: 0.67334765 | F18: 0.67819467 | H18: 0.64214261 | J18: 0.4684939 | Q18: 0.73423486 | R18: 0.67334765 | T18: 0.67819467 | V18: 0.64214261 | W18: =ABS(($AH18-V18)/$AH18) -> 0.082653417 | Y18: 0.4684939 | Z18: =ABS(($AH18-Y18)/$AH18) -> 0.330723 | AG18: 0.73423486 | AH18: =AJ18 -> 0.7 | AJ18: 0.7 | AK18: Rudenko 2024 [178]
A19: 0.465LiF-0.115NaF-0.42KF | B19: 735 | C19: 742.4 | D19: 0.75544862 | F19: 0.76389433 | G19: 1.0241817 | H19: 0.6954626 | I19: 0.90509687 | J19: 0.65005469 | K19: 0.77295464 | Q19: 1.0993871 | R19: 0.75296021 | T19: 0.7613781 | U19: 1.0203939 | V19: 0.69317886 | W19: =ABS(($AH19-V19)/$AH19) -> 0.1226106 | X19: 0.90175871 | Y19: 0.6459406 | Z19: =ABS(($AH19-Y19)/$AH19) -> 0.1824023 | AA19: 0.76685546 | AG19: 1.0964289 | AH19: 0.79004699 | AI19: 0.465LiF-0.115NaF-0.42KF (Merritt, 2022),0.465LiF-0.115NaF-0.42KF (Gallagher, 2022),0.465LiF-0.115NaF-0.42KF (Rudenko, 2022)
A20: 0.2046NaCl-0.4131KCl-0.3823MgCl2 | B20: 700 | C20: 722.73281 | D20: 0.42631828 | F20: 0.39868607 | G20: 0.35511104 | H20: 0.39369828 | I20: 0.38744636 | J20: 0.34234495 | Q20: 0.47430496 | R20: 0.42244769 | T20: 0.39506636 | U20: 0.35163381 | V20: 0.39011154 | W20: =ABS(($AH20-V20)/$AH20) -> 0.17217062 | X20: 0.3836404 | Y20: 0.33784078 | Z20: =ABS(($AH20-Y20)/$AH20) -> 0.28309088 | AG20: 0.47038278 | AH20: 0.47124631 | AI20: 0.2046NaCl-0.4131KCl-0.3823MgCl2 (Wang, 2021)
A21: 0.345NaF-0.59KF-0.065MgF2 | B21: 958 | C21: 993.01378 | D21: 0.6779149 | F21: 0.67261166 | H21: 0.57197135 | I21: 0.59758621 | J21: 0.4860452 | K21: 0.49336011 | Q21: 0.74453173 | R21: 0.66907211 | T21: 0.66383804 | V21: 0.56448951 | W21: =ABS(($AH21-V21)/$AH21) -> 0.26308813 | X21: 0.58988275 | Y21: 0.47418606 | Z21: =ABS(($AH21-Y21)/$AH21) -> 0.38097462 | AA21: 0.48283679 | AG21: 0.73580725 | AH21: 0.76602038 | AI21: 0.345NaF-0.59KF-0.065MgF2 (Rudenko, 2024)
A22: 1.0LiCl | B22: 883 | C22: 965.57734 | D22: 0.68568905 | F22: 0.72519297 | H22: 0.68631947 | J22: 0.41038419 | Q22: 0.68524115 | R22: 0.66731827 | T22: 0.70576381 | V22: 0.6679318 | W22: =ABS(($AH22-V22)/$AH22) -> 0.018943205 | Y22: 0.3868412 | Z22: =ABS(($AH22-Y22)/$AH22) -> 0.40986607 | AG22: 0.66685348 | AH22: 0.65551426 | AI22: LiCl (Nagasaka, 1992)
A23: 1.0NaCl | B23: 1073.8 | C23: 1169.4387 | D23: 0.48765041 | F23: 0.492992 | H23: 0.48681288 | J23: 0.31017075 | Q23: 0.48673467 | R23: 0.46764534 | T23: 0.4727678 | V23: 0.46684217 | W23: =ABS(($AH23-V23)/$AH23) -> 0.11307557 | Y23: 0.28504925 | Z23: =ABS(($AH23-Y23)/$AH23) -> 0.45845264 | AG23: 0.46682997 | AH23: 0.5263607 | AI23: NaCl (Nagasaka 1992)
A24: 1.0KCl | B24: 1042.7 | C24: 1052.1639 | D24: 0.37448386 | F24: 0.39772402 | H24: 0.3742357 | J24: 0.26186835 | Q24: 0.37411661 | R24: 0.37273884 | T24: 0.39587071 | V24: 0.37249184 | W24: =ABS(($AH24-V24)/$AH24) -> 0.013588159 | Y24: 0.25964867 | Z24: =ABS(($AH24-Y24)/$AH24) -> 0.29346958 | AG24: 0.37237546 | AH24: 0.36749822 | AI24: KCl (Harada, 1992),KCl (Nagasaka, 1992)
A25: 1.0LiF | B25: 1121.2 | C25: 1121.2 | D25: 1.3492012 | F25: 1.4344247 | H25: 1.3498415 | J25: 0.80194503 | Q25: 1.3569764 | R25: 1.3492012 | T25: 1.4344247 | V25: 1.3498415 | W25: =ABS(($AH25-V25)/$AH25) -> 0.071577209 | Y25: 0.80194503 | Z25: =ABS(($AH25-Y25)/$AH25) -> 0.36337265 | AG25: 1.3569764 | AH25: 1.2596773 | AI25: LiF (Golyshev, 1982),LiF (Golyshev, 1983),LiF (Golyshev, 1992),LiF (Smirnov, 1987),LiF (Khlebnikov, 1981)
A26: 1.0NaF | B26: 1268 | C26: 1276.2108 | D26: 0.84228951 | F26: 0.90253851 | H26: 0.8422681 | J26: 0.53047696 | Q26: 0.84054676 | R26: 0.83982795 | T26: 0.89990088 | V26: 0.83980661 | W26: =ABS(($AH26-V26)/$AH26) -> 0.28778769 | Y26: 0.52656453 | Z26: =ABS(($AH26-Y26)/$AH26) -> 0.55343797 | AG26: 0.83809041 | AH26: 1.179152 | AI26: NaF (Smirnov, 1987),NaF (Polyakov, 1975)
A27: 1.0KF | B27: 1131.2 | C27: 1130.597 | D27: 0.58239325 | F27: 0.56777343 | H27: 0.58268228 | J27: 0.36409719 | Q27: 0.58236909 | R27: 0.58239325 | T27: 0.56777343 | V27: 0.58268228 | W27: =ABS(($AH27-V27)/$AH27) -> 0.064372614 | Y27: 0.36409719 | Z27: =ABS(($AH27-Y27)/$AH27) -> 0.41536011 | AG27: 0.58236909 | AH27: 0.62277172 | AI27: KF (Smirnov, 1987)
A28: 1.0MgCl2 | B28: 987 | C28: 986.86211 | D28: 0.43829221 | F28: 0.36348786 | H28: 0.4382922 | J28: 0.28861058 | Q28: 0.4382922 | R28: 0.43829221 | T28: 0.36348786 | V28: 0.4382922 | W28: =ABS(($AH28-V28)/$AH28) -> 0.19417783 | Y28: 0.28861058 | Z28: =ABS(($AH28-Y28)/$AH28) -> 0.469375 | AG28: 0.4382922 | AH28: 0.54390686 | AI28: MgCl2 (Filatov, 2005)
A29: 1.0MgF2 | B29: 1534.2 | C29: 1554.2416 | D29: 0.76994949 | F29: 0.65134847 | H29: 0.76994949 | J29: 0.55165642 | Q29: 0.76994949 | R29: 0.76680975 | T29: 0.64869236 | V29: 0.76680975 | W29: =ABS(($AH29-V29)/$AH29) -> 0.091875731 | Y29: 0.54942631 | Z29: =ABS(($AH29-Y29)/$AH29) -> 0.21766089 | AG29: 0.76680975 | AH29: 0.70228665 | AI29: MgF2 (Khlebnikov, 1981),MgF2 (Golyshev, 1992)
A30: 1.0CaF2 | B30: 1692 | C30: 1697.8471 | D30: 0.53240327 | F30: 0.56536852 | H30: 0.53240327 | J30: 0.42810664 | Q30: 0.53240327 | R30: 0.53209376 | T30: 0.56503984 | V30: 0.53209375 | W30: =ABS(($AH30-V30)/$AH30) -> 0.10256458 | Y30: 0.4277441 | Z30: =ABS(($AH30-Y30)/$AH30) -> 0.2785619 | AG30: 0.53209375 | AH30: 0.59290478 | AI30: CaF2 (Golyshev, 1992),CaF2 (Khlebnikov, 1981)
U35: Gheribi | V35: Zhao | X35: Labels
S36: Avg Error | T36: Actinide | U36: =AVERAGE(W6:W15) -> 0.55680469 | V36: =AVERAGE(Z6:Z15) -> 0.28725646 | X36: Gheribi; 11.8% MAE | Z36: Non-Actinides
T37: Non-actinide | U37: =AVERAGE(W16:W30) -> 0.11828279 | V37: =AVERAGE(Z16:Z30) -> 0.3312135 | X37: Zhao; 33.1% MAE | Z37: Actinides
X38: Gheribi; 55.7% MAE
U39: Deviation | X39: Zhao; 28.7% MAE
T40: 0 | U40: 1.15
T41: 0 | U41: 0.85

Sheet MFP-rsum
A1: Compound | B1: S/cm | C1: order | D1: protons | E1: electrons | F1: Mp/molecule | G1: Me/molecule | H1: ratio of Mpe*# | I1: ratio | J1: Dif mass | K1: M_i (g/mol) | L1: Visc (N*s/m^2) | M1: T_i_m (K) inverse | N1: T_i_m (K) | O1: V_i_m (m^3/mol) | P1: alpha_i_m (K^-1) | Q1: n (atoms/m#) | R1: r_c (m) | S1: r_a (m) | T1: sum_radii | U1: V_m-dist | V1: 1stPeak | W1: delta | X1: --> Scaled | Y1: rho_m (g/m^3) | Z1: SoS(T)_A (A+B*T) | AA1: SoS(T)_B | AB1: A (Density (g/cm3): A - BT(K)) | AC1: B (Density (g/cm3): A - BT(K)) | AD1: m_cation | AE1: m_anion | AF1: mass_disparity | AH1: #_cations | AI1: #_anions | AJ1: sum_ions | AK1: Psi | AL1: λ_meas | AM1: 1/3*Cp*vs*r_sumCorrect | AN1: Error | AO1: 1/3*Cp*vs*1stPk | AP1: 1/3*Cp*vs*AvgPk | AQ1: 1/3*Cp*vs*r_sum | AR1: dev_λ | AS1: c_BC,rsum | AT1: c_BC_λBC | AU1: 1/3*Cp*vs | AV1: r_sum | AW1: 1stPeak | AX1: AvgMFP | AY1: λBC | AZ1: MFP_calc | BA1: MFP_dev | BB1: 1/3*Cp*r_sum | BC1: SoS_Tm | BD1: SoS_metal | BE1: vs_calc | BF1: vs_dev | BG1: 1/3*vs*r_sum | BH1: C_i_p (J/mol/K) | BI1: kB*n | BJ1: Psi*kB*n | BK1: Cp(MJ/m3-K) | BL1: Cp(J/m3-K) | BM1: Cp_calc | BN1: Cp_dev | BO1: vs*cp | BP1: --> Scaled | BQ1: 1/3*vs*cp*rsum | BR1: mu | BS1: V_ca(r ) | BT1: R(pm) | BU1: R(pm)/mu | BV1: 1/sqrt(mu) | BW1: x_ca,peak | BX1: R(pm)/mu | BY1: V/mu | BZ1: R | CA1: Visc/(Dens*C0)
A2: LiF | B2: 9.95 | C2: 1 | D2: 12 | E2: 12 | F2: =D2*1.6726219E-27 -> 2.0071463e-26 | G2: =E2*9.1093856E-31 -> 1.0931263e-29 | H2: =((F2*D2)/(G2*E2)) -> 1836.1523 | I2: =D2/E2 -> 1 | J2: =(F2)-(G2) -> 2.0060532e-26 | K2: 25.939 | L2: =0.115*EXP(27000/(8.3144598*N2))/1000 -> 0.0020988673 | M2: =N2^-1 -> 0.00089433439 | N2: 1118.15 | O2: 1.42e-05 | P2: 0.000268 | Q2: =6.02214076E+23/O2 -> 4.2409442e+28 | R2: 7.6e-11 | S2: 1.33e-10 | T2: =S2+R2 -> 2.09e-10 | U2: =(( (O2/6.02214076E+23)^(1/3)) + (T2)) / 2 -> 2.4787799e-10 | V2: 1.87745 | W2: =S2/R2 -> 1.75 | X2: =T2*10000000000 -> 2.09 | Y2: 1810000 | Z2: 2547.8 | AA2: 0 | AB2: 2.3581 | AC2: -0.0004902 | AD2: 6.941 | AE2: 18.998403 | AF2: =ABS(AE2-AD2) -> 12.057403 | AG2: =K2/BR2 -> 5.1023951 | AH2: 1 | AI2: 1 | AJ2: =AH2+AI2 -> 2 | AK2: =1+AH2/AI2 -> 2 | AL2: 1.33125 | AM2: =1/3*BL2*BC2*T2 -> 0.80248523 | AN2: =ABS((AL2-AM2)/AL2) -> 0.39719419 | AO2: =1/3*BL2*BC2*AW2 -> 0.72246878 | AP2: =1/3*BL2*BC2*AX2 -> 0.90368251 | AQ2: 0.79448872 | AR2: =(AL2-AQ2)/AL2 -> 0.40320096 | AS2: =AL2/(1/3*BC2*T2) -> 7500138 | AT2: =AL2/(1/3*BC2*AY2) -> 4521126.8 | AU2: 3.8013815e+09 | AV2: =AQ2/AU2 -> 2.09e-10 | AW2: 1.8816044e-10 | AX2: 2.3535591e-10 | AY2: =AL2/(1/3*BL2*BC2) -> 3.4671199e-10 | AZ2: =AL2/AU2 -> 3.5020164e-10 | BA2: =(AZ2-AV2)/AV2 -> 0.67560591 | BB2: =AQ2/BC2 -> 0.00031183324 | BC2: =Z2+AA2*N2 -> 2547.8 | BD2: 3500 | BE2: =AL2/BB2 -> 4269.1087 | BF2: =(BE2-BC2)/BC2 -> 0.67560591 | BG2: =AQ2/BH2 -> 0.012375214 | BH2: 64.2 | BI2: =1.380649E-23*Q2 -> 585525.54 | BJ2: =BI2*AK2 -> 1171051.1 | BK2: =BL2/1000000 -> 4.5211268 | BL2: =BH2/O2 -> 4521126.8 | BM2: =AL2/(BG2) -> 107.5739 | BN2: =(BM2-BH2)/BH2 -> 0.67560591 | BO2: =BC2*BL2 -> 1.1518927e+10 | BP2: =BO2*0.0000000001 -> 1.1518927 | BQ2: =BO2*T2 -> 2.4074557 | BR2: 5.083691 | BS2: -6.5464269e-05 | BT2: 0.87109136 | BU2: =SQRT(BT2/BR2) -> 0.41394466 | BV2: =SQRT(1/BR2) -> 0.44351716 | BW2: 1.84e-10 | BX2: =BW2*SQRT(BT2/BR2) -> 7.6165817e-11 | BY2: =SQRT(ABS(BS2))/BR2 -> 0.00159156 | BZ2: =BC2^(2/3)*O2 -> 0.002648898 | CA2: =L2/(Y2/1000*(Z2+AA2*N2)) -> 4.5513588e-10
A3: NaF | B3: 6.9 | C3: 1 | D3: 20 | E3: 20 | F3: =D3*1.6726219E-27 -> 3.3452438e-26 | G3: =E3*9.1093856E-31 -> 1.8218771e-29 | H3: =((F3*D3)/(G3*E3)) -> 1836.1523 | I3: =D3/E3 -> 1 | J3: =(F3)-(G3) -> 3.3434219e-26 | K3: 41.988 | L3: =0.12*EXP(26500/(8.3144598*N3))/1000 -> 0.0014814456 | M3: =N3^-1 -> 0.00078855025 | N3: 1268.15 | O3: 2.16e-05 | P3: 0.000288 | Q3: =6.02214076E+23/O3 -> 2.7880281e+28 | R3: 1.02e-10 | S3: 1.33e-10 | T3: =S3+R3 -> 2.35e-10 | U3: =(( (O3/6.02214076E+23)^(1/3)) + (T3)) / 2 -> 2.8239379e-10 | V3: 2.16677 | W3: =S3/R3 -> 1.3039216 | X3: =T3*10000000000 -> 2.35 | Y3: 1950000 | Z3: 2085.5 | AA3: 0 | AB3: 2.755 | AC3: -0.000636 | AD3: 22.989769 | AE3: 18.998403 | AF3: =ABS(AE3-AD3) -> 3.991366 | AG3: =K3/BR3 -> 4.0364581 | AH3: 1 | AI3: 1 | AJ3: =AH3+AI3 -> 2 | AK3: =1+AH3/AI3 -> 2 | AL3: 0.8279 | AM3: =1/3*BL3*BC3*T3 -> 0.53093354 | AN3: =ABS((AL3-AM3)/AL3) -> 0.35869846 | AO3: =1/3*BL3*BC3*AW3 -> 0.49109756 | AP3: =1/3*BL3*BC3*AX3 -> 0.59812176 | AQ3: 0.53220718 | AR3: =(AL3-AQ3)/AL3 -> 0.35716007 | AS3: =AL3/(1/3*BC3*T3) -> 5067818.8 | AT3: =AL3/(1/3*BC3*AY3) -> 3250000 | AU3: 2.2647114e+09 | AV3: =AQ3/AU3 -> 2.35e-10 | AW3: 2.1736793e-10 | AX3: 2.6473862e-10 | AY3: =AL3/(1/3*BL3*BC3) -> 3.6644228e-10 | AZ3: =AL3/AU3 -> 3.6556535e-10 | BA3: =(AZ3-AV3)/AV3 -> 0.55559722 | BB3: =AQ3/BC3 -> 0.00025519404 | BC3: =Z3+AA3*N3 -> 2085.5 | BD3: 2720 | BE3: =AL3/BB3 -> 3244.198 | BF3: =(BE3-BC3)/BC3 -> 0.55559722 | BG3: =AQ3/BH3 -> 0.0075812988 | BH3: 70.2 | BI3: =1.380649E-23*Q3 -> 384928.82 | BJ3: =BI3*AK3 -> 769857.65 | BK3: =BL3/1000000 -> 3.25 | BL3: =BH3/O3 -> 3250000 | BM3: =AL3/(BG3) -> 109.20292 | BN3: =(BM3-BH3)/BH3 -> 0.55559722 | BO3: =BC3*BL3 -> 6777875000 | BP3: =BO3*0.0000000001 -> 0.6777875 | BQ3: =BO3*T3 -> 1.5928006 | BR3: 10.402189 | BS3: -0.00064235936 | BT3: 0.88236536 | BU3: =SQRT(BT3/BR3) -> 0.29124726 | BV3: =SQRT(1/BR3) -> 0.31005421 | BW3: 2.14e-10 | BX3: =BW3*SQRT(BT3/BR3) -> 6.2326915e-11 | BY3: =SQRT(ABS(BS3))/BR3 -> 0.0024364881 | BZ3: =BC3^(2/3)*O3 -> 0.0035258233 | CA3: =L3/(Y3/1000*(Z3+AA3*N3)) -> 3.6428469e-10
A4: KF | B4: 5.1 | C4: 1 | D4: 28 | E4: 28 | F4: =D4*1.6726219E-27 -> 4.6833413e-26 | G4: =E4*9.1093856E-31 -> 2.550628e-29 | H4: =((F4*D4)/(G4*E4)) -> 1836.1523 | I4: =D4/E4 -> 1 | J4: =(F4)-(G4) -> 4.6807907e-26 | K4: 58.097 | L4: =0.107*EXP(23800/(8.3144598*N4))/1000 -> 0.001350063 | M4: =N4^-1 -> 0.00088562193 | N4: 1129.15 | O4: 3.04e-05 | P4: 0.000341 | Q4: =6.02214076E+23/O4 -> 1.9809674e+28 | R4: 1.38e-10 | S4: 1.33e-10 | T4: =S4+R4 -> 2.71e-10 | U4: =(( (O4/6.02214076E+23)^(1/3)) + (T4)) / 2 -> 3.2028962e-10 | V4: 2.48194 | W4: =S4/R4 -> 0.96376812 | X4: =T4*10000000000 -> 2.71 | Y4: 1910000 | Z4: 1816.4 | AA4: 0 | AB4: 2.6464 | AC4: -0.0006515 | AD4: 39.0983 | AE4: 18.998403 | AF4: =ABS(AE4-AD4) -> 20.099897 | AG4: =K4/BR4 -> 4.5439152 | AH4: 1 | AI4: 1 | AJ4: =AH4+AI4 -> 2 | AK4: =1+AH4/AI4 -> 2 | AL4: 0.57 | AM4: =1/3*BL4*BC4*T4 -> 0.36108718 | AN4: =ABS((AL4-AM4)/AL4) -> 0.36651373 | AO4: =1/3*BL4*BC4*AW4 -> 0.32961603 | AP4: =1/3*BL4*BC4*AX4 -> 0.40376311 | AQ4: 0.36077309 | AR4: =(AL4-AQ4)/AL4 -> 0.36706476 | AS4: =AL4/(1/3*BC4*T4) -> 3473884.1 | AT4: =AL4/(1/3*BC4*AY4) -> 2200657.9 | AU4: 1.331266e+09 | AV4: =AQ4/AU4 -> 2.71e-10 | AW4: 2.4738055e-10 | AX4: 3.0302877e-10 | AY4: =AL4/(1/3*BL4*BC4) -> 4.2779143e-10 | AZ4: =AL4/AU4 -> 4.2816386e-10 | BA4: =(AZ4-AV4)/AV4 -> 0.57994046 | BB4: =AQ4/BC4 -> 0.00019861985 | BC4: =Z4+AA4*N4 -> 1816.4 | BD4: 2360 | BE4: =AL4/BB4 -> 2869.8038 | BF4: =(BE4-BC4)/BC4 -> 0.57994046 | BG4: =AQ4/BH4 -> 0.0053927218 | BH4: 66.9 | BI4: =1.380649E-23*Q4 -> 273502.06 | BJ4: =BI4*AK4 -> 547004.12 | BK4: =BL4/1000000 -> 2.2006579 | BL4: =BH4/O4 -> 2200657.9 | BM4: =AL4/(BG4) -> 105.69802 | BN4: =(BM4-BH4)/BH4 -> 0.57994046 | BO4: =BC4*BL4 -> 3.997275e+09 | BP4: =BO4*0.0000000001 -> 0.3997275 | BQ4: =BO4*T4 -> 1.0832615 | BR4: 12.78567 | BS4: -0.0013975067 | BT4: 0.88025103 | BU4: =SQRT(BT4/BR4) -> 0.26238652 | BV4: =SQRT(1/BR4) -> 0.27966509 | BW4: 2.44e-10 | BX4: =BW4*SQRT(BT4/BR4) -> 6.4022312e-11 | BY4: =SQRT(ABS(BS4))/BR4 -> 0.0029238391 | BZ4: =BC4^(2/3)*O4 -> 0.0045256529 | CA4: =L4/(Y4/1000*(Z4+AA4*N4)) -> 3.8914297e-10
A5: RbF | C5: 1 | D5: 46 | E5: 46 | F5: =D5*1.6726219E-27 -> 7.6940607e-26 | G5: =E5*9.1093856E-31 -> 4.1903174e-29 | H5: =((F5*D5)/(G5*E5)) -> 1836.1523 | I5: =D5/E5 -> 1 | J5: =(F5)-(G5) -> 7.6898704e-26 | K5: 104.4662 | L5: =0.115*EXP(27000/(8.3144598*N5))/1000 -> 0.0025481161 | M5: =N5^-1 -> 0.00095406192 | N5: 1048.15 | O5: 3.57e-05 | P5: 0.000349 | Q5: =6.02214076E+23/O5 -> 1.6868742e+28 | R5: 1.52e-10 | S5: 1.33e-10 | T5: =S5+R5 -> 2.85e-10 | U5: =(( (O5/6.02214076E+23)^(1/3)) + (T5)) / 2 -> 3.3745862e-10 | W5: =S5/R5 -> 0.875 | X5: =T5*10000000000 -> 2.85 | Y5: =K5/O5 -> 2926224.1 | Z5: 1760.4 | AA5: 0 | AB5: =Y5*100^3/1000 -> 2.9262241e+09 | AC5: 0 | AD5: 85.4678 | AE5: 18.998403 | AF5: =ABS(AE5-AD5) -> 66.469397 | AG5: =K5/BR5 -> 6.7209704 | AH5: 1 | AI5: 1 | AK5: =1+AH5/AI5 -> 2 | AL5: 0.48965 | AM5: =1/3*BL5*BC5*T5 -> 0.32557538 | AN5: =ABS((AL5-AM5)/AL5) -> 0.33508551 | AO5: =1/3*BL5*BC5*AW5 -> 0.29579641 | AS5: =AL5/(1/3*BC5*T5) -> 2927863.3 | AT5: =AL5/(1/3*BC5*AY5) -> 1946778.7 | AW5: 2.5893228e-10 | AY5: =AL5/(1/3*BL5*BC5) -> 4.2862655e-10 | AZ5: 2.5893228e-10 | BC5: =Z5+AA5*N5 -> 1760.4 | BG5: =AQ5/BH5 -> 0 | BH5: 69.5 | BI5: =1.380649E-23*Q5 -> 232898.11 | BJ5: =BI5*AK5 -> 465796.23 | BK5: =BL5/1000000 -> 1.9467787 | BL5: =BH5/O5 -> 1946778.7 | BO5: =BC5*BL5 -> 3.4271092e+09 | BP5: =BO5*0.0000000001 -> 0.34271092 | BQ5: =BO5*T5 -> 0.97672613 | BR5: 15.543321 | BS5: -0.0018393987 | BV5: =SQRT(1/BR5) -> 0.25364604 | BW5: 2.56e-10 | BX5: =T5*SQRT(0.9/BR5) -> 6.8579483e-11 | BY5: =SQRT(ABS(BS5))/BR5 -> 0.0027592695 | BZ5: =BC5^(2/3)*O5 -> 0.0052048608 | CA5: =L5/(Y5/1000*(Z5+AA5*N5)) -> 4.9465257e-10
A6: CsF | C6: 1 | D6: 64 | E6: 64 | F6: =D6*1.6726219E-27 -> 1.070478e-25 | G6: =E6*9.1093856E-31 -> 5.8300068e-29 | H6: =((F6*D6)/(G6*E6)) -> 1836.1523 | I6: =D6/E6 -> 1 | J6: =(F6)-(G6) -> 1.069895e-25 | K6: 58.44 | L6: =0.115*EXP(27000/(8.3144598*N6))/1000 -> 0.0034453112 | M6: =N6^-1 -> 0.001046956 | N6: 955.15 | O6: 4.57e-05 | P6: 0.000385 | Q6: =6.02214076E+23/O6 -> 1.3177551e+28 | R6: 1.67e-10 | S6: 1.33e-10 | T6: =S6+R6 -> 3e-10 | U6: =(( (O6/6.02214076E+23)^(1/3)) + (T6)) / 2 -> 3.6168582e-10 | W6: =S6/R6 -> 0.79640719 | X6: =T6*10000000000 -> 3 | Y6: 2196977.2 | Z6: 2732.9322 | AA6: -0.915 | AB6: 4.8985 | AC6: -0.000543 | AD6: 132.90545 | AE6: 18.998403 | AF6: =ABS(AE6-AD6) -> 113.90705 | AG6: =K6/BR6 -> 3.5157592 | AH6: 1 | AI6: 1 | AK6: =1+AH6/AI6 -> 2 | AL6: 0.36715 | AM6: =1/3*BL6*BC6*T6 -> 0.30142161 | AN6: =ABS((AL6-AM6)/AL6) -> 0.17902325 | AO6: =1/3*BL6*BC6*AW6 -> 0.28095437 | AS6: =AL6/(1/3*BC6*T6) -> 1975018.4 | AT6: =AL6/(1/3*BC6*AY6) -> 1621444.2 | AW6: 2.7962928e-10 | AY6: =AL6/(1/3*BL6*BC6) -> 3.6541839e-10 | AZ6: 2.7962928e-10 | BC6: =Z6+AA6*N6 -> 1858.97 | BG6: =AQ6/BH6 -> 0 | BH6: 74.1 | BI6: =1.380649E-23*Q6 -> 181935.72 | BJ6: =BI6*AK6 -> 363871.45 | BK6: =BL6/1000000 -> 1.6214442 | BL6: =BH6/O6 -> 1621444.2 | BO6: =BC6*BL6 -> 3.0142161e+09 | BP6: =BO6*0.0000000001 -> 0.30142161 | BQ6: =BO6*T6 -> 0.90426484 | BR6: 16.622299 | BS6: -0.0029196881 | BV6: =SQRT(1/BR6) -> 0.24527566 | BW6: 2.76e-10 | BX6: =T6*SQRT(0.9/BR6) -> 6.9806677e-11 | BY6: =SQRT(ABS(BS6))/BR6 -> 0.0032507018 | BZ6: =BC6^(2/3)*O6 -> 0.0069092534 | CA6: =L6/(Y6/1000*(Z6+AA6*N6)) -> 8.4358824e-10
A7: LiCl | B7: 3.67 | C7: 1 | D7: 20 | E7: 20 | F7: =D7*1.6726219E-27 -> 3.3452438e-26 | G7: =E7*9.1093856E-31 -> 1.8218771e-29 | H7: =((F7*D7)/(G7*E7)) -> 1836.1523 | I7: =D7/E7 -> 1 | J7: =(F7)-(G7) -> 3.3434219e-26 | K7: 42.394 | L7: =0.0726*EXP(22400/(8.3144598*N7))/1000 -> 0.0015609789 | M7: =N7^-1 -> 0.0011388225 | N7: 878.1 | O7: =K7/Y7 -> 2.8281521e-05 | P7: 0.000288 | Q7: =6.02214076E+23/O7 -> 2.1293553e+28 | R7: 7.6e-11 | S7: 1.81e-10 | T7: =S7+R7 -> 2.57e-10 | U7: =(( (O7/6.02214076E+23)^(1/3)) + (T7)) / 2 -> 3.0889339e-10 | V7: 2.37294 | W7: =S7/R7 -> 2.3815789 | X7: =T7*10000000000 -> 2.57 | Y7: 1499000 | Z7: 2787.9043 | AA7: -0.849 | AB7: 1.8842 | AC7: -0.0004328 | AD7: 6.941 | AE7: 35.45 | AF7: =ABS(AE7-AD7) -> 28.509 | AG7: =K7/BR7 -> 7.3036475 | AH7: 1 | AI7: 1 | AJ7: =AH7+AI7 -> 2 | AK7: =1+AH7/AI7 -> 2 | AL7: 0.6126 | AM7: =1/3*BL7*BC7*T7 -> 0.40225026 | AN7: =ABS((AL7-AM7)/AL7) -> 0.34337209 | AO7: =1/3*BL7*BC7*AW7 -> 0.37226977 | AP7: =1/3*BL7*BC7*AX7 -> 0.46741266 | AQ7: 0.40224439 | AR7: =(AL7-AQ7)/AL7 -> 0.34338166 | AS7: =AL7/(1/3*BC7*T7) -> 3501264 | AT7: =AL7/(1/3*BC7*AY7) -> 2299027.7 | AU7: 1.5651533e+09 | AV7: =AQ7/AU7 -> 2.57e-10 | AW7: 2.378453e-10 | AX7: 2.9863264e-10 | AY7: =AL7/(1/3*BL7*BC7) -> 3.9139366e-10 | AZ7: =AL7/AU7 -> 3.9139937e-10 | BA7: =(AZ7-AV7)/AV7 -> 0.52295473 | BB7: =AQ7/BC7 -> 0.00019694717 | BC7: =Z7+AA7*N7 -> 2042.3974 | BD7: 3500 | BE7: =AL7/BB7 -> 3110.4789 | BF7: =(BE7-BC7)/BC7 -> 0.52295473 | BG7: =AQ7/BH7 -> 0.0061864717 | BH7: 65.02 | BI7: =1.380649E-23*Q7 -> 293989.23 | BJ7: =BI7*AK7 -> 587978.46 | BK7: =BL7/1000000 -> 2.2990277 | BL7: =BH7/O7 -> 2299027.7 | BM7: =AL7/(BG7) -> 99.022517 | BN7: =(BM7-BH7)/BH7 -> 0.52295473 | BO7: =BC7*BL7 -> 4.6955283e+09 | BP7: =BO7*0.0000000001 -> 0.46955283 | BQ7: =BO7*T7 -> 1.2067508 | BR7: 5.804497 | BS7: -0.00044547221 | BT7: 0.88854851 | BU7: =SQRT(BT7/BR7) -> 0.39125354 | BV7: =SQRT(1/BR7) -> 0.41506652 | BW7: 2.36e-10 | BX7: =BW7*SQRT(BT7/BR7) -> 9.2335835e-11 | BY7: =SQRT(ABS(BS7))/BR7 -> 0.0036361829 | BZ7: =BC7^(2/3)*O7 -> 0.0045526361 | CA7: =L7/(Y7/1000*(Z7+AA7*N7)) -> 5.0986493e-10
A8: NaCl | B8: 3.94 | C8: 1 | D8: 28 | E8: 28 | F8: =D8*1.6726219E-27 -> 4.6833413e-26 | G8: =E8*9.1093856E-31 -> 2.550628e-29 | H8: =((F8*D8)/(G8*E8)) -> 1836.1523 | I8: =D8/E8 -> 1 | J8: =(F8)-(G8) -> 4.6807907e-26 | K8: 58.44 | L8: =0.0893*EXP(22000/(8.3144598*N8))/1000 -> 0.0010321391 | M8: =N8^-1 -> 0.00092494104 | N8: 1081.15 | O8: 3.765e-05 | P8: 0.00035 | Q8: =6.02214076E+23/O8 -> 1.5995062e+28 | R8: 1.02e-10 | S8: 1.81e-10 | T8: =S8+R8 -> 2.83e-10 | U8: =(( (O8/6.02214076E+23)^(1/3)) + (T8)) / 2 -> 3.3994555e-10 | V8: 2.65901 | W8: =S8/R8 -> 1.7745098 | X8: =T8*10000000000 -> 2.83 | Y8: 1560000 | Z8: 2732.9322 | AA8: -0.915 | AB8: 2.1393 | AC8: -0.000543 | AD8: 22.989769 | AE8: 35.45 | AF8: =ABS(AE8-AD8) -> 12.460231 | AG8: =K8/BR8 -> 4.1905192 | AH8: 1 | AI8: 1 | AJ8: =AH8+AI8 -> 2 | AK8: =1+AH8/AI8 -> 2 | AL8: 0.4665 | AM8: =1/3*BL8*BC8*T8 -> 0.30415923 | AN8: =ABS((AL8-AM8)/AL8) -> 0.34799736 | AO8: =1/3*BL8*BC8*AW8 -> 0.28617344 | AP8: =1/3*BL8*BC8*AX8 -> 0.34614447 | AQ8: 0.30612615 | AR8: =(AL8-AQ8)/AL8 -> 0.34378102 | AS8: =AL8/(1/3*BC8*T8) -> 2836087.9 | AT8: =AL8/(1/3*BC8*AY8) -> 1849136.8 | AU8: 1.0817179e+09 | AV8: =AQ8/AU8 -> 2.83e-10 | AW8: 2.6626541e-10 | AX8: 3.2206448e-10 | AY8: =AL8/(1/3*BL8*BC8) -> 4.3404732e-10 | AZ8: =AL8/AU8 -> 4.3125848e-10 | BA8: =(AZ8-AV8)/AV8 -> 0.52388156 | BB8: =AQ8/BC8 -> 0.00017556326 | BC8: =Z8+AA8*N8 -> 1743.68 | BD8: 2720 | BE8: =AL8/BB8 -> 2657.1618 | BF8: =(BE8-BC8)/BC8 -> 0.52388156 | BG8: =AQ8/BH8 -> 0.0043971007 | BH8: 69.62 | BI8: =1.380649E-23*Q8 -> 220835.66 | BJ8: =BI8*AK8 -> 441671.32 | BK8: =BL8/1000000 -> 1.8491368 | BL8: =BH8/O8 -> 1849136.8 | BM8: =AL8/(BG8) -> 106.09263 | BN8: =(BM8-BH8)/BH8 -> 0.52388156 | BO8: =BC8*BL8 -> 3.2243028e+09 | BP8: =BO8*0.0000000001 -> 0.32243028 | BQ8: =BO8*T8 -> 0.9124777 | BR8: 13.945766 | BS8: -0.0023782148 | BT8: 0.89095701 | BU8: =SQRT(BT8/BR8) -> 0.25275933 | BV8: =SQRT(1/BR8) -> 0.26778042 | BW8: 2.64e-10 | BX8: =BW8*SQRT(BT8/BR8) -> 6.6728462e-11 | BY8: =SQRT(ABS(BS8))/BR8 -> 0.0034968996 | BZ8: =BC8^(2/3)*O8 -> 0.0054543479 | CA8: =L8/(Y8/1000*(Z8+AA8*N8)) -> 3.7944326e-10
A9: KCl | B9: 3.34 | C9: 1 | D9: 36 | E9: 36 | F9: =D9*1.6726219E-27 -> 6.0214388e-26 | G9: =E9*9.1093856E-31 -> 3.2793788e-29 | H9: =((F9*D9)/(G9*E9)) -> 1836.1523 | I9: =D9/E9 -> 1 | J9: =(F9)-(G9) -> 6.0181595e-26 | K9: 74.5513 | L9: =0.0708*EXP(23900/(8.3144598*N9))/1000 -> 0.0011078669 | M9: =N9^-1 -> 0.00095680046 | N9: 1045.15 | O9: 4.884e-05 | P9: 0.000382 | Q9: =6.02214076E+23/O9 -> 1.2330346e+28 | R9: 1.38e-10 | S9: 1.81e-10 | T9: =S9+R9 -> 3.19e-10 | U9: =(( (O9/6.02214076E+23)^(1/3)) + (T9)) / 2 -> 3.7592707e-10 | V9: 2.98522 | W9: =S9/R9 -> 1.3115942 | X9: =T9*10000000000 -> 3.19 | Y9: 1530000 | Z9: 2514.8257 | AA9: -0.878 | AB9: 2.1359 | AC9: -0.0005831 | AD9: 39.0983 | AE9: 35.45 | AF9: =ABS(AE9-AD9) -> 3.6483 | AG9: =K9/BR9 -> 4.0097644 | AH9: 1 | AI9: 1 | AJ9: =AH9+AI9 -> 2 | AK9: =1+AH9/AI9 -> 2 | AL9: 0.35505 | AM9: =1/3*BL9*BC9*T9 -> 0.25593315 | AN9: =ABS((AL9-AM9)/AL9) -> 0.27916308 | AO9: =1/3*BL9*BC9*AW9 -> 0.23977579 | AP9: =1/3*BL9*BC9*AX9 -> 0.2878106 | AQ9: 0.25652334 | AR9: =(AL9-AQ9)/AL9 -> 0.2775008 | AS9: =AL9/(1/3*BC9*T9) -> 2090572 | AT9: =AL9/(1/3*BC9*AY9) -> 1506961.5 | AU9: 8.041484e+08 | AV9: =AQ9/AU9 -> 3.19e-10 | AW9: 2.9886116e-10 | AX9: 3.5873267e-10 | AY9: =AL9/(1/3*BL9*BC9) -> 4.4254115e-10 | AZ9: =AL9/AU9 -> 4.4152298e-10 | BA9: =(AZ9-AV9)/AV9 -> 0.38408459 | BB9: =AQ9/BC9 -> 0.00016060976 | BC9: =Z9+AA9*N9 -> 1597.184 | BD9: 2360 | BE9: =AL9/BB9 -> 2210.6378 | BF9: =(BE9-BC9)/BC9 -> 0.38408459 | BG9: =AQ9/BH9 -> 0.0034853715 | BH9: 73.6 | BI9: =1.380649E-23*Q9 -> 170238.79 | BJ9: =BI9*AK9 -> 340477.58 | BK9: =BL9/1000000 -> 1.5069615 | BL9: =BH9/O9 -> 1506961.5 | BM9: =AL9/(BG9) -> 101.86863 | BN9: =(BM9-BH9)/BH9 -> 0.38408459 | BO9: =BC9*BL9 -> 2.4068948e+09 | BP9: =BO9*0.0000000001 -> 0.24068948 | BQ9: =BO9*T9 -> 0.76779944 | BR9: 18.592439 | BS9: -0.0036120436 | BT9: 0.8909863 | BU9: =SQRT(BT9/BR9) -> 0.21891087 | BV9: =SQRT(1/BR9) -> 0.23191659 | BW9: 2.96e-10 | BX9: =BW9*SQRT(BT9/BR9) -> 6.4797618e-11 | BY9: =SQRT(ABS(BS9))/BR9 -> 0.0032325119 | BZ9: =BC9^(2/3)*O9 -> 0.0066733764 | CA9: =L9/(Y9/1000*(Z9+AA9*N9)) -> 4.5335792e-10
A10: BeF2 | B10: 0.52 | C10: 1 | D10: 13 | E10: 12 | F10: =D10*1.6726219E-27 -> 2.1744085e-26 | G10: =E10*9.1093856E-31 -> 1.0931263e-29 | H10: =((F10*D10)/(G10*E10)) -> 2154.9287 | I10: =D10/E10 -> 1.0833333 | J10: =(F10)-(G10) -> 2.1733153e-26 | K10: 47.01 | L10: =10^(-8.12+11500/N10+639000/N10^2)/1000 -> 1.5280163 | M10: =N10^-1 -> 0.00093444844 | N10: 1070.15 | O10: 2.4e-05 | P10: 7.42e-06 | Q10: =6.02214076E+23/O10 -> 2.5092253e+28 | R10: 3.4e-11 | S10: 1.33e-10 | T10: =S10+R10 -> 1.67e-10 | U10: =(( (O10/6.02214076E+23)^(1/3)) + (T10)) / 2 -> 2.5428778e-10 | W10: =S10/R10 -> 3.9117647 | X10: =T10*10000000000 -> 1.67 | Y10: 1960000 | Z10: 2547.8 | AA10: 0 | AB10: 1.972 | AC10: -1.45e-05 | AD10: 9.012183 | AE10: 18.998403 | AF10: =ABS(AE10-AD10) -> 9.98622 | AG10: =K10/BR10 -> 7.6906906 | AH10: 1 | AI10: 2 | AJ10: =AH10+AI10 -> 3 | AK10: =1+AH10/AI10 -> 1.5 | AL10: 0.79925906 | AM10: =1/3*BL10*BC10*T10 -> 0.51944334 | AN10: =ABS((AL10-AM10)/AL10) -> 0.35009389 | AQ10: 0.51979939 | AR10: =(AL10-AQ10)/AL10 -> 0.34964842 | AS10: =AL10/(1/3*BC10*T10) -> 5635429.4 | AT10: =AL10/(1/3*BC10*AY10) -> 3662500 | AU10: 3.1125712e+09 | AV10: =AQ10/AU10 -> 1.67e-10 | AY10: =AL10/(1/3*BL10*BC10) -> 2.569602e-10 | AZ10: =AL10/AU10 -> 2.5678419e-10 | BA10: =(AZ10-AV10)/AV10 -> 0.53762986 | BB10: =AQ10/BC10 -> 0.00020401891 | BC10: =Z10+AA10*N10 -> 2547.8 | BE10: =AL10/BB10 -> 3917.5733 | BF10: =(BE10-BC10)/BC10 -> 0.53762986 | BG10: =AQ10/BH10 -> 0.0059135311 | BH10: 87.9 | BI10: =1.380649E-23*Q10 -> 346435.94 | BJ10: =BI10*AK10 -> 519653.91 | BK10: =BL10/1000000 -> 3.6625 | BL10: =BH10/O10 -> 3662500 | BM10: =AL10/(BG10) -> 135.15766 | BN10: =(BM10-BH10)/BH10 -> 0.53762986 | BO10: =BC10*BL10 -> 9331317500 | BP10: =BO10*0.0000000001 -> 0.93313175 | BQ10: =BO10*T10 -> 1.55833 | BR10: 6.112585 | BS10: -4.1051313e-06 | BV10: =SQRT(1/BR10) -> 0.40447114 | BX10: =T10*SQRT(0.9/BR10) -> 6.4080408e-11 | BY10: =SQRT(ABS(BS10))/BR10 -> 0.00033146571 | BZ10: =BC10^(2/3)*O10 -> 0.0044770107
A11: MgF2 | B11: 0.02 | C11: 1 | D11: 21 | E11: 20 | F11: =D11*1.6726219E-27 -> 3.512506e-26 | G11: =E11*9.1093856E-31 -> 1.8218771e-29 | H11: =((F11*D11)/(G11*E11)) -> 2024.3579 | I11: =D11/E11 -> 1.05 | J11: =(F11)-(G11) -> 3.5106841e-26 | K11: 62.3018 | L11: =0.187*EXP(32100/(8.3144598*N11))/1000 -> 0.002315921 | M11: =N11^-1 -> 0.0006518055 | N11: 1534.2 | O11: =K11/Y11 -> 2.557462e-05 | P11: 0.000216 | Q11: =6.02214076E+23/O11 -> 2.3547332e+28 | R11: 7.2e-11 | S11: 1.33e-10 | T11: =S11+R11 -> 2.05e-10 | U11: =(( (O11/6.02214076E+23)^(1/3)) + (T11)) / 2 -> 2.7694403e-10 | W11: =S11/R11 -> 1.8472222 | X11: =T11*10000000000 -> 2.05 | Y11: =(AB11+N11*AC11)*1000000 -> 2436079.2 | Z11: 2175.6 | AA11: 0 | AB11: 3.24 | AC11: -0.000524 | AD11: 24.305 | AE11: 18.998403 | AF11: =ABS(AE11-AD11) -> 5.306597 | AG11: =K11/BR11 -> 5.8426504 | AH11: 1 | AI11: 2 | AJ11: =AH11+AI11 -> 3 | AK11: =1+AH11/AI11 -> 1.5 | AL11: 0.6506778 | AM11: =1/3*BL11*BC11*T11 -> 0.55165642 | AN11: =ABS((AL11-AM11)/AL11) -> 0.15218189 | AQ11: 0.55165642 | AR11: =(AL11-AQ11)/AL11 -> 0.15218189 | AS11: =AL11/(1/3*BC11*T11) -> 4376776.1 | AT11: =AL11/(1/3*BC11*AY11) -> 3710710.1 | AU11: 2.6910069e+09 | AV11: =AQ11/AU11 -> 2.05e-10 | AY11: =AL11/(1/3*BL11*BC11) -> 2.4179715e-10 | AZ11: =AL11/AU11 -> 2.4179715e-10 | BA11: =(AZ11-AV11)/AV11 -> 0.17949828 | BB11: =AQ11/BC11 -> 0.00025356519 | BC11: =Z11+AA11*N11 -> 2175.6 | BE11: =AL11/BB11 -> 2566.1165 | BF11: =(BE11-BC11)/BC11 -> 0.17949828 | BG11: =AQ11/BH11 -> 0.0058130287 | BH11: 94.9 | BI11: =1.380649E-23*Q11 -> 325106.01 | BJ11: =BI11*AK11 -> 487659.01 | BK11: =BL11/1000000 -> 3.7107101 | BL11: =BH11/O11 -> 3710710.1 | BM11: =AL11/(BG11) -> 111.93439 | BN11: =(BM11-BH11)/BH11 -> 0.17949828 | BO11: =BC11*BL11 -> 8.0730208e+09 | BP11: =BO11*0.0000000001 -> 0.80730208 | BQ11: =BO11*T11 -> 1.6549693 | BR11: 10.663277 | BS11: -4.942153e-05 | BV11: =SQRT(1/BR11) -> 0.30623488 | BX11: =T11*SQRT(0.9/BR11) -> 5.9556583e-11 | BY11: =SQRT(ABS(BS11))/BR11 -> 0.00065927621 | BZ11: =BC11^(2/3)*O11 -> 0.0042939985 | CA11: =L11/(Y11/1000*(Z11+AA11*N11)) -> 4.3697168e-10
A12: CaF2 | B12: 0.12 | C12: 1 | D12: 29 | E12: 28 | F12: =D12*1.6726219E-27 -> 4.8506035e-26 | G12: =E12*9.1093856E-31 -> 2.550628e-29 | H12: =((F12*D12)/(G12*E12)) -> 1969.648 | I12: =D12/E12 -> 1.0357143 | J12: =(F12)-(G12) -> 4.8480529e-26 | K12: 78.0748 | L12: =0.1*EXP(47600/(8.3144598*N12))/1000 -> 0.0029475213 | M12: =N12^-1 -> 0.00059101655 | N12: 1692 | O12: =K12/Y12 -> 3.1001402e-05 | P12: 0.000155 | Q12: =6.02214076E+23/O12 -> 1.9425382e+28 | R12: 1e-10 | S12: 1.33e-10 | T12: =S12+R12 -> 2.33e-10 | U12: =(( (O12/6.02214076E+23)^(1/3)) + (T12)) / 2 -> 3.0250023e-10 | W12: =S12/R12 -> 1.33 | X12: =T12*10000000000 -> 2.33 | Y12: =(AB12+N12*AC12)*1000000 -> 2518428 | Z12: 1710.3 | AA12: 0 | AB12: 3.18 | AC12: -0.000391 | AD12: 40.078 | AE12: 18.998403 | AF12: =ABS(AE12-AD12) -> 21.079597 | AG12: =K12/BR12 -> 6.0576168 | AH12: 1 | AI12: 2 | AJ12: =AH12+AI12 -> 3 | AK12: =1+AH12/AI12 -> 1.5 | AL12: 0.5648032 | AM12: =1/3*BL12*BC12*T12 -> 0.42810664 | AN12: =ABS((AL12-AM12)/AL12) -> 0.24202511 | AQ12: 0.42810664 | AR12: =(AL12-AQ12)/AL12 -> 0.24202511 | AS12: =AL12/(1/3*BC12*T12) -> 4251970 | AT12: =AL12/(1/3*BC12*AY12) -> 3222886.5 | AU12: 1.8373676e+09 | AV12: =AQ12/AU12 -> 2.33e-10 | AY12: =AL12/(1/3*BL12*BC12) -> 3.0739805e-10 | AZ12: =AL12/AU12 -> 3.0739805e-10 | BA12: =(AZ12-AV12)/AV12 -> 0.31930492 | BB12: =AQ12/BC12 -> 0.00025031085 | BC12: =Z12+AA12*N12 -> 1710.3 | BE12: =AL12/BB12 -> 2256.4072 | BF12: =(BE12-BC12)/BC12 -> 0.31930492 | BG12: =AQ12/BH12 -> 0.0042847513 | BH12: 99.914 | BI12: =1.380649E-23*Q12 -> 268196.34 | BJ12: =BI12*AK12 -> 402294.51 | BK12: =BL12/1000000 -> 3.2228865 | BL12: =BH12/O12 -> 3222886.5 | BM12: =AL12/(BG12) -> 131.81703 | BN12: =(BM12-BH12)/BH12 -> 0.31930492 | BO12: =BC12*BL12 -> 5.5121027e+09 | BP12: =BO12*0.0000000001 -> 0.55121027 | BQ12: =BO12*T12 -> 1.2843199 | BR12: 12.888699 | BS12: -0.00020540721 | BV12: =SQRT(1/BR12) -> 0.27854506 | BX12: =T12*SQRT(0.9/BR12) -> 6.1570494e-11 | BY12: =SQRT(ABS(BS12))/BR12 -> 0.0011119846 | BZ12: =BC12^(2/3)*O12 -> 0.004433665 | CA12: =L12/(Y12/1000*(Z12+AA12*N12)) -> 6.8431351e-10
A13: SrF2 | C13: 1 | D13: 47 | E13: 46 | F13: =D13*1.6726219E-27 -> 7.8613229e-26 | G13: =E13*9.1093856E-31 -> 4.1903174e-29 | H13: =((F13*D13)/(G13*E13)) -> 1916.8527 | I13: =D13/E13 -> 1.0217391 | J13: =(F13)-(G13) -> 7.8571326e-26 | K13: 125.6168 | L13: =0.0703*EXP(54500/(8.3144598*N13))/1000 -> 0.0030018345 | M13: =N13^-1 -> 0.00057273769 | N13: 1746 | O13: =K13/Y13 -> 3.621381e-05 | P13: 0.000213 | Q13: =6.02214076E+23/O13 -> 1.6629404e+28 | R13: 1.18e-10 | S13: 1.33e-10 | T13: =S13+R13 -> 2.51e-10 | U13: =(( (O13/6.02214076E+23)^(1/3)) + (T13)) / 2 -> 3.2138948e-10 | W13: =S13/R13 -> 1.1271186 | X13: =T13*10000000000 -> 2.51 | Y13: =(AB13+N13*AC13)*1000000 -> 3468754 | Z13: 1398.6 | AA13: 0 | AB13: 4.78 | AC13: -0.000751 | AD13: 87.62 | AE13: 18.998403 | AF13: =ABS(AE13-AD13) -> 68.621597 | AG13: =K13/BR13 -> 8.0456208 | AH13: 1 | AI13: 2 | AJ13: =AH13+AI13 -> 3 | AK13: =1+AH13/AI13 -> 1.5 | AL13: 0.390415 | AM13: =1/3*BL13*BC13*T13 -> 0.31989464 | AN13: =ABS((AL13-AM13)/AL13) -> 0.18062923 | AQ13: 0.31989464 | AR13: =(AL13-AQ13)/AL13 -> 0.18062923 | AS13: =AL13/(1/3*BC13*T13) -> 3336418.4 | AT13: =AL13/(1/3*BC13*AY13) -> 2733763.7 | AU13: 1.2744806e+09 | AV13: =AQ13/AU13 -> 2.51e-10 | AY13: =AL13/(1/3*BL13*BC13) -> 3.0633263e-10 | AZ13: =AL13/AU13 -> 3.0633263e-10 | BA13: =(AZ13-AV13)/AV13 -> 0.22044872 | BB13: =AQ13/BC13 -> 0.00022872489 | BC13: =Z13+AA13*N13 -> 1398.6 | BE13: =AL13/BB13 -> 1706.9196 | BF13: =(BE13-BC13)/BC13 -> 0.22044872 | BG13: =AQ13/BH13 -> 0.003231259 | BH13: 99 | BI13: =1.380649E-23*Q13 -> 229593.7 | BJ13: =BI13*AK13 -> 344390.54 | BK13: =BL13/1000000 -> 2.7337637 | BL13: =BH13/O13 -> 2733763.7 | BM13: =AL13/(BG13) -> 120.82442 | BN13: =(BM13-BH13)/BH13 -> 0.22044872 | BO13: =BC13*BL13 -> 3.8234419e+09 | BP13: =BO13*0.0000000001 -> 0.38234419 | BQ13: =BO13*T13 -> 0.95968391 | BR13: 15.613065 | BS13: -0.00046321913 | BV13: =SQRT(1/BR13) -> 0.25307889 | BX13: =T13*SQRT(0.9/BR13) -> 6.026302e-11 | BY13: =SQRT(ABS(BS13))/BR13 -> 0.0013784946 | BZ13: =BC13^(2/3)*O13 -> 0.0045290096 | CA13: =L13/(Y13/1000*(Z13+AA13*N13)) -> 6.1875642e-10
A14: MgCl2 | B14: 0.8 | C14: 1 | D14: 29 | E14: 28 | F14: =D14*1.6726219E-27 -> 4.8506035e-26 | G14: =E14*9.1093856E-31 -> 2.550628e-29 | H14: =((F14*D14)/(G14*E14)) -> 1969.648 | I14: =D14/E14 -> 1.0357143 | J14: =(F14)-(G14) -> 4.8480529e-26 | K14: 95.211 | L14: =0.18*EXP(20500/(8.3144598*N14))/1000 -> 0.0021885965 | M14: =N14^-1 -> 0.0010131712 | N14: 987 | O14: =K14/Y14 -> 5.6510276e-05 | P14: 0.00018 | Q14: =6.02214076E+23/O14 -> 1.0656718e+28 | R14: 7.2e-11 | S14: 1.81e-10 | T14: =S14+R14 -> 2.53e-10 | U14: =(( (O14/6.02214076E+23)^(1/3)) + (T14)) / 2 -> 3.5371074e-10 | V14: 2.36 | W14: =S14/R14 -> 2.5138889 | X14: =T14*10000000000 -> 2.53 | Y14: =(AB14+N14*AC14)*1000000 -> 1684844 | Z14: 2101 | AA14: 0 | AB14: 1.9691 | AC14: -0.000288 | AD14: 24.305 | AE14: 35.45 | AF14: =ABS(AE14-AD14) -> 11.145 | AG14: =K14/BR14 -> 6.6031249 | AH14: 1 | AI14: 2 | AJ14: =AH14+AI14 -> 3 | AK14: =1+AH14/AI14 -> 1.5 | AL14: 0.4568 | AM14: =1/3*BL14*BC14*T14 -> 0.28861058 | AN14: =ABS((AL14-AM14)/AL14) -> 0.3681905 | AO14: =1/3*BL14*BC14*AW14 -> 0.26994066 | AP14: =1/3*BL14*BC14*AX14 -> 0.33370075 | AQ14: 0.28861058 | AR14: =(AL14-AQ14)/AL14 -> 0.3681905 | AS14: =AL14/(1/3*BC14*T14) -> 2578106 | AT14: =AL14/(1/3*BC14*AY14) -> 1628871.9 | AU14: 1.1407533e+09 | AV14: =AQ14/AU14 -> 2.53e-10 | AW14: 2.3663369e-10 | AX14: 2.9252667e-10 | AY14: =AL14/(1/3*BL14*BC14) -> 4.0043716e-10 | AZ14: =AL14/AU14 -> 4.0043716e-10 | BA14: =(AZ14-AV14)/AV14 -> 0.58275557 | BB14: =AQ14/BC14 -> 0.0001373682 | BC14: =Z14+AA14*N14 -> 2101 | BD14: 3400 | BE14: =AL14/BB14 -> 3325.3695 | BF14: =(BE14-BC14)/BC14 -> 0.58275557 | BG14: =AQ14/BH14 -> 0.0031354356 | BH14: 92.048 | BI14: =1.380649E-23*Q14 -> 147131.87 | BJ14: =BI14*AK14 -> 220697.8 | BK14: =BL14/1000000 -> 1.6288719 | BL14: =BH14/O14 -> 1628871.9 | BM14: =AL14/(BG14) -> 145.68948 | BN14: =(BM14-BH14)/BH14 -> 0.58275557 | BO14: =BC14*BL14 -> 3.4222598e+09 | BP14: =BO14*0.0000000001 -> 0.34222598 | BQ14: =BO14*T14 -> 0.86583173 | BR14: 14.419082 | BS14: -0.00017252442 | BT14: 0.94057284 | BU14: =SQRT(BT14/BR14) -> 0.25540383 | BV14: =SQRT(1/BR14) -> 0.26334871 | BW14: 2.36e-10 | BX14: =BW14*SQRT(BT14/BR14) -> 6.0275304e-11 | BY14: =SQRT(ABS(BS14))/BR14 -> 0.0009109356 | BZ14: =BC14^(2/3)*O14 -> 0.0092699658 | CA14: =L14/(Y14/1000*(Z14+AA14*N14)) -> 6.1827252e-10
A15: CaCl2 | B15: 2.5 | C15: 1 | D15: 37 | E15: 36 | F15: =D15*1.6726219E-27 -> 6.188701e-26 | G15: =E15*9.1093856E-31 -> 3.2793788e-29 | H15: =((F15*D15)/(G15*E15)) -> 1939.5775 | I15: =D15/E15 -> 1.0277778 | J15: =(F15)-(G15) -> 6.1854217e-26 | K15: 110.984 | L15: =10^(-0.545+597/N15+546000/N15^2)/1000 -> 0.0033595447 | M15: =N15^-1 -> 0.0009569378 | N15: 1045 | O15: =K15/Y15 -> 5.3154148e-05 | P15: 0.000203 | Q15: =6.02214076E+23/O15 -> 1.1329578e+28 | R15: 1e-10 | S15: 1.81e-10 | T15: =S15+R15 -> 2.81e-10 | U15: =(( (O15/6.02214076E+23)^(1/3)) + (T15)) / 2 -> 3.6312064e-10 | V15: 2.70336 | W15: =S15/R15 -> 1.81 | X15: =T15*10000000000 -> 2.81 | Y15: =(AB15+N15*AC15)*1000000 -> 2087965 | Z15: 2065.03 | AA15: 0 | AB15: 2.53 | AC15: -0.000423 | AD15: 40.078 | AE15: 35.45 | AF15: =ABS(AE15-AD15) -> 4.628 | AG15: =K15/BR15 -> 5.8999195 | AH15: 1 | AI15: 2 | AK15: =1+AH15/AI15 -> 1.5 | AL15: 0.44125 | AM15: =1/3*BL15*BC15*T15 -> 0.3731109 | AN15: =ABS((AL15-AM15)/AL15) -> 0.15442289 | AO15: =1/3*BL15*BC15*AW15 -> 0.3702431 | AP15: =1/3*BL15*BC15*AX15 -> 0.400395 | AS15: =AL15/(1/3*BC15*T15) -> 2281252.1 | AT15: =AL15/(1/3*BC15*AY15) -> 1928974.6 | AW15: 2.7884018e-10 | AX15: 3.015484e-10 | AY15: =AL15/(1/3*BL15*BC15) -> 3.3231742e-10 | BC15: =Z15+AA15*N15 -> 2065.03 | BD15: 2200 | BG15: =AQ15/BH15 -> 0 | BH15: 102.533 | BI15: =1.380649E-23*Q15 -> 156421.71 | BJ15: =BI15*AK15 -> 234632.56 | BK15: =BL15/1000000 -> 1.9289746 | BL15: =BH15/O15 -> 1928974.6 | BO15: =BC15*BL15 -> 3.9833904e+09 | BP15: =BO15*0.0000000001 -> 0.39833904 | BQ15: =BO15*T15 -> 1.1193327 | BR15: 18.811104 | BS15: -0.00016920232 | BT15: 0.99389548 | BU15: =SQRT(BT15/BR15) -> 0.2298599 | BV15: =SQRT(1/BR15) -> 0.23056472 | BW15: 2.78e-10 | BX15: =BW15*SQRT(BT15/BR15) -> 6.3901053e-11 | BY15: =SQRT(ABS(BS15))/BR15 -> 0.00069149472 | BZ15: =BC15^(2/3)*O15 -> 0.008619619 | CA15: =L15/(Y15/1000*(Z15+AA15*N15)) -> 7.7916752e-10
A16: SrCl2 | C16: 1 | D16: 55 | E16: 54 | F16: =D16*1.6726219E-27 -> 9.1994204e-26 | G16: =E16*9.1093856E-31 -> 4.9190682e-29 | H16: =((F16*D16)/(G16*E16)) -> 1904.7876 | I16: =D16/E16 -> 1.0185185 | J16: =(F16)-(G16) -> 9.1945014e-26 | K16: 158.526 | L16: =10^(-0.439+398/N16+879000/N16^2)/1000 -> 0.0037808819 | M16: =N16^-1 -> 0.00087260035 | N16: 1146 | O16: =K16/Y16 -> 5.811897e-05 | P16: 0.000212 | Q16: =6.02214076E+23/O16 -> 1.0361747e+28 | R16: 1.18e-10 | S16: 1.81e-10 | T16: =S16+R16 -> 2.99e-10 | U16: =(( (O16/6.02214076E+23)^(1/3)) + (T16)) / 2 -> 3.7884662e-10 | V16: 2.9 | W16: =S16/R16 -> 1.5338983 | X16: =T16*10000000000 -> 2.99 | Y16: =(AB16+N16*AC16)*1000000 -> 2727612 | Z16: 1873.13 | AA16: 0 | AB16: 3.39 | AC16: -0.000578 | AD16: 87.62 | AE16: 35.45 | AF16: =ABS(AE16-AD16) -> 52.17 | AG16: =K16/BR16 -> 6.2810639 | AH16: 1 | AI16: 2 | AJ16: =AH16+AI16 -> 3 | AK16: =1+AH16/AI16 -> 1.5 | AL16: 0.37705 | AM16: =1/3*BL16*BC16*T16 -> 0.33599408 | AN16: =ABS((AL16-AM16)/AL16) -> 0.1088872 | AO16: =1/3*BL16*BC16*AW16 -> 0.32666099 | AP16: =1/3*BL16*BC16*AX16 -> 0.36759448 | AQ16: 0.33599408 | AR16: =(AL16-AQ16)/AL16 -> 0.1088872 | AS16: =AL16/(1/3*BC16*T16) -> 2019673.2 | AT16: =AL16/(1/3*BC16*AY16) -> 1799756.6 | AU16: 1.123726e+09 | AV16: =AQ16/AU16 -> 2.99e-10 | AW16: 2.9069451e-10 | AX16: 3.2712108e-10 | AY16: =AL16/(1/3*BL16*BC16) -> 3.3553552e-10 | AZ16: =AL16/AU16 -> 3.3553552e-10 | BA16: =(AZ16-AV16)/AV16 -> 0.12219238 | BB16: =AQ16/BC16 -> 0.00017937574 | BC16: =Z16+AA16*N16 -> 1873.13 | BE16: =AL16/BB16 -> 2102.0122 | BF16: =(BE16-BC16)/BC16 -> 0.12219238 | BG16: =AQ16/BH16 -> 0.0032121805 | BH16: 104.6 | BI16: =1.380649E-23*Q16 -> 143059.36 | BJ16: =BI16*AK16 -> 214589.04 | BK16: =BL16/1000000 -> 1.7997566 | BL16: =BH16/O16 -> 1799756.6 | BM16: =AL16/(BG16) -> 117.38132 | BN16: =(BM16-BH16)/BH16 -> 0.12219238 | BO16: =BC16*BL16 -> 3.3711781e+09 | BP16: =BO16*0.0000000001 -> 0.33711781 | BQ16: =BO16*T16 -> 1.0079822 | BR16: 25.238718 | BS16: -0.00038382394 | BT16: 0.9081546 | BU16: =SQRT(BT16/BR16) -> 0.18969079 | BV16: =SQRT(1/BR16) -> 0.19905191 | BW16: 2.9e-10 | BX16: =BW16*SQRT(BT16/BR16) -> 5.501033e-11 | BY16: =SQRT(ABS(BS16))/BR16 -> 0.00077624486 | BZ16: =BC16^(2/3)*O16 -> 0.0088314061 | CA16: =L16/(Y16/1000*(Z16+AA16*N16)) -> 7.4001854e-10
A17: NaNO3 | B17: 0.3 | C17: 1 | D17: 26 | E17: 25 | F17: =D17*1.6726219E-27 -> 4.3488169e-26 | G17: =E17*9.1093856E-31 -> 2.2773464e-29 | H17: =((F17*D17)/(G17*E17)) -> 1985.9823 | I17: =D17/E17 -> 1.04 | J17: =(F17)-(G17) -> 4.3465396e-26 | K17: 84.99 | M17: =N17^-1 -> 0.0017148247 | N17: 583.15 | O17: 4.467e-05 | P17: 0.000376 | Q17: =6.02214076E+23/O17 -> 1.3481399e+28 | R17: 1.02e-10 | S17: 2.31e-10 | T17: =S17+R17 -> 3.33e-10 | U17: =(( (O17/6.02214076E+23)^(1/3)) + (T17)) / 2 -> 3.7658338e-10 | W17: =S17/R17 -> 2.2647059 | X17: =T17*10000000000 -> 3.33 | Y17: =(AB17+N17*AC17)*1000000 -> 1886915.5 | Z17: 2490.4882 | AA17: -1.155 | AB17: 2.3339 | AC17: -0.0007665 | AD17: 22.989769 | AE17: 62.0037 | AF17: =ABS(AE17-AD17) -> 39.013931 | AG17: =K17/BR17 -> 5.06758 | AH17: 1 | AI17: 4 | AJ17: =AH17+AI17 -> 5 | AK17: =1+AH17/AI17 -> 1.25 | AL17: 0.51225 | AM17: =1/3*BL17*BC17*T17 -> 0.70252146 | AN17: =ABS((AL17-AM17)/AL17) -> 0.37144258 | AO17: =1/3*BL17*BC17*AW17 -> 0.43236429 | AQ17: 0.6982846 | AR17: =(AL17-AQ17)/AL17 -> -0.36317149 | AS17: =AL17/(1/3*BC17*T17) -> 2539896.5 | AT17: =AL17/(1/3*BC17*AY17) -> 3483322.1 | AU17: 2.0969507e+09 | AV17: =AQ17/AU17 -> 3.33e-10 | AW17: 2.0494365e-10 | AY17: =AL17/(1/3*BL17*BC17) -> 2.4281002e-10 | AZ17: =AL17/AU17 -> 2.4428328e-10 | BA17: =(AZ17-AV17)/AV17 -> -0.26641658 | BB17: =AQ17/BC17 -> 0.0003843169 | BC17: =Z17+AA17*N17 -> 1816.95 | BE17: =AL17/BB17 -> 1332.8844 | BF17: =(BE17-BC17)/BC17 -> -0.26641658 | BG17: =AQ17/BH17 -> 0.0044876902 | BH17: 155.6 | BI17: =1.380649E-23*Q17 -> 186130.8 | BJ17: =BI17*AK17 -> 232663.49 | BK17: =BL17/1000000 -> 3.4833221 | BL17: =BH17/O17 -> 3483322.1 | BM17: =AL17/(BG17) -> 114.14558 | BN17: =(BM17-BH17)/BH17 -> -0.26641658 | BO17: =BC17*BL17 -> 6.3290222e+09 | BP17: =BO17*0.0000000001 -> 0.63290222 | BQ17: =BO17*T17 -> 2.1075644 | BR17: 16.771319 | BS17: -0.0062307897 | BV17: =SQRT(1/BR17) -> 0.24418354 | BX17: =T17*SQRT(0.9/BR17) -> 7.7140399e-11 | BY17: =SQRT(ABS(BS17))/BR17 -> 0.0047065679 | BZ17: =BC17^(2/3)*O17 -> 0.0066513725
A18: KNO3 | B18: 0.2 | C18: 1 | D18: 34 | E18: 33 | F18: =D18*1.6726219E-27 -> 5.6869145e-26 | G18: =E18*9.1093856E-31 -> 3.0060972e-29 | H18: =((F18*D18)/(G18*E18)) -> 1949.1203 | I18: =D18/E18 -> 1.030303 | J18: =(F18)-(G18) -> 5.6839084e-26 | K18: 101.1 | M18: =N18^-1 -> 0.0016389412 | N18: 610.15 | O18: 5.406e-05 | P18: 0.00039 | Q18: =6.02214076E+23/O18 -> 1.1139735e+28 | R18: 1.38e-10 | S18: 2.31e-10 | T18: =S18+R18 -> 3.69e-10 | U18: =(( (O18/6.02214076E+23)^(1/3)) + (T18)) / 2 -> 4.0837815e-10 | W18: =S18/R18 -> 1.673913 | X18: =T18*10000000000 -> 3.69 | Y18: =(AB18+N18*AC18)*1000000 -> 1870200.6 | Z18: 2449.928 | AA18: -1.12 | AB18: 2.315 | AC18: -0.000729 | AD18: 39.0983 | AE18: 62.0037 | AF18: =ABS(AE18-AD18) -> 22.9054 | AG18: =K18/BR18 -> 4.2163302 | AH18: 1 | AI18: 4 | AJ18: =AH18+AI18 -> 5 | AK18: =1+AH18/AI18 -> 1.25 | AL18: 0.4092 | AM18: =1/3*BL18*BC18*T18 -> 0.56673049 | AN18: =ABS((AL18-AM18)/AL18) -> 0.38497186 | AQ18: 0.53083305 | AR18: =(AL18-AQ18)/AL18 -> -0.29724596 | AS18: =AL18/(1/3*BC18*T18) -> 1883224.6 | AT18: =AL18/(1/3*BC18*AY18) -> 2608213.1 | AU18: 1.4385719e+09 | AV18: =AQ18/AU18 -> 3.69e-10 | AY18: =AL18/(1/3*BL18*BC18) -> 2.6643141e-10 | AZ18: =AL18/AU18 -> 2.8444876e-10 | BA18: =(AZ18-AV18)/AV18 -> -0.22913616 | BB18: =AQ18/BC18 -> 0.00030048968 | BC18: =Z18+AA18*N18 -> 1766.56 | BE18: =AL18/BB18 -> 1361.7772 | BF18: =(BE18-BC18)/BC18 -> -0.22913616 | BG18: =AQ18/BH18 -> 0.0037647734 | BH18: 141 | BI18: =1.380649E-23*Q18 -> 153800.64 | BJ18: =BI18*AK18 -> 192250.8 | BK18: =BL18/1000000 -> 2.6082131 | BL18: =BH18/O18 -> 2608213.1 | BM18: =AL18/(BG18) -> 108.6918 | BN18: =(BM18-BH18)/BH18 -> -0.22913616 | BO18: =BC18*BL18 -> 4.6075649e+09 | BP18: =BO18*0.0000000001 -> 0.46075649 | BQ18: =BO18*T18 -> 1.7001915 | BR18: 23.978198 | BS18: -0.010344196 | BV18: =SQRT(1/BR18) -> 0.20421692 | BX18: =T18*SQRT(0.9/BR18) -> 7.1489021e-11 | BY18: =SQRT(ABS(BS18))/BR18 -> 0.0042416208 | BZ18: =BC18^(2/3)*O18 -> 0.007900022
