Workbook

Sheet Figs
B3: MFP | R3: Scaled | U3: Cp
B4: Gh-l | C4: Zh-l | R4: Gh-l | S4: Zh-l | U4: At min measured temp
A5: Salt Composition | B5: n (atoms/m#)^-1/3 | C5: sum_radii | R5: n (atoms/m#)^-1/3 | S5: sum_radii | T5: psi | U5: Psi*kB*n | V5: 1/3cp | Y5: Gheribi-KT24 | Z5: % Dev | AA5: Gheribi-KT24, Mix Data (W/m-K) | AB5: Zhao-PGM | AC5: % Dev | AD5: Zhao-PGM, Mix Data (W/m-K) | AE5: Present Model (W/m-K) | AF5: Present Model, Mix Data (W/m-K) | AG5: Present Model-VelCorr (W/m-K) | AH5: Bridgman (W/m-K) | AI5: Chapman-Enskog (W/m-K) | AJ5: Ideal (W/m-K) | AK5: TC Experimental (W/m-K) | AM5: cp | AN5: vs | AO5: cp_scaled | AP5: vs_scaled
A6: 0.63NaCl-0.37UCl3 | B6: 4.2453705e-10 | C6: 2.8818e-10 | R6: =B6*10000000000 -> 4.2453705 | S6: =C6*10000000000 -> 2.8818 | T6: 1.7533333 | U6: =T6*1.380649E-23*(B6^(-3)) -> 316374.15 | V6: =1/3*AM6 -> 628501.55 | Y6: 0.11446562 | Z6: =ABS(($AK6-Y6)/$AK6) -> 0.52402136 | AB6: 0.26282059 | AC6: =ABS(($AK6-AB6)/$AK6) -> 0.092878283 | AJ6: 1.3058004 | AK6: 0.24048477 | AL6: 63NaCl-37UCl3 (Termini, 2024) | AM6: 1885504.7 | AN6: 1456.1091
A7: 0.658NaCl-0.342UCl3 | B7: 4.2173561e-10 | C7: 2.87788e-10 | R7: =B7*10000000000 -> 4.2173561 | S7: =C7*10000000000 -> 2.87788 | T7: 1.772 | U7: =T7*1.380649E-23*(B7^(-3)) -> 326156.61 | V7: =1/3*AM7 -> 628501.55 | Y7: 0.10982982 | Z7: =ABS(($AK7-Y7)/$AK7) -> 0.52976827 | AB7: 0.25730458 | AC7: =ABS(($AK7-AB7)/$AK7) -> 0.10163867 | AJ7: 0.44198046 | AK7: 0.23356531 | AL7: 65.8NaCl-34.2UCl3 (Rose, 2023) | AM7: 1885504.7 | AN7: 1475.141
A8: 0.265BeF2-0.725LiF-0.01UF4 | B8: 2.9966126e-10 | C8: 1.98e-10 | R8: =B8*10000000000 -> 2.9966126 | S8: =C8*10000000000 -> 1.98 | T8: 1.86 | U8: =T8*1.380649E-23*(B8^(-3)) -> 954342.82 | V8: =1/3*AM8 -> 1474339.6 | Y8: 0.67764177 | Z8: =ABS(($AK8-Y8)/$AK8) -> 0.11956058 | AB8: 0.74150709 | AC8: =ABS(($AK8-AB8)/$AK8) -> 0.036582314 | AJ8: 1.3049988 | AK8: 0.76966315 | AL8: 0.725LiF-0.265BeF2-0.01UF4 (Bobrova, 2023) | AM8: 4423018.8 | AN8: 2677.0334
A9: 0.26BeF2-0.72LiF-0.02UF4 | B9: 3.0126944e-10 | C9: 1.9834e-10 | R9: =B9*10000000000 -> 3.0126944 | S9: =C9*10000000000 -> 1.9834 | T9: 1.855 | U9: =T9*1.380649E-23*(B9^(-3)) -> 936616.86 | V9: =1/3*AM9 -> 1470705 | Y9: 0.55560102 | Z9: =ABS(($AK9-Y9)/$AK9) -> 0.22313456 | AB9: 0.72251361 | AC9: =ABS(($AK9-AB9)/$AK9) -> 0.01024987 | AJ9: 1.2304066 | AK9: 0.71518308 | AL9: 0.72LiF-0.26BeF2-0.02UF4 (Bobrova, 2023) | AM9: 4412115 | AN9: 2564.9936
A10: 0.23BeF2-0.712LiF-0.008UF4-0.05ZrF4 | B10: 3.0400599e-10 | C10: 1.99244e-10 | R10: =B10*10000000000 -> 3.0400599 | S10: =C10*10000000000 -> 1.99244 | T10: 1.8415 | U10: =T10*1.380649E-23*(B10^(-3)) -> 904916.7 | V10: =1/3*AM10 -> 1444244.9 | Y10: 0.46140985 | Z10: =ABS(($AK10-Y10)/$AK10) -> 0.6310634 | AB10: 0.71237519 | AC10: =ABS(($AK10-AB10)/$AK10) -> 0.43039516 | AK10: 1.2506481 | AL10: 0.712LiF-0.23BeF2-0.05ZrF4-0.008UF4 (Rosenthal, 1969) | AM10: 4332734.8 | AN10: 2527.74
A11: 0.2BeF2-0.675LiF-0.12ThF4-0.005UF4 | B11: 3.1710616e-10 | C11: 2.0225e-10 | R11: =B11*10000000000 -> 3.1710616 | S11: =C11*10000000000 -> 2.0225 | T11: 1.80625 | U11: =T11*1.380649E-23*(B11^(-3)) -> 782072.65 | V11: =1/3*AM11 -> 1420715.9 | Y11: 0.10755709 | Z11: =ABS(($AK11-Y11)/$AK11) -> 0.91496844 | AB11: 0.58324254 | AC11: =ABS(($AK11-AB11)/$AK11) -> 0.53890513 | AK11: 1.2649079 | AL11: 0.675LiF-0.20BeF2-0.12ThF4-0.005UF4 (Rosenthal, 1969) | AM11: 4262147.6 | AN11: 2073.8105
A12: 0.42KF-0.28NaF-0.3UF4 | B12: 3.6894363e-10 | C12: 3.08518e-10 | R12: =B12*10000000000 -> 3.6894363 | S12: =C12*10000000000 -> 3.08518 | T12: 1.775 | U12: =T12*1.380649E-23*(B12^(-3)) -> 487979.5 | V12: =1/3*AM12 -> 1083530.3 | Y12: 0.14310813 | Z12: =ABS(($AK12-Y12)/$AK12) -> 0.72426835 | AB12: 0.35998157 | AC12: =ABS(($AK12-AB12)/$AK12) -> 0.3064104 | AK12: 0.51901235 | AL12: 0.42KF-0.28NaF-0.30UF4 (Rudenko, 2024) | AM12: 3250591 | AN12: 1437.969
A13: 0.36KF-0.24NaF-0.4UF4 | B13: 3.7846224e-10 | C13: 3.28224e-10 | R13: =B13*10000000000 -> 3.7846224 | S13: =C13*10000000000 -> 3.28224 | T13: 1.7 | U13: =T13*1.380649E-23*(B13^(-3)) -> 432976.7 | V13: =1/3*AM13 -> 1121608.2 | Y13: 0.15119707 | Z13: =ABS(($AK13-Y13)/$AK13) -> 0.70250515 | AB13: 0.33869469 | AC13: =ABS(($AK13-AB13)/$AK13) -> 0.33358545 | AJ13: 0.59800659 | AK13: 0.50823423 | AL13: 0.36KF-0.24NaF-0.40UF4 (Rudenko, 2024) | AM13: 3364824.5 | AN13: 1339.6109
A14: 0.3KF-0.2NaF-0.5UF4 | B14: 3.871642e-10 | C14: 3.4793e-10 | R14: =B14*10000000000 -> 3.871642 | S14: =C14*10000000000 -> 3.4793 | T14: 1.625 | U14: =T14*1.380649E-23*(B14^(-3)) -> 386590.39 | V14: =1/3*AM14 -> 1155110.5 | Y14: 0.16871447 | Z14: =ABS(($AK14-Y14)/$AK14) -> 0.57851489 | AB14: 0.32857551 | AC14: =ABS(($AK14-AB14)/$AK14) -> 0.17914754 | AJ14: 0.54654293 | AK14: 0.40028571 | AL14: 0.30KF-0.20NaF-0.50UF4 (Rudenko, 2024) | AM14: 3465331.4 | AN14: 1265.4415
A15: 0.27BeF2-0.73LiF | B15: 2.9803564e-10 | C15: 1.9766e-10 | R15: =B15*10000000000 -> 2.9803564 | S15: =C15*10000000000 -> 1.9766 | T15: 1.865 | U15: =T15*1.380649E-23*(B15^(-3)) -> 972652.08 | V15: =1/3*AM15 -> 1478093.8 | Y15: 0.99246904 | Z15: =ABS(($AK15-Y15)/$AK15) -> 0.094752495 | AB15: 0.77402744 | AC15: =ABS(($AK15-AB15)/$AK15) -> 0.1462016 | AJ15: 0.50439481 | AK15: 0.90656933 | AL15: 0.73LiF-0.27BeF2 (Bobrova, 2023) | AM15: 4434281.4 | AN15: 2804.7105
A16: 1.0LiF | B16: 2.2759837e-10 | C16: 2.09e-10 | R16: =B16*10000000000 -> 2.2759837 | S16: =C16*10000000000 -> 2.09 | T16: 2 | U16: =T16*1.380649E-23*(B16^(-3)) -> 2342102.1 | V16: =1/3*AM16 -> 1492025.1 | Y16: 1.3498415 | Z16: =ABS(($AK16-Y16)/$AK16) -> 0.070728963 | AB16: 0.80194503 | AC16: =ABS(($AK16-AB16)/$AK16) -> 0.36387659 | AJ16: 1.310565 | AK16: 1.2606752 | AL16: LiF (Golyshev, 1992),LiF (Smirnov, 1987),LiF (Khlebnikov, 1981) | AM16: 4476075.2 | AN16: 2571.7112
A17: 1.0NaF | B17: 2.6175257e-10 | C17: 2.35e-10 | R17: =B17*10000000000 -> 2.6175257 | S17: =C17*10000000000 -> 2.35 | T17: 2 | U17: =T17*1.380649E-23*(B17^(-3)) -> 1539715.3 | V17: =1/3*AM17 -> 1085932.1 | Y17: 0.83980661 | Z17: =ABS(($AK17-Y17)/$AK17) -> 0.28778769 | AB17: 0.52656453 | AC17: =ABS(($AK17-AB17)/$AK17) -> 0.55343797 | AK17: 1.179152 | AL17: NaF (Smirnov, 1987),NaF (Polyakov, 1975) | AM17: 3257796.3 | AN17: 2078.72
A18: 1.0KF | B18: 2.9333523e-10 | C18: 2.71e-10 | R18: =B18*10000000000 -> 2.9333523 | S18: =C18*10000000000 -> 2.71 | T18: 2 | U18: =T18*1.380649E-23*(B18^(-3)) -> 1094008.2 | V18: =1/3*AM18 -> 732914.56 | Y18: 0.58268228 | Z18: =ABS(($AK18-Y18)/$AK18) -> 0.064372614 | AB18: 0.36409719 | AC18: =ABS(($AK18-AB18)/$AK18) -> 0.41536011 | AK18: 0.62277172 | AL18: KF (Smirnov, 1987) | AM18: 2198743.7 | AN18: 1833.136
A19: 1.0LiCl | B19: 2.8635666e-10 | C19: 2.57e-10 | R19: =B19*10000000000 -> 2.8635666 | S19: =C19*10000000000 -> 2.57 | T19: 2 | U19: =T19*1.380649E-23*(B19^(-3)) -> 1175956.9 | V19: =1/3*AM19 -> 767895.49 | Y19: 0.66848974 | Z19: =ABS(($AK19-Y19)/$AK19) -> 0.019794358 | AB19: 0.38754566 | AC19: =ABS(($AK19-AB19)/$AK19) -> 0.40879141 | AK19: 0.65551426 | AL19: LiCl (Nagasaka, 1992) | AM19: 2303686.5 | AN19: 2079.483
A20: 1.0NaCl | B20: 3.1501267e-10 | C20: 2.83e-10 | R20: =B20*10000000000 -> 3.1501267 | S20: =C20*10000000000 -> 2.83 | T20: 2 | U20: =T20*1.380649E-23*(B20^(-3)) -> 883342.64 | V20: =1/3*AM20 -> 617949.66 | Y20: 0.48411361 | Z20: =ABS(($AK20-Y20)/$AK20) -> 0.014110761 | AB20: 0.30671571 | AC20: =ABS(($AK20-AB20)/$AK20) -> 0.37537862 | AK20: 0.4910426 | AL20: NaCl (Harada, 1992),NaCl (Nagasaka 1992) | AM20: 1853849 | AN20: 1773.623
A21: 1.0KCl | B21: 3.4355657e-10 | C21: 3.19e-10 | R21: =B21*10000000000 -> 3.4355657 | S21: =C21*10000000000 -> 3.19 | T21: 2 | U21: =T21*1.380649E-23*(B21^(-3)) -> 680955.17 | V21: =1/3*AM21 -> 502801.69 | Y21: 0.37249184 | Z21: =ABS(($AK21-Y21)/$AK21) -> 0.013588159 | AB21: 0.25964867 | AC21: =ABS(($AK21-AB21)/$AK21) -> 0.29346958 | AK21: 0.36749822 | AL21: KCl (Harada, 1992),KCl (Nagasaka, 1992) | AM21: 1508405.1 | AN21: 1632.6594
A22: 1.0MgCl2 | B22: 3.1507825e-10 | C22: 2.53e-10 | R22: =B22*10000000000 -> 3.1507825 | S22: =C22*10000000000 -> 2.53 | T22: 1.5 | U22: =T22*1.380649E-23*(B22^(-3)) -> 662093.41 | V22: =1/3*AM22 -> 542957.29 | Y22: 0.4382922 | Z22: =ABS(($AK22-Y22)/$AK22) -> 0.19417783 | AB22: 0.28861058 | AC22: =ABS(($AK22-AB22)/$AK22) -> 0.469375 | AK22: 0.54390686 | AL22: MgCl2 (Filatov, 2005) | AM22: 1628871.9 | AN22: 2101
A23: 0.6LiF-0.4NaF | B23: 2.9768075e-10 | C23: 2.194e-10 | R23: =B23*10000000000 -> 2.9768075 | S23: =C23*10000000000 -> 2.194 | T23: 2 | U23: =T23*1.380649E-23*(B23^(-3)) -> 1046793.5 | V23: =1/3*AM23 -> 1313197.6 | Y23: 1.1656382 | Z23: =ABS(($AK23-Y23)/$AK23) -> 0.34183571 | AB23: 0.72195417 | AC23: =ABS(($AK23-AB23)/$AK23) -> 0.16891547 | AK23: 0.86868921 | AL23: 0.6LiF-0.4NaF (BYU) | AM23: 3939592.8 | AN23: 2514.3329
A24: 0.34BeF2-0.66LiF | B24: 3.0276895e-10 | C24: 1.9472e-10 | R24: =B24*10000000000 -> 3.0276895 | S24: =C24*10000000000 -> 1.9472 | T24: 1.83 | U24: =T24*1.380649E-23*(B24^(-3)) -> 910333.16 | V24: =1/3*AM24 -> 1658980.8 | Y24: 1.452807 | Z24: =ABS(($AK24-Y24)/$AK24) -> 0.32069064 | AB24: 1.1065518 | AC24: =ABS(($AK24-AB24)/$AK24) -> 0.0059233725 | AK24: 1.1000358 | AL24: 0.66LiF-0.34BeF2 (Redkin, 2022),0.66LiF-0.34BeF2 (Kato, 1983),0.66LiF-0.34BeF2 (Bobrova, 2023) | AM24: 4976942.5 | AN24: 3486.4683
A25: 0.42KF-0.465LiF-0.115NaF | B25: 3.1821841e-10 | C25: 2.3803e-10 | R25: =B25*10000000000 -> 3.1821841 | S25: =C25*10000000000 -> 2.3803 | T25: 2 | U25: =T25*1.380649E-23*(B25^(-3)) -> 856914.25 | V25: =1/3*AM25 -> 1454587.3 | Y25: 1.0027509 | Z25: =ABS(($AK25-Y25)/$AK25) -> 0.26922941 | AB25: 0.83183122 | AC25: =ABS(($AK25-AB25)/$AK25) -> 0.052888289 | AJ25: 0.73423486 | AK25: 0.79004699 | AL25: 0.465LiF-0.115NaF-0.42KF (Merritt, 2022),0.465LiF-0.115NaF-0.42KF (Gallagher, 2022),0.465LiF-0.115NaF-0.42KF (Rudenko, 2022) | AM25: 4363761.9 | AN25: 2413.78
A26: 0.59KF-0.065MgF2-0.345NaF | B26: 3.471557e-10 | C26: 2.5429e-10 | R26: =B26*10000000000 -> 3.471557 | S26: =C26*10000000000 -> 2.5429 | T26: 1.9675 | U26: =T26*1.380649E-23*(B26^(-3)) -> 649269.69 | V26: =1/3*AM26 -> 944836.2 | Y26: 0.59275939 | Z26: =ABS(($AK26-Y26)/$AK26) -> 0.22618327 | AA26: 0.90175871 | AB26: 0.48485749 | AC26: =ABS(($AK26-AB26)/$AK26) -> 0.36704362 | AD26: 0.76685546 | AJ26: 1.0964289 | AK26: 0.76602038 | AL26: 0.345NaF-0.59KF-0.065MgF2 (Rudenko, 2024) | AM26: 2834508.6 | AN26: 2066.8356
A27: 0.5097CaCl2-0.4903NaCl | B27: 4.2291555e-10 | C27: 2.819806e-10 | R27: =B27*10000000000 -> 4.2291555 | S27: =C27*10000000000 -> 2.819806 | T27: 1.74515 | U27: =T27*1.380649E-23*(B27^(-3)) -> 318533.47 | V27: =1/3*AM27 -> 755287.63 | Y27: 0.41067549 | Z27: =ABS(($AK27-Y27)/$AK27) -> 0.29283646 | AB27: 0.42643936 | AC27: =ABS(($AK27-AB27)/$AK27) -> 0.26569182 | AJ27: 0.66685348 | AK27: 0.58073622 | AL27: 0.52NaCl-0.48CaCl2 (Tian, 2021) | AM27: 2265862.9 | AN27: 2039.9777
A28: 0.15CaCl2-0.315MgCl2-0.535NaCl | B28: 4.2403949e-10 | C28: 2.7325e-10 | R28: =B28*10000000000 -> 4.2403949 | S28: =C28*10000000000 -> 2.7325 | T28: 1.7675 | U28: =T28*1.380649E-23*(B28^(-3)) -> 320054.4 | V28: =1/3*AM28 -> 626139.96 | Y28: 0.4039794 | Z28: =ABS(($AK28-Y28)/$AK28) -> 0.13596398 | AB28: 0.36058592 | AC28: =ABS(($AK28-AB28)/$AK28) -> 0.22877448 | AJ28: 0.76680975 | AK28: 0.46754926 | AL28: 0.535NaCl-0.315MgCl2-0.15CaCl2 (Rong, 2015) | AM28: 1878419.9 | AN28: 2095.8299
U33: Gheribi | V33: Zhao | X33: Labels
S34: Avg Error | T34: Actinide | U34: =AVERAGE(Z6:Z14) -> 0.54975611 | V34: =AVERAGE(AC6:AC14) -> 0.22553254 | W34: Non-Actinides | X34: KTM: 16.8% MAE
T35: Non-actinide | U35: =AVERAGE(Z15:Z28) -> 0.16757517 | V35: =AVERAGE(AC15:AC28) -> 0.29393771 | X35: PGM: 29.4% MAE | Y35: R2
X36: Fit - Gheribi; | Y36: =RSQ(Y15:Y28,AK15:AK28) -> 0.74941069
U37: Deviation | X37: Fit - Zhao; | Y37: =RSQ(AB15:AB28,AK15:AK28) -> 0.60575885
T38: 0 | U38: 1.15 | W38: Actinides | X38: KTM: 55.0% MAE
T39: 0 | U39: 0.85 | X39: PGM: 22.6% MAE
C40: Figures below | X40: Fit - Gheribi (All); | Y40: =RSQ(Y6:Y14,AK6:AK14) -> 0.15332877
X41: Fit - Zhao (All) | Y41: =RSQ(AB6:AB14,AK6:AK14) -> 0.61665071
B42: Fig 1 -->
B65: Fig 2 -->
AM81: +
B96: Fig 3 -->
B116: Fig 4 -->
...

Sheet SCM_parity_plot
A1: Index | B1: Salt Composition | C1: TC Experimental (W/m-K) | D1: Gheribi-KT24 at Min Meas Temp (W/m-K) | E1: Dev-KT | F1: # within Exp. Error | G1: # within max var | I1: Present Model at Min Meas Temp (W/m-K) | J1: Dev-SCM | K1: # within Exp. Error | L1: # within max var | R1: Exp. Reference
A2: 1 | B2: LiF | C2: 1.2606752 | D2: 1.3498415 | E2: =(D2-C2)/C2*100 -> 7.0728963 | F2: =IF(ABS(E2)<=15,1,"") -> 1 | G2: =IF(ABS(E2)<=28,1,"") -> 1 | H2: =ABS(E2) -> 7.0728963 | I2: 1.3235354 | J2: =(I2-C2)/C2*100 -> 4.9862332 | K2: =IF(ABS(J2)<=15,1,"") -> 1 | L2: =IF(ABS(J2)<=28,1,"") -> 1 | M2: =ABS(J2) -> 4.9862332 | N2: Simple | R2: LiF (Golyshev, 1992),LiF (Smirnov, 1987),LiF (Khlebnikov, 1981)
A3: 2 | B3: NaF | C3: 1.179152 | D3: 0.83980661 | E3: =(D3-C3)/C3*100 -> -28.778769 | F3: =IF(ABS(E3)<=15,1,"") | G3: =IF(ABS(E3)<=28,1,"") | H3: =ABS(E3) -> 28.778769 | I3: 0.88115532 | J3: =(I3-C3)/C3*100 -> -25.272121 | K3: =IF(ABS(J3)<=15,1,"") | L3: =IF(ABS(J3)<=28,1,"") -> 1 | M3: =ABS(J3) -> 25.272121 | N3: Simple | R3: NaF (Smirnov, 1987),NaF (Polyakov, 1975)
A4: 3 | B4: KF | C4: 0.62277172 | D4: 0.58268228 | E4: =(D4-C4)/C4*100 -> -6.4372614 | F4: =IF(ABS(E4)<=15,1,"") -> 1 | G4: =IF(ABS(E4)<=28,1,"") -> 1 | H4: =ABS(E4) -> 6.4372614 | I4: 0.58671239 | J4: =(I4-C4)/C4*100 -> -5.790136 | K4: =IF(ABS(J4)<=15,1,"") -> 1 | L4: =IF(ABS(J4)<=28,1,"") -> 1 | M4: =ABS(J4) -> 5.790136 | N4: Simple | R4: KF (Smirnov, 1987)
A5: 4 | B5: LiCl | C5: 0.65551426 | D5: 0.66848974 | E5: =(D5-C5)/C5*100 -> 1.9794358 | F5: =IF(ABS(E5)<=15,1,"") -> 1 | G5: =IF(ABS(E5)<=28,1,"") -> 1 | H5: =ABS(E5) -> 1.9794358 | I5: 0.64227173 | J5: =(I5-C5)/C5*100 -> -2.0201743 | K5: =IF(ABS(J5)<=15,1,"") -> 1 | L5: =IF(ABS(J5)<=28,1,"") -> 1 | M5: =ABS(J5) -> 2.0201743 | N5: Simple | R5: LiCl (Nagasaka, 1992)
A6: 5 | B6: NaCl | C6: 0.4910426 | D6: 0.48411361 | E6: =(D6-C6)/C6*100 -> -1.4110761 | F6: =IF(ABS(E6)<=15,1,"") -> 1 | G6: =IF(ABS(E6)<=28,1,"") -> 1 | H6: =ABS(E6) -> 1.4110761 | I6: 0.49173897 | J6: =(I6-C6)/C6*100 -> 0.14181636 | K6: =IF(ABS(J6)<=15,1,"") -> 1 | L6: =IF(ABS(J6)<=28,1,"") -> 1 | M6: =ABS(J6) -> 0.14181636 | N6: Simple | R6: NaCl (Harada, 1992),NaCl (Nagasaka 1992)
A7: 6 | B7: KCl | C7: 0.36749822 | D7: 0.37249184 | E7: =(D7-C7)/C7*100 -> 1.3588159 | F7: =IF(ABS(E7)<=15,1,"") -> 1 | G7: =IF(ABS(E7)<=28,1,"") -> 1 | H7: =ABS(E7) -> 1.3588159 | I7: 0.41446032 | J7: =(I7-C7)/C7*100 -> 12.778866 | K7: =IF(ABS(J7)<=15,1,"") -> 1 | L7: =IF(ABS(J7)<=28,1,"") -> 1 | M7: =ABS(J7) -> 12.778866 | N7: Simple | R7: KCl (Harada, 1992),KCl (Nagasaka, 1992)
A8: 7 | B8: MgCl2 | C8: 0.54390686 | D8: 0.4382922 | E8: =(D8-C8)/C8*100 -> -19.417783 | F8: =IF(ABS(E8)<=15,1,"") | G8: =IF(ABS(E8)<=28,1,"") -> 1 | H8: =ABS(E8) -> 19.417783 | I8: 0.51755063 | J8: =(I8-C8)/C8*100 -> -4.8457238 | K8: =IF(ABS(J8)<=15,1,"") -> 1 | L8: =IF(ABS(J8)<=28,1,"") -> 1 | M8: =ABS(J8) -> 4.8457238 | N8: Simple | R8: MgCl2 (Filatov, 2005)
A9: 8 | B9: 0.6LiF-0.4NaF | C9: 0.86868921 | D9: 1.1656382 | E9: =(D9-C9)/C9*100 -> 34.183571 | F9: =IF(ABS(E9)<=15,1,"") | G9: =IF(ABS(E9)<=28,1,"") | H9: =ABS(E9) -> 34.183571 | I9: 0.75089815 | J9: =(I9-C9)/C9*100 -> -13.559632 | K9: =IF(ABS(J9)<=15,1,"") -> 1 | L9: =IF(ABS(J9)<=28,1,"") -> 1 | M9: =ABS(J9) -> 13.559632 | N9: Simple | R9: 0.6LiF-0.4NaF (BYU)
A10: 9 | B10: 0.42KF-0.465LiF-0.115NaF | C10: 0.79004699 | D10: 1.0027509 | E10: =(D10-C10)/C10*100 -> 26.922941 | F10: =IF(ABS(E10)<=15,1,"") | G10: =IF(ABS(E10)<=28,1,"") -> 1 | H10: =ABS(E10) -> 26.922941 | I10: 0.81775128 | J10: =(I10-C10)/C10*100 -> 3.5066641 | K10: =IF(ABS(J10)<=15,1,"") -> 1 | L10: =IF(ABS(J10)<=28,1,"") -> 1 | M10: =ABS(J10) -> 3.5066641 | N10: Simple | P10: K | R10: 0.465LiF-0.115NaF-0.42KF (Merritt, 2022),0.465LiF-0.115NaF-0.42KF (Gallagher, 2022),0.465LiF-0.115NaF-0.42KF (Rudenko, 2022)
A11: 10 | B11: 0.5KCl-0.5LiCl | C11: 0.6411837 | D11: 0.41311721 | E11: =(D11-C11)/C11*100 -> -35.569602 | F11: =IF(ABS(E11)<=15,1,"") | G11: =IF(ABS(E11)<=28,1,"") | H11: =ABS(E11) -> 35.569602 | I11: 0.34492501 | J11: =(I11-C11)/C11*100 -> -46.204962 | K11: =IF(ABS(J11)<=15,1,"") | L11: =IF(ABS(J11)<=28,1,"") | M11: =ABS(J11) -> 46.204962 | N11: Simple | P11: K | R11: 0.582LiCl-0.418KCl (Merritt, 2022)
A12: 11 | B12: 0.363KCl-0.637LiCl | C12: 0.62505654 | D12: 0.45917507 | E12: =(D12-C12)/C12*100 -> -26.538634 | F12: =IF(ABS(E12)<=15,1,"") | G12: =IF(ABS(E12)<=28,1,"") -> 1 | H12: =ABS(E12) -> 26.538634 | I12: 0.38724302 | J12: =(I12-C12)/C12*100 -> -38.046721 | K12: =IF(ABS(J12)<=15,1,"") | L12: =IF(ABS(J12)<=28,1,"") | M12: =ABS(J12) -> 38.046721 | N12: Simple | P12: K | R12: 0.582LiCl-0.418KCl (Merritt, 2022)
A13: 12 | B13: 0.5KCl-0.5NaCl | C13: 0.44780366 | D13: 0.42416468 | E13: =(D13-C13)/C13*100 -> -5.2788707 | F13: =IF(ABS(E13)<=15,1,"") -> 1 | G13: =IF(ABS(E13)<=28,1,"") -> 1 | H13: =ABS(E13) -> 5.2788707 | I13: 0.29663676 | J13: =(I13-C13)/C13*100 -> -33.757405 | K13: =IF(ABS(J13)<=15,1,"") | L13: =IF(ABS(J13)<=28,1,"") | M13: =ABS(J13) -> 33.757405 | N13: Simple | P13: K | R13: 0.51NaCl-0.49KCl (Ruth, 2024),0.44NaCl-0.56KCl (Birri, 2023),0.44NaCl-0.56KCl (Birri, 2022)
A14: 13 | B14: 0.5097CaCl2-0.4903NaCl | C14: 0.58073622 | D14: 0.3961107 | E14: =(D14-C14)/C14*100 -> -31.791632 | F14: =IF(ABS(E14)<=15,1,"") | G14: =IF(ABS(E14)<=28,1,"") | H14: =ABS(E14) -> 31.791632 | I14: 0.55191833 | J14: =(I14-C14)/C14*100 -> -4.9623032 | K14: =IF(ABS(J14)<=15,1,"") -> 1 | L14: =IF(ABS(J14)<=28,1,"") -> 1 | M14: =ABS(J14) -> 4.9623032 | N14: Simple | R14: 0.52NaCl-0.48CaCl2 (Tian, 2021)
A15: 14 | B15: 0.34BeF2-0.66LiF | C15: 1.1000358 | D15: 1.452807 | E15: =(D15-C15)/C15*100 -> 32.069064 | F15: =IF(ABS(E15)<=15,1,"") | G15: =IF(ABS(E15)<=28,1,"") | H15: =ABS(E15) -> 32.069064 | I15: 1.1826329 | J15: =(I15-C15)/C15*100 -> 7.508577 | K15: =IF(ABS(J15)<=15,1,"") -> 1 | L15: =IF(ABS(J15)<=28,1,"") -> 1 | M15: =ABS(J15) -> 7.508577 | N15: Complexing | R15: 0.66LiF-0.34BeF2 (Redkin, 2022),0.66LiF-0.34BeF2 (Kato, 1983),0.66LiF-0.34BeF2 (Bobrova, 2023)
A16: 15 | B16: 0.59KF-0.065MgF2-0.345NaF | C16: 0.76602038 | D16: 0.59295335 | E16: =(D16-C16)/C16*100 -> -22.593006 | F16: =IF(ABS(E16)<=15,1,"") | G16: =IF(ABS(E16)<=28,1,"") -> 1 | H16: =ABS(E16) -> 22.593006 | I16: 0.5107782 | J16: =(I16-C16)/C16*100 -> -33.320547 | K16: =IF(ABS(J16)<=15,1,"") | L16: =IF(ABS(J16)<=28,1,"") | M16: =ABS(J16) -> 33.320547 | N16: Complexing | O16: Mg | P16: K | R16: 0.345NaF-0.59KF-0.065MgF2 (Rudenko, 2024)
A17: 16 | B17: 0.41KCl-0.38MgCl2-0.21NaCl | C17: 0.48154458 | D17: 0.40743517 | E17: =(D17-C17)/C17*100 -> -15.389938 | F17: =IF(ABS(E17)<=15,1,"") | G17: =IF(ABS(E17)<=28,1,"") -> 1 | H17: =ABS(E17) -> 15.389938 | I17: 0.35422899 | J17: =(I17-C17)/C17*100 -> -26.439004 | K17: =IF(ABS(J17)<=15,1,"") | L17: =IF(ABS(J17)<=28,1,"") -> 1 | M17: =ABS(J17) -> 26.439004 | N17: Complexing | O17: Mg | P17: K | R17: 0.1511NaCl-0.3891KCl-0.4598MgCl2 (Wang, 2021)
A18: 17 | B18: 0.15CaCl2-0.315MgCl2-0.535NaCl | C18: 0.53550323 | D18: 0.38902203 | E18: =(D18-C18)/C18*100 -> -27.353935 | F18: =IF(ABS(E18)<=15,1,"") | G18: =IF(ABS(E18)<=28,1,"") -> 1 | H18: =ABS(E18) -> 27.353935 | I18: 0.15275869 | J18: =(I18-C18)/C18*100 -> -71.473805 | K18: =IF(ABS(J18)<=15,1,"") | L18: =IF(ABS(J18)<=28,1,"") | M18: =ABS(J18) -> 71.473805 | N18: Complexing | O18: Mg | R18: 0.535NaCl-0.15CaCl2-0.315MgCl2 (Wei, 2015)
A19: 18 | B19: 0.63NaCl-0.37UCl3 | C19: 0.24048477 | D19: 0.11439103 | E19: =(D19-C19)/C19*100 -> -52.433151 | F19: =IF(ABS(E19)<=15,1,"") | G19: =IF(ABS(E19)<=28,1,"") | H19: =ABS(E19) -> 52.433151 | I19: 0.20924461 | J19: =(I19-C19)/C19*100 -> -12.990495 | K19: =IF(ABS(J19)<=15,1,"") -> 1 | L19: =IF(ABS(J19)<=28,1,"") -> 1 | M19: =ABS(J19) -> 12.990495 | N19: Actinide | R19: 63NaCl-37UCl3 (Termini, 2024)
A20: 19 | B20: 0.658NaCl-0.342UCl3 | C20: 0.23356531 | D20: 0.10907665 | E20: =(D20-C20)/C20*100 -> -53.299292 | F20: =IF(ABS(E20)<=15,1,"") | G20: =IF(ABS(E20)<=28,1,"") | H20: =ABS(E20) -> 53.299292 | I20: 0.20485304 | J20: =(I20-C20)/C20*100 -> -12.293037 | K20: =IF(ABS(J20)<=15,1,"") -> 1 | L20: =IF(ABS(J20)<=28,1,"") -> 1 | M20: =ABS(J20) -> 12.293037 | N20: Actinide | R20: 65.8NaCl-34.2UCl3 (Rose, 2023)
D22: Salt Type | E22: Model | F22: MAE | G22: # within Exp. Error | H22: # within max var | K22: MAE
C23: 12 | D23: Simple | E23: KT | F23: =AVERAGE((H$2:H$14)) -> 17.441638 | G23: =COUNT(F$2:F$14) -> 6 | H23: =COUNT(G$2:G$14) -> 9 | I23: =G23/$C23 -> 0.5 | J23: =H23/$C23 -> 0.75
C24: 12 | E24: SCM | F24: =AVERAGE((M$2:M$14)) -> 15.067135 | G24: =COUNT(K$2:K$14) -> 9 | H24: =COUNT(L2:L14) -> 10 | I24: =G24/$C24 -> 0.75 | J24: =H24/$C24 -> 0.83333333
C25: 6 | D25: Complex | E25: KT | F25: =AVERAGE((H$15:H$20)) -> 33.856398 | G25: =COUNT(F$15:F$20) -> 0 | H25: =COUNT(G$15:G$20) -> 3 | I25: =G25/$C25 -> 0 | J25: =H25/$C25 -> 0.5
C26: 6 | E26: SCM | F26: =AVERAGE((M$15:M$20)) -> 27.337578 | G26: =COUNT(K$15:K$20) -> 3 | H26: =COUNT(L15:L20) -> 4 | I26: =G26/$C26 -> 0.5 | J26: =H26/$C26 -> 0.66666667
C27: 2 | D27: Act | E27: KT | F27: =AVERAGE((H$19:H$20)) -> 52.866222 | G27: =COUNT(F$19:F$20) -> 0 | H27: =COUNT(G$19:G$20) -> 0 | I27: =G27/$C27 -> 0 | J27: =H27/$C27 -> 0
C28: 2 | E28: SCM | F28: =AVERAGE((M$19:M$20)) -> 12.641766 | G28: =COUNT(K$19:K$20) -> 2 | H28: =COUNT(L19:L20) -> 2 | I28: =G28/$C28 -> 1 | J28: =H28/$C28 -> 1
C29: 3 | D29: Mg | E29: KT | F29: =AVERAGE((H$16:H$18)) -> 21.77896 | G29: =COUNT(F$16:F$18) -> 0 | H29: =COUNT(G$16:G$18) -> 3 | I29: =G29/$C29 -> 0 | J29: =H29/$C29 -> 1
C30: 3 | E30: SCM | F30: =AVERAGE((M$16:M$18)) -> 43.744452 | G30: =COUNT(K$16:K$18) -> 0 | H30: =COUNT(L16:L18) -> 1 | I30: =G30/$C30 -> 0 | J30: =H30/$C30 -> 0.33333333
C31: 19 | D31: All | E31: KT | F31: =AVERAGE((H$2:H$20)) -> 22.625246 | G31: =COUNT(F$2:F$20) -> 6 | H31: =COUNT(G$2:G$20) -> 12 | I31: =G31/$C31 -> 0.31578947 | J31: =H31/$C31 -> 0.63157895
C32: 19 | E32: SCM | F32: =AVERAGE((M$2:M$20)) -> 18.942012 | G32: =COUNT(K$2:K$20) -> 12 | H32: =COUNT(L2:L20) -> 14 | I32: =G32/$C32 -> 0.63157895 | J32: =H32/$C32 -> 0.73684211

Sheet Fig1_Fig2 (2)
R4: At min measured temp
A5: Salt Composition | B5: Melting Temp (K) | C5: Min Measured Temp (K) | D5: Gheribi-KTCPÎ» at Melt Temp (W/m-K) | E5: Gheribi-KTCPÎ», Mix Data at Melt Temp (W/m-K) | F5: Gheribi-KT-Emp at Melt Temp (W/m-K) | G5: Gheribi-KT-Emp-Mix at Melt Temp (W/m-K) | H5: Gheribi-KT24 at Melt Temp (W/m-K) | I5: Gheribi-KT24, Mix Data at Melt Temp (W/m-K) | J5: Zhao-PGM at Melt Temp (W/m-K) | K5: Zhao-PGM, Mix Data at Melt Temp (W/m-K) | L5: Present Model at Melt Temp (W/m-K) | M5: Present Model, Mix Data at Melt Temp (W/m-K) | N5: Present Model-VelCorr at Melt Temp (W/m-K) | O5: Bridgman at Melt Temp (W/m-K) | P5: Chapman-Enskog at Melt Temp (W/m-K) | Q5: Ideal at Melt Temp (W/m-K) | R5: Gheribi-KT-k_min (W/m-K) | S5: Gheribi-KT-k_min, Mix Data (W/m-K) | T5: Gheribi-KT-Emp (W/m-K) | U5: Gheribi-KT-Emp-Mix (W/m-K) | V5: Gheribi-KT24 | W5: % Dev | X5: Gheribi-KT24, Mix Data (W/m-K) | Y5: Zhao-PGM | Z5: % Dev | AA5: Zhao-PGM, Mix Data (W/m-K) | AB5: Present Model (W/m-K) | AC5: Present Model, Mix Data (W/m-K) | AD5: Present Model-VelCorr (W/m-K) | AE5: Bridgman (W/m-K) | AF5: Chapman-Enskog (W/m-K) | AG5: Ideal (W/m-K) | AH5: TC Experimental (W/m-K) | AI5: Exp. Reference | AJ5: TC MSTDB (W/m-K) | AK5: MSTDB Reference
A6: 0.725LiF-0.265BeF2-0.01UF4 | B6: 723 | C6: 882 | D6: 0.36678342 | F6: 0.39875169 | H6: 0.69535872 | J6: 0.78147755 | Q6: 1.3452379 | R6: 0.3588139 | T6: 0.39008756 | V6: 0.67741221 | W6: =ABS(($AH6-V6)/$AH6) -> 0.11985885 | Y6: 0.74096563 | Z6: =ABS(($AH6-Y6)/$AH6) -> 0.037285823 | AG6: 1.3016119 | AH6: 0.76966315 | AI6: 0.725LiF-0.265BeF2-0.01UF4 (Bobrova, 2023)
A7: 0.72LiF-0.26BeF2-0.02UF4 | B7: 723 | C7: 832 | D7: -0.1376048 | F7: -0.030277384 | H7: 0.56670078 | J7: 0.74820769 | Q7: 1.3360263 | R7: -0.13553534 | T7: -0.029822039 | V7: 0.55550594 | W7: =ABS(($AH7-V7)/$AH7) -> 0.2232675 | Y7: 0.72228652 | Z7: =ABS(($AH7-Y7)/$AH7) -> 0.009932345 | AG7: 1.3058004 | AH7: 0.71518308 | AI7: 0.72LiF-0.26BeF2-0.02UF4 (Bobrova, 2023)
A8: 0.63NaCl-0.37UCl3 | B8: 750 | C8: 802 | D8: 0.12623785 | F8: 0.13414681 | H8: 0.11469448 | J8: 0.30786468 | Q8: 0.45071802 | R8: 0.12332465 | T8: 0.13105109 | V8: 0.11214895 | W8: =ABS(($AH8-V8)/$AH8) -> 0.55163115 | Y8: 0.29987597 | Z8: =ABS(($AH8-Y8)/$AH8) -> 0.19889702 | AG8: 0.44198046 | AH8: 0.25012655 | AI8: 63NaCl-37UCl3 (Termini, 2024)
A9: 0.658NaCl-0.342UCl3 | B9: 750 | C9: 869.15 | D9: 0.11100367 | F9: 0.12242465 | H9: 0.11113907 | J9: 0.3107182 | Q9: 0.45854797 | R9: 0.10497932 | T9: 0.11578047 | V9: 0.10540828 | W9: =ABS(($AH9-V9)/$AH9) -> 0.49064414 | Y9: 0.29112923 | Z9: =ABS(($AH9-Y9)/$AH9) -> 0.40680012 | AG9: 0.43759544 | AH9: 0.20694427 | AI9: 65.8NaCl-34.2UCl3 (Rose, 2023)
A10: 0.712LiF-0.23BeF2-0.05ZrF4-0.008UF4 | B10: 723 | C10: 785.88122 | D10: 0.11450404 | F10: 0.21993592 | H10: 0.46469757 | J10: 0.72737521 | Q10: 1.322616 | R10: 0.11327849 | T10: 0.21758192 | V10: 0.46141777 | W10: =ABS(($AH10-V10)/$AH10) -> 0.63105706 | Y10: 0.71241195 | Z10: =ABS(($AH10-Y10)/$AH10) -> 0.43036576 | AG10: 1.3049988 | AH10: 1.2506481 | AI10: 0.712LiF-0.23BeF2-0.05ZrF4-0.008UF4 (Rosenthal, 1969)
A11: 0.675LiF-0.2BeF2-0.12ThF4-0.005UF4 | B11: 723 | C11: 811.82664 | D11: -0.68451425 | F11: -0.44302642 | H11: 0.11179706 | J11: 0.59758238 | Q11: 1.2528784 | R11: -0.67658391 | T11: -0.4378938 | V11: 0.10753765 | W11: =ABS(($AH11-V11)/$AH11) -> 0.91498381 | Y11: 0.58317547 | Z11: =ABS(($AH11-Y11)/$AH11) -> 0.53895815 | AG11: 1.2304066 | AH11: 1.2649079 | AI11: 0.675LiF-0.20BeF2-0.12ThF4-0.005UF4 (Rosenthal, 1969)
A12: 0.28NaF-0.42KF-0.3UF4 | B12: 878 | C12: 1023 | D12: 0.11971805 | F12: 0.13951714 | H12: 0.15108649 | J12: 0.3836312 | Q12: 0.62595318 | R12: 0.11574283 | T12: 0.1348845 | V12: 0.14300503 | W12: =ABS(($AH12-V12)/$AH12) -> 0.72446699 | Y12: 0.35966985 | Z12: =ABS(($AH12-Y12)/$AH12) -> 0.30701098 | AG12: 0.59800659 | AH12: 0.51901235 | AI12: 0.42KF-0.28NaF-0.30UF4 (Rudenko, 2024)
A13: 0.24NaF-0.36KF-0.4UF4 | B13: 878 | C13: 1073 | D13: 0.18851371 | F13: 0.19057901 | H13: 0.15917343 | J13: 0.36475139 | Q13: 0.57924146 | R13: 0.18133469 | T13: 0.18332134 | V13: 0.15118127 | W13: =ABS(($AH13-V13)/$AH13) -> 0.70253623 | Y13: 0.33864101 | Z13: =ABS(($AH13-Y13)/$AH13) -> 0.33369106 | AG13: 0.54654293 | AH13: 0.50823423 | AI13: 0.36KF-0.24NaF-0.40UF4 (Rudenko, 2024)
A14: 0.2NaF-0.3KF-0.5UF4 | B14: 878 | C14: 1073 | D14: 0.23423673 | F14: 0.21977532 | H14: 0.17464564 | J14: 0.34979074 | Q14: 0.53252974 | R14: 0.22647803 | T14: 0.21249562 | V14: 0.16870277 | W14: =ABS(($AH14-V14)/$AH14) -> 0.57854411 | Y14: 0.32853146 | Z14: =ABS(($AH14-Y14)/$AH14) -> 0.17925758 | AG14: 0.50439481 | AH14: 0.40028571 | AI14: 0.30KF-0.20NaF-0.50UF4 (Rudenko, 2024)
A15: 0.712LiF-0.23BeF2-0.05ZrF4-0.008UF4 | B15: 735 | C15: 785.88122 | D15: 0.11450404 | F15: 0.21993592 | H15: 0.46469757 | J15: 0.72737521 | L15: 0.72737521 | Q15: 1.322616 | R15: 0.11327849 | T15: 0.21758192 | V15: 0.46141777 | W15: =ABS(($AH15-V15)/$AH15) -> 0.63105706 | Y15: 0.71241195 | Z15: =ABS(($AH15-Y15)/$AH15) -> 0.43036576 | AB15: 0.71241195 | AG15: 1.3049988 | AH15: 1.2506481 | AI15: 0.465LiF-0.115NaF-0.42KF (Merritt, 2022),0.465LiF-0.115NaF-0.42KF (Gallagher, 2022),0.465LiF-0.115NaF-0.42KF (Rudenko, 2022)
A16: 0.73LiF-0.27BeF2 | B16: 723 | C16: 884 | D16: 1.1694201 | F16: 1.0901411 | H16: 1.0169508 | J16: 0.81942429 | Q16: 1.3544496 | R16: 1.143821 | T16: 1.0662774 | V16: 0.99333381 | W16: =ABS(($AH16-V16)/$AH16) -> 0.095706389 | Y16: 0.77570442 | Z16: =ABS(($AH16-Y16)/$AH16) -> 0.1443518 | AG16: 1.310565 | AH16: 0.90656933 | AI16: 0.73LiF-0.27BeF2 (Bobrova, 2023)
A17: 0.66LiF-0.34BeF2 | B17: 733 | C17: 884 | D17: 1.1321639 | E17: 1.6545464 | F17: 1.0327876 | G17: 1.5087682 | H17: 1.0025337 | I17: 1.518486 | J17: 0.77455399 | K17: 1.194875 | R17: 1.1128792 | S17: 1.6155238 | T17: 1.0151956 | U17: 1.4731838 | V17: 0.98447068 | W17: =ABS(($AH17-V17)/$AH17) -> 0.080050058 | X17: 1.4811883 | Y17: 0.74095938 | Z17: =ABS(($AH17-Y17)/$AH17) -> 0.18710304 | AA17: 1.1045267 | AH17: 0.91150468 | AI17: 0.73LiF-0.27BeF2 (Bobrova, 2023) | AJ17: 1.1 | AK17: Rosenthal 1969 [122]
A18: 0.4NaF-0.6KF | B18: 1000 | D18: 0.67334765 | F18: 0.67819467 | H18: 0.64214261 | J18: 0.4684939 | Q18: 0.73423486 | R18: 0.67334765 | T18: 0.67819467 | V18: 0.64214261 | W18: =ABS(($AH18-V18)/$AH18) -> 0.082653417 | Y18: 0.4684939 | Z18: =ABS(($AH18-Y18)/$AH18) -> 0.330723 | AG18: 0.73423486 | AH18: =AJ18 -> 0.7 | AJ18: 0.7 | AK18: Rudenko 2024 [178]
A19: 0.465LiF-0.115NaF-0.42KF | B19: 735 | C19: 742.4 | D19: 0.75544862 | F19: 0.76389433 | G19: 1.0241817 | H19: 0.6954626 | I19: 0.90509687 | J19: 0.65005469 | K19: 0.77295464 | Q19: 1.0993871 | R19: 0.75296021 | T19: 0.7613781 | U19: 1.0203939 | V19: 0.69317886 | W19: =ABS(($AH19-V19)/$AH19) -> 0.1226106 | X19: 0.90175871 | Y19: 0.6459406 | Z19: =ABS(($AH19-Y19)/$AH19) -> 0.1824023 | AA19: 0.76685546 | AG19: 1.0964289 | AH19: 0.79004699 | AI19: 0.465LiF-0.115NaF-0.42KF (Merritt, 2022),0.465LiF-0.115NaF-0.42KF (Gallagher, 2022),0.465LiF-0.115NaF-0.42KF (Rudenko, 2022)
A20: 0.2046NaCl-0.4131KCl-0.3823MgCl2 | B20: 700 | C20: 722.73281 | D20: 0.42631828 | F20: 0.39868607 | G20: 0.35511104 | H20: 0.39369828 | I20: 0.38744636 | J20: 0.34234495 | Q20: 0.47430496 | R20: 0.42244769 | T20: 0.39506636 | U20: 0.35163381 | V20: 0.39011154 | W20: =ABS(($AH20-V20)/$AH20) -> 0.17217062 | X20: 0.3836404 | Y20: 0.33784078 | Z20: =ABS(($AH20-Y20)/$AH20) -> 0.28309088 | AG20: 0.47038278 | AH20: 0.47124631 | AI20: 0.2046NaCl-0.4131KCl-0.3823MgCl2 (Wang, 2021)
A21: 0.345NaF-0.59KF-0.065MgF2 | B21: 958 | C21: 993.01378 | D21: 0.6779149 | F21: 0.67261166 | H21: 0.57197135 | I21: 0.59758621 | J21: 0.4860452 | K21: 0.49336011 | Q21: 0.74453173 | R21: 0.66907211 | T21: 0.66383804 | V21: 0.56448951 | W21: =ABS(($AH21-V21)/$AH21) -> 0.26308813 | X21: 0.58988275 | Y21: 0.47418606 | Z21: =ABS(($AH21-Y21)/$AH21) -> 0.38097462 | AA21: 0.48283679 | AG21: 0.73580725 | AH21: 0.76602038 | AI21: 0.345NaF-0.59KF-0.065MgF2 (Rudenko, 2024)
A22: 1.0LiCl | B22: 883 | C22: 965.57734 | D22: 0.68568905 | F22: 0.72519297 | H22: 0.68631947 | J22: 0.41038419 | Q22: 0.68524115 | R22: 0.66731827 | T22: 0.70576381 | V22: 0.6679318 | W22: =ABS(($AH22-V22)/$AH22) -> 0.018943205 | Y22: 0.3868412 | Z22: =ABS(($AH22-Y22)/$AH22) -> 0.40986607 | AG22: 0.66685348 | AH22: 0.65551426 | AI22: LiCl (Nagasaka, 1992)
A23: 1.0NaCl | B23: 1073.8 | C23: 1169.4387 | D23: 0.48765041 | F23: 0.492992 | H23: 0.48681288 | J23: 0.31017075 | Q23: 0.48673467 | R23: 0.46764534 | T23: 0.4727678 | V23: 0.46684217 | W23: =ABS(($AH23-V23)/$AH23) -> 0.11307557 | Y23: 0.28504925 | Z23: =ABS(($AH23-Y23)/$AH23) -> 0.45845264 | AG23: 0.46682997 | AH23: 0.5263607 | AI23: NaCl (Nagasaka 1992)
A24: 1.0KCl | B24: 1042.7 | C24: 1052.1639 | D24: 0.37448386 | F24: 0.39772402 | H24: 0.3742357 | J24: 0.26186835 | Q24: 0.37411661 | R24: 0.37273884 | T24: 0.39587071 | V24: 0.37249184 | W24: =ABS(($AH24-V24)/$AH24) -> 0.013588159 | Y24: 0.25964867 | Z24: =ABS(($AH24-Y24)/$AH24) -> 0.29346958 | AG24: 0.37237546 | AH24: 0.36749822 | AI24: KCl (Harada, 1992),KCl (Nagasaka, 1992)
A25: 1.0LiF | B25: 1121.2 | C25: 1121.2 | D25: 1.3492012 | F25: 1.4344247 | H25: 1.3498415 | J25: 0.80194503 | Q25: 1.3569764 | R25: 1.3492012 | T25: 1.4344247 | V25: 1.3498415 | W25: =ABS(($AH25-V25)/$AH25) -> 0.071577209 | Y25: 0.80194503 | Z25: =ABS(($AH25-Y25)/$AH25) -> 0.36337265 | AG25: 1.3569764 | AH25: 1.2596773 | AI25: LiF (Golyshev, 1982),LiF (Golyshev, 1983),LiF (Golyshev, 1992),LiF (Smirnov, 1987),LiF (Khlebnikov, 1981)
A26: 1.0NaF | B26: 1268 | C26: 1276.2108 | D26: 0.84228951 | F26: 0.90253851 | H26: 0.8422681 | J26: 0.53047696 | Q26: 0.84054676 | R26: 0.83982795 | T26: 0.89990088 | V26: 0.83980661 | W26: =ABS(($AH26-V26)/$AH26) -> 0.28778769 | Y26: 0.52656453 | Z26: =ABS(($AH26-Y26)/$AH26) -> 0.55343797 | AG26: 0.83809041 | AH26: 1.179152 | AI26: NaF (Smirnov, 1987),NaF (Polyakov, 1975)
A27: 1.0KF | B27: 1131.2 | C27: 1130.597 | D27: 0.58239325 | F27: 0.56777343 | H27: 0.58268228 | J27: 0.36409719 | Q27: 0.58236909 | R27: 0.58239325 | T27: 0.56777343 | V27: 0.58268228 | W27: =ABS(($AH27-V27)/$AH27) -> 0.064372614 | Y27: 0.36409719 | Z27: =ABS(($AH27-Y27)/$AH27) -> 0.41536011 | AG27: 0.58236909 | AH27: 0.62277172 | AI27: KF (Smirnov, 1987)
A28: 1.0MgCl2 | B28: 987 | C28: 986.86211 | D28: 0.43829221 | F28: 0.36348786 | H28: 0.4382922 | J28: 0.28861058 | Q28: 0.4382922 | R28: 0.43829221 | T28: 0.36348786 | V28: 0.4382922 | W28: =ABS(($AH28-V28)/$AH28) -> 0.19417783 | Y28: 0.28861058 | Z28: =ABS(($AH28-Y28)/$AH28) -> 0.469375 | AG28: 0.4382922 | AH28: 0.54390686 | AI28: MgCl2 (Filatov, 2005)
A29: 1.0MgF2 | B29: 1534.2 | C29: 1554.2416 | D29: 0.76994949 | F29: 0.65134847 | H29: 0.76994949 | J29: 0.55165642 | Q29: 0.76994949 | R29: 0.76680975 | T29: 0.64869236 | V29: 0.76680975 | W29: =ABS(($AH29-V29)/$AH29) -> 0.091875731 | Y29: 0.54942631 | Z29: =ABS(($AH29-Y29)/$AH29) -> 0.21766089 | AG29: 0.76680975 | AH29: 0.70228665 | AI29: MgF2 (Khlebnikov, 1981),MgF2 (Golyshev, 1992)
A30: 1.0CaF2 | B30: 1692 | C30: 1697.8471 | D30: 0.53240327 | F30: 0.56536852 | H30: 0.53240327 | J30: 0.42810664 | Q30: 0.53240327 | R30: 0.53209376 | T30: 0.56503984 | V30: 0.53209375 | W30: =ABS(($AH30-V30)/$AH30) -> 0.10256458 | Y30: 0.4277441 | Z30: =ABS(($AH30-Y30)/$AH30) -> 0.2785619 | AG30: 0.53209375 | AH30: 0.59290478 | AI30: CaF2 (Golyshev, 1992),CaF2 (Khlebnikov, 1981)
U35: Gheribi | V35: Zhao | X35: Labels
S36: Avg Error | T36: Actinide | U36: =AVERAGE(W6:W15) -> 0.55680469 | V36: =AVERAGE(Z6:Z15) -> 0.28725646 | X36: Gheribi; 11.8% MAE | Z36: Non-Actinides
T37: Non-actinide | U37: =AVERAGE(W16:W30) -> 0.11828279 | V37: =AVERAGE(Z16:Z30) -> 0.3312135 | X37: Zhao; 33.1% MAE | Z37: Actinides
X38: Gheribi; 55.7% MAE
U39: Deviation | X39: Zhao; 28.7% MAE
T40: 0 | U40: 1.15
T41: 0 | U41: 0.85

Sheet MFP-rsum
Q1: Gh-l | R1: Zh-l | Z1: Gh-l | AA1: Zh-l | BG1: scaled | BO1: Gh-c | BP1: Zh-c | BQ1: Gh-c scaled | BR1: Zh-c scaled | CB1: Zh-cv | CC1: Zh-cv | CD1: Gh-cv | CE1: Gh-cv | CF1: Zh_tot | CG1: Gh-tot
A2: Compound | B2: S/cm | C2: order | D2: protons | E2: electrons | F2: Mp/molecule | G2: Me/molecule | H2: ratio of Mpe*# | I2: ratio | J2: Dif mass | K2: M_i (g/mol) | L2: Visc (N*s/m^2) | M2: T_i_m (K) inverse | N2: T_i_m (K) | O2: V_i_m (m^3/mol) | P2: alpha_i_m (K^-1) | Q2: n (atoms/m#)^-1/3 | R2: sum_radii | S2: dif_Avg | T2: %dev | U2: r_c (m) | V2: r_a (m) | W2: V_m-dist | X2: 1stPeak | Y2: delta | Z2: --> Scaled | AA2: --> Scaled | AB2: rho_m (g/m^3) | AC2: SoS(T)_A (A+B*T) | AD2: SoS(T)_B | AE2: A (Density (g/cm3): A - BT(K)) | AF2: B (Density (g/cm3): A - BT(K)) | AG2: m_cation | AH2: m_anion | AI2: mass_disparity | AK2: #_cations | AL2: #_anions | AM2: sum_ions | AN2: Psi | AO2: λ_meas_OG | AP2: λ_meas | AQ2: 1/3*Cp*vs*r_sumCorrect | AR2: Error | AS2: 1/3*Cp*vs*1stPk | AT2: 1/3*Cp*vs*AvgPk | AU2: 1/3*Cp*vs*r_sum | AV2: dev_λ | AW2: c_BC,rsum | AX2: c_BC_λBC | AY2: 1/3*Cp*vs | AZ2: r_sum | BA2: 1stPeak | BB2: AvgMFP | BC2: λBC | BD2: MFP_calc | BE2: MFP_dev | BF2: 1/3*Cp*r_sum | BG2: SoS_Tm | BH2: SoS_Tm | BI2: SoS_metal | BJ2: vs_calc | BK2: vs_dev | BL2: 1/3*vs*r_sum | BM2: C_i_p (J/mol/K) | BN2: kB*n | BO2: Psi*kB*n | BP2: 1/3*c_p' | BQ2: Psi*kB*n | BR2: 1/3*c_p' | BS2: difAvg | BT2: %dev | BU2: Gh-c*l | BV2: Zh-c*l | BW2: %Dev | BX2: Cp(MJ/m3-K) | BY2: Cp(J/m3-K) | BZ2: Cp_calc | CA2: Cp_dev | CB2: 1/3*vs*cp | CC2: --> Scaled | CD2: vs*cp | CE2: --> Scaled | CF2: 1/3*vs*cp*rsum | CG2: Psi*kB*n*mfp | CH2: mu | CI2: V_ca(r ) | CJ2: R(pm) | CK2: R(pm)/mu | CL2: 1/sqrt(mu) | CM2: x_ca,peak | CN2: R(pm)/mu | CO2: V/mu | CP2: R | CQ2: Visc/(Dens*C0)
A3: LiF | B3: 9.95 | C3: 1 | D3: 12 | E3: 12 | F3: =D3*1.6726219E-27 -> 2.0071463e-26 | G3: =E3*9.1093856E-31 -> 1.0931263e-29 | H3: =((F3*D3)/(G3*E3)) -> 1836.1523 | I3: =D3/E3 -> 1 | J3: =(F3)-(G3) -> 2.0060532e-26 | K3: 25.939 | L3: =0.115*EXP(27000/(8.3144598*N3))/1000 -> 0.0020988673 | M3: =N3^-1 -> 0.00089433439 | N3: 1118.15 | O3: 1.42e-05 | P3: 0.000268 | Q3: =((6.02214076E+23*AM3)/O3)^(-1/3) -> 2.2759837e-10 | R3: =V3+U3 -> 2.09e-10 | S3: =Q3-R3 -> 1.8598371e-11 | T3: =(Q3-R3)/Q3 -> 0.081715746 | U3: 7.6e-11 | V3: 1.33e-10 | W3: =(( (O3/6.02214076E+23)^(1/3)) + (R3)) / 2 -> 2.4787799e-10 | X3: 1.87745 | Y3: =V3/U3 -> 1.75 | Z3: =Q3*10000000000 -> 2.2759837 | AA3: =R3*10000000000 -> 2.09 | AB3: 1810000 | AC3: 2547.8 | AD3: 0 | AE3: 2.3581 | AF3: -0.0004902 | AG3: 6.941 | AH3: 18.998403 | AI3: =ABS(AH3-AG3) -> 12.057403 | AJ3: =K3/CH3 -> 5.1023951 | AK3: 1 | AL3: 1 | AM3: =AK3+AL3 -> 2 | AN3: =1+AK3/AL3 -> 2 | AO3: 1.33125 | AP3: 1.2606752 | AQ3: =1/3*BY3*BH3*R3 -> 0.80248523 | AR3: =ABS((AP3-AQ3)/AP3) -> 0.36344809 | AS3: =1/3*BY3*BH3*BA3 -> 0.72246878 | AT3: =1/3*BY3*BH3*BB3 -> 0.90368251 | AU3: 0.79448872 | AV3: =(AP3-AU3)/AP3 -> 0.36979113 | AW3: =AP3/(1/3*BH3*R3) -> 7102526.4 | AX3: =AP3/(1/3*BH3*BC3) -> 4521126.8 | AY3: 3.8013815e+09 | AZ3: =AU3/AY3 -> 2.09e-10 | BA3: 1.8816044e-10 | BB3: 2.3535591e-10 | BC3: =AP3/(1/3*BY3*BH3) -> 3.2833143e-10 | BD3: =AP3/AY3 -> 3.3163608e-10 | BE3: =(BD3-AZ3)/AZ3 -> 0.5867755 | BF3: =AU3/BH3 -> 0.00031183324 | BG3: =BH3/1000 -> 2.5478 | BH3: =AC3+AD3*N3 -> 2547.8 | BI3: 3500 | BJ3: =AP3/BF3 -> 4042.7866 | BK3: =(BJ3-BH3)/BH3 -> 0.5867755 | BL3: =AU3/BM3 -> 0.012375214 | BM3: 64.2 | BN3: =1.380649E-23*(Q3^(-3)) -> 1171051.1 | BO3: =BN3*AN3 -> 2342102.1 | BP3: =1/3*BX3*10^6 -> 1507042.3 | BQ3: =BO3*0.000001 -> 2.3421021 | BR3: =BP3*0.000001 -> 1.5070423 | BS3: =BO3-BP3 -> 835059.89 | BT3: =(BO3-BP3)/BO3 -> 0.3565429 | BU3: =Q3*BO3 -> 0.00053305863 | BV3: =S3*BP3 -> 2.8028531e-05 | BW3: =(BU3-BV3)/BU3 -> 0.94741942 | BX3: =BY3/1000000 -> 4.5211268 | BY3: =BM3/O3 -> 4521126.8 | BZ3: =AP3/(BL3) -> 101.87099 | CA3: =(BZ3-BM3)/BM3 -> 0.5867755 | CB3: =BH3*BP3 -> 3.8396423e+09 | CC3: =CB3*0.000000001 -> 3.8396423 | CD3: =BH3*BO3 -> 5.9672078e+09 | CE3: =CD3*0.000000001 -> 5.9672078 | CF3: =CB3*R3 -> 0.80248523 | CG3: =CD3*Q3 -> 1.3581268 | CH3: 5.083691 | CI3: -6.5464269e-05 | CJ3: 0.87109136 | CK3: =SQRT(CJ3/CH3) -> 0.41394466 | CL3: =SQRT(1/CH3) -> 0.44351716 | CM3: 1.84e-10 | CN3: =CM3*SQRT(CJ3/CH3) -> 7.6165817e-11 | CO3: =SQRT(ABS(CI3))/CH3 -> 0.00159156 | CP3: =BH3^(2/3)*O3 -> 0.002648898 | CQ3: =L3/(AB3/1000*(AC3+AD3*N3)) -> 4.5513588e-10
A4: NaF | B4: 6.9 | C4: 1 | D4: 20 | E4: 20 | F4: =D4*1.6726219E-27 -> 3.3452438e-26 | G4: =E4*9.1093856E-31 -> 1.8218771e-29 | H4: =((F4*D4)/(G4*E4)) -> 1836.1523 | I4: =D4/E4 -> 1 | J4: =(F4)-(G4) -> 3.3434219e-26 | K4: 41.988 | L4: =0.12*EXP(26500/(8.3144598*N4))/1000 -> 0.0014814456 | M4: =N4^-1 -> 0.00078855025 | N4: 1268.15 | O4: 2.16e-05 | P4: 0.000288 | Q4: =((6.02214076E+23*AM4)/O4)^(-1/3) -> 2.6175257e-10 | R4: =V4+U4 -> 2.35e-10 | S4: =Q4-R4 -> 2.6752568e-11 | T4: =(Q4-R4)/Q4 -> 0.10220556 | U4: 1.02e-10 | V4: 1.33e-10 | W4: =(( (O4/6.02214076E+23)^(1/3)) + (R4)) / 2 -> 2.8239379e-10 | X4: 2.16677 | Y4: =V4/U4 -> 1.3039216 | Z4: =Q4*10000000000 -> 2.6175257 | AA4: =R4*10000000000 -> 2.35 | AB4: 1950000 | AC4: 2085.5 | AD4: 0 | AE4: 2.755 | AF4: -0.000636 | AG4: 22.989769 | AH4: 18.998403 | AI4: =ABS(AH4-AG4) -> 3.991366 | AJ4: =K4/CH4 -> 4.0364581 | AK4: 1 | AL4: 1 | AM4: =AK4+AL4 -> 2 | AN4: =1+AK4/AL4 -> 2 | AO4: 0.8279 | AP4: 1.179152 | AQ4: =1/3*BY4*BH4*R4 -> 0.53093354 | AR4: =ABS((AP4-AQ4)/AP4) -> 0.54973276 | AS4: =1/3*BY4*BH4*BA4 -> 0.49109756 | AT4: =1/3*BY4*BH4*BB4 -> 0.59812176 | AU4: 0.53220718 | AV4: =(AP4-AU4)/AP4 -> 0.54865263 | AW4: =AP4/(1/3*BH4*R4) -> 7217935.7 | AX4: =AP4/(1/3*BH4*BC4) -> 3250000 | AY4: 2.2647114e+09 | AZ4: =AU4/AY4 -> 2.35e-10 | BA4: 2.1736793e-10 | BB4: 2.6473862e-10 | BC4: =AP4/(1/3*BY4*BH4) -> 5.2191227e-10 | BD4: =AP4/AY4 -> 5.2066327e-10 | BE4: =(BD4-AZ4)/AZ4 -> 1.2155884 | BF4: =AU4/BH4 -> 0.00025519404 | BG4: =BH4/1000 -> 2.0855 | BH4: =AC4+AD4*N4 -> 2085.5 | BI4: 2720 | BJ4: =AP4/BF4 -> 4620.6096 | BK4: =(BJ4-BH4)/BH4 -> 1.2155884 | BL4: =AU4/BM4 -> 0.0075812988 | BM4: 70.2 | BN4: =1.380649E-23*(Q4^(-3)) -> 769857.65 | BO4: =BN4*AN4 -> 1539715.3 | BP4: =1/3*BX4*10^6 -> 1083333.3 | BQ4: =BO4*0.000001 -> 1.5397153 | BR4: =BP4*0.000001 -> 1.0833333 | BS4: =BO4-BP4 -> 456381.97 | BT4: =(BO4-BP4)/BO4 -> 0.29640672 | BU4: =Q4*BO4 -> 0.00040302443 | BV4: =S4*BP4 -> 2.8981949e-05 | BW4: =(BU4-BV4)/BU4 -> 0.92808885 | BX4: =BY4/1000000 -> 3.25 | BY4: =BM4/O4 -> 3250000 | BZ4: =AP4/(BL4) -> 155.53431 | CA4: =(BZ4-BM4)/BM4 -> 1.2155884 | CB4: =BH4*BP4 -> 2.2592917e+09 | CC4: =CB4*0.000000001 -> 2.2592917 | CD4: =BH4*BO4 -> 3.2110763e+09 | CE4: =CD4*0.000000001 -> 3.2110763 | CF4: =CB4*R4 -> 0.53093354 | CG4: =CD4*Q4 -> 0.84050746 | CH4: 10.402189 | CI4: -0.00064235936 | CJ4: 0.88236536 | CK4: =SQRT(CJ4/CH4) -> 0.29124726 | CL4: =SQRT(1/CH4) -> 0.31005421 | CM4: 2.14e-10 | CN4: =CM4*SQRT(CJ4/CH4) -> 6.2326915e-11 | CO4: =SQRT(ABS(CI4))/CH4 -> 0.0024364881 | CP4: =BH4^(2/3)*O4 -> 0.0035258233 | CQ4: =L4/(AB4/1000*(AC4+AD4*N4)) -> 3.6428469e-10
A5: KF | B5: 5.1 | C5: 1 | D5: 28 | E5: 28 | F5: =D5*1.6726219E-27 -> 4.6833413e-26 | G5: =E5*9.1093856E-31 -> 2.550628e-29 | H5: =((F5*D5)/(G5*E5)) -> 1836.1523 | I5: =D5/E5 -> 1 | J5: =(F5)-(G5) -> 4.6807907e-26 | K5: 58.097 | L5: =0.107*EXP(23800/(8.3144598*N5))/1000 -> 0.001350063 | M5: =N5^-1 -> 0.00088562193 | N5: 1129.15 | O5: 3.04e-05 | P5: 0.000341 | Q5: =((6.02214076E+23*AM5)/O5)^(-1/3) -> 2.9333523e-10 | R5: =V5+U5 -> 2.71e-10 | S5: =Q5-R5 -> 2.2335232e-11 | T5: =(Q5-R5)/Q5 -> 0.076142344 | U5: 1.38e-10 | V5: 1.33e-10 | W5: =(( (O5/6.02214076E+23)^(1/3)) + (R5)) / 2 -> 3.2028962e-10 | X5: 2.48194 | Y5: =V5/U5 -> 0.96376812 | Z5: =Q5*10000000000 -> 2.9333523 | AA5: =R5*10000000000 -> 2.71 | AB5: 1910000 | AC5: 1816.4 | AD5: 0 | AE5: 2.6464 | AF5: -0.0006515 | AG5: 39.0983 | AH5: 18.998403 | AI5: =ABS(AH5-AG5) -> 20.099897 | AJ5: =K5/CH5 -> 4.5439152 | AK5: 1 | AL5: 1 | AM5: =AK5+AL5 -> 2 | AN5: =1+AK5/AL5 -> 2 | AO5: 0.57 | AP5: 0.62277172 | AQ5: =1/3*BY5*BH5*R5 -> 0.36108718 | AR5: =ABS((AP5-AQ5)/AP5) -> 0.42019337 | AS5: =1/3*BY5*BH5*BA5 -> 0.32961603 | AT5: =1/3*BY5*BH5*BB5 -> 0.40376311 | AU5: 0.36077309 | AV5: =(AP5-AU5)/AP5 -> 0.4206977 | AW5: =AP5/(1/3*BH5*R5) -> 3795503.1 | AX5: =AP5/(1/3*BH5*BC5) -> 2200657.9 | AY5: 1.331266e+09 | AZ5: =AU5/AY5 -> 2.71e-10 | BA5: 2.4738055e-10 | BB5: 3.0302877e-10 | BC5: =AP5/(1/3*BY5*BH5) -> 4.6739721e-10 | BD5: =AP5/AY5 -> 4.6780412e-10 | BE5: =(BD5-AZ5)/AZ5 -> 0.72621446 | BF5: =AU5/BH5 -> 0.00019861985 | BG5: =BH5/1000 -> 1.8164 | BH5: =AC5+AD5*N5 -> 1816.4 | BI5: 2360 | BJ5: =AP5/BF5 -> 3135.4959 | BK5: =(BJ5-BH5)/BH5 -> 0.72621446 | BL5: =AU5/BM5 -> 0.0053927218 | BM5: 66.9 | BN5: =1.380649E-23*(Q5^(-3)) -> 547004.12 | BO5: =BN5*AN5 -> 1094008.2 | BP5: =1/3*BX5*10^6 -> 733552.63 | BQ5: =BO5*0.000001 -> 1.0940082 | BR5: =BP5*0.000001 -> 0.73355263 | BS5: =BO5-BP5 -> 360455.61 | BT5: =(BO5-BP5)/BO5 -> 0.32948162 | BU5: =Q5*BO5 -> 0.00032091116 | BV5: =S5*BP5 -> 1.6384068e-05 | BW5: =(BU5-BV5)/BU5 -> 0.94894516 | BX5: =BY5/1000000 -> 2.2006579 | BY5: =BM5/O5 -> 2200657.9 | BZ5: =AP5/(BL5) -> 115.48375 | CA5: =(BZ5-BM5)/BM5 -> 0.72621446 | CB5: =BH5*BP5 -> 1332425000 | CC5: =CB5*0.000000001 -> 1.332425 | CD5: =BH5*BO5 -> 1.9871566e+09 | CE5: =CD5*0.000000001 -> 1.9871566 | CF5: =CB5*R5 -> 0.36108717 | CG5: =CD5*Q5 -> 0.58290303 | CH5: 12.78567 | CI5: -0.0013975067 | CJ5: 0.88025103 | CK5: =SQRT(CJ5/CH5) -> 0.26238652 | CL5: =SQRT(1/CH5) -> 0.27966509 | CM5: 2.44e-10 | CN5: =CM5*SQRT(CJ5/CH5) -> 6.4022312e-11 | CO5: =SQRT(ABS(CI5))/CH5 -> 0.0029238391 | CP5: =BH5^(2/3)*O5 -> 0.0045256529 | CQ5: =L5/(AB5/1000*(AC5+AD5*N5)) -> 3.8914297e-10
A6: RbF | C6: 1 | D6: 46 | E6: 46 | F6: =D6*1.6726219E-27 -> 7.6940607e-26 | G6: =E6*9.1093856E-31 -> 4.1903174e-29 | H6: =((F6*D6)/(G6*E6)) -> 1836.1523 | I6: =D6/E6 -> 1 | J6: =(F6)-(G6) -> 7.6898704e-26 | K6: 104.4662 | L6: =0.115*EXP(27000/(8.3144598*N6))/1000 -> 0.0025481161 | M6: =N6^-1 -> 0.00095406192 | N6: 1048.15 | O6: 3.57e-05 | P6: 0.000349 | Q6: =((6.02214076E+23*AM6)/O6)^(-1/3) -> 3.0947752e-10 | R6: =V6+U6 -> 2.85e-10 | S6: =Q6-R6 -> 2.4477519e-11 | T6: =(Q6-R6)/Q6 -> 0.079093043 | U6: 1.52e-10 | V6: 1.33e-10 | W6: =(( (O6/6.02214076E+23)^(1/3)) + (R6)) / 2 -> 3.3745862e-10 | Y6: =V6/U6 -> 0.875 | Z6: =Q6*10000000000 -> 3.0947752 | AA6: =R6*10000000000 -> 2.85 | AB6: =K6/O6 -> 2926224.1 | AC6: 1760.4 | AD6: 0 | AE6: =AB6*100^3/1000 -> 2.9262241e+09 | AF6: 0 | AG6: 85.4678 | AH6: 18.998403 | AI6: =ABS(AH6-AG6) -> 66.469397 | AJ6: =K6/CH6 -> 6.7209704 | AK6: 1 | AL6: 1 | AM6: =AK6+AL6 -> 2 | AN6: =1+AK6/AL6 -> 2 | AO6: 0.48965 | AP6: 0.48965 | AQ6: =1/3*BY6*BH6*R6 -> 0.32557538 | AR6: =ABS((AP6-AQ6)/AP6) -> 0.33508551 | AS6: =1/3*BY6*BH6*BA6 -> 0.29579641 | AW6: =AP6/(1/3*BH6*R6) -> 2927863.3 | AX6: =AP6/(1/3*BH6*BC6) -> 1946778.7 | BA6: 2.5893228e-10 | BC6: =AP6/(1/3*BY6*BH6) -> 4.2862655e-10 | BD6: 2.5893228e-10 | BG6: =BH6/1000 -> 1.7604 | BH6: =AC6+AD6*N6 -> 1760.4 | BL6: =AU6/BM6 -> 0 | BM6: 69.5 | BN6: =1.380649E-23*(Q6^(-3)) -> 465796.23 | BO6: =BN6*AN6 -> 931592.45 | BP6: =1/3*BX6*10^6 -> 648926.24 | BQ6: =BO6*0.000001 -> 0.93159245 | BR6: =BP6*0.000001 -> 0.64892624 | BS6: =BO6-BP6 -> 282666.21 | BT6: =(BO6-BP6)/BO6 -> 0.30342261 | BU6: =Q6*BO6 -> 0.00028830692 | BV6: =S6*BP6 -> 1.5884104e-05 | BW6: =(BU6-BV6)/BU6 -> 0.94490557 | BX6: =BY6/1000000 -> 1.9467787 | BY6: =BM6/O6 -> 1946778.7 | CB6: =BH6*BP6 -> 1.1423697e+09 | CC6: =CB6*0.000000001 -> 1.1423697 | CD6: =BH6*BO6 -> 1.6399753e+09 | CE6: =CD6*0.000000001 -> 1.6399753 | CF6: =CB6*R6 -> 0.32557538 | CG6: =CD6*Q6 -> 0.5075355 | CH6: 15.543321 | CI6: -0.0018393987 | CL6: =SQRT(1/CH6) -> 0.25364604 | CM6: 2.56e-10 | CN6: =R6*SQRT(0.9/CH6) -> 6.8579483e-11 | CO6: =SQRT(ABS(CI6))/CH6 -> 0.0027592695 | CP6: =BH6^(2/3)*O6 -> 0.0052048608 | CQ6: =L6/(AB6/1000*(AC6+AD6*N6)) -> 4.9465257e-10
A7: CsF | C7: 1 | D7: 64 | E7: 64 | F7: =D7*1.6726219E-27 -> 1.070478e-25 | G7: =E7*9.1093856E-31 -> 5.8300068e-29 | H7: =((F7*D7)/(G7*E7)) -> 1836.1523 | I7: =D7/E7 -> 1 | J7: =(F7)-(G7) -> 1.069895e-25 | K7: 58.44 | L7: =0.115*EXP(27000/(8.3144598*N7))/1000 -> 0.0034453112 | M7: =N7^-1 -> 0.001046956 | N7: 955.15 | O7: 4.57e-05 | P7: 0.000385 | Q7: =((6.02214076E+23*AM7)/O7)^(-1/3) -> 3.360303e-10 | R7: =V7+U7 -> 3e-10 | S7: =Q7-R7 -> 3.6030296e-11 | T7: =(Q7-R7)/Q7 -> 0.10722335 | U7: 1.67e-10 | V7: 1.33e-10 | W7: =(( (O7/6.02214076E+23)^(1/3)) + (R7)) / 2 -> 3.6168582e-10 | Y7: =V7/U7 -> 0.79640719 | Z7: =Q7*10000000000 -> 3.360303 | AA7: =R7*10000000000 -> 3 | AB7: 2196977.2 | AC7: 2732.9322 | AD7: -0.915 | AE7: 4.8985 | AF7: -0.000543 | AG7: 132.90545 | AH7: 18.998403 | AI7: =ABS(AH7-AG7) -> 113.90705 | AJ7: =K7/CH7 -> 3.5157592 | AK7: 1 | AL7: 1 | AM7: =AK7+AL7 -> 2 | AN7: =1+AK7/AL7 -> 2 | AO7: 0.36715 | AP7: 0.36715 | AQ7: =1/3*BY7*BH7*R7 -> 0.30142161 | AR7: =ABS((AP7-AQ7)/AP7) -> 0.17902325 | AS7: =1/3*BY7*BH7*BA7 -> 0.28095437 | AW7: =AP7/(1/3*BH7*R7) -> 1975018.4 | AX7: =AP7/(1/3*BH7*BC7) -> 1621444.2 | BA7: 2.7962928e-10 | BC7: =AP7/(1/3*BY7*BH7) -> 3.6541839e-10 | BD7: 2.7962928e-10 | BG7: =BH7/1000 -> 1.85897 | BH7: =AC7+AD7*N7 -> 1858.97 | BL7: =AU7/BM7 -> 0 | BM7: 74.1 | BN7: =1.380649E-23*(Q7^(-3)) -> 363871.45 | BO7: =BN7*AN7 -> 727742.9 | BP7: =1/3*BX7*10^6 -> 540481.4 | BQ7: =BO7*0.000001 -> 0.7277429 | BR7: =BP7*0.000001 -> 0.5404814 | BS7: =BO7-BP7 -> 187261.5 | BT7: =(BO7-BP7)/BO7 -> 0.25731821 | BU7: =Q7*BO7 -> 0.00024454366 | BV7: =S7*BP7 -> 1.9473705e-05 | BW7: =(BU7-BV7)/BU7 -> 0.92036717 | BX7: =BY7/1000000 -> 1.6214442 | BY7: =BM7/O7 -> 1621444.2 | CB7: =BH7*BP7 -> 1.0047387e+09 | CC7: =CB7*0.000000001 -> 1.0047387 | CD7: =BH7*BO7 -> 1.3528522e+09 | CE7: =CD7*0.000000001 -> 1.3528522 | CF7: =CB7*R7 -> 0.30142161 | CG7: =CD7*Q7 -> 0.45459933 | CH7: 16.622299 | CI7: -0.0029196881 | CL7: =SQRT(1/CH7) -> 0.24527566 | CM7: 2.76e-10 | CN7: =R7*SQRT(0.9/CH7) -> 6.9806677e-11 | CO7: =SQRT(ABS(CI7))/CH7 -> 0.0032507018 | CP7: =BH7^(2/3)*O7 -> 0.0069092534 | CQ7: =L7/(AB7/1000*(AC7+AD7*N7)) -> 8.4358824e-10
A8: LiCl | B8: 3.67 | C8: 1 | D8: 20 | E8: 20 | F8: =D8*1.6726219E-27 -> 3.3452438e-26 | G8: =E8*9.1093856E-31 -> 1.8218771e-29 | H8: =((F8*D8)/(G8*E8)) -> 1836.1523 | I8: =D8/E8 -> 1 | J8: =(F8)-(G8) -> 3.3434219e-26 | K8: 42.394 | L8: =0.0726*EXP(22400/(8.3144598*N8))/1000 -> 0.0015609789 | M8: =N8^-1 -> 0.0011388225 | N8: 878.1 | O8: =K8/AB8 -> 2.8281521e-05 | P8: 0.000288 | Q8: =((6.02214076E+23*AM8)/O8)^(-1/3) -> 2.8635666e-10 | R8: =V8+U8 -> 2.57e-10 | S8: =Q8-R8 -> 2.935666e-11 | T8: =(Q8-R8)/Q8 -> 0.10251782 | U8: 7.6e-11 | V8: 1.81e-10 | W8: =(( (O8/6.02214076E+23)^(1/3)) + (R8)) / 2 -> 3.0889339e-10 | X8: 2.37294 | Y8: =V8/U8 -> 2.3815789 | Z8: =Q8*10000000000 -> 2.8635666 | AA8: =R8*10000000000 -> 2.57 | AB8: 1499000 | AC8: 2787.9043 | AD8: -0.849 | AE8: 1.8842 | AF8: -0.0004328 | AG8: 6.941 | AH8: 35.45 | AI8: =ABS(AH8-AG8) -> 28.509 | AJ8: =K8/CH8 -> 7.3036475 | AK8: 1 | AL8: 1 | AM8: =AK8+AL8 -> 2 | AN8: =1+AK8/AL8 -> 2 | AO8: 0.6126 | AP8: 0.65551426 | AQ8: =1/3*BY8*BH8*R8 -> 0.40225026 | AR8: =ABS((AP8-AQ8)/AP8) -> 0.38635926 | AS8: =1/3*BY8*BH8*BA8 -> 0.37226977 | AT8: =1/3*BY8*BH8*BB8 -> 0.46741266 | AU8: 0.40224439 | AV8: =(AP8-AU8)/AP8 -> 0.38636821 | AW8: =AP8/(1/3*BH8*R8) -> 3746536.9 | AX8: =AP8/(1/3*BH8*BC8) -> 2299027.7 | AY8: 1.5651533e+09 | AZ8: =AU8/AY8 -> 2.57e-10 | BA8: 2.378453e-10 | BB8: 2.9863264e-10 | BC8: =AP8/(1/3*BY8*BH8) -> 4.1881183e-10 | BD8: =AP8/AY8 -> 4.1881793e-10 | BE8: =(BD8-AZ8)/AZ8 -> 0.62964176 | BF8: =AU8/BH8 -> 0.00019694717 | BG8: =BH8/1000 -> 2.0423974 | BH8: =AC8+AD8*N8 -> 2042.3974 | BI8: 3500 | BJ8: =AP8/BF8 -> 3328.3762 | BK8: =(BJ8-BH8)/BH8 -> 0.62964176 | BL8: =AU8/BM8 -> 0.0061864717 | BM8: 65.02 | BN8: =1.380649E-23*(Q8^(-3)) -> 587978.46 | BO8: =BN8*AN8 -> 1175956.9 | BP8: =1/3*BX8*10^6 -> 766342.56 | BQ8: =BO8*0.000001 -> 1.1759569 | BR8: =BP8*0.000001 -> 0.76634256 | BS8: =BO8-BP8 -> 409614.36 | BT8: =(BO8-BP8)/BO8 -> 0.34832429 | BU8: =Q8*BO8 -> 0.0003367431 | BV8: =S8*BP8 -> 2.2497258e-05 | BW8: =(BU8-BV8)/BU8 -> 0.93319163 | BX8: =BY8/1000000 -> 2.2990277 | BY8: =BM8/O8 -> 2299027.7 | BZ8: =AP8/(BL8) -> 105.95931 | CA8: =(BZ8-BM8)/BM8 -> 0.62964176 | CB8: =BH8*BP8 -> 1.5651761e+09 | CC8: =CB8*0.000000001 -> 1.5651761 | CD8: =BH8*BO8 -> 2.4017714e+09 | CE8: =CD8*0.000000001 -> 2.4017714 | CF8: =CB8*R8 -> 0.40225026 | CG8: =CD8*Q8 -> 0.68776324 | CH8: 5.804497 | CI8: -0.00044547221 | CJ8: 0.88854851 | CK8: =SQRT(CJ8/CH8) -> 0.39125354 | CL8: =SQRT(1/CH8) -> 0.41506652 | CM8: 2.36e-10 | CN8: =CM8*SQRT(CJ8/CH8) -> 9.2335835e-11 | CO8: =SQRT(ABS(CI8))/CH8 -> 0.0036361829 | CP8: =BH8^(2/3)*O8 -> 0.0045526361 | CQ8: =L8/(AB8/1000*(AC8+AD8*N8)) -> 5.0986493e-10
A9: NaCl | B9: 3.94 | C9: 1 | D9: 28 | E9: 28 | F9: =D9*1.6726219E-27 -> 4.6833413e-26 | G9: =E9*9.1093856E-31 -> 2.550628e-29 | H9: =((F9*D9)/(G9*E9)) -> 1836.1523 | I9: =D9/E9 -> 1 | J9: =(F9)-(G9) -> 4.6807907e-26 | K9: 58.44 | L9: =0.0893*EXP(22000/(8.3144598*N9))/1000 -> 0.0010321391 | M9: =N9^-1 -> 0.00092494104 | N9: 1081.15 | O9: 3.765e-05 | P9: 0.00035 | Q9: =((6.02214076E+23*AM9)/O9)^(-1/3) -> 3.1501267e-10 | R9: =V9+U9 -> 2.83e-10 | S9: =Q9-R9 -> 3.2012674e-11 | T9: =(Q9-R9)/Q9 -> 0.10162345 | U9: 1.02e-10 | V9: 1.81e-10 | W9: =(( (O9/6.02214076E+23)^(1/3)) + (R9)) / 2 -> 3.3994555e-10 | X9: 2.65901 | Y9: =V9/U9 -> 1.7745098 | Z9: =Q9*10000000000 -> 3.1501267 | AA9: =R9*10000000000 -> 2.83 | AB9: 1560000 | AC9: 2732.9322 | AD9: -0.915 | AE9: 2.1393 | AF9: -0.000543 | AG9: 22.989769 | AH9: 35.45 | AI9: =ABS(AH9-AG9) -> 12.460231 | AJ9: =K9/CH9 -> 4.1905192 | AK9: 1 | AL9: 1 | AM9: =AK9+AL9 -> 2 | AN9: =1+AK9/AL9 -> 2 | AO9: 0.4665 | AP9: 0.4910426 | AQ9: =1/3*BY9*BH9*R9 -> 0.30415923 | AR9: =ABS((AP9-AQ9)/AP9) -> 0.38058483 | AS9: =1/3*BY9*BH9*BA9 -> 0.28617344 | AT9: =1/3*BY9*BH9*BB9 -> 0.34614447 | AU9: 0.30612615 | AV9: =(AP9-AU9)/AP9 -> 0.37657923 | AW9: =AP9/(1/3*BH9*R9) -> 2985294.6 | AX9: =AP9/(1/3*BH9*BC9) -> 1849136.8 | AY9: 1.0817179e+09 | AZ9: =AU9/AY9 -> 2.83e-10 | BA9: 2.6626541e-10 | BB9: 3.2206448e-10 | BC9: =AP9/(1/3*BY9*BH9) -> 4.5688258e-10 | BD9: =AP9/AY9 -> 4.5394702e-10 | BE9: =(BD9-AZ9)/AZ9 -> 0.60405307 | BF9: =AU9/BH9 -> 0.00017556326 | BG9: =BH9/1000 -> 1.74368 | BH9: =AC9+AD9*N9 -> 1743.68 | BI9: 2720 | BJ9: =AP9/BF9 -> 2796.9553 | BK9: =(BJ9-BH9)/BH9 -> 0.60405307 | BL9: =AU9/BM9 -> 0.0043971007 | BM9: 69.62 | BN9: =1.380649E-23*(Q9^(-3)) -> 441671.32 | BO9: =BN9*AN9 -> 883342.64 | BP9: =1/3*BX9*10^6 -> 616378.93 | BQ9: =BO9*0.000001 -> 0.88334264 | BR9: =BP9*0.000001 -> 0.61637893 | BS9: =BO9-BP9 -> 266963.71 | BT9: =(BO9-BP9)/BO9 -> 0.30221989 | BU9: =Q9*BO9 -> 0.00027826413 | BV9: =S9*BP9 -> 1.9731938e-05 | BW9: =(BU9-BV9)/BU9 -> 0.92908918 | BX9: =BY9/1000000 -> 1.8491368 | BY9: =BM9/O9 -> 1849136.8 | BZ9: =AP9/(BL9) -> 111.67417 | CA9: =(BZ9-BM9)/BM9 -> 0.60405307 | CB9: =BH9*BP9 -> 1.0747676e+09 | CC9: =CB9*0.000000001 -> 1.0747676 | CD9: =BH9*BO9 -> 1.5402669e+09 | CE9: =CD9*0.000000001 -> 1.5402669 | CF9: =CB9*R9 -> 0.30415923 | CG9: =CD9*Q9 -> 0.48520359 | CH9: 13.945766 | CI9: -0.0023782148 | CJ9: 0.89095701 | CK9: =SQRT(CJ9/CH9) -> 0.25275933 | CL9: =SQRT(1/CH9) -> 0.26778042 | CM9: 2.64e-10 | CN9: =CM9*SQRT(CJ9/CH9) -> 6.6728462e-11 | CO9: =SQRT(ABS(CI9))/CH9 -> 0.0034968996 | CP9: =BH9^(2/3)*O9 -> 0.0054543479 | CQ9: =L9/(AB9/1000*(AC9+AD9*N9)) -> 3.7944326e-10
A10: KCl | B10: 3.34 | C10: 1 | D10: 36 | E10: 36 | F10: =D10*1.6726219E-27 -> 6.0214388e-26 | G10: =E10*9.1093856E-31 -> 3.2793788e-29 | H10: =((F10*D10)/(G10*E10)) -> 1836.1523 | I10: =D10/E10 -> 1 | J10: =(F10)-(G10) -> 6.0181595e-26 | K10: 74.5513 | L10: =0.0708*EXP(23900/(8.3144598*N10))/1000 -> 0.0011078669 | M10: =N10^-1 -> 0.00095680046 | N10: 1045.15 | O10: 4.884e-05 | P10: 0.000382 | Q10: =((6.02214076E+23*AM10)/O10)^(-1/3) -> 3.4355657e-10 | R10: =V10+U10 -> 3.19e-10 | S10: =Q10-R10 -> 2.4556565e-11 | T10: =(Q10-R10)/Q10 -> 0.071477503 | U10: 1.38e-10 | V10: 1.81e-10 | W10: =(( (O10/6.02214076E+23)^(1/3)) + (R10)) / 2 -> 3.7592707e-10 | X10: 2.98522 | Y10: =V10/U10 -> 1.3115942 | Z10: =Q10*10000000000 -> 3.4355657 | AA10: =R10*10000000000 -> 3.19 | AB10: 1530000 | AC10: 2514.8257 | AD10: -0.878 | AE10: 2.1359 | AF10: -0.0005831 | AG10: 39.0983 | AH10: 35.45 | AI10: =ABS(AH10-AG10) -> 3.6483 | AJ10: =K10/CH10 -> 4.0097644 | AK10: 1 | AL10: 1 | AM10: =AK10+AL10 -> 2 | AN10: =1+AK10/AL10 -> 2 | AO10: 0.35505 | AP10: 0.36749822 | AQ10: =1/3*BY10*BH10*R10 -> 0.25593315 | AR10: =ABS((AP10-AQ10)/AP10) -> 0.30357989 | AS10: =1/3*BY10*BH10*BA10 -> 0.23977579 | AT10: =1/3*BY10*BH10*BB10 -> 0.2878106 | AU10: 0.25652334 | AV10: =(AP10-AU10)/AP10 -> 0.30197392 | AW10: =AP10/(1/3*BH10*R10) -> 2163868.4 | AX10: =AP10/(1/3*BH10*BC10) -> 1506961.5 | AY10: 8.041484e+08 | AZ10: =AU10/AY10 -> 3.19e-10 | BA10: 2.9886116e-10 | BB10: 3.5873267e-10 | BC10: =AP10/(1/3*BY10*BH10) -> 4.5805685e-10 | BD10: =AP10/AY10 -> 4.5700298e-10 | BE10: =(BD10-AZ10)/AZ10 -> 0.43261122 | BF10: =AU10/BH10 -> 0.00016060976 | BG10: =BH10/1000 -> 1.597184 | BH10: =AC10+AD10*N10 -> 1597.184 | BI10: 2360 | BJ10: =AP10/BF10 -> 2288.1437 | BK10: =(BJ10-BH10)/BH10 -> 0.43261122 | BL10: =AU10/BM10 -> 0.0034853715 | BM10: 73.6 | BN10: =1.380649E-23*(Q10^(-3)) -> 340477.58 | BO10: =BN10*AN10 -> 680955.17 | BP10: =1/3*BX10*10^6 -> 502320.5 | BQ10: =BO10*0.000001 -> 0.68095517 | BR10: =BP10*0.000001 -> 0.5023205 | BS10: =BO10-BP10 -> 178634.67 | BT10: =(BO10-BP10)/BO10 -> 0.26232956 | BU10: =Q10*BO10 -> 0.00023394662 | BV10: =S10*BP10 -> 1.2335266e-05 | BW10: =(BU10-BV10)/BU10 -> 0.94727316 | BX10: =BY10/1000000 -> 1.5069615 | BY10: =BM10/O10 -> 1506961.5 | BZ10: =AP10/(BL10) -> 105.44019 | CA10: =(BZ10-BM10)/BM10 -> 0.43261122 | CB10: =BH10*BP10 -> 8.0229827e+08 | CC10: =CB10*0.000000001 -> 0.80229827 | CD10: =BH10*BO10 -> 1.0876107e+09 | CE10: =CD10*0.000000001 -> 1.0876107 | CF10: =CB10*R10 -> 0.25593315 | CG10: =CD10*Q10 -> 0.3736558 | CH10: 18.592439 | CI10: -0.0036120436 | CJ10: 0.8909863 | CK10: =SQRT(CJ10/CH10) -> 0.21891087 | CL10: =SQRT(1/CH10) -> 0.23191659 | CM10: 2.96e-10 | CN10: =CM10*SQRT(CJ10/CH10) -> 6.4797618e-11 | CO10: =SQRT(ABS(CI10))/CH10 -> 0.0032325119 | CP10: =BH10^(2/3)*O10 -> 0.0066733764 | CQ10: =L10/(AB10/1000*(AC10+AD10*N10)) -> 4.5335792e-10
A11: BeF2 | B11: 0.52 | C11: 1 | D11: 13 | E11: 12 | F11: =D11*1.6726219E-27 -> 2.1744085e-26 | G11: =E11*9.1093856E-31 -> 1.0931263e-29 | H11: =((F11*D11)/(G11*E11)) -> 2154.9287 | I11: =D11/E11 -> 1.0833333 | J11: =(F11)-(G11) -> 2.1733153e-26 | K11: 47.01 | L11: =10^(-8.12+11500/N11+639000/N11^2)/1000 -> 1.5280163 | M11: =N11^-1 -> 0.00093444844 | N11: 1070.15 | O11: 2.4e-05 | P11: 7.42e-06 | Q11: =((6.02214076E+23*AM11)/O11)^(-1/3) -> 2.3683526e-10 | R11: =V11+U11 -> 1.67e-10 | S11: =Q11-R11 -> 6.9835261e-11 | T11: =(Q11-R11)/Q11 -> 0.29486851 | U11: 3.4e-11 | V11: 1.33e-10 | W11: =(( (O11/6.02214076E+23)^(1/3)) + (R11)) / 2 -> 2.5428778e-10 | Y11: =V11/U11 -> 3.9117647 | Z11: =Q11*10000000000 -> 2.3683526 | AA11: =R11*10000000000 -> 1.67 | AB11: 1960000 | AC11: 2547.8 | AD11: 0 | AE11: 1.972 | AF11: -1.45e-05 | AG11: 9.012183 | AH11: 18.998403 | AI11: =ABS(AH11-AG11) -> 9.98622 | AJ11: =K11/CH11 -> 7.6906906 | AK11: 1 | AL11: 2 | AM11: =AK11+AL11 -> 3 | AN11: =1+AK11/AL11 -> 1.5 | AO11: 0.79925906 | AP11: 0.79925906 | AQ11: =1/3*BY11*BH11*R11 -> 0.51944334 | AR11: =ABS((AP11-AQ11)/AP11) -> 0.35009389 | AU11: 0.51979939 | AV11: =(AP11-AU11)/AP11 -> 0.34964842 | AW11: =AP11/(1/3*BH11*R11) -> 5635429.4 | AX11: =AP11/(1/3*BH11*BC11) -> 3662500 | AY11: 3.1125712e+09 | AZ11: =AU11/AY11 -> 1.67e-10 | BC11: =AP11/(1/3*BY11*BH11) -> 2.569602e-10 | BD11: =AP11/AY11 -> 2.5678419e-10 | BE11: =(BD11-AZ11)/AZ11 -> 0.53762986 | BF11: =AU11/BH11 -> 0.00020401891 | BG11: =BH11/1000 -> 2.5478 | BH11: =AC11+AD11*N11 -> 2547.8 | BJ11: =AP11/BF11 -> 3917.5733 | BK11: =(BJ11-BH11)/BH11 -> 0.53762986 | BL11: =AU11/BM11 -> 0.0059135311 | BM11: 87.9 | BN11: =1.380649E-23*(Q11^(-3)) -> 1039307.8 | BO11: =BN11*AN11 -> 1558961.7 | BP11: =1/3*BX11*10^6 -> 1220833.3 | BQ11: =BO11*0.000001 -> 1.5589617 | BR11: =BP11*0.000001 -> 1.2208333 | BS11: =BO11-BP11 -> 338128.41 | BT11: =(BO11-BP11)/BO11 -> 0.21689333 | BU11: =Q11*BO11 -> 0.00036921711 | BV11: =S11*BP11 -> 8.5257214e-05 | BW11: =(BU11-BV11)/BU11 -> 0.7690865 | BX11: =BY11/1000000 -> 3.6625 | BY11: =BM11/O11 -> 3662500 | BZ11: =AP11/(BL11) -> 135.15766 | CA11: =(BZ11-BM11)/BM11 -> 0.53762986 | CB11: =BH11*BP11 -> 3.1104392e+09 | CC11: =CB11*0.000000001 -> 3.1104392 | CD11: =BH11*BO11 -> 3.9719227e+09 | CE11: =CD11*0.000000001 -> 3.9719227 | CF11: =CB11*R11 -> 0.51944334 | CG11: =CD11*Q11 -> 0.94069135 | CH11: 6.112585 | CI11: -4.1051313e-06 | CL11: =SQRT(1/CH11) -> 0.40447114 | CN11: =R11*SQRT(0.9/CH11) -> 6.4080408e-11 | CO11: =SQRT(ABS(CI11))/CH11 -> 0.00033146571 | CP11: =BH11^(2/3)*O11 -> 0.0044770107
